Workbook

Sheet STR
A1: POSISI | B1: NAMA | C1: CIF | D1: No Rek/ Kartu Kredit | E1: RESIKO | F1: BRILINK | G1: STATUS PEKERJA | H1: DIGITAL SAVING | I1: SKENARIO | J1: SCORING | K1: INFO PARAM | L1: KATEGORI | M1: UNIT KERJA | N1: KANTOR CABANG | O1: KANTOR KANWIL | P1: REKOMENDASI UKER | Q1: REKOMENDASI UKK | R1: STATUS UKER | S1: STATUS | T1: DISPOSISI | U1: INFO LAINNYA | V1: Disposisi RAC | W1: Tanggal | X1: Status TL
A2: {=_xlfn._xlws.FILTER('[3]STR-2026-8-2026-8'!$A:$U, ISNUMBER(SEARCH("Semarang", '[3]STR-2026-8-2026-8'!$O:$O)), "")} -> 46265 | B2: ADANG FERRI UTOMO | C2: AAKRU21 | D2: 600401025631539 | E2: SEDANG | F2: Tidak | G2: Tidak | H2: Tidak | I2: Narkotika - Area Lapas | J2: 63 | K2: 48 | L2: Narkotika | M2: UNIT PENGKOL PURWODADI | N2: KC Purwodadi | O2: Semarang | P2: 0 | Q2: 0 | R2: Belum TL | S2: Belum TL | T2: 90186796 - Devito Arya Wiradila | U2: "-" | V2: =IF([1]STR!$V2 = "", "", [1]STR!$V2) -> Syamsul Arifianto | X2: =[1]STR!$X2 -> TRUE | Y2: =_xlfn.XLOOKUP(TRIM(B2), [4]STR!$2:$2,[4]STR!$44:$44, "")
A3: 46265 | B3: BUSRO | C3: BJM9587 | D3: 224001023184506 | E3: 0 | F3: Tidak | G3: Tidak | H3: 0 | I3: Jual Beli Rekening - E channel Trx | J3: 33 | K3: 113 | L3: Narkotika/Judi Online/Penipuan | M3: KCP KALINYAMATAN | N3: KC Jepara | O3: Semarang | P3: 0 | Q3: 0 | R3: Belum TL | S3: Belum TL | T3: 0 | U3: "-" | V3: =IF([1]STR!$V3 = "", "", [1]STR!$V3) -> Veronica Dwi Kurniasih | X3: =[1]STR!$X3 -> TRUE | Y3: =_xlfn.XLOOKUP(TRIM(B3), [4]STR!$2:$2,[4]STR!$44:$44, "")
A4: 46265 | B4: DPC PARTAI GERINDRA KABUPATEN TEGAL | C4: DCMH946 | D4: 66101000899560 | E4: SEDANG | F4: Tidak | G4: Tidak | H4: Tidak | I4: Perpajakan | J4: 48 | K4: 41 | L4: Perpajakan | M4: KC Slawi | N4: KC Slawi | O4: Semarang | P4: 0 | Q4: 0 | R4: Belum TL | S4: Belum TL | T4: 90186790 - Muhammad Alfin Farha | U4: "-" | V4: =IF([1]STR!$V4 = "", "", [1]STR!$V4) -> Veronica Dwi Kurniasih | W4: 46279 | X4: =[1]STR!$X4 -> TRUE | Y4: =_xlfn.XLOOKUP(TRIM(B4), [4]STR!$2:$2,[4]STR!$44:$44, "")
A5: 46265 | B5: FARID AGUS PRIYONO | C5: FLI1424 | D5: 2201003091301 | E5: SEDANG | F5: Tidak | G5: Tidak | H5: Tidak | I5: Perpajakan | J5: 49 | K5: 1.33 | L5: Perpajakan | M5: KC Jepara | N5: KC Jepara | O5: Semarang | P5: 0 | Q5: 0 | R5: Belum TL | S5: Belum TL | T5: 90185537 - Moh.Khoerul Fajar Ar | U5: "-" | V5: =IF([1]STR!$V5 = "", "", [1]STR!$V5) -> Syamsul Arifianto | W5: 46276 | X5: =[1]STR!$X5 -> TRUE | Y5: =_xlfn.XLOOKUP(TRIM(B5), [4]STR!$2:$2,[4]STR!$44:$44, "") -> 2.3700893 | Z5: .
A6: 46265 | B6: GOSHEN ANUGERAH SEJAHTERA | C6: GL45413 | D6: 105801000447561 | E6: SEDANG | F6: Tidak | G6: Tidak | H6: Tidak | I6: Perpajakan | J6: 48 | K6: 41 | L6: Perpajakan | M6: KCP HAMKA | N6: KC Semarang Pandanaran | O6: Semarang | P6: 0 | Q6: 0 | R6: Belum TL | S6: Belum TL | T6: 00394520 - Frida Akbar Rani | U6: "-" | V6: =IF([1]STR!$V6 = "", "", [1]STR!$V6) -> Syamsul Arifianto | W6: 46275 | X6: =[1]STR!$X6 -> TRUE | Y6: =_xlfn.XLOOKUP(TRIM(B6), [4]STR!$2:$2,[4]STR!$44:$44, "")
A7: 46265 | B7: ATNA TUKIMAN | C7: HB96041 | D7: 14201000023565 | E7: SEDANG | F7: Ya | G7: Tidak | H7: Tidak | I7: Perpajakan | J7: 58 | K7: 1.33 | L7: Perpajakan | M7: KC Rembang | N7: KC Rembang | O7: Semarang | P7: 0 | Q7: 0 | R7: Belum TL | S7: Belum TL | T7: 00394521 - Muhammad Hibbanduta | U7: "-" | V7: =IF([1]STR!$V7 = "", "", [1]STR!$V7) -> Syamsul Arifianto | W7: 46274 | X7: =[1]STR!$X7 -> TRUE | Y7: =_xlfn.XLOOKUP(TRIM(B7), [4]STR!$2:$2,[4]STR!$44:$44, "")
A8: 46265 | B8: KOPERASI GAPOKTAN BUDI LUHUR | C8: KANZ210 | D8: 66101001396565 | E8: 0 | F8: Tidak | G8: Tidak | H8: Tidak | I8: Perpajakan | J8: 34 | K8: 41 | L8: Perpajakan | M8: KC Slawi | N8: KC Slawi | O8: Semarang | P8: 0 | Q8: 0 | R8: Belum TL | S8: Belum TL | T8: 00394520 - Frida Akbar Rani | U8: "-" | V8: =IF([1]STR!$V8 = "", "", [1]STR!$V8) -> Veronica Dwi Kurniasih | W8: 46279 | X8: =[1]STR!$X8 -> TRUE | Y8: =_xlfn.XLOOKUP(TRIM(B8), [4]STR!$2:$2,[4]STR!$44:$44, "")
A9: 46265 | B9: NOOR ROZAQ | C9: NHSZ791 | D9: 592201054791537 | E9: SEDANG | F9: Tidak | G9: Tidak | H9: Tidak | I9: Narkotika - Area Lapas | J9: 53 | K9: 46 | L9: Narkotika | M9: UNIT DAWE KUDUS | N9: KC Kudus | O9: Semarang | P9: 0 | Q9: 0 | R9: Belum TL | S9: Belum TL | T9: 90185538 - Muhammad Fahikal Auz | U9: "-" | V9: =IF([1]STR!$V9 = "", "", [1]STR!$V9) -> Veronica Dwi Kurniasih | X9: =[1]STR!$X9 -> TRUE | Y9: =_xlfn.XLOOKUP(TRIM(B9), [4]STR!$2:$2,[4]STR!$44:$44, "")
A10: 46265 | B10: NADIN ARIN NAJWA | C10: NMDE959 | D10: 2201003092307 | E10: 0 | F10: Tidak | G10: Tidak | H10: Tidak | I10: Perpajakan | J10: 35 | K10: 1.33 | L10: Perpajakan | M10: KC Jepara | N10: KC Jepara | O10: Semarang | P10: 0 | Q10: 0 | R10: Belum TL | S10: Belum TL | T10: 90170665 - Mutiara Ayuningtyas | U10: "-" | V10: =IF([1]STR!$V10 = "", "", [1]STR!$V10) -> Syamsul Arifianto | W10: 46276 | X10: =[1]STR!$X10 -> TRUE | Y10: =_xlfn.XLOOKUP(TRIM(B10), [4]STR!$2:$2,[4]STR!$44:$44, "") -> 2.3700893
A11: 46265 | B11: PUSAKA HIDUP | C11: PKS3555 | D11: 8301003905308 | E11: SEDANG | F11: Tidak | G11: Tidak | H11: Tidak | I11: Perpajakan | J11: 50 | K11: 1.33 | L11: Perpajakan | M11: KC Semarang Patimura | N11: KC Semarang Patimura | O11: Semarang | P11: 0 | Q11: 0 | R11: Belum TL | S11: Belum TL | T11: 90171841 - Rifqi Aziz | U11: "-" | V11: =IF([1]STR!$V11 = "", "", [1]STR!$V11) -> Veronica Dwi Kurniasih | X11: =[1]STR!$X11 -> TRUE | Y11: =_xlfn.XLOOKUP(TRIM(B11), [4]STR!$2:$2,[4]STR!$44:$44, "")
A12: 46265 | B12: RESTU RAHMA AULIA | C12: RBPL029 | D12: 592701011976500 | E12: 0 | F12: Tidak | G12: Tidak | H12: 0 | I12: Jual Beli Rekening - E channel Trx | J12: 33 | K12: 113 | L12: Narkotika/Judi Online/Penipuan | M12: UNIT NGETUK KUDUS | N12: KC Kudus | O12: Semarang | P12: 0 | Q12: 0 | R12: Belum TL | S12: Belum TL | T12: 0 | U12: "-" | V12: =IF([1]STR!$V12 = "", "", [1]STR!$V12) -> Veronica Dwi Kurniasih | X12: =[1]STR!$X12 -> TRUE | Y12: =_xlfn.XLOOKUP(TRIM(B12), [4]STR!$2:$2,[4]STR!$44:$44, "")
A13: 46265 | B13: SRI ROHATI | C13: SACMD03 | D13: 379201013099509 | E13: 0 | F13: Tidak | G13: Tidak | H13: 0 | I13: Jual Beli Rekening - E channel Trx | J13: 33 | K13: 113 | L13: Narkotika/Judi Online/Penipuan | M13: UNIT MULYOHARJO PEMALANG | N13: KC Pemalang | O13: Semarang | P13: 0 | Q13: 0 | R13: Belum TL | S13: Belum TL | T13: 0 | U13: "-" | V13: =IF([1]STR!$V13 = "", "", [1]STR!$V13) -> Veronica Dwi Kurniasih | X13: =[1]STR!$X13 -> TRUE | Y13: =_xlfn.XLOOKUP(TRIM(B13), [4]STR!$2:$2,[4]STR!$44:$44, "")
A14: 46265 | B14: UD INNAYA | C14: UJ25185 | D14: 66101001049304 | E14: SEDANG | F14: Tidak | G14: Tidak | H14: Tidak | I14: Perpajakan | J14: 48 | K14: 41 | L14: Perpajakan | M14: KC Slawi | N14: KC Slawi | O14: Semarang | P14: 0 | Q14: 0 | R14: Belum TL | S14: Belum TL | T14: 90171841 - Rifqi Aziz | U14: "-" | V14: =IF([1]STR!$V14 = "", "", [1]STR!$V14) -> Veronica Dwi Kurniasih | W14: 46279 | X14: =[1]STR!$X14 -> TRUE | Y14: =_xlfn.XLOOKUP(TRIM(B14), [4]STR!$2:$2,[4]STR!$44:$44, "")
A15: 46265 | B15: YAYASAN SYUBANUL WATHAN NUSANTARA | C15: YQV3280 | D15: 66101001344568 | E15: 0 | F15: Tidak | G15: Tidak | H15: Tidak | I15: Perpajakan | J15: 33 | K15: 41 | L15: Perpajakan | M15: KC Slawi | N15: KC Slawi | O15: Semarang | P15: 0 | Q15: 0 | R15: Belum TL | S15: Belum TL | T15: 00394520 - Frida Akbar Rani | U15: "-" | V15: =IF([1]STR!$V15 = "", "", [1]STR!$V15) -> Veronica Dwi Kurniasih | W15: 46279 | X15: =[1]STR!$X15 -> TRUE | Y15: =_xlfn.XLOOKUP(TRIM(B15), [4]STR!$2:$2,[4]STR!$44:$44, "")
A16: 46265 | B16: YANTI | C16: YX10337 | D16: 379201013101500 | E16: 0 | F16: Tidak | G16: Tidak | H16: 0 | I16: Jual Beli Rekening - E channel Trx | J16: 33 | K16: 113 | L16: Narkotika/Judi Online/Penipuan | M16: UNIT MULYOHARJO PEMALANG | N16: KC Pemalang | O16: Semarang | P16: 0 | Q16: 0 | R16: Belum TL | S16: Belum TL | T16: 0 | U16: "-" | V16: =IF([1]STR!$V16 = "", "", [1]STR!$V16) -> Syamsul Arifianto | X16: =[1]STR!$X16 -> TRUE | Y16: =_xlfn.XLOOKUP(TRIM(B16), [4]STR!$2:$2,[4]STR!$44:$44, "")
A17: 46265 | B17: CV MULTI PESONA MALANG | C17: CS90357 | D17: 8101010806563 | E17: SEDANG | F17: Tidak | G17: Tidak | H17: Tidak | I17: Perpajakan | J17: 53 | K17: 41 | L17: Perpajakan | M17: KC Salatiga | N17: KC Salatiga | O17: Semarang | P17: Tidak | Q17: 0 | R17: Done | S17: Belum TL | T17: 00394521 - Muhammad Hibbanduta | U17: "-" | V17: =IF([1]STR!$V17 = "", "", [1]STR!$V17) -> Veronica Dwi Kurniasih | W17: 46274 | X17: =[1]STR!$X17 -> TRUE | Y17: =_xlfn.XLOOKUP(TRIM(B17), [4]STR!$2:$2,[4]STR!$44:$44, "")
A18: 46265 | B18: CV JAYA ELANG SALATIGA | C18: CZ10112 | D18: 8101010118562 | E18: 0 | F18: Tidak | G18: Tidak | H18: Tidak | I18: Perpajakan | J18: 33 | K18: 41 | L18: Perpajakan | M18: KC Salatiga | N18: KC Salatiga | O18: Semarang | P18: Tidak | Q18: 0 | R18: Done | S18: Belum TL | T18: 00394521 - Muhammad Hibbanduta | U18: "-" | V18: =IF([1]STR!$V18 = "", "", [1]STR!$V18) -> Syamsul Arifianto | W18: 09-09-2026 | X18: =[1]STR!$X18 -> TRUE | Y18: =_xlfn.XLOOKUP(TRIM(B18), [4]STR!$2:$2,[4]STR!$44:$44, "")
A19: 46265 | B19: CV JAYA ELANG PEKALONGAN | C19: CZ10126 | D19: 8101011505568 | E19: 0 | F19: Tidak | G19: Tidak | H19: Tidak | I19: Perpajakan | J19: 36 | K19: 41 | L19: Perpajakan | M19: KC Salatiga | N19: KC Salatiga | O19: Semarang | P19: Tidak | Q19: 0 | R19: Done | S19: Belum TL | T19: 90170665 - Mutiara Ayuningtyas | U19: "-" | V19: =IF([1]STR!$V19 = "", "", [1]STR!$V19) -> Syamsul Arifianto | W19: 46274 | X19: =[1]STR!$X19 -> TRUE | Y19: =_xlfn.XLOOKUP(TRIM(B19), [4]STR!$2:$2,[4]STR!$44:$44, "")
A20: 46265 | B20: CV GELORA ABADI PEKALONGAN | C20: CZ10142 | D20: 8101011506564 | E20: 0 | F20: Tidak | G20: Tidak | H20: Tidak | I20: Perpajakan | J20: 33 | K20: 41 | L20: Perpajakan | M20: KC Salatiga | N20: KC Salatiga | O20: Semarang | P20: Tidak | Q20: 0 | R20: Done | S20: Belum TL | T20: 90171841 - Rifqi Aziz | U20: "-" | V20: =IF([1]STR!$V20 = "", "", [1]STR!$V20) -> Veronica Dwi Kurniasih | W20: 09-09-2026 | X20: =[1]STR!$X20 -> TRUE | Y20: =_xlfn.XLOOKUP(TRIM(B20), [4]STR!$2:$2,[4]STR!$44:$44, "")
A21: 46265 | B21: CV GELORA BINTANG PEKALONGAN | C21: CZ10193 | D21: 8101011507560 | E21: 0 | F21: Tidak | G21: Tidak | H21: Tidak | I21: Perpajakan | J21: 33 | K21: 41 | L21: Perpajakan | M21: KC Salatiga | N21: KC Salatiga | O21: Semarang | P21: Tidak | Q21: 0 | R21: Done | S21: Belum TL | T21: 90150130 - Intan Aida Pratiwi | U21: "-" | V21: =IF([1]STR!$V21 = "", "", [1]STR!$V21) -> Veronica Dwi Kurniasih | W21: 46274 | X21: =[1]STR!$X21 -> TRUE | Y21: =_xlfn.XLOOKUP(TRIM(B21), [4]STR!$2:$2,[4]STR!$44:$44, "")
A22: 46265 | B22: CV GELORA CAHAYA PEKALONGAN | C22: CZ10208 | D22: 8101011508566 | E22: 0 | F22: Tidak | G22: Tidak | H22: Tidak | I22: Perpajakan | J22: 33 | K22: 41 | L22: Perpajakan | M22: KC Salatiga | N22: KC Salatiga | O22: Semarang | P22: Tidak | Q22: 0 | R22: Done | S22: Belum TL | T22: 90170665 - Mutiara Ayuningtyas | U22: "-" | V22: =IF([1]STR!$V22 = "", "", [1]STR!$V22) -> Veronica Dwi Kurniasih | W22: 46274 | X22: =[1]STR!$X22 -> TRUE | Y22: =_xlfn.XLOOKUP(TRIM(B22), [4]STR!$2:$2,[4]STR!$44:$44, "")
A23: 46265 | B23: CV KENCANA CAKRA PEKALONGAN | C23: CZ10215 | D23: 8101011509562 | E23: 0 | F23: Tidak | G23: Tidak | H23: Tidak | I23: Perpajakan | J23: 33 | K23: 41 | L23: Perpajakan | M23: KC Salatiga | N23: KC Salatiga | O23: Semarang | P23: Tidak | Q23: 0 | R23: Done | S23: Belum TL | T23: 90171841 - Rifqi Aziz | U23: "-" | V23: =IF([1]STR!$V23 = "", "", [1]STR!$V23) -> Syamsul Arifianto | W23: 09-09-2026 | X23: =[1]STR!$X23 -> TRUE | Y23: =_xlfn.XLOOKUP(TRIM(B23), [4]STR!$2:$2,[4]STR!$44:$44, "")
A24: 46265 | B24: CV AGUNG SEJAHTERA CIANJUR | C24: CW99462 | D24: 8101011302562 | E24: 0 | F24: Tidak | G24: Tidak | H24: Tidak | I24: Perpajakan | J24: 33 | K24: 41 | L24: Perpajakan | M24: KC Salatiga | N24: KC Salatiga | O24: Semarang | P24: Tidak | Q24: 0 | R24: Done | S24: Belum TL | T24: 90185538 - Muhammad Fahikal Auz | U24: "-" | V24: =IF([1]STR!$V24 = "", "", [1]STR!$V24) -> Veronica Dwi Kurniasih | W24: 46274 | X24: =[1]STR!$X24 -> TRUE | Y24: =_xlfn.XLOOKUP(TRIM(B24), [4]STR!$2:$2,[4]STR!$44:$44, "")
A25: 46265 | B25: GONDOSARI HARTA NUSANTARA | C25: GN06499 | D25: 3801002924566 | E25: TINGGI | F25: Tidak | G25: Tidak | H25: Tidak | I25: Perpajakan | J25: 63 | K25: 41 | L25: Perpajakan | M25: KC Kudus | N25: KC Kudus | O25: Semarang | P25: Tidak | Q25: 0 | R25: Done | S25: Belum TL | T25: 90170665 - Mutiara Ayuningtyas | U25: "-" | V25: =IF([1]STR!$V25 = "", "", [1]STR!$V25) -> Veronica Dwi Kurniasih | W25: 46274 | X25: =[1]STR!$X25 -> TRUE | Y25: =_xlfn.XLOOKUP(TRIM(B25), [4]STR!$2:$2,[4]STR!$44:$44, "")
A26: 46265 | B26: MUARA TALENTA MERR | C26: MCTBT47 | D26: 8101011207568 | E26: 0 | F26: Tidak | G26: Tidak | H26: Tidak | I26: Perpajakan | J26: 38 | K26: 41 | L26: Perpajakan | M26: KC Salatiga | N26: KC Salatiga | O26: Semarang | P26: Tidak | Q26: 0 | R26: Done | S26: Belum TL | T26: 00394521 - Muhammad Hibbanduta | U26: "-" | V26: =IF([1]STR!$V26 = "", "", [1]STR!$V26) -> Veronica Dwi Kurniasih | W26: 46274 | X26: =[1]STR!$X26 -> TRUE | Y26: =_xlfn.XLOOKUP(TRIM(B26), [4]STR!$2:$2,[4]STR!$44:$44, "")
A27: 46265 | B27: MULIA ABADI SEMARANG | C27: MCTBV50 | D27: 8101010208561 | E27: 0 | F27: Tidak | G27: Tidak | H27: Tidak | I27: Perpajakan | J27: 38 | K27: 41 | L27: Perpajakan | M27: KC Salatiga | N27: KC Salatiga | O27: Semarang | P27: Tidak | Q27: Tidak | R27: Done | S27: Pending Checker | T27: 90185538 - Muhammad Fahikal Auz | U27: "-" | V27: =IF([1]STR!$V27 = "", "", [1]STR!$V27) -> Veronica Dwi Kurniasih | W27: 46271 | X27: =[1]STR!$X27 -> TRUE | Y27: =_xlfn.XLOOKUP(TRIM(B27), [4]STR!$2:$2,[4]STR!$44:$44, "")
A28: 46265 | B28: MULTI PESONA SURABAYA | C28: MCTBV76 | D28: 8101010506561 | E28: 0 | F28: Tidak | G28: Tidak | H28: Tidak | I28: Perpajakan | J28: 34 | K28: 41 | L28: Perpajakan | M28: KC Salatiga | N28: KC Salatiga | O28: Semarang | P28: Tidak | Q28: Tidak | R28: Done | S28: Pending Checker | T28: 90186790 - Muhammad Alfin Farha | U28: "-" | V28: =IF([1]STR!$V28 = "", "", [1]STR!$V28) -> Veronica Dwi Kurniasih | W28: 46271 | X28: =[1]STR!$X28 -> TRUE | Y28: =_xlfn.XLOOKUP(TRIM(B28), [4]STR!$2:$2,[4]STR!$44:$44, "")
A29: 46265 | B29: MULTI PESONA SIDOARJO | C29: MCTCQ09 | D29: 8101010608567 | E29: 0 | F29: Tidak | G29: Tidak | H29: Tidak | I29: Perpajakan | J29: 38 | K29: 41 | L29: Perpajakan | M29: KC Salatiga | N29: KC Salatiga | O29: Semarang | P29: Tidak | Q29: Tidak | R29: Done | S29: Pending Checker | T29: 90150130 - Intan Aida Pratiwi | U29: "-" | V29: =IF([1]STR!$V29 = "", "", [1]STR!$V29) -> Veronica Dwi Kurniasih | W29: 46271 | X29: =[1]STR!$X29 -> TRUE | Y29: =_xlfn.XLOOKUP(TRIM(B29), [4]STR!$2:$2,[4]STR!$44:$44, "")
A30: 46265 | B30: MULIA ABADI SALATIGA | C30: MCTCU74 | D30: 8101010108567 | E30: 0 | F30: Tidak | G30: Tidak | H30: Tidak | I30: Perpajakan | J30: 38 | K30: 41 | L30: Perpajakan | M30: KC Salatiga | N30: KC Salatiga | O30: Semarang | P30: Tidak | Q30: Tidak | R30: Done | S30: Pending Checker | T30: 90150130 - Intan Aida Pratiwi | U30: "-" | V30: =IF([1]STR!$V30 = "", "", [1]STR!$V30) -> Veronica Dwi Kurniasih | W30: 46269 | X30: =[1]STR!$X30 -> TRUE | Y30: =_xlfn.XLOOKUP(TRIM(B30), [4]STR!$2:$2,[4]STR!$44:$44, "")
A31: 46265 | B31: MULIA ABADI SIDOARJO | C31: MCTCU84 | D31: 8101010607561 | E31: 0 | F31: Tidak | G31: Tidak | H31: Tidak | I31: Perpajakan | J31: 36 | K31: 41 | L31: Perpajakan | M31: KC Salatiga | N31: KC Salatiga | O31: Semarang | P31: Tidak | Q31: Tidak | R31: Done | S31: Pending Checker | T31: 90170665 - Mutiara Ayuningtyas | U31: "-" | V31: =IF([1]STR!$V31 = "", "", [1]STR!$V31) -> Veronica Dwi Kurniasih | W31: 46271 | X31: =[1]STR!$X31 -> TRUE | Y31: =_xlfn.XLOOKUP(TRIM(B31), [4]STR!$2:$2,[4]STR!$44:$44, "")
A32: 46265 | B32: MULTI PESONA KUDUS | C32: MCTCU98 | D32: 8101010707565 | E32: 0 | F32: Tidak | G32: Tidak | H32: Tidak | I32: Perpajakan | J32: 38 | K32: 41 | L32: Perpajakan | M32: KC Salatiga | N32: KC Salatiga | O32: Semarang | P32: Tidak | Q32: Tidak | R32: Done | S32: Pending Checker | T32: 90171841 - Rifqi Aziz | U32: "-" | V32: =IF([1]STR!$V32 = "", "", [1]STR!$V32) -> Veronica Dwi Kurniasih | W32: 46271 | X32: =[1]STR!$X32 -> TRUE | Y32: =_xlfn.XLOOKUP(TRIM(B32), [4]STR!$2:$2,[4]STR!$44:$44, "")
A33: 46265 | B33: MULTI PESONA MOJOKERTO | C33: MCTDD93 | D33: 8101011106568 | E33: 0 | F33: Tidak | G33: Tidak | H33: Tidak | I33: Perpajakan | J33: 38 | K33: 41 | L33: Perpajakan | M33: KC Salatiga | N33: KC Salatiga | O33: Semarang | P33: Tidak | Q33: Tidak | R33: Done | S33: Pending Checker | T33: 90186796 - Devito Arya Wiradila | U33: "-" | V33: =IF([1]STR!$V33 = "", "", [1]STR!$V33) -> Veronica Dwi Kurniasih | W33: 46272 | X33: =[1]STR!$X33 -> TRUE | Y33: =_xlfn.XLOOKUP(TRIM(B33), [4]STR!$2:$2,[4]STR!$44:$44, "")
A34: 46265 | B34: MULIA ABADI MALANG | C34: MCTDU21 | D34: 8101010809561 | E34: 0 | F34: Tidak | G34: Tidak | H34: Tidak | I34: Perpajakan | J34: 38 | K34: 41 | L34: Perpajakan | M34: KC Salatiga | N34: KC Salatiga | O34: Semarang | P34: Tidak | Q34: Tidak | R34: Done | S34: Pending Checker | T34: 00336949 - Mochammad Al Farabi | U34: "-" | V34: =IF([1]STR!$V34 = "", "", [1]STR!$V34) -> Veronica Dwi Kurniasih | W34: 46272 | X34: =[1]STR!$X34 -> TRUE | Y34: =_xlfn.XLOOKUP(TRIM(B34), [4]STR!$2:$2,[4]STR!$44:$44, "")
A35: 46265 | B35: MULTI PESONA MERR | C35: MCSNR34 | D35: 8101011201562 | E35: 0 | F35: Tidak | G35: Tidak | H35: Tidak | I35: Perpajakan | J35: 38 | K35: 41 | L35: Perpajakan | M35: KC Salatiga | N35: KC Salatiga | O35: Semarang | P35: Tidak | Q35: Tidak | R35: Done | S35: Pending Checker | T35: 90150130 - Intan Aida Pratiwi | U35: "-" | V35: =IF([1]STR!$V35 = "", "", [1]STR!$V35) -> Veronica Dwi Kurniasih | W35: 46272 | X35: =[1]STR!$X35 -> TRUE | Y35: =_xlfn.XLOOKUP(TRIM(B35), [4]STR!$2:$2,[4]STR!$44:$44, "")
A36: 46265 | B36: PT ALBISINDO SEHAT BAROKAH | C36: PMW3707 | D36: 3801003288303 | E36: SEDANG | F36: Tidak | G36: Tidak | H36: Tidak | I36: Perpajakan | J36: 48 | K36: 41 | L36: Perpajakan | M36: KC Kudus | N36: KC Kudus | O36: Semarang | P36: Tidak | Q36: Tidak | R36: Done | S36: Pending Checker | T36: 00394520 - Frida Akbar Rani | U36: "-" | V36: =IF([1]STR!$V36 = "", "", [1]STR!$V36) -> Veronica Dwi Kurniasih | W36: 46266 | X36: =[1]STR!$X36 -> TRUE | Y36: =_xlfn.XLOOKUP(TRIM(B36), [4]STR!$2:$2,[4]STR!$44:$44, "")
A37: 46265 | B37: PUNCAK JAYA SAMUDRA | C37: PCJ0611 | D37: 6902000006303 | E37: SEDANG | F37: Tidak | G37: Tidak | H37: Tidak | I37: TPPO - Perusahaan PJTKI | J37: 48 | K37: 102 | L37: TPPO | M37: KC Pemalang | N37: KC Pemalang | O37: Semarang | P37: Tidak | Q37: Tidak | R37: Done | S37: Pending Checker | T37: 90186796 - Devito Arya Wiradila | U37: "-" | V37: =IF([1]STR!$V37 = "", "", [1]STR!$V37) -> Syamsul Arifianto | W37: 46255 | X37: =[1]STR!$X37 -> TRUE | Y37: =_xlfn.XLOOKUP(TRIM(B37), [4]STR!$2:$2,[4]STR!$44:$44, "")
A38: 46265 | B38: SANTIKA DIVA SEMARANG | C38: SJFHZ83 | D38: 8101010210568 | E38: 0 | F38: Tidak | G38: Tidak | H38: Tidak | I38: Perpajakan | J38: 34 | K38: 41 | L38: Perpajakan | M38: KC Salatiga | N38: KC Salatiga | O38: Semarang | P38: Tidak | Q38: Tidak | R38: Done | S38: Pending Checker | T38: 90186790 - Muhammad Alfin Farha | U38: "-" | V38: =IF([1]STR!$V38 = "", "", [1]STR!$V38) -> Veronica Dwi Kurniasih | W38: 46271 | X38: =[1]STR!$X38 -> TRUE | Y38: =_xlfn.XLOOKUP(TRIM(B38), [4]STR!$2:$2,[4]STR!$44:$44, "")
A39: 46265 | B39: SANTIKA DIVA SIDOARJO | C39: SJFIN30 | D39: 8101010606565 | E39: 0 | F39: Tidak | G39: Tidak | H39: Tidak | I39: Perpajakan | J39: 38 | K39: 41 | L39: Perpajakan | M39: KC Salatiga | N39: KC Salatiga | O39: Semarang | P39: Tidak | Q39: Tidak | R39: Done | S39: Pending Checker | T39: 90170665 - Mutiara Ayuningtyas | U39: "-" | V39: =IF([1]STR!$V39 = "", "", [1]STR!$V39) -> Veronica Dwi Kurniasih | W39: 46271 | X39: =[1]STR!$X39 -> TRUE | Y39: =_xlfn.XLOOKUP(TRIM(B39), [4]STR!$2:$2,[4]STR!$44:$44, "")
A40: 46265 | B40: SANTIKA DIVA MALANG | C40: SJFJF77 | D40: 8101010810562 | E40: 0 | F40: Tidak | G40: Tidak | H40: Tidak | I40: Perpajakan | J40: 34 | K40: 41 | L40: Perpajakan | M40: KC Salatiga | N40: KC Salatiga | O40: Semarang | P40: Tidak | Q40: Tidak | R40: Done | S40: Pending Checker | T40: 90186796 - Devito Arya Wiradila | U40: "-" | V40: =IF([1]STR!$V40 = "", "", [1]STR!$V40) -> Veronica Dwi Kurniasih | W40: 46272 | X40: =[1]STR!$X40 -> TRUE | Y40: =_xlfn.XLOOKUP(TRIM(B40), [4]STR!$2:$2,[4]STR!$44:$44, "")
...

Sheet EDD PEP PPATK
D1: 46280
A2: No. | B2: Unit Kerja | C2: PIC RAC | D2: %TL PEP Done | E2: Average
A3: 1 | B3: KC Batang | C3: Syamsul Arifianto | D3: =_xlfn.XLOOKUP(B3, [2]PEP!$B:$B,[2]PEP!$G:$G) -> 1 | E3: =AVERAGE(D3:D13) -> 0.97928746
A4: 2 | B4: KC Blora | C4: Syamsul Arifianto | D4: =_xlfn.XLOOKUP(B4, [2]PEP!$B:$B,[2]PEP!$G:$G) -> 0.97368421
A5: 3 | B5: KC Cepu | C5: Syamsul Arifianto | D5: =_xlfn.XLOOKUP(B5, [2]PEP!$B:$B,[2]PEP!$G:$G) -> 1
A6: 4 | B6: KC Kendal | C6: Syamsul Arifianto | D6: =_xlfn.XLOOKUP(B6, [2]PEP!$B:$B,[2]PEP!$G:$G) -> 1
A7: 5 | B7: KC Pati | C7: Syamsul Arifianto | D7: =_xlfn.XLOOKUP(B7, [2]PEP!$B:$B,[2]PEP!$G:$G) -> 0.95454545
A8: 6 | B8: KC Pekalongan | C8: Syamsul Arifianto | D8: =_xlfn.XLOOKUP(B8, [2]PEP!$B:$B,[2]PEP!$G:$G) -> 0.96774194
A9: 7 | B9: KC Pemalang | C9: Syamsul Arifianto | D9: =_xlfn.XLOOKUP(B9, [2]PEP!$B:$B,[2]PEP!$G:$G) -> 1
A10: 8 | B10: KC Rembang | C10: Syamsul Arifianto | D10: =_xlfn.XLOOKUP(B10, [2]PEP!$B:$B,[2]PEP!$G:$G) -> 1
A11: 9 | B11: KC Salatiga | C11: Syamsul Arifianto | D11: =_xlfn.XLOOKUP(B11, [2]PEP!$B:$B,[2]PEP!$G:$G) -> 0.93333333
A12: 10 | B12: KC Brigjen Sudiarto | C12: Syamsul Arifianto | D12: =_xlfn.XLOOKUP(B12, [2]PEP!$B:$B,[2]PEP!$G:$G) -> 1
A13: 11 | B13: KC Semarang Patimura | C13: Syamsul Arifianto | D13: =_xlfn.XLOOKUP(B13, [2]PEP!$B:$B,[2]PEP!$G:$G) -> 0.94285714
A14: 12 | B14: KC Brebes | C14: Veronica Dwi Kurniasih | D14: =_xlfn.XLOOKUP(B14, [2]PEP!$B:$B,[2]PEP!$G:$G) -> 1 | E14: =AVERAGE(D14:D24) -> 0.98749337
A15: 13 | B15: KC Bumiayu | C15: Veronica Dwi Kurniasih | D15: =_xlfn.XLOOKUP(B15, [2]PEP!$B:$B,[2]PEP!$G:$G) -> 1
A16: 14 | B16: KC Demak | C16: Veronica Dwi Kurniasih | D16: =_xlfn.XLOOKUP(B16, [2]PEP!$B:$B,[2]PEP!$G:$G) -> 0.96666667
A17: 15 | B17: KC Jepara | C17: Veronica Dwi Kurniasih | D17: =_xlfn.XLOOKUP(B17, [2]PEP!$B:$B,[2]PEP!$G:$G) -> 0.96666667
A18: 16 | B18: KC Kudus | C18: Veronica Dwi Kurniasih | D18: =_xlfn.XLOOKUP(B18, [2]PEP!$B:$B,[2]PEP!$G:$G) -> 0.95454545
A19: 17 | B19: KC Purwodadi | C19: Veronica Dwi Kurniasih | D19: =_xlfn.XLOOKUP(B19, [2]PEP!$B:$B,[2]PEP!$G:$G) -> 1
A20: 18 | B20: KC Semarang A. Yani | C20: Veronica Dwi Kurniasih | D20: =_xlfn.XLOOKUP(B20, [2]PEP!$B:$B,[2]PEP!$G:$G) -> 0.98947368
A21: 19 | B21: KC Semarang Pandanaran | C21: Veronica Dwi Kurniasih | D21: =_xlfn.XLOOKUP(B21, [2]PEP!$B:$B,[2]PEP!$G:$G) -> 0.98507463
A22: 20 | B22: KC Slawi | C22: Veronica Dwi Kurniasih | D22: =_xlfn.XLOOKUP(B22, [2]PEP!$B:$B,[2]PEP!$G:$G) -> 1
A23: 21 | B23: KC Tegal | C23: Veronica Dwi Kurniasih | D23: =_xlfn.XLOOKUP(B23, [2]PEP!$B:$B,[2]PEP!$G:$G) -> 1
A24: 22 | B24: KC Ungaran | C24: Veronica Dwi Kurniasih | D24: =_xlfn.XLOOKUP(B24, [2]PEP!$B:$B,[2]PEP!$G:$G) -> 1

Sheet Pengkinian Data
D1: 46280
A2: No. | B2: Unit Kerja | C2: PIC RAC | D2: %Pengkinian Data | E2: Average
A3: 1 | B3: KC Batang | C3: Syamsul Arifianto | D3: 1 | E3: =AVERAGE(D3:D13) -> 1
A4: 2 | B4: KC Blora | C4: Syamsul Arifianto | D4: 1
A5: 3 | B5: KC Brebes | C5: Veronica Dwi Kurniasih | D5: 1
A6: 4 | B6: KC Bumiayu | C6: Veronica Dwi Kurniasih | D6: 1
A7: 5 | B7: KC Cepu | C7: Syamsul Arifianto | D7: 1
A8: 6 | B8: KC Demak | C8: Veronica Dwi Kurniasih | D8: 1
A9: 7 | B9: KC Jepara | C9: Veronica Dwi Kurniasih | D9: 1
A10: 8 | B10: KC Kendal | C10: Syamsul Arifianto | D10: 1
A11: 9 | B11: KC Kudus | C11: Veronica Dwi Kurniasih | D11: 1
A12: 10 | B12: KC Pati | C12: Syamsul Arifianto | D12: 1
A13: 11 | B13: KC Pekalongan | C13: Syamsul Arifianto | D13: 1
A14: 12 | B14: KC Pemalang | C14: Syamsul Arifianto | D14: 1 | E14: =AVERAGE(D14:D24) -> 1
A15: 13 | B15: KC Purwodadi | C15: Veronica Dwi Kurniasih | D15: 1
A16: 14 | B16: KC Rembang | C16: Syamsul Arifianto | D16: 1
A17: 15 | B17: KC Salatiga | C17: Syamsul Arifianto | D17: 1
A18: 16 | B18: KC Semarang Ahmad Yani | C18: Veronica Dwi Kurniasih | D18: 1
A19: 17 | B19: KC Semarang Brigjen Sudiarto | C19: Syamsul Arifianto | D19: 1
A20: 18 | B20: KC Semarang Pandanaran | C20: Veronica Dwi Kurniasih | D20: 1
A21: 19 | B21: KC Semarang Patimura | C21: Syamsul Arifianto | D21: 1
A22: 20 | B22: KC Slawi | C22: Veronica Dwi Kurniasih | D22: 1
A23: 21 | B23: KC Tegal | C23: Veronica Dwi Kurniasih | D23: 1
A24: 22 | B24: KC Ungaran | C24: Veronica Dwi Kurniasih | D24: 1

Sheet Bad Data
D1: 46280
A2: No. | B2: Unit Kerja | C2: PIC RAC | D2: %Bad Data | E2: Average
A3: 1 | B3: KC Batang | C3: Syamsul Arifianto | D3: =_xlfn.XLOOKUP(B3, '[2]Bad Data'!$B:$B, '[2]Bad Data'!$D:$D) -> 0.00342 | E3: =AVERAGE(D3:D13) -> 0.00099090909
A4: 2 | B4: KC Blora | C4: Syamsul Arifianto | D4: =_xlfn.XLOOKUP(B4, '[2]Bad Data'!$B:$B, '[2]Bad Data'!$D:$D) -> 0.00029
A5: 3 | B5: KC Cepu | C5: Syamsul Arifianto | D5: =_xlfn.XLOOKUP(B5, '[2]Bad Data'!$B:$B, '[2]Bad Data'!$D:$D) -> 0.00024
A6: 4 | B6: KC Kendal | C6: Syamsul Arifianto | D6: =_xlfn.XLOOKUP(B6, '[2]Bad Data'!$B:$B, '[2]Bad Data'!$D:$D) -> 0.00107
A7: 5 | B7: KC Pati | C7: Syamsul Arifianto | D7: =_xlfn.XLOOKUP(B7, '[2]Bad Data'!$B:$B, '[2]Bad Data'!$D:$D) -> 0.00137
A8: 6 | B8: KC Pekalongan | C8: Syamsul Arifianto | D8: =_xlfn.XLOOKUP(B8, '[2]Bad Data'!$B:$B, '[2]Bad Data'!$D:$D) -> 0.0017
A9: 7 | B9: KC Pemalang | C9: Syamsul Arifianto | D9: =_xlfn.XLOOKUP(B9, '[2]Bad Data'!$B:$B, '[2]Bad Data'!$D:$D) -> 0.00114
A10: 8 | B10: KC Rembang | C10: Syamsul Arifianto | D10: =_xlfn.XLOOKUP(B10, '[2]Bad Data'!$B:$B, '[2]Bad Data'!$D:$D) -> 0.00062
A11: 9 | B11: KC Salatiga | C11: Syamsul Arifianto | D11: =_xlfn.XLOOKUP(B11, '[2]Bad Data'!$B:$B, '[2]Bad Data'!$D:$D) -> 0.00067
A12: 10 | B12: KC Brigjen Sudiarto | C12: Syamsul Arifianto | D12: =_xlfn.XLOOKUP(B12, '[2]Bad Data'!$B:$B, '[2]Bad Data'!$D:$D) -> 0.00035
A13: 11 | B13: KC Semarang Patimura | C13: Syamsul Arifianto | D13: =_xlfn.XLOOKUP(B13, '[2]Bad Data'!$B:$B, '[2]Bad Data'!$D:$D) -> 3e-05
A14: 12 | B14: KC Brebes | C14: Veronica Dwi Kurniasih | D14: =_xlfn.XLOOKUP(B14, '[2]Bad Data'!$B:$B, '[2]Bad Data'!$D:$D) -> 0.00076 | E14: =AVERAGE(D14:D24) -> 0.00079727273
A15: 13 | B15: KC Bumiayu | C15: Veronica Dwi Kurniasih | D15: =_xlfn.XLOOKUP(B15, '[2]Bad Data'!$B:$B, '[2]Bad Data'!$D:$D) -> 0.00184
A16: 14 | B16: KC Demak | C16: Veronica Dwi Kurniasih | D16: =_xlfn.XLOOKUP(B16, '[2]Bad Data'!$B:$B, '[2]Bad Data'!$D:$D) -> 0.00072
A17: 15 | B17: KC Jepara | C17: Veronica Dwi Kurniasih | D17: =_xlfn.XLOOKUP(B17, '[2]Bad Data'!$B:$B, '[2]Bad Data'!$D:$D) -> 0.00082
A18: 16 | B18: KC Kudus | C18: Veronica Dwi Kurniasih | D18: =_xlfn.XLOOKUP(B18, '[2]Bad Data'!$B:$B, '[2]Bad Data'!$D:$D) -> 0.00019
A19: 17 | B19: KC Purwodadi | C19: Veronica Dwi Kurniasih | D19: =_xlfn.XLOOKUP(B19, '[2]Bad Data'!$B:$B, '[2]Bad Data'!$D:$D) -> 0.001
A20: 18 | B20: KC Semarang A. Yani | C20: Veronica Dwi Kurniasih | D20: =_xlfn.XLOOKUP(B20, '[2]Bad Data'!$B:$B, '[2]Bad Data'!$D:$D) -> 0.00087
A21: 19 | B21: KC Semarang Pandanaran | C21: Veronica Dwi Kurniasih | D21: =_xlfn.XLOOKUP(B21, '[2]Bad Data'!$B:$B, '[2]Bad Data'!$D:$D) -> 0.0003
A22: 20 | B22: KC Slawi | C22: Veronica Dwi Kurniasih | D22: =_xlfn.XLOOKUP(B22, '[2]Bad Data'!$B:$B, '[2]Bad Data'!$D:$D) -> 0.00069
A23: 21 | B23: KC Tegal | C23: Veronica Dwi Kurniasih | D23: =_xlfn.XLOOKUP(B23, '[2]Bad Data'!$B:$B, '[2]Bad Data'!$D:$D) -> 0.00072
A24: 22 | B24: KC Ungaran | C24: Veronica Dwi Kurniasih | D24: =_xlfn.XLOOKUP(B24, '[2]Bad Data'!$B:$B, '[2]Bad Data'!$D:$D) -> 0.00086

Sheet Sosialisasi
A1: No. | B1: Unit Kerja | C1: PIC RAC | D1: Materi* | E1: Tanggal Rencana Pelaksanaan | F1: Tanggal Pelaksanaan* | G1: Jumlah Peserta* | H1: Jabatan Peserta* | I1: Dokumen Evidence**
A2: 1 | B2: KC Balige
A3: 2 | B3: KC Binjai
A4: 3 | B4: KC Gunung Sitoli
A5: 4 | B5: KC Kabanjahe
A6: 5 | B6: KC Kisaran
A7: 6 | B7: KC Kota Pinang
A8: 7 | B8: KC Lubuk Pakam
A9: 8 | B9: KC Medan Gatot Subroto
A10: 9 | B10: KC Medan Iskandar Muda
A11: 10 | B11: KC Medan Putri Hijau
A12: 11 | B12: KC Medan Sisingamangaraja
A13: 12 | B13: KC Medan Thamrin
... A25: 24 | B25: KC Tebing Tinggi
B27: Keterangan:
B28: *Diisi jika telah dilaksanakan
B29: **https://bbri.id/MonevaRAC
B31: Evidence terdiri dari:
B32: 1. Dokumentasi Foto
B33: 2. Berita Acara
B34: 3. Absensi
B35: 4. Materi Sosisalisasi
B36: 5. List Pertanyaan

Sheet Uji Petik
A1: No. | B1: Unit Kerja | C1: PIC RAC | D1: Rencana Pelaksanaan | E1: Tanggal Pelaksanaan* | F1: Dokumen Evidence**
A3: 1 | B3: KC Salatiga | C3: Syamsul Arifianto | D3: 46282
A4: 2 | B4: KC Ungaran | C4: Veronica Dwi Kurniasih | D4: 46283
A5: 3 | B5: KC Semarang Ahmad Yani | C5: Veronica Dwi Kurniasih | D5: 46286
A6: 4 | B6: KC Semarang Pandanaran | C6: Veronica Dwi Kurniasih | D6: 46287
A7: 5 | B7: KC Semarang Patimura | C7: Syamsul Arifianto | D7: 46288
A8: 6 | B8: KC Semarang Brigjen Sudiarto | C8: Syamsul Arifianto | D8: 46289
A9: 7 | B9: KC Cepu | C9: Syamsul Arifianto | D9: 1 Oktober 2026
A10: 8 | B10: KC Blora | C10: Syamsul Arifianto | D10: 2 Oktober 2026
A11: 9 | B11: KC Rembang | C11: Syamsul Arifianto | D11: 5 Oktober 2026
A12: 10 | B12: KC Pati | C12: Syamsul Arifianto | D12: 6 Oktober 2026
A13: 11 | B13: KC Kudus | C13: Veronica Dwi Kurniasih | D13: 7 Oktober 2026
A14: 12 | B14: KC Jepara | C14: Veronica Dwi Kurniasih | D14: 8 Oktober 2026
A15: 13 | B15: KC Demak | C15: Veronica Dwi Kurniasih | D15: 9 Oktober 2026
A16: 14 | B16: KC Purwodadi | C16: Veronica Dwi Kurniasih | D16: 12 Oktober 2026
A17: 15 | B17: KC Bumiayu | C17: Veronica Dwi Kurniasih | D17: 13 Oktober 2026
A18: 16 | B18: KC Slawi | C18: Veronica Dwi Kurniasih | D18: 14 Oktober 2026
A19: 17 | B19: KC Tegal | C19: Veronica Dwi Kurniasih | D19: 15 Oktober 2026
A20: 18 | B20: KC Brebes | C20: Veronica Dwi Kurniasih | D20: 16 Oktober 2026
... A24: 22 | B24: KC Kendal | C24: Syamsul Arifianto | D24: 22 Oktober 2026
B29: Keterangan:
B30: *Diisi jika telah dilaksanakan
B31: **https://bri2-my.sharepoint.com/:f:/g/personal/00136153_hq_bri_co_id/IgDa3hABZ1toR7yxMRAO163UAXn4_97WpTspKfjy6Z32Xms?e=UtcLii
B34: Evidence terdiri dari:
B35: 1. Dokumentasi Foto
B36: 2. Berita Acara
B37: 3. Absensi
B38: 4.Kertas Kerja
B39: 5. Laporan Uji Petik

Sheet Nilai Maturitas
A1: No. | B1: Unit Kerja | C1: PIC RAC | D1: Nilai maturitas | E1: Nilai maturitas | F1: Rating maturitas
A2: 1 | B2: BO Batang | C2: Syamsul Arifianto | D2: 7.8073042 | E2: =AVERAGE(D1:D12) -> 7.7925651 | F2: B
A3: 2 | B3: BO Blora | C3: Syamsul Arifianto | D3: 8.1432094
A4: 5 | B4: BO Cepu | C4: Syamsul Arifianto | D4: 6.8352298
A5: 8 | B5: BO Kendal | C5: Syamsul Arifianto | D5: 8.2681638
A6: 10 | B6: BO Pati | C6: Syamsul Arifianto | D6: 7.8292079
A7: 11 | B7: BO Pekalongan | C7: Syamsul Arifianto | D7: 6.1682928
A8: 12 | B8: BO Pemalang | C8: Syamsul Arifianto | D8: 5.4314842
A9: 14 | B9: BO Rembang | C9: Syamsul Arifianto | D9: 9.6833934
A10: 15 | B10: BO Salatiga | C10: Syamsul Arifianto | D10: 8.1651145
A11: 17 | B11: BO Semarang Brigjen Sudiarto | C11: Syamsul Arifianto | D11: 8.64505
A12: 19 | B12: BO Semarang Patimura | C12: Syamsul Arifianto | D12: 8.7417661
A13: 3 | B13: BO Brebes | C13: Veronica Dwi Kurniasih | D13: 9.1903862 | E13: =AVERAGE(D12:D23) -> 8.2668625 | F13: AB
A14: 4 | B14: BO Bumiayu | C14: Veronica Dwi Kurniasih | D14: 7.9548758
A15: 6 | B15: BO Demak | C15: Veronica Dwi Kurniasih | D15: 9.7651389
A16: 7 | B16: BO Jepara | C16: Veronica Dwi Kurniasih | D16: 7.0683309
A17: 9 | B17: BO Kudus | C17: Veronica Dwi Kurniasih | D17: 9.3502547
A18: 13 | B18: BO Purwodadi | C18: Veronica Dwi Kurniasih | D18: 7.4823027
A19: 16 | B19: BO Semarang Ahmad Yani | C19: Veronica Dwi Kurniasih | D19: 8.5660304
A20: 18 | B20: BO Semarang Pandanaran | C20: Veronica Dwi Kurniasih | D20: 9.1138707
A21: 20 | B21: BO Slawi | C21: Veronica Dwi Kurniasih | D21: 8.3742338
A22: 21 | B22: BO Tegal | C22: Veronica Dwi Kurniasih | D22: 6.2182811
A23: 22 | B23: BO Ungaran | C23: Veronica Dwi Kurniasih | D23: 7.3768791

Sheet Penilaian Resiko
A1: No. | B1: Unit Kerja | C1: PIC RAC | D1: Nilai Risiko | E1: Nilai Risiko PIC | F1: Rating Risiko PIC
A2: 1 | B2: BO Batang | C2: Syamsul Arifianto | D2: 5.1961524 | E2: =AVERAGE(D1:D12) -> 5.3715943 | F2: Medium
A3: 2 | B3: BO Blora | C3: Syamsul Arifianto | D3: 6.2048368
A4: 5 | B4: BO Cepu | C4: Syamsul Arifianto | D4: 5.7008771
A5: 8 | B5: BO Kendal | C5: Syamsul Arifianto | D5: 5.2915026
A6: 10 | B6: BO Pati | C6: Syamsul Arifianto | D6: 5.7445626
A7: 11 | B7: BO Pekalongan | C7: Syamsul Arifianto | D7: 4.9749372
A8: 12 | B8: BO Pemalang | C8: Syamsul Arifianto | D8: 4.6904158
A9: 14 | B9: BO Rembang | C9: Syamsul Arifianto | D9: 5.9791304
A10: 15 | B10: BO Salatiga | C10: Syamsul Arifianto | D10: 5.9791304
A11: 17 | B11: BO Semarang Brigjen Sudiarto | C11: Syamsul Arifianto | D11: 4.5825757
A12: 19 | B12: BO Semarang Patimura | C12: Syamsul Arifianto | D12: 4.7434165
A13: 3 | B13: BO Brebes | C13: Veronica Dwi Kurniasih | D13: 5 | E13: =AVERAGE(D12:D23) -> 4.9714702 | F13: Medium
A14: 4 | B14: BO Bumiayu | C14: Veronica Dwi Kurniasih | D14: 4.3874822
A15: 6 | B15: BO Demak | C15: Veronica Dwi Kurniasih | D15: 5.4083269
A16: 7 | B16: BO Jepara | C16: Veronica Dwi Kurniasih | D16: 5.0990195
A17: 9 | B17: BO Kudus | C17: Veronica Dwi Kurniasih | D17: 4.2426407
A18: 13 | B18: BO Purwodadi | C18: Veronica Dwi Kurniasih | D18: 5.9791304
A19: 16 | B19: BO Semarang Ahmad Yani | C19: Veronica Dwi Kurniasih | D19: 5.1961524
A20: 18 | B20: BO Semarang Pandanaran | C20: Veronica Dwi Kurniasih | D20: 4.7434165
A21: 20 | B21: BO Slawi | C21: Veronica Dwi Kurniasih | D21: 4.6904158
A22: 21 | B22: BO Tegal | C22: Veronica Dwi Kurniasih | D22: 4.6904158
A23: 22 | B23: BO Ungaran | C23: Veronica Dwi Kurniasih | D23: 5.4772256

Sheet Maturitas Dashboard
A1: No. | B1: Unit Kerja | C1: PIC RAC | D1: Nilai Maturitas | E1: Nilai Maturitas PIC | F1: Rating Maturitas PIC
A2: 1 | B2: BO Batang | C2: Syamsul Arifianto | D2: 6.875 | E2: =AVERAGE(D1:D12) -> 6.9659091 | F2: CB
A3: 2 | B3: BO Blora | C3: Syamsul Arifianto | D3: 6.875
A4: 5 | B4: BO Cepu | C4: Syamsul Arifianto | D4: 7.375
A5: 8 | B5: BO Kendal | C5: Syamsul Arifianto | D5: 5.875
A6: 10 | B6: BO Pati | C6: Syamsul Arifianto | D6: 6.375
A7: 11 | B7: BO Pekalongan | C7: Syamsul Arifianto | D7: 7.375
A8: 12 | B8: BO Pemalang | C8: Syamsul Arifianto | D8: 6.375
A9: 14 | B9: BO Rembang | C9: Syamsul Arifianto | D9: 7.375
A10: 15 | B10: BO Salatiga | C10: Syamsul Arifianto | D10: 7.375
A11: 17 | B11: BO Semarang Brigjen Sudiarto | C11: Syamsul Arifianto | D11: 7.375
A12: 19 | B12: BO Semarang Patimura | C12: Syamsul Arifianto | D12: 7.375
A13: 3 | B13: BO Brebes | C13: Veronica Dwi Kurniasih | D13: 6.875 | E13: =AVERAGE(D12:D23) -> 7.0208333 | F13: B
A14: 4 | B14: BO Bumiayu | C14: Veronica Dwi Kurniasih | D14: 6.375
A15: 6 | B15: BO Demak | C15: Veronica Dwi Kurniasih | D15: 6.875
A16: 7 | B16: BO Jepara | C16: Veronica Dwi Kurniasih | D16: 7.375
A17: 9 | B17: BO Kudus | C17: Veronica Dwi Kurniasih | D17: 7.375
A18: 13 | B18: BO Purwodadi | C18: Veronica Dwi Kurniasih | D18: 6.875
A19: 16 | B19: BO Semarang Ahmad Yani | C19: Veronica Dwi Kurniasih | D19: 8.125
A20: 18 | B20: BO Semarang Pandanaran | C20: Veronica Dwi Kurniasih | D20: 7.375
A21: 20 | B21: BO Slawi | C21: Veronica Dwi Kurniasih | D21: 5.875
A22: 21 | B22: BO Tegal | C22: Veronica Dwi Kurniasih | D22: 7.375
A23: 22 | B23: BO Ungaran | C23: Veronica Dwi Kurniasih | D23: 6.375

Sheet Overview
A2: No | B2: Aspek Penilaian | C2: Syamsul Arifianto | F2: Veronica Dwi Kurniasih
C3: Nilai | D3: Bobotan | E3: Score | F3: Nilai | G3: Bobotan | H3: Score
A4: 1 | B4: STR | C4: =IFERROR(COUNTIFS(STR!$V:$V, Overview!C$2, STR!$X:$X, "TRUE")/COUNTIFS(STR!$V:$V, Overview!C2), 0) -> 1 | D4: 0.15 | E4: =D4*C4 -> 0.15 | F4: =IFERROR(COUNTIFS(STR!$V:$V, Overview!F$2, STR!$X:$X, "TRUE")/COUNTIFS(STR!$V:$V, Overview!F2), 0) -> 1 | G4: 0.15 | H4: =G4*F4 -> 0.15
A5: 2 | B5: Bad Data | C5: =1-AVERAGEIF('Bad Data'!$C:$C, Overview!C$2, 'Bad Data'!$D:$D) -> 0.99900909 | D5: 0.1 | E5: =D5*C5 -> 0.099900909 | F5: =1-AVERAGEIF('Bad Data'!$C:$C, Overview!F$2, 'Bad Data'!$D:$D) -> 0.99920273 | G5: 0.1 | H5: =G5*F5 -> 0.099920273
A6: 3 | B6: Pengkinian Data | C6: =AVERAGEIF('Pengkinian Data'!$C:$C, Overview!C$2, 'Pengkinian Data'!$D:$D) -> 1 | D6: 0.1 | E6: =D6*C6 -> 0.1 | F6: =AVERAGEIF('Pengkinian Data'!$C:$C, Overview!F$2, 'Pengkinian Data'!$D:$D) -> 1 | G6: 0.1 | H6: =G6*F6 -> 0.1 | O6: .
A7: 4 | B7: Uji Petik | C7: {=IFERROR(SUMPRODUCT(--('[1]Uji Petik'!$E$3:$E$73<>""), --('[1]Uji Petik'!$C$3:$C$73=C2)) / SUMPRODUCT(--('[1]Uji Petik'!$C$3:$C$73=C2)), 0)} -> 0 | D7: 0 | E7: =D7*C7 -> 0 | F7: {=IFERROR(SUMPRODUCT(--('[1]Uji Petik'!$E$3:$E$73<>""), --('[1]Uji Petik'!$C$3:$C$73=C2)) / SUMPRODUCT(--('[1]Uji Petik'!$C$3:$C$73=C2)), 0)} -> 0 | G7: 0 | H7: =G7*F7 -> 0
A8: 5 | B8: Sosialisasi | C8: {=IFERROR(AVERAGE(IF([2]Sosialisasi!$C$1:$C$10000=C2, [2]Sosialisasi!$D$1:$D$10000)), 0)} -> 0.18181818 | D8: 0.15 | E8: =D8*C8 -> 0.027272727 | F8: {=IFERROR(AVERAGE(IF([2]Sosialisasi!$C$1:$C$10000=F2, [2]Sosialisasi!$D$1:$D$10000)), 0)} -> 0 | G8: 0.15 | H8: =G8*F8 -> 0
A9: 6 | B9: EDD | C9: =AVERAGEIF('EDD PEP PPATK'!$C:$C, Overview!C$2, 'EDD PEP PPATK'!$D:$D) -> 0.97928746 | D9: 0.1 | E9: =D9*C9 -> 0.097928746 | F9: =AVERAGEIF('EDD PEP PPATK'!$C:$C, Overview!F$2, 'EDD PEP PPATK'!$D:$D) -> 0.98749337 | G9: 0.1 | H9: =G9*F9 -> 0.098749337
A10: 7 | B10: Self Learning Keikutsertaan | C10: {=IF(IFERROR(AVERAGE(IF('[2]Sheet2 (2)'!$C$1:$C$10000=C$2, '[2]Sheet2 (2)'!$D$1:$D$10000)), 0)>0.9, 1, IFERROR(AVERAGE(IF('[2]Sheet2 (2)'!$C$1:$C$10000=C$2, '[2]Sheet2 (2)'!$D$1:$D$10000)), 0))} -> 1 | D10: 0.05 | E10: =D10*C10 -> 0.05 | F10: {=IF(IFERROR(AVERAGE(IF('[2]Sheet2 (2)'!$C$1:$C$10000=F$2, '[2]Sheet2 (2)'!$D$1:$D$10000)), 0)>0.9, 1, IFERROR(AVERAGE(IF('[2]Sheet2 (2)'!$C$1:$C$10000=F$2, '[2]Sheet2 (2)'!$D$1:$D$10000)), 0))} -> 1 | G10: 0.05 | H10: =G10*F10 -> 0.05
A11: 8 | B11: Self Learning Score | C11: {=IF(IFERROR(AVERAGE(IF('[2]Sheet2 (3)'!$C$1:$C$10000=C2, '[2]Sheet2 (3)'!$D$1:$D$10000)), 0)>90, 1, IFERROR(AVERAGE(IF('[2]Sheet2 (3)'!$C$1:$C$10000=C2, '[2]Sheet2 (3)'!$D$1:$D$10000)), 0)/90)} -> 1 | D11: 0.05 | E11: =D11*C11 -> 0.05 | F11: {=IF(IFERROR(AVERAGE(IF('[2]Sheet2 (3)'!$C$1:$C$10000=F2, '[2]Sheet2 (3)'!$D$1:$D$10000)), 0)>90, 1, IFERROR(AVERAGE(IF('[2]Sheet2 (3)'!$C$1:$C$10000=F2, '[2]Sheet2 (3)'!$D$1:$D$10000)), 0)/90)} -> 1 | G11: 0.05 | H11: =G11*F11 -> 0.05
A12: 9 | B12: Maturitas | C12: =IF(AVERAGEIF('Nilai Maturitas'!$C:$C, Overview!C2, 'Nilai Maturitas'!$D:$D) > 8, 110%, AVERAGEIF('Nilai Maturitas'!$C:$C, Overview!C2, 'Nilai Maturitas'!$D:$D)/8*100%) -> 0.97407064 | D12: 0.1 | E12: =D12*C12 -> 0.097407064 | F12: =IF(AVERAGEIF('Nilai Maturitas'!$C:$C, Overview!F2, 'Nilai Maturitas'!$D:$D) > 8, 110%, AVERAGEIF('Nilai Maturitas'!$C:$C, Overview!F2, 'Nilai Maturitas'!$D:$D)/8*100%) -> 1.1 | G12: 0.1 | H12: =G12*F12 -> 0.11
A13: 10 | B13: Maturitas Dashboard | C13: =IF(AVERAGEIF('Maturitas Dashboard'!$C:$C, Overview!C$2, 'Maturitas Dashboard'!$D:$D) > 8, 110%, AVERAGEIF('Maturitas Dashboard'!$C:$C, Overview!C$2, 'Maturitas Dashboard'!$D:$D)/8*100%) -> 0.87073864 | D13: 0.1 | E13: =D13*C13 -> 0.087073864 | F13: =IF(AVERAGEIF('Maturitas Dashboard'!$C:$C, Overview!F$2, 'Maturitas Dashboard'!$D:$D) > 8, 110%, AVERAGEIF('Maturitas Dashboard'!$C:$C, Overview!F$2, 'Maturitas Dashboard'!$D:$D)/8*100%) -> 0.87357955 | G13: 0.1 | H13: =G13*F13 -> 0.087357955
A14: 11 | B14: Penilaian Resiko | C14: =IF(AVERAGEIF('Penilaian Resiko'!$C:$C, Overview!C$2, 'Penilaian Resiko'!$D:$D) < 5.8, 110%, IF(AVERAGEIF('Penilaian Resiko'!$C:$C, Overview!C$2, 'Penilaian Resiko'!$D:$D) <7.4, 3/4*100%, 3/5*100%)) -> 1.1 | D14: 0.1 | E14: =D14*C14 -> 0.11 | F14: =IF(AVERAGEIF('Penilaian Resiko'!$C:$C, Overview!F$2, 'Penilaian Resiko'!$D:$D) < 5.8, 110%, IF(AVERAGEIF('Penilaian Resiko'!$C:$C, Overview!F$2, 'Penilaian Resiko'!$D:$D) <7.4, 3/4*100%, 3/5*100%)) -> 1.1 | G14: 0.1 | H14: =G14*F14 -> 0.11
C15: Progress | E15: =SUM(E4:E14) -> 0.86958331 | F15: Progress | H15: =SUM(H4:H14) -> 0.85602756

Sheet Overview tanpa KPI
A2: No | B2: Aspek Penilaian | C2: Syamsul Arifianto | F2: Veronica Dwi Kurniasih
C3: Nilai | D3: Bobotan | E3: Score | F3: Nilai | G3: Bobotan | H3: Score
A4: 1 | B4: STR | C4: =IFERROR(COUNTIFS(STR!$V:$V, 'Overview tanpa KPI'!C$2, STR!$X:$X, "TRUE")/COUNTIFS(STR!$V:$V, 'Overview tanpa KPI'!C2), 0) -> 1 | D4: 0.15 | E4: =D4*C4 -> 0.15 | F4: =IFERROR(COUNTIFS(STR!$V:$V, 'Overview tanpa KPI'!F$2, STR!$X:$X, "TRUE")/COUNTIFS(STR!$V:$V, 'Overview tanpa KPI'!F2), 0) -> 1 | G4: 0.15 | H4: =G4*F4 -> 0.15
A5: 2 | B5: Bad Data | C5: =1-AVERAGEIF('Bad Data'!$C:$C, 'Overview tanpa KPI'!C$2, 'Bad Data'!$D:$D) -> 0.99900909 | D5: 0.1 | E5: =D5*C5 -> 0.099900909 | F5: =1-AVERAGEIF('Bad Data'!$C:$C, 'Overview tanpa KPI'!F$2, 'Bad Data'!$D:$D) -> 0.99920273 | G5: 0.1 | H5: =G5*F5 -> 0.099920273
A6: 3 | B6: Pengkinian Data | C6: =AVERAGEIF('Pengkinian Data'!$C:$C, 'Overview tanpa KPI'!C$2, 'Pengkinian Data'!$D:$D) -> 1 | D6: 0.1 | E6: =D6*C6 -> 0.1 | F6: =AVERAGEIF('Pengkinian Data'!$C:$C, 'Overview tanpa KPI'!F$2, 'Pengkinian Data'!$D:$D) -> 1 | G6: 0.1 | H6: =G6*F6 -> 0.1 | O6: .
A7: 4 | B7: Uji Petik | C7: {=IFERROR(SUMPRODUCT(--('[1]Uji Petik'!$E$3:$E$73<>""), --('[1]Uji Petik'!$C$3:$C$73=C2)) / SUMPRODUCT(--('[1]Uji Petik'!$C$3:$C$73=C2)), 0)} -> 0 | D7: 0 | E7: =D7*C7 -> 0 | F7: {=IFERROR(SUMPRODUCT(--('[1]Uji Petik'!$E$3:$E$73<>""), --('[1]Uji Petik'!$C$3:$C$73=C2)) / SUMPRODUCT(--('[1]Uji Petik'!$C$3:$C$73=C2)), 0)} -> 0 | G7: 0 | H7: =G7*F7 -> 0
A8: 5 | B8: Sosialisasi | C8: {=IFERROR(AVERAGE(IF([2]Sosialisasi!$C$1:$C$10000=C2, [2]Sosialisasi!$D$1:$D$10000)), 0)} -> 0.18181818 | D8: 0.15 | E8: =D8*C8 -> 0.027272727 | F8: {=IFERROR(AVERAGE(IF([2]Sosialisasi!$C$1:$C$10000=F2, [2]Sosialisasi!$D$1:$D$10000)), 0)} -> 0 | G8: 0.15 | H8: =G8*F8 -> 0
A9: 6 | B9: EDD | C9: =AVERAGEIF('EDD PEP PPATK'!$C:$C, 'Overview tanpa KPI'!C$2, 'EDD PEP PPATK'!$D:$D) -> 0.97928746 | D9: 0.1 | E9: =D9*C9 -> 0.097928746 | F9: =AVERAGEIF('EDD PEP PPATK'!$C:$C, 'Overview tanpa KPI'!F$2, 'EDD PEP PPATK'!$D:$D) -> 0.98749337 | G9: 0.1 | H9: =G9*F9 -> 0.098749337
A10: 7 | B10: Self Learning Keikutsertaan | C10: {=IFERROR(AVERAGE(IF('[2]Sheet2 (2)'!$C$1:$C$10000=C$2, '[2]Sheet2 (2)'!$D$1:$D$10000)), 0)} -> 0.96100037 | D10: 0.05 | E10: =D10*C10 -> 0.048050018 | F10: {=IFERROR(AVERAGE(IF('[2]Sheet2 (2)'!$C$1:$C$10000=F$2, '[2]Sheet2 (2)'!$D$1:$D$10000)), 0)} -> 0.9345266 | G10: 0.05 | H10: =G10*F10 -> 0.04672633
A11: 8 | B11: Self Learning Score | C11: {=IFERROR(AVERAGE(IF('[2]Sheet2 (3)'!$C$1:$C$10000=C2, '[2]Sheet2 (3)'!$D$1:$D$10000)), 0)} -> 97.599749 | D11: 0.05 | E11: =D11*C11 -> 4.8799874 | F11: {=IFERROR(AVERAGE(IF('[2]Sheet2 (3)'!$C$1:$C$10000=F2, '[2]Sheet2 (3)'!$D$1:$D$10000)), 0)} -> 97.546193 | G11: 0.05 | H11: =G11*F11 -> 4.8773096
A12: 9 | B12: Maturitas | C12: =AVERAGEIF('Nilai Maturitas'!$C:$C, 'Overview tanpa KPI'!C2, 'Nilai Maturitas'!$D:$D) -> 7.7925651 | D12: 0.1 | E12: =D12*C12 -> 0.77925651 | F12: =AVERAGEIF('Nilai Maturitas'!$C:$C, 'Overview tanpa KPI'!F2, 'Nilai Maturitas'!$D:$D) -> 8.2236895 | G12: 0.1 | H12: =G12*F12 -> 0.82236895
A13: 10 | B13: Maturitas Dashboard | C13: =AVERAGEIF('Maturitas Dashboard'!$C:$C, 'Overview tanpa KPI'!C$2, 'Maturitas Dashboard'!$D:$D) -> 6.9659091 | D13: 0.1 | E13: =D13*C13 -> 0.69659091 | F13: =AVERAGEIF('Maturitas Dashboard'!$C:$C, 'Overview tanpa KPI'!F$2, 'Maturitas Dashboard'!$D:$D) -> 6.9886364 | G13: 0.1 | H13: =G13*F13 -> 0.69886364
A14: 11 | B14: Penilaian Resiko | C14: =AVERAGEIF('Penilaian Resiko'!$C:$C, 'Overview tanpa KPI'!C$2, 'Penilaian Resiko'!$D:$D) -> 5.3715943 | D14: 0.1 | E14: =D14*C14 -> 0.53715943 | F14: =AVERAGEIF('Penilaian Resiko'!$C:$C, 'Overview tanpa KPI'!F$2, 'Penilaian Resiko'!$D:$D) -> 4.9922023 | G14: 0.1 | H14: =G14*F14 -> 0.49922023
C15: Progress | E15: =SUM(E4:E14) -> 7.4161467 | F15: Progress | H15: =SUM(H4:H14) -> 7.3931584

Sheet Overview KPI
A2: No | B2: Aspek Penilaian | C2: Syamsul Arifianto | F2: Veronica Dwi Kurniasih
C3: Nilai | D3: Bobotan | E3: Score | F3: Nilai | G3: Bobotan | H3: Score
A4: 1 | B4: STR | C4: =IFERROR(COUNTIFS(STR!$V:$V, 'Overview KPI'!C$2, STR!$X:$X, "TRUE")/COUNTIFS(STR!$V:$V, 'Overview KPI'!C2), 0) -> 1 | D4: 0.05 | E4: =D4*C4 -> 0.05 | F4: =IFERROR(COUNTIFS(STR!$V:$V, 'Overview KPI'!F$2, STR!$X:$X, "TRUE")/COUNTIFS(STR!$V:$V, 'Overview KPI'!F2), 0) -> 1 | G4: 0.05 | H4: =G4*F4 -> 0.05
A5: 2 | B5: Kualitas STR | C5: =IFERROR(AVERAGEIF(STR!$V:$V, 'Overview KPI'!C2, STR!$Y:$Y), 0)/4 -> 0.59252232 | D5: 0.15 | E5: =D5*C5 -> 0.088878348 | F5: =IFERROR(AVERAGEIF(STR!$V:$V, 'Overview KPI'!C2, STR!$Y:$Y), 0)/4 -> 0.59252232 | G5: 0.15 | H5: =G5*F5 -> 0.088878348
A6: 3 | B6: Bad Data | C6: =1-AVERAGEIF('Bad Data'!$C:$C, 'Overview KPI'!C$2, 'Bad Data'!$D:$D) -> 0.99900909 | D6: 0.1 | E6: =D6*C6 -> 0.099900909 | F6: =1-AVERAGEIF('Bad Data'!$C:$C, 'Overview KPI'!F$2, 'Bad Data'!$D:$D) -> 0.99920273 | G6: 0.1 | H6: =G6*F6 -> 0.099920273
A7: 4 | B7: Pengkinian Data | C7: =AVERAGEIF('Pengkinian Data'!$C:$C, 'Overview KPI'!C$2, 'Pengkinian Data'!$D:$D) -> 1 | D7: 0.1 | E7: =D7*C7 -> 0.1 | F7: =AVERAGEIF('Pengkinian Data'!$C:$C, 'Overview KPI'!F$2, 'Pengkinian Data'!$D:$D) -> 1 | G7: 0.1 | H7: =G7*F7 -> 0.1 | O7: .
A8: 5 | B8: Uji Petik | C8: {=IFERROR(SUMPRODUCT(--('[1]Uji Petik'!$E$3:$E$73<>""), --('[1]Uji Petik'!$C$3:$C$73=C2)) / SUMPRODUCT(--('[1]Uji Petik'!$C$3:$C$73=C2)), 0)} -> 0 | D8: 0.075 | E8: =D8*C8 -> 0 | F8: {=IFERROR(SUMPRODUCT(--('[1]Uji Petik'!$E$3:$E$73<>""), --('[1]Uji Petik'!$C$3:$C$73=C2)) / SUMPRODUCT(--('[1]Uji Petik'!$C$3:$C$73=C2)), 0)} -> 0 | G8: 0.075 | H8: =G8*F8 -> 0
A9: 6 | B9: Sosialisasi | C9: {=IFERROR(AVERAGE(IF([2]Sosialisasi!$C$1:$C$10000=C2, [2]Sosialisasi!$D$1:$D$10000)), 0)} -> 0.18181818 | D9: 0.075 | E9: =D9*C9 -> 0.013636364 | F9: {=IFERROR(AVERAGE(IF([2]Sosialisasi!$C$1:$C$10000=F2, [2]Sosialisasi!$D$1:$D$10000)), 0)} -> 0 | G9: 0.075 | H9: =G9*F9 -> 0
A10: 7 | B10: EDD | C10: =AVERAGEIF('EDD PEP PPATK'!$C:$C, 'Overview KPI'!C$2, 'EDD PEP PPATK'!$D:$D) -> 0.97928746 | D10: 0.1 | E10: =D10*C10 -> 0.097928746 | F10: =AVERAGEIF('EDD PEP PPATK'!$C:$C, 'Overview KPI'!F$2, 'EDD PEP PPATK'!$D:$D) -> 0.98749337 | G10: 0.1 | H10: =G10*F10 -> 0.098749337
A11: 8 | B11: Self Learning Keikutsertaan | C11: {=IF(IFERROR(AVERAGE(IF('[2]Sheet2 (2)'!$C$1:$C$10000=C$2, '[2]Sheet2 (2)'!$D$1:$D$10000)), 0)>0.9, 1, IFERROR(AVERAGE(IF('[2]Sheet2 (2)'!$C$1:$C$10000=C$2, '[2]Sheet2 (2)'!$D$1:$D$10000)), 0))} -> 1 | D11: 0.025 | E11: =D11*C11 -> 0.025 | F11: {=IF(IFERROR(AVERAGE(IF('[2]Sheet2 (2)'!$C$1:$C$10000=F$2, '[2]Sheet2 (2)'!$D$1:$D$10000)), 0)>0.9, 1, IFERROR(AVERAGE(IF('[2]Sheet2 (2)'!$C$1:$C$10000=F$2, '[2]Sheet2 (2)'!$D$1:$D$10000)), 0))} -> 1 | G11: 0.025 | H11: =G11*F11 -> 0.025
A12: 9 | B12: Self Learning Score | C12: {=IF(IFERROR(AVERAGE(IF('[2]Sheet2 (3)'!$C$1:$C$10000=C2, '[2]Sheet2 (3)'!$D$1:$D$10000)), 0)>90, 1, IFERROR(AVERAGE(IF('[2]Sheet2 (3)'!$C$1:$C$10000=C2, '[2]Sheet2 (3)'!$D$1:$D$10000)), 0)/90)} -> 1 | D12: 0.025 | E12: =D12*C12 -> 0.025 | F12: {=IF(IFERROR(AVERAGE(IF('[2]Sheet2 (3)'!$C$1:$C$10000=F2, '[2]Sheet2 (3)'!$D$1:$D$10000)), 0)>90, 1, IFERROR(AVERAGE(IF('[2]Sheet2 (3)'!$C$1:$C$10000=F2, '[2]Sheet2 (3)'!$D$1:$D$10000)), 0)/90)} -> 1 | G12: 0.025 | H12: =G12*F12 -> 0.025
A13: 10 | B13: Maturitas | C13: =IF(AVERAGEIF('Nilai Maturitas'!$C:$C, 'Overview KPI'!C2, 'Nilai Maturitas'!$D:$D) > 8, 110%, AVERAGEIF('Nilai Maturitas'!$C:$C, 'Overview KPI'!C2, 'Nilai Maturitas'!$D:$D)/8*100%) -> 0.97407064 | D13: 0.1 | E13: =D13*C13 -> 0.097407064 | F13: =IF(AVERAGEIF('Nilai Maturitas'!$C:$C, 'Overview KPI'!F2, 'Nilai Maturitas'!$D:$D) > 8, 110%, AVERAGEIF('Nilai Maturitas'!$C:$C, 'Overview KPI'!F2, 'Nilai Maturitas'!$D:$D)/8*100%) -> 1.1 | G13: 0.1 | H13: =G13*F13 -> 0.11
A14: 11 | B14: Maturitas Dashboard | C14: =IF(AVERAGEIF('Maturitas Dashboard'!$C:$C, 'Overview KPI'!C$2, 'Maturitas Dashboard'!$D:$D) > 8, 110%, AVERAGEIF('Maturitas Dashboard'!$C:$C, 'Overview KPI'!C$2, 'Maturitas Dashboard'!$D:$D)/8*100%) -> 0.87073864 | D14: 0.1 | E14: =D14*C14 -> 0.087073864 | F14: =IF(AVERAGEIF('Maturitas Dashboard'!$C:$C, 'Overview KPI'!F$2, 'Maturitas Dashboard'!$D:$D) > 8, 110%, AVERAGEIF('Maturitas Dashboard'!$C:$C, 'Overview KPI'!F$2, 'Maturitas Dashboard'!$D:$D)/8*100%) -> 0.87357955 | G14: 0.1 | H14: =G14*F14 -> 0.087357955
A15: 12 | B15: Penilaian Resiko | C15: =IF(AVERAGEIF('Penilaian Resiko'!$C:$C, 'Overview KPI'!C$2, 'Penilaian Resiko'!$D:$D) < 5.8, 110%, IF(AVERAGEIF('Penilaian Resiko'!$C:$C, 'Overview KPI'!C$2, 'Penilaian Resiko'!$D:$D) <7.4, 3/4*100%, 3/5*100%)) -> 1.1 | D15: 0.1 | E15: =D15*C15 -> 0.11 | F15: =IF(AVERAGEIF('Penilaian Resiko'!$C:$C, 'Overview KPI'!F$2, 'Penilaian Resiko'!$D:$D) < 5.8, 110%, IF(AVERAGEIF('Penilaian Resiko'!$C:$C, 'Overview KPI'!F$2, 'Penilaian Resiko'!$D:$D) <7.4, 3/4*100%, 3/5*100%)) -> 1.1 | G15: 0.1 | H15: =G15*F15 -> 0.11
C16: Progress | E16: =SUM(E4:E15) -> 0.79482529 | F16: Progress | H16: =SUM(H4:H15) -> 0.79490591
