Workbook

Sheet STR
A1: POSISI | B1: NAMA | C1: CIF | D1: No Rek/ Kartu Kredit | E1: RESIKO | F1: BRILINK | G1: STATUS PEKERJA | H1: DIGITAL SAVING | I1: SKENARIO | J1: SCORING | K1: INFO PARAM | L1: KATEGORI | M1: UNIT KERJA | N1: KANTOR CABANG | O1: KANTOR KANWIL | P1: REKOMENDASI UKER | Q1: REKOMENDASI UKK | R1: STATUS UKER | S1: STATUS | T1: DISPOSISI | U1: INFO LAINNYA | V1: Disposisi RAC | W1: Tanggal | X1: Status TL
A2: {=_xlfn._xlws.FILTER('[2]STR-2026-8-2026-8'!$A:$U, ISNUMBER(SEARCH("Malang", '[2]STR-2026-8-2026-8'!$O:$O)), "")} -> 46265 | B2: ADIPUTRO WIRASEJATI PT. | C2: A274622 | D2: 5101005001569 | E2: SEDANG | F2: Tidak | G2: Tidak | H2: Tidak | I2: Perpajakan | J2: 48 | K2: 1.33 | L2: Perpajakan | M2: KC Malang Kawi | N2: KC Malang Kawi | O2: KANWIL MALANG | P2: 0 | Q2: 0 | R2: Belum TL | S2: Belum TL | T2: 00336949 - Mochammad Al Farabi | U2: "-" | V2: Made Windu Kuntara | X2: =[3]STR!$X2 -> TRUE
A3: 46265 | B3: AMAL JUM'AT MASJID AL MANAR | C3: ACPMC89 | D3: 612901000004565 | E3: SEDANG | F3: Tidak | G3: Tidak | H3: Tidak | I3: Perpajakan | J3: 48 | K3: 41 | L3: Perpajakan | M3: UNIT SAMBIREJO BANYUWANGI | N3: KC Banyuwangi | O3: KANWIL MALANG | P3: 0 | Q3: 0 | R3: Belum TL | S3: Belum TL | T3: 90170665 - Mutiara Ayuningtyas | U3: "-" | V3: Made Windu Kuntara | X3: =[3]STR!$X3 -> TRUE
A4: 46265 | B4: ANDIKA PRAYUDO | C4: AEUAW19 | D4: 652901034665539 | E4: 0 | F4: Tidak | G4: Tidak | H4: 0 | I4: Jual Beli Rekening - E channel Trx | J4: 33 | K4: 113 | L4: Narkotika/Judi Online/Penipuan | M4: UNIT BANYUPUTIH SITUBONDO | N4: KC Situbondo | O4: KANWIL MALANG | P4: 0 | Q4: 0 | R4: Belum TL | S4: Belum TL | T4: 0 | U4: "-" | V4: Made Windu Kuntara | X4: =[3]STR!$X4 -> TRUE
A5: 46265 | B5: BINTANG PUTRI KARISMA | C5: BFH6079 | D5: 2101307308309 | E5: SEDANG | F5: Tidak | G5: Tidak | H5: Tidak | I5: Perpajakan | J5: 48 | K5: 41 | L5: Perpajakan | M5: KC Jember | N5: KC Jember | O5: KANWIL MALANG | P5: 0 | Q5: 0 | R5: Belum TL | S5: Belum TL | T5: 90185538 - Muhammad Fahikal Auz | U5: "-" | V5: Made Windu Kuntara | X5: =[3]STR!$X5 -> TRUE | Z5: .
A6: 46265 | B6: BUDIANTO | C6: BHX6448 | D6: 17701027578532 | E6: 0 | F6: Tidak | G6: Tidak | H6: Tidak | I6: Narkotika - Area Lapas | J6: 34 | K6: 46 | L6: Narkotika | M6: KC Trenggalek | N6: KC Trenggalek | O6: KANWIL MALANG | P6: 0 | Q6: 0 | R6: Belum TL | S6: Belum TL | T6: 90185538 - Muhammad Fahikal Auz | U6: "-" | V6: Febri Dwi Prabowo | X6: =[3]STR!$X6 -> TRUE
A7: 46265 | B7: CV RIZQY MAJU MAKMUR SEJAHTERA | C7: CA62663 | D7: 6501001303308 | E7: SEDANG | F7: Tidak | G7: Tidak | H7: Tidak | I7: Perpajakan | J7: 50 | K7: 41 | L7: Perpajakan | M7: KC Pasuruan | N7: KC Pasuruan | O7: KANWIL MALANG | P7: 0 | Q7: 0 | R7: Belum TL | S7: Belum TL | T7: 90185538 - Muhammad Fahikal Auz | U7: "-" | V7: Made Windu Kuntara | X7: =[3]STR!$X7 -> TRUE
A8: 46265 | B8: BUKIT ANUGERAH SENTOSA | C8: CG39577 | D8: 51801000336305 | E8: SEDANG | F8: Tidak | G8: Tidak | H8: Tidak | I8: Perpajakan | J8: 48 | K8: 41 | L8: Perpajakan | M8: KCP Pandaan | N8: KC Pasuruan | O8: KANWIL MALANG | P8: 0 | Q8: 0 | R8: Belum TL | S8: Belum TL | T8: 90185537 - Moh.Khoerul Fajar Ar | U8: "-" | V8: Made Windu Kuntara | X8: =[3]STR!$X8 -> TRUE
A9: 46265 | B9: CV FAJAR TOBACCO | C9: CJ57325 | D9: 51801000458563 | E9: SEDANG | F9: Tidak | G9: Tidak | H9: Tidak | I9: Perpajakan | J9: 51 | K9: 41 | L9: Perpajakan | M9: KCP Pandaan | N9: KC Pasuruan | O9: KANWIL MALANG | P9: 0 | Q9: 0 | R9: Belum TL | S9: Belum TL | T9: 90171841 - Rifqi Aziz | U9: "-" | V9: Made Windu Kuntara | X9: =[3]STR!$X9 -> TRUE
A10: 46265 | B10: CV TENTREM JAYA SENTOSA | C10: CR64018 | D10: 11001002726560 | E10: SEDANG | F10: Tidak | G10: Tidak | H10: Tidak | I10: Perpajakan | J10: 50 | K10: 41 | L10: Perpajakan | M10: KC Tulungagung | N10: KC Tulungagung | O10: KANWIL MALANG | P10: 0 | Q10: 0 | R10: Belum TL | S10: Belum TL | T10: 90185538 - Muhammad Fahikal Auz | U10: "-" | V10: Made Windu Kuntara | X10: =[3]STR!$X10 -> TRUE
A11: 46265 | B11: DJAIMAN | C11: DALX370 | D11: 640201039747538 | E11: SEDANG | F11: Ya | G11: Tidak | H11: Tidak | I11: Narkotika - Area Lapas | J11: 50 | K11: 46 | L11: Narkotika | M11: UNIT SUMBERMANJING MLG MARTA | N11: KC Malang Martadinata | O11: KANWIL MALANG | P11: 0 | Q11: 0 | R11: Belum TL | S11: Belum TL | T11: 90186790 - Muhammad Alfin Farha | U11: "-" | V11: Febri Dwi Prabowo | X11: =[3]STR!$X11 -> TRUE
A12: 46265 | B12: DELLY INDRA SETIAWAN | C12: DTZ8649 | D12: 766701006801534 | E12: SEDANG | F12: Tidak | G12: Tidak | H12: Tidak | I12: Prostitusi | J12: 46 | K12: 104 | L12: Prostitusi | M12: UNIT MLILIR MADIUN | N12: KC Madiun | O12: KANWIL MALANG | P12: 0 | Q12: 0 | R12: Belum TL | S12: Belum TL | T12: 90186790 - Muhammad Alfin Farha | U12: "-" | V12: Made Windu Kuntara | X12: =[3]STR!$X12 -> TRUE
A13: 46265 | B13: GUNADI | C13: G025100 | D13: 5101483199504 | E13: SEDANG | F13: Tidak | G13: Tidak | H13: Tidak | I13: Perpajakan | J13: 60 | K13: 1.33 | L13: Perpajakan | M13: KC Malang Kawi | N13: KC Malang Kawi | O13: KANWIL MALANG | P13: 0 | Q13: 0 | R13: Belum TL | S13: Belum TL | T13: 90186790 - Muhammad Alfin Farha | U13: "-" | V13: Made Windu Kuntara | X13: =[3]STR!$X13 -> TRUE
A14: 46265 | B14: GRAMITRAMA BATTERY | C14: GV88489 | D14: 51601188888309 | E14: 0 | F14: Tidak | G14: Tidak | H14: Tidak | I14: Perpajakan | J14: 33 | K14: 41 | L14: Perpajakan | M14: KC Kepanjen | N14: KC Kepanjen | O14: KANWIL MALANG | P14: 0 | Q14: 0 | R14: Belum TL | S14: Belum TL | T14: 90150130 - Intan Aida Pratiwi | U14: "-" | V14: Febri Dwi Prabowo | X14: =[3]STR!$X14 -> TRUE
A15: 46265 | B15: LILIANA WINOTO | C15: L353117 | D15: 3301024333505 | E15: SEDANG | F15: Tidak | G15: Tidak | H15: Tidak | I15: Perpajakan | J15: 59 | K15: 1.33 | L15: Perpajakan | M15: KC Kediri | N15: KC Kediri | O15: KANWIL MALANG | P15: 0 | Q15: 0 | R15: Belum TL | S15: Belum TL | T15: 90185538 - Muhammad Fahikal Auz | U15: "-" | V15: Febri Dwi Prabowo | X15: =[3]STR!$X15 -> TRUE
A16: 46265 | B16: MUHAMAD FIRMAN PUTRA MAULANA | C16: MEMHZ61 | D16: 626501005766506 | E16: 0 | F16: Tidak | G16: Tidak | H16: 0 | I16: Jual Beli Rekening - E channel Trx | J16: 33 | K16: 113 | L16: Narkotika/Judi Online/Penipuan | M16: UNIT PELAS KEDIRI | N16: KC Kediri | O16: KANWIL MALANG | P16: 0 | Q16: 0 | R16: Belum TL | S16: Belum TL | T16: 0 | U16: "-" | V16: Febri Dwi Prabowo | X16: =[3]STR!$X16 -> TRUE
A17: 46265 | B17: RAKHMAT RAMDHAN IKHSAN PRAKOSO | C17: RQWZ333 | D17: 216601888883567 | E17: 0 | F17: Tidak | G17: Tidak | H17: Tidak | I17: Perpajakan | J17: 34 | K17: 1.33 | L17: Perpajakan | M17: KCP SAWOJAJAR | N17: KC Malang Sutoyo | O17: KANWIL MALANG | P17: 0 | Q17: 0 | R17: Belum TL | S17: Belum TL | T17: 90171841 - Rifqi Aziz | U17: "-" | V17: Made Windu Kuntara | X17: =[3]STR!$X17 -> TRUE
A18: 46265 | B18: SITI BINTARKIMUNA NY | C18: S759970 | D18: 5.32659e+15 | E18: TINGGI | F18: Tidak | G18: Ya | H18: Tidak | I18: Private or Priority Customer Investment | J18: 93 | K18: 93 | L18: Pasar Modal | M18: SLP MALANG | N18: KC Malang Kawi | O18: KANWIL MALANG | P18: 0 | Q18: 0 | R18: Belum TL | S18: Belum TL | T18: 90170665 - Mutiara Ayuningtyas | U18: "-" | V18: Made Windu Kuntara | X18: =[3]STR!$X18 -> TRUE
A19: 46265 | B19: VANESA ANGEL ROSANANTA | C19: V829146 | D19: 387801009518509 | E19: SEDANG | F19: Tidak | G19: Tidak | H19: Tidak | I19: Perpajakan | J19: 48 | K19: 41 | L19: Perpajakan | M19: UNIT PARANG MAGETAN | N19: KC Magetan | O19: KANWIL MALANG | P19: 0 | Q19: 0 | R19: Belum TL | S19: Belum TL | T19: 90185537 - Moh.Khoerul Fajar Ar | U19: "-" | V19: Febri Dwi Prabowo | X19: =[3]STR!$X19 -> TRUE
A20: 46265 | B20: EKO CAHYO SAPUTRO | C20: EAY9464 | D20: 644901000592500 | E20: SEDANG | F20: Tidak | G20: Tidak | H20: Tidak | I20: Perikanan dan Kelautan | J20: 48 | K20: 98 | L20: Perikanan dan Kelautan | M20: UNIT TEGUHAN NGAWI | N20: KC Ngawi | O20: KANWIL MALANG | P20: Ya | Q20: 0 | R20: Done | S20: Belum TL | T20: 00394520 - Frida Akbar Rani | U20: "-" | V20: Febri Dwi Prabowo | X20: =[3]STR!$X20 -> TRUE
A21: 46265 | B21: DAVID SURJA SAPUTRA | C21: DFYX126 | D21: 702000239502 | E21: 0 | F21: Tidak | G21: Tidak | H21: Tidak | I21: Perikanan dan Kelautan | J21: 43 | K21: 98 | L21: Perikanan dan Kelautan | M21: KC Banyuwangi | N21: KC Banyuwangi | O21: KANWIL MALANG | P21: Tidak | Q21: Tidak | R21: Done | S21: Pending Checker | T21: 00394520 - Frida Akbar Rani | U21: "-" | V21: Made Windu Kuntara | X21: =[3]STR!$X21 -> TRUE
A22: 46265 | B22: EMPAT MACAN ASIA | C22: EYV9064 | D22: 51601601602567 | E22: 0 | F22: Tidak | G22: Tidak | H22: Tidak | I22: Perpajakan | J22: 33 | K22: 41 | L22: Perpajakan | M22: KC Kepanjen | N22: KC Kepanjen | O22: KANWIL MALANG | P22: Tidak | Q22: Tidak | R22: Done | S22: Approved | T22: 90185537 - Moh.Khoerul Fajar Ar | U22: "-" | V22: Febri Dwi Prabowo | X22: =[3]STR!$X22 -> TRUE
A23: 46265 | B23: GELANG EMAS | C23: GK86225 | D23: 5101013300567 | E23: SEDANG | F23: Tidak | G23: Tidak | H23: Tidak | I23: Perpajakan | J23: 48 | K23: 41 | L23: Perpajakan | M23: KC Malang Kawi | N23: KC Malang Kawi | O23: KANWIL MALANG | P23: Tidak | Q23: Tidak | R23: Done | S23: Approved | T23: 90185538 - Muhammad Fahikal Auz | U23: "-" | V23: Made Windu Kuntara | X23: =[3]STR!$X23 -> TRUE
A24: 46265 | B24: KOPONTREN SIDOGIRI | C24: KFF0449 | D24: 6501001182566 | E24: SEDANG | F24: Tidak | G24: Tidak | H24: Tidak | I24: Perpajakan | J24: 50 | K24: 1.33 | L24: Perpajakan | M24: KC Pasuruan | N24: KC Pasuruan | O24: KANWIL MALANG | P24: Tidak | Q24: Tidak | R24: Done | S24: Approved | T24: 00394520 - Frida Akbar Rani | U24: "-" | V24: Made Windu Kuntara | X24: =[3]STR!$X24 -> TRUE
A25: 46265 | B25: KHOIRUL ANHAR | C25: KDQ6630 | D25: 51801001064561 | E25: TINGGI | F25: Tidak | G25: Tidak | H25: Tidak | I25: Perpajakan | J25: 75 | K25: 1.33 | L25: Perpajakan | M25: KCP Pandaan | N25: KC Pasuruan | O25: KANWIL MALANG | P25: Tidak | Q25: Tidak | R25: Done | S25: Approved | T25: 90171841 - Rifqi Aziz | U25: "-" | V25: Made Windu Kuntara | X25: =[3]STR!$X25 -> TRUE
A26: 46265 | B26: IMAM HANAFI | C26: ICT3541 | D26: 321201041256537 | E26: SEDANG | F26: Ya | G26: Tidak | H26: Tidak | I26: Pencurian Rekening | J26: 49 | K26: 59 | L26: Perbankan | M26: UNIT DOLOPO MADIUN | N26: KC Madiun | O26: KANWIL MALANG | P26: Tidak | Q26: Tidak | R26: Done | S26: Approved | T26: 00394520 - Frida Akbar Rani | U26: "-" | V26: Made Windu Kuntara | X26: =[3]STR!$X26 -> TRUE
A27: 46265 | B27: AMARTA WISESA | C27: ACGLL30 | D27: 34401002514304 | E27: SEDANG | F27: Tidak | G27: Tidak | H27: Tidak | I27: Perpajakan | J27: 48 | K27: 41 | L27: Perpajakan | M27: KC Malang Martadinata | N27: KC Malang Martadinata | O27: KANWIL MALANG | P27: Tidak | Q27: Tidak | R27: Done | S27: Approved | T27: 00394521 - Muhammad Hibbanduta | U27: "-" | V27: Febri Dwi Prabowo | X27: =[3]STR!$X27 -> TRUE
A28: 46265 | B28: BRITS INDONESIA BANDUNG | C28: BHV1485 | D28: 166201000208566 | E28: 0 | F28: Tidak | G28: Tidak | H28: Tidak | I28: Perpajakan | J28: 33 | K28: 41 | L28: Perpajakan | M28: KK UIN MALANG | N28: KC Malang Martadinata | O28: KANWIL MALANG | P28: Tidak | Q28: Tidak | R28: Done | S28: Approved | T28: 90150130 - Intan Aida Pratiwi | U28: "-" | V28: Febri Dwi Prabowo | X28: =[3]STR!$X28 -> TRUE
A29: 46265 | B29: BRITS INDONESIA YOGYAKARTA | C29: BHV1534 | D29: 166201000209562 | E29: 0 | F29: Tidak | G29: Tidak | H29: Tidak | I29: Perpajakan | J29: 36 | K29: 41 | L29: Perpajakan | M29: KK UIN MALANG | N29: KC Malang Martadinata | O29: KANWIL MALANG | P29: Tidak | Q29: Tidak | R29: Done | S29: Approved | T29: 90171841 - Rifqi Aziz | U29: "-" | V29: Febri Dwi Prabowo | X29: =[3]STR!$X29 -> TRUE
A30: 46265 | B30: BRITS INDONESIA SAMARINDA | C30: BHV2441 | D30: 166201000211569 | E30: 0 | F30: Tidak | G30: Tidak | H30: Tidak | I30: Perpajakan | J30: 35 | K30: 41 | L30: Perpajakan | M30: KK UIN MALANG | N30: KC Malang Martadinata | O30: KANWIL MALANG | P30: Tidak | Q30: Tidak | R30: Done | S30: Approved | T30: 00336949 - Mochammad Al Farabi | U30: "-" | V30: Febri Dwi Prabowo | X30: =[3]STR!$X30 -> TRUE
A31: 46265 | B31: BRITS INDONESIA JOGJA TAMSIS | C31: BIW4016 | D31: 166201000263566 | E31: 0 | F31: Tidak | G31: Tidak | H31: Tidak | I31: Perpajakan | J31: 33 | K31: 41 | L31: Perpajakan | M31: KK UIN MALANG | N31: KC Malang Martadinata | O31: KANWIL MALANG | P31: Tidak | Q31: Tidak | R31: Done | S31: Approved | T31: 90186790 - Muhammad Alfin Farha | U31: "-" | V31: Febri Dwi Prabowo | X31: =[3]STR!$X31 -> TRUE
A32: 46265 | B32: BRITS INDONESIA SEMARANG | C32: BIW4071 | D32: 166201000264562 | E32: 0 | F32: Tidak | G32: Tidak | H32: Tidak | I32: Perpajakan | J32: 33 | K32: 41 | L32: Perpajakan | M32: KK UIN MALANG | N32: KC Malang Martadinata | O32: KANWIL MALANG | P32: Tidak | Q32: Tidak | R32: Done | S32: Approved | T32: 90170665 - Mutiara Ayuningtyas | U32: "-" | V32: Febri Dwi Prabowo | X32: =[3]STR!$X32 -> TRUE
A33: 46265 | B33: CV PUTRA AIRLANGGA SEJAHTERA | C33: CL38835 | D33: 51801000497567 | E33: TINGGI | F33: Tidak | G33: Tidak | H33: Tidak | I33: Perpajakan | J33: 64 | K33: 1.33 | L33: Perpajakan | M33: KCP Pandaan | N33: KC Pasuruan | O33: KANWIL MALANG | P33: Tidak | Q33: Tidak | R33: Done | S33: Approved | T33: 90186796 - Devito Arya Wiradila | U33: "-" | V33: Made Windu Kuntara | X33: =[3]STR!$X33 -> TRUE
A34: 46265 | B34: TRIJAYA FAJAR PERSADA | C34: TGG5477 | D34: 57701000775309 | E34: TINGGI | F34: Tidak | G34: Tidak | H34: Tidak | I34: Perpajakan | J34: 63 | K34: 41 | L34: Perpajakan | M34: KC Genteng | N34: KC Genteng | O34: KANWIL MALANG | P34: Tidak | Q34: Tidak | R34: Done | S34: Approved | T34: 00394520 - Frida Akbar Rani | U34: "-" | V34: Febri Dwi Prabowo | X34: =[3]STR!$X34 -> TRUE
A35: 46265 | B35: RINAWATI | C35: RR20112 | D35: 646301000243501 | E35: SEDANG | F35: Tidak | G35: Tidak | H35: Tidak | I35: Perikanan dan Kelautan | J35: 49 | K35: 101 | L35: Perikanan dan Kelautan | M35: UNIT PACITAN KOTA | N35: KC Pacitan | O35: KANWIL MALANG | P35: Tidak | Q35: Tidak | R35: Done | S35: Approved | T35: 90185537 - Moh.Khoerul Fajar Ar | U35: "-" | V35: Febri Dwi Prabowo | X35: =[3]STR!$X35 -> TRUE
A36: 46265 | B36: SERBA GUNA SEJATI | C36: SLEEI36 | D36: 5101035000567 | E36: 0 | F36: Tidak | G36: Tidak | H36: Tidak | I36: Perpajakan | J36: 33 | K36: 41 | L36: Perpajakan | M36: KC Malang Kawi | N36: KC Malang Kawi | O36: KANWIL MALANG | P36: Tidak | Q36: Tidak | R36: Done | S36: Approved | T36: 90150130 - Intan Aida Pratiwi | U36: "-" | V36: Made Windu Kuntara | X36: =[3]STR!$X36 -> TRUE
A37: 46265 | B37: PT SIDOGIRI MITRA UTAMA | C37: PEC7409 | D37: 6501001583306 | E37: TINGGI | F37: Tidak | G37: Tidak | H37: Tidak | I37: Perpajakan | J37: 65 | K37: 1.33 | L37: Perpajakan | M37: KC Pasuruan | N37: KC Pasuruan | O37: KANWIL MALANG | P37: Tidak | Q37: Tidak | R37: Done | S37: Approved | T37: 90185538 - Muhammad Fahikal Auz | U37: "-" | V37: Made Windu Kuntara | X37: =[3]STR!$X37 -> TRUE
A38: 46265 | B38: PT RODA MULIA ABADI | C38: PFK7831 | D38: 5101003235308 | E38: SEDANG | F38: Tidak | G38: Tidak | H38: Tidak | I38: Perpajakan | J38: 48 | K38: 41 | L38: Perpajakan | M38: KC Malang Kawi | N38: KC Malang Kawi | O38: KANWIL MALANG | P38: Tidak | Q38: Tidak | R38: Done | S38: Approved | T38: 90185537 - Moh.Khoerul Fajar Ar | U38: "-" | V38: Made Windu Kuntara | X38: =[3]STR!$X38 -> TRUE
A39: 46265 | B39: POETRA SAKTI MAKMUR | C39: PKQ9443 | D39: 34401118899309 | E39: TINGGI | F39: Tidak | G39: Tidak | H39: Tidak | I39: Perpajakan | J39: 64 | K39: 1.33 | L39: Perpajakan | M39: KC Malang Martadinata | N39: KC Malang Martadinata | O39: KANWIL MALANG | P39: Tidak | Q39: Tidak | R39: Done | S39: Approved | T39: 90185537 - Moh.Khoerul Fajar Ar | U39: "-" | V39: Febri Dwi Prabowo | X39: =[3]STR!$X39 -> TRUE
A40: 46265 | B40: PT INDOMARCO ADI PRIMA | C40: P595578 | D40: 34401000123301 | E40: SEDANG | F40: Tidak | G40: Tidak | H40: Tidak | I40: Narkotika - Area Lapas | J40: 50 | K40: 46 | L40: Narkotika | M40: KC Malang Martadinata | N40: KC Malang Martadinata | O40: KANWIL MALANG | P40: Tidak | Q40: Tidak | R40: Done | S40: Approved | T40: 90185537 - Moh.Khoerul Fajar Ar | U40: "-" | V40: Febri Dwi Prabowo | X40: =[3]STR!$X40 -> TRUE
...

Sheet EDD PEP PPATK
D1: 46280
A2: No. | B2: Unit Kerja | C2: PIC RAC | D2: %TL PEP Done | E2: Average
A3: 1 | B3: KC Bondowoso | C3: Febri Dwi Prabowo | D3: =_xlfn.XLOOKUP(B3, [1]PEP!$B:$B,[1]PEP!$G:$G) -> 1 | E3: =AVERAGE(D3:D15) -> 0.99033488
A4: 2 | B4: KC Genteng | C4: Febri Dwi Prabowo | D4: =_xlfn.XLOOKUP(B4, [1]PEP!$B:$B,[1]PEP!$G:$G) -> 1
A5: 3 | B5: KC Kediri | C5: Febri Dwi Prabowo | D5: =_xlfn.XLOOKUP(B5, [1]PEP!$B:$B,[1]PEP!$G:$G) -> 1
A6: 4 | B6: KC Kepanjen | C6: Febri Dwi Prabowo | D6: =_xlfn.XLOOKUP(B6, [1]PEP!$B:$B,[1]PEP!$G:$G) -> 0.95238095
A7: 5 | B7: KC Magetan | C7: Febri Dwi Prabowo | D7: =_xlfn.XLOOKUP(B7, [1]PEP!$B:$B,[1]PEP!$G:$G) -> 1
A8: 6 | B8: KC Malang Martadinata | C8: Febri Dwi Prabowo | D8: =_xlfn.XLOOKUP(B8, [1]PEP!$B:$B,[1]PEP!$G:$G) -> 1
A9: 7 | B9: KC Malang Soekarno Hatta | C9: Febri Dwi Prabowo | D9: =_xlfn.XLOOKUP(B9, [1]PEP!$B:$B,[1]PEP!$G:$G) -> 0.97752809
A10: 8 | B10: KC Nganjuk | C10: Febri Dwi Prabowo | D10: =_xlfn.XLOOKUP(B10, [1]PEP!$B:$B,[1]PEP!$G:$G) -> 1
A11: 9 | B11: KC Ngawi | C11: Febri Dwi Prabowo | D11: =_xlfn.XLOOKUP(B11, [1]PEP!$B:$B,[1]PEP!$G:$G) -> 1
A12: 10 | B12: KC Pacitan | C12: Febri Dwi Prabowo | D12: =_xlfn.XLOOKUP(B12, [1]PEP!$B:$B,[1]PEP!$G:$G) -> 1
A13: 11 | B13: KC Pare | C13: Febri Dwi Prabowo | D13: =_xlfn.XLOOKUP(B13, [1]PEP!$B:$B,[1]PEP!$G:$G) -> 1
A14: 12 | B14: KC Trenggalek | C14: Febri Dwi Prabowo | D14: =_xlfn.XLOOKUP(B14, [1]PEP!$B:$B,[1]PEP!$G:$G) -> 1
A15: 13 | B15: KC Tulungagung | C15: Febri Dwi Prabowo | D15: =_xlfn.XLOOKUP(B15, [1]PEP!$B:$B,[1]PEP!$G:$G) -> 0.94444444
A16: 14 | B16: KC Banyuwangi | C16: Made Windu Kuntara | D16: =_xlfn.XLOOKUP(B16, [1]PEP!$B:$B,[1]PEP!$G:$G) -> 1 | E16: =AVERAGE(D16:D27) -> 0.99462366
A17: 15 | B17: KC Blitar | C17: Made Windu Kuntara | D17: =_xlfn.XLOOKUP(B17, [1]PEP!$B:$B,[1]PEP!$G:$G) -> 1
A18: 16 | B18: KC Jember | C18: Made Windu Kuntara | D18: =_xlfn.XLOOKUP(B18, [1]PEP!$B:$B,[1]PEP!$G:$G) -> 1
A19: 17 | B19: KC Lumajang | C19: Made Windu Kuntara | D19: =_xlfn.XLOOKUP(B19, [1]PEP!$B:$B,[1]PEP!$G:$G) -> 1
A20: 18 | B20: KC Madiun | C20: Made Windu Kuntara | D20: =_xlfn.XLOOKUP(B20, [1]PEP!$B:$B,[1]PEP!$G:$G) -> 1
A21: 19 | B21: KC Malang Kawi | C21: Made Windu Kuntara | D21: =_xlfn.XLOOKUP(B21, [1]PEP!$B:$B,[1]PEP!$G:$G) -> 1
A22: 20 | B22: KC Malang Sutoyo | C22: Made Windu Kuntara | D22: =_xlfn.XLOOKUP(B22, [1]PEP!$B:$B,[1]PEP!$G:$G) -> 1
A23: 21 | B23: KC Pasuruan | C23: Made Windu Kuntara | D23: =_xlfn.XLOOKUP(B23, [1]PEP!$B:$B,[1]PEP!$G:$G) -> 0.96774194
A24: 22 | B24: KC Ponorogo | C24: Made Windu Kuntara | D24: =_xlfn.XLOOKUP(B24, [1]PEP!$B:$B,[1]PEP!$G:$G) -> 1
A25: 23 | B25: KC Probolinggo | C25: Made Windu Kuntara | D25: =_xlfn.XLOOKUP(B25, [1]PEP!$B:$B,[1]PEP!$G:$G) -> 0.96774194
A26: 24 | B26: KC Situbondo | C26: Made Windu Kuntara | D26: =_xlfn.XLOOKUP(B26, [1]PEP!$B:$B,[1]PEP!$G:$G) -> 1
A27: 25 | B27: KC Batu | C27: Made Windu Kuntara | D27: =_xlfn.XLOOKUP(B27, [1]PEP!$B:$B,[1]PEP!$G:$G) -> 1

Sheet Bad Data
D1: 46280
A2: No. | B2: Unit Kerja | C2: PIC RAC | D2: %Bad Data | E2: Average
A3: 1 | B3: KC Banyuwangi | C3: Made Windu Kuntara | D3: =_xlfn.XLOOKUP(B3, '[1]Bad Data'!$B:$B, '[1]Bad Data'!$D:$D) -> 0.00061 | E3: =AVERAGE(D3:D15) -> 0.00081923077
A4: 2 | B4: KC Blitar | C4: Made Windu Kuntara | D4: =_xlfn.XLOOKUP(B4, '[1]Bad Data'!$B:$B, '[1]Bad Data'!$D:$D) -> 0.00048
A5: 3 | B5: KC Jember | C5: Made Windu Kuntara | D5: =_xlfn.XLOOKUP(B5, '[1]Bad Data'!$B:$B, '[1]Bad Data'!$D:$D) -> 0.00089
A6: 4 | B6: KC Lumajang | C6: Made Windu Kuntara | D6: =_xlfn.XLOOKUP(B6, '[1]Bad Data'!$B:$B, '[1]Bad Data'!$D:$D) -> 0.00066
A7: 5 | B7: KC Madiun | C7: Made Windu Kuntara | D7: =_xlfn.XLOOKUP(B7, '[1]Bad Data'!$B:$B, '[1]Bad Data'!$D:$D) -> 0.00042
A8: 6 | B8: KC Malang Kawi | C8: Made Windu Kuntara | D8: =_xlfn.XLOOKUP(B8, '[1]Bad Data'!$B:$B, '[1]Bad Data'!$D:$D) -> 0.00011
A9: 7 | B9: KC Malang Sutoyo | C9: Made Windu Kuntara | D9: =_xlfn.XLOOKUP(B9, '[1]Bad Data'!$B:$B, '[1]Bad Data'!$D:$D) -> 0.00131
A10: 8 | B10: KC Pasuruan | C10: Made Windu Kuntara | D10: =_xlfn.XLOOKUP(B10, '[1]Bad Data'!$B:$B, '[1]Bad Data'!$D:$D) -> 0.00153
A11: 9 | B11: KC Ponorogo | C11: Made Windu Kuntara | D11: =_xlfn.XLOOKUP(B11, '[1]Bad Data'!$B:$B, '[1]Bad Data'!$D:$D) -> 0.00112
A12: 10 | B12: KC Probolinggo | C12: Made Windu Kuntara | D12: =_xlfn.XLOOKUP(B12, '[1]Bad Data'!$B:$B, '[1]Bad Data'!$D:$D) -> 0.00122
A13: 11 | B13: KC Situbondo | C13: Made Windu Kuntara | D13: =_xlfn.XLOOKUP(B13, '[1]Bad Data'!$B:$B, '[1]Bad Data'!$D:$D) -> 0.00096
A14: 12 | B14: KC Trenggalek | C14: Made Windu Kuntara | D14: =_xlfn.XLOOKUP(B14, '[1]Bad Data'!$B:$B, '[1]Bad Data'!$D:$D) -> 0.00062
A15: 13 | B15: KC Batu | C15: Made Windu Kuntara | D15: =_xlfn.XLOOKUP(B15, '[1]Bad Data'!$B:$B, '[1]Bad Data'!$D:$D) -> 0.00072
A16: 14 | B16: KC Bondowoso | C16: Febri Dwi Prabowo | D16: =_xlfn.XLOOKUP(B16, '[1]Bad Data'!$B:$B, '[1]Bad Data'!$D:$D) -> 0.00036 | E16: =AVERAGE(D16:D27) -> 0.0004975
A17: 15 | B17: KC Genteng | C17: Febri Dwi Prabowo | D17: =_xlfn.XLOOKUP(B17, '[1]Bad Data'!$B:$B, '[1]Bad Data'!$D:$D) -> 0.00022
A18: 16 | B18: KC Kediri | C18: Febri Dwi Prabowo | D18: =_xlfn.XLOOKUP(B18, '[1]Bad Data'!$B:$B, '[1]Bad Data'!$D:$D) -> 0.00034
A19: 17 | B19: KC Kepanjen | C19: Febri Dwi Prabowo | D19: =_xlfn.XLOOKUP(B19, '[1]Bad Data'!$B:$B, '[1]Bad Data'!$D:$D) -> 0.00019
A20: 18 | B20: KC Magetan | C20: Febri Dwi Prabowo | D20: =_xlfn.XLOOKUP(B20, '[1]Bad Data'!$B:$B, '[1]Bad Data'!$D:$D) -> 0.00027
A21: 19 | B21: KC Malang Martadinata | C21: Febri Dwi Prabowo | D21: =_xlfn.XLOOKUP(B21, '[1]Bad Data'!$B:$B, '[1]Bad Data'!$D:$D) -> 0.00037
A22: 20 | B22: KC Malang Soekarno Hatta | C22: Febri Dwi Prabowo | D22: =_xlfn.XLOOKUP(B22, '[1]Bad Data'!$B:$B, '[1]Bad Data'!$D:$D) -> 0.00092
A23: 21 | B23: KC Nganjuk | C23: Febri Dwi Prabowo | D23: =_xlfn.XLOOKUP(B23, '[1]Bad Data'!$B:$B, '[1]Bad Data'!$D:$D) -> 0.00083
A24: 22 | B24: KC Ngawi | C24: Febri Dwi Prabowo | D24: =_xlfn.XLOOKUP(B24, '[1]Bad Data'!$B:$B, '[1]Bad Data'!$D:$D) -> 0.00027
A25: 23 | B25: KC Pacitan | C25: Febri Dwi Prabowo | D25: =_xlfn.XLOOKUP(B25, '[1]Bad Data'!$B:$B, '[1]Bad Data'!$D:$D) -> 0.00057
A26: 24 | B26: KC Pare | C26: Febri Dwi Prabowo | D26: =_xlfn.XLOOKUP(B26, '[1]Bad Data'!$B:$B, '[1]Bad Data'!$D:$D) -> 0.0009
A27: 25 | B27: KC Tulungagung | C27: Febri Dwi Prabowo | D27: =_xlfn.XLOOKUP(B27, '[1]Bad Data'!$B:$B, '[1]Bad Data'!$D:$D) -> 0.00073

Sheet Pengkinian Data
D1: 46287
A2: No. | B2: Unit Kerja | C2: PIC RAC | D2: %Pengkinian Data | E2: Average
A3: 1 | B3: KC Banyuwangi | C3: Made Windu Kuntara | D3: =_xlfn.XLOOKUP(B3, '[1]Pengkinian Data'!$B:$B, '[1]Pengkinian Data'!$E:$E) -> 0.9977 | E3: =AVERAGE(D3:D15) -> 0.99604615
A4: 2 | B4: KC Blitar | C4: Made Windu Kuntara | D4: =_xlfn.XLOOKUP(B4, '[1]Pengkinian Data'!$B:$B, '[1]Pengkinian Data'!$E:$E) -> 0.9968
A5: 3 | B5: KC Jember | C5: Made Windu Kuntara | D5: =_xlfn.XLOOKUP(B5, '[1]Pengkinian Data'!$B:$B, '[1]Pengkinian Data'!$E:$E) -> 0.9948
A6: 4 | B6: KC Lumajang | C6: Made Windu Kuntara | D6: =_xlfn.XLOOKUP(B6, '[1]Pengkinian Data'!$B:$B, '[1]Pengkinian Data'!$E:$E) -> 0.9994
A7: 5 | B7: KC Madiun | C7: Made Windu Kuntara | D7: =_xlfn.XLOOKUP(B7, '[1]Pengkinian Data'!$B:$B, '[1]Pengkinian Data'!$E:$E) -> 1
A8: 6 | B8: KC Malang Kawi | C8: Made Windu Kuntara | D8: =_xlfn.XLOOKUP(B8, '[1]Pengkinian Data'!$B:$B, '[1]Pengkinian Data'!$E:$E) -> 1
A9: 7 | B9: KC Malang Sutoyo | C9: Made Windu Kuntara | D9: =_xlfn.XLOOKUP(B9, '[1]Pengkinian Data'!$B:$B, '[1]Pengkinian Data'!$E:$E) -> 0.9929
A10: 8 | B10: KC Pasuruan | C10: Made Windu Kuntara | D10: =_xlfn.XLOOKUP(B10, '[1]Pengkinian Data'!$B:$B, '[1]Pengkinian Data'!$E:$E) -> 0.991
A11: 9 | B11: KC Ponorogo | C11: Made Windu Kuntara | D11: =_xlfn.XLOOKUP(B11, '[1]Pengkinian Data'!$B:$B, '[1]Pengkinian Data'!$E:$E) -> 0.9919
A12: 10 | B12: KC Probolinggo | C12: Made Windu Kuntara | D12: =_xlfn.XLOOKUP(B12, '[1]Pengkinian Data'!$B:$B, '[1]Pengkinian Data'!$E:$E) -> 0.9976
A13: 11 | B13: KC Situbondo | C13: Made Windu Kuntara | D13: =_xlfn.XLOOKUP(B13, '[1]Pengkinian Data'!$B:$B, '[1]Pengkinian Data'!$E:$E) -> 0.9879
A14: 12 | B14: KC Trenggalek | C14: Made Windu Kuntara | D14: =_xlfn.XLOOKUP(B14, '[1]Pengkinian Data'!$B:$B, '[1]Pengkinian Data'!$E:$E) -> 1
A15: 13 | B15: KC Batu | C15: Made Windu Kuntara | D15: =_xlfn.XLOOKUP(B15, '[1]Pengkinian Data'!$B:$B, '[1]Pengkinian Data'!$E:$E) -> 0.9986
A16: 14 | B16: KC Bondowoso | C16: Febri Dwi Prabowo | D16: =_xlfn.XLOOKUP(B16, '[1]Pengkinian Data'!$B:$B, '[1]Pengkinian Data'!$E:$E) -> 0.9993 | E16: =AVERAGE(D16:D27) -> 0.99823333
A17: 15 | B17: KC Genteng | C17: Febri Dwi Prabowo | D17: =_xlfn.XLOOKUP(B17, '[1]Pengkinian Data'!$B:$B, '[1]Pengkinian Data'!$E:$E) -> 0.9996
A18: 16 | B18: KC Kediri | C18: Febri Dwi Prabowo | D18: =_xlfn.XLOOKUP(B18, '[1]Pengkinian Data'!$B:$B, '[1]Pengkinian Data'!$E:$E) -> 0.9999
A19: 17 | B19: KC Kepanjen | C19: Febri Dwi Prabowo | D19: =_xlfn.XLOOKUP(B19, '[1]Pengkinian Data'!$B:$B, '[1]Pengkinian Data'!$E:$E) -> 1
A20: 18 | B20: KC Magetan | C20: Febri Dwi Prabowo | D20: =_xlfn.XLOOKUP(B20, '[1]Pengkinian Data'!$B:$B, '[1]Pengkinian Data'!$E:$E) -> 0.9999
A21: 19 | B21: KC Malang Martadinata | C21: Febri Dwi Prabowo | D21: =_xlfn.XLOOKUP(B21, '[1]Pengkinian Data'!$B:$B, '[1]Pengkinian Data'!$E:$E) -> 0.9997
A22: 20 | B22: KC Malang Soekarno Hatta | C22: Febri Dwi Prabowo | D22: =_xlfn.XLOOKUP(B22, '[1]Pengkinian Data'!$B:$B, '[1]Pengkinian Data'!$E:$E) -> 0.9964
A23: 21 | B23: KC Nganjuk | C23: Febri Dwi Prabowo | D23: =_xlfn.XLOOKUP(B23, '[1]Pengkinian Data'!$B:$B, '[1]Pengkinian Data'!$E:$E) -> 0.9894
A24: 22 | B24: KC Ngawi | C24: Febri Dwi Prabowo | D24: =_xlfn.XLOOKUP(B24, '[1]Pengkinian Data'!$B:$B, '[1]Pengkinian Data'!$E:$E) -> 0.9994
A25: 23 | B25: KC Pacitan | C25: Febri Dwi Prabowo | D25: =_xlfn.XLOOKUP(B25, '[1]Pengkinian Data'!$B:$B, '[1]Pengkinian Data'!$E:$E) -> 1
A26: 24 | B26: KC Pare | C26: Febri Dwi Prabowo | D26: =_xlfn.XLOOKUP(B26, '[1]Pengkinian Data'!$B:$B, '[1]Pengkinian Data'!$E:$E) -> 0.9998
A27: 25 | B27: KC Tulungagung | C27: Febri Dwi Prabowo | D27: =_xlfn.XLOOKUP(B27, '[1]Pengkinian Data'!$B:$B, '[1]Pengkinian Data'!$E:$E) -> 0.9954

Sheet Sosialisasi
A1: No. | B1: Unit Kerja | C1: PIC RAC | D1: Materi* | E1: Tanggal Rencana Pelaksanaan | F1: Tanggal Pelaksanaan* | G1: Jumlah Peserta* | H1: Jabatan Peserta* | I1: Dokumen Evidence**
A2: 1 | B2: KC Balige
A3: 2 | B3: KC Binjai
A4: 3 | B4: KC Gunung Sitoli
A5: 4 | B5: KC Kabanjahe
A6: 5 | B6: KC Kisaran
A7: 6 | B7: KC Kota Pinang
A8: 7 | B8: KC Lubuk Pakam
A9: 8 | B9: KC Medan Gatot Subroto
A10: 9 | B10: KC Medan Iskandar Muda
A11: 10 | B11: KC Medan Putri Hijau
A12: 11 | B12: KC Medan Sisingamangaraja
A13: 12 | B13: KC Medan Thamrin
... A25: 24 | B25: KC Tebing Tinggi
B27: Keterangan:
B28: *Diisi jika telah dilaksanakan
B29: **https://bbri.id/MonevaRAC
B31: Evidence terdiri dari:
B32: 1. Dokumentasi Foto
B33: 2. Berita Acara
B34: 3. Absensi
B35: 4. Materi Sosisalisasi
B36: 5. List Pertanyaan

Sheet Uji Petik
A1: No. | B1: Unit Kerja | D1: PIC RAC | E1: Rencana Pelaksanaan | F1: Tanggal Pelaksanaan* | G1: Dokumen Evidence**
A3: 1 | B3: BO Malang Kawi | D3: Made Windu K | E3: 46273 | F3: 46273
A4: 2 | B4: BO Malang Soekarno Hatta | D4: Febri Dwi Prabowo | E4: 46274 | F4: 46274
A5: 3 | B5: BO Batu | D5: Made Wndu K | E5: 46275 | F5: 46275
A6: 4 | B6: BO Malang Martadinata | D6: Febri Dwi Prabowo | E6: 46276 | F6: 46276
A7: 5 | B7: BO Pasuruan | D7: Made Windu K | E7: 46286 | F7: 46286
A8: 6 | B8: BO Probolinggo | D8: Made Windu K | E8: 46287 | F8: 46287
A9: 7 | B9: BO Lumajang | D9: Made Windu K | E9: 46288 | F9: 46288
A10: 8 | B10: BO Jember | D10: Made Windu K | E10: 46289 | F10: 46289
A11: 9 | B11: BO Bondowoso | D11: Febri Dwi Prabowo | E11: 46290 | F11: 46290
A12: 10 | B12: BO Pacitan | D12: Febri Dwi Prabowo | E12: 5 Oktober 2026 | F12: 5 Oktober 2026
A13: 11 | B13: Bo Ponorogo | D13: Made Windu k | E13: 6 Oktober 2026 | F13: 6 Oktober 2026
A14: 12 | B14: BO Madiun | D14: Made Windu K | E14: 7 Oktober 2026 | F14: 7 Oktober 2026
A15: 13 | B15: BO Magetan | D15: Febri Dwi Prabowo | E15: 8 Oktober 2026 | F15: 8 Oktober 2026
A16: 14 | B16: BO Ngawi | D16: Febri Dwi Prabowo | E16: 9 Oktober 2026 | F16: 9 Oktober 2026
A17: 15 | B17: BO Trenggalek | D17: Febri Dwi Prabowo | E17: 12 Oktober 2026 | F17: 12 Oktober 2026
A18: 16 | B18: BO Tulungangung | D18: Made Windu K | E18: 13 Oktober 2026 | F18: 13 Oktober 2026
A19: 17 | B19: BO Kediri | D19: Ferbri Dwi Prabowo | E19: 14 Oktober 2026 | F19: 14 Oktober 2026
A20: 18 | B20: BO Pare | D20: Febri Dwi Prabowo | E20: 15 Oktober 2026 | F20: 15 Oktober 2026
A21: 19 | B21: BO Nganjuk | D21: Febri Dwi Prabowo | E21: 16 Oktober 2026 | F21: 16 Oktober 2026
A22: 20 | B22: BO Banyuwangi | D22: Made Windu K | E22: 19 Oktober 2026 | F22: 19 Oktober 2026
A23: 21 | B23: BO Genteng | D23: Febri Dwi Prabowo | E23: 20 Oktober 2026 | F23: 20 Oktober 2026
... A27: 25 | B27: BO Malang Sutoyo | D27: Made Windu K | E27: 24 Oktober 2026 | F27: 24 Oktober 2026
B30: Keterangan:
B31: *Diisi jika telah dilaksanakan
B32: **https://bri2-my.sharepoint.com/:f:/g/personal/00136153_hq_bri_co_id/IgDKyb_LCrC8RL6aLet5fhAnAVgP5YmVANRkNo95lLX-DEw?e=1Igwpo
B35: Evidence terdiri dari:
B36: 1. Dokumentasi Foto
B37: 2. Berita Acara
B38: 3. Absensi
B39: 4.Kertas Kerja
B40: 5. Laporan Uji Petik

Sheet Nilai Maturitas
A1: No. | B1: Unit Kerja | C1: PIC RAC | D1: Nilai maturitas | E1: Nilai maturitas | F1: Rating maturitas
A2: 3 | B2: BO Bondowoso | C2: Febri Dwi Prabowo | D2: 8.9345114 | E2: =AVERAGE(D2:D14) -> 8.458403 | F2: AB
A3: 4 | B3: BO Genteng | C3: Febri Dwi Prabowo | D3: 9.4197034
A4: 6 | B4: BO Kediri | C4: Febri Dwi Prabowo | D4: 8.2969195
A5: 7 | B5: BO Kepanjen | C5: Febri Dwi Prabowo | D5: 9.0017994
A6: 10 | B6: BO Magetan | C6: Febri Dwi Prabowo | D6: 9.0265267
A7: 12 | B7: BO Malang Marthadinata | C7: Febri Dwi Prabowo | D7: 9.6120147
A8: 13 | B8: BO Malang Soekarno Hatta | C8: Febri Dwi Prabowo | D8: 8.075122
A9: 15 | B9: BO Nganjuk | C9: Febri Dwi Prabowo | D9: 7.9716848
A10: 16 | B10: BO Ngawi | C10: Febri Dwi Prabowo | D10: 7.8784926
A11: 17 | B11: BO Pacitan | C11: Febri Dwi Prabowo | D11: 8.1995947
A12: 18 | B12: BO Pare | C12: Febri Dwi Prabowo | D12: 9.0017326
A13: 23 | B13: BO Trenggalek | C13: Febri Dwi Prabowo | D13: 9.2373549
A14: 24 | B14: BO Tulungagung | C14: Febri Dwi Prabowo | D14: 5.3037826
A15: 1 | B15: BO Banyuwangi | C15: Made Windu Kuntara | D15: 8.5519669 | E15: =AVERAGE(D15:D26) -> 8.5231051 | F15: AB
A16: 2 | B16: BO Blitar | C16: Made Windu Kuntara | D16: 8.4644643
A17: 5 | B17: BO Jember | C17: Made Windu Kuntara | D17: 9.5965768
A18: 8 | B18: BO Lumajang | C18: Made Windu Kuntara | D18: 7.5982713
A19: 9 | B19: BO Madiun | C19: Made Windu Kuntara | D19: 8.4328219
A20: 11 | B20: BO Malang Kawi | C20: Made Windu Kuntara | D20: 7.4723299
A21: 14 | B21: BO Malang Sutoyo | C21: Made Windu Kuntara | D21: 8.8887569
A22: 19 | B22: BO Pasuruan | C22: Made Windu Kuntara | D22: 6.9628799
A23: 20 | B23: BO Ponorogo | C23: Made Windu Kuntara | D23: 7.9455699
A24: 21 | B24: BO Probolinggo | C24: Made Windu Kuntara | D24: 9.736127
A25: 22 | B25: BO Situbondo | C25: Made Windu Kuntara | D25: 9.7366287
A26: 25 | B26: BO Batu | C26: Made Windu Kuntara | D26: 8.8908682

Sheet Penilaian Resiko
A1: No. | B1: Unit Kerja | C1: PIC RAC | D1: Nilai Risiko | E1: Nilai Risiko PIC | F1: Rating Risiko PIC
A2: 3 | B2: BO Bondowoso | C2: Febri Dwi Prabowo | D2: 5.7008771 | E2: =AVERAGE(D2:D14) -> 6.4519503 | F2: Medium to High
A3: 4 | B3: BO Genteng | C3: Febri Dwi Prabowo | D3: 6.7082039
A4: 6 | B4: BO Kediri | C4: Febri Dwi Prabowo | D4: 6.7082039
A5: 7 | B5: BO Kepanjen | C5: Febri Dwi Prabowo | D5: 6.4807407
A6: 10 | B6: BO Magetan | C6: Febri Dwi Prabowo | D6: 6.7082039
A7: 12 | B7: BO Malang Marthadinata | C7: Febri Dwi Prabowo | D7: 5.5
A8: 13 | B8: BO Malang Soekarno Hatta | C8: Febri Dwi Prabowo | D8: 5.5
A9: 15 | B9: BO Nganjuk | C9: Febri Dwi Prabowo | D9: 6.4807407
A10: 16 | B10: BO Ngawi | C10: Febri Dwi Prabowo | D10: 6.98212
A11: 17 | B11: BO Pacitan | C11: Febri Dwi Prabowo | D11: 6.7082039
A12: 18 | B12: BO Pare | C12: Febri Dwi Prabowo | D12: 6.2048368
A13: 23 | B13: BO Trenggalek | C13: Febri Dwi Prabowo | D13: 7.2111026
A14: 24 | B14: BO Tulungagung | C14: Febri Dwi Prabowo | D14: 6.98212
A15: 1 | B15: BO Banyuwangi | C15: Made Windu Kuntara | D15: 6.7082039 | E15: =AVERAGE(D15:D26) -> 5.9959205 | F15: Medium to High
A16: 2 | B16: BO Blitar | C16: Made Windu Kuntara | D16: 6.7082039
A17: 5 | B17: BO Jember | C17: Made Windu Kuntara | D17: 5.7008771
A18: 8 | B18: BO Lumajang | C18: Made Windu Kuntara | D18: 6.4226163
A19: 9 | B19: BO Madiun | C19: Made Windu Kuntara | D19: 6.5
A20: 11 | B20: BO Malang Kawi | C20: Made Windu Kuntara | D20: 4.6904158
A21: 14 | B21: BO Malang Sutoyo | C21: Made Windu Kuntara | D21: 5.7445626
A22: 19 | B22: BO Pasuruan | C22: Made Windu Kuntara | D22: 5.4772256
A23: 20 | B23: BO Ponorogo | C23: Made Windu Kuntara | D23: 6.4807407
A24: 21 | B24: BO Probolinggo | C24: Made Windu Kuntara | D24: 5.6124861
A25: 22 | B25: BO Situbondo | C25: Made Windu Kuntara | D25: 5.7008771
A26: 25 | B26: BO Batu | C26: Made Windu Kuntara | D26: 6.2048368

Sheet Maturitas Dashboard
A1: No. | B1: Unit Kerja | C1: PIC RAC | D1: Nilai Maturitas | E1: Nilai Maturitas PIC | F1: Rating Maturitas PIC
A2: 3 | B2: BO Bondowoso | C2: Febri Dwi Prabowo | D2: 7.375 | E2: =AVERAGE(D2:D14) -> 7.3365385 | F2: Baik
A3: 4 | B3: BO Genteng | C3: Febri Dwi Prabowo | D3: 7.375
A4: 6 | B4: BO Kediri | C4: Febri Dwi Prabowo | D4: 7.375
A5: 7 | B5: BO Kepanjen | C5: Febri Dwi Prabowo | D5: 7.375
A6: 10 | B6: BO Magetan | C6: Febri Dwi Prabowo | D6: 7.375
A7: 12 | B7: BO Malang Marthadinata | C7: Febri Dwi Prabowo | D7: 7.375
A8: 13 | B8: BO Malang Soekarno Hatta | C8: Febri Dwi Prabowo | D8: 7.375
A9: 15 | B9: BO Nganjuk | C9: Febri Dwi Prabowo | D9: 7.375
A10: 16 | B10: BO Ngawi | C10: Febri Dwi Prabowo | D10: 7.375
A11: 17 | B11: BO Pacitan | C11: Febri Dwi Prabowo | D11: 7.375
A12: 18 | B12: BO Pare | C12: Febri Dwi Prabowo | D12: 7.375
A13: 23 | B13: BO Trenggalek | C13: Febri Dwi Prabowo | D13: 7.375
A14: 24 | B14: BO Tulungagung | C14: Febri Dwi Prabowo | D14: 6.875
A15: 1 | B15: BO Banyuwangi | C15: Made Windu Kuntara | D15: 6.875 | E15: =AVERAGE(D15:D26) -> 7.2916667 | F15: Baik
A16: 2 | B16: BO Blitar | C16: Made Windu Kuntara | D16: 7.375
A17: 5 | B17: BO Jember | C17: Made Windu Kuntara | D17: 6.875
A18: 8 | B18: BO Lumajang | C18: Made Windu Kuntara | D18: 7.375
A19: 9 | B19: BO Madiun | C19: Made Windu Kuntara | D19: 7.375
A20: 11 | B20: BO Malang Kawi | C20: Made Windu Kuntara | D20: 7.375
A21: 14 | B21: BO Malang Sutoyo | C21: Made Windu Kuntara | D21: 7.375
A22: 19 | B22: BO Pasuruan | C22: Made Windu Kuntara | D22: 7.375
A23: 20 | B23: BO Ponorogo | C23: Made Windu Kuntara | D23: 7.375
A24: 21 | B24: BO Probolinggo | C24: Made Windu Kuntara | D24: 7.375
A25: 22 | B25: BO Situbondo | C25: Made Windu Kuntara | D25: 7.375
A26: 25 | B26: BO Batu | C26: Made Windu Kuntara | D26: 7.375

Sheet Overview
A2: No | B2: Aspek Penilaian | C2: Febri Dwi Prabowo | F2: Made Windu Kuntara
C3: Nilai | D3: Bobotan | E3: Score | F3: Nilai | G3: Bobotan | H3: Score
A4: 1 | B4: STR | C4: =IFERROR(COUNTIFS(STR!$V:$V, Overview!C$2, STR!$X:$X, "TRUE")/COUNTIFS(STR!$V:$V, Overview!C2), 0) -> 1 | D4: 0.15 | E4: =D4*C4 -> 0.15 | F4: =IFERROR(COUNTIFS(STR!$V:$V, Overview!F$2, STR!$X:$X, "TRUE")/COUNTIFS(STR!$V:$V, Overview!F2), 0) -> 1 | G4: 0.15 | H4: =G4*F4 -> 0.15
A5: 2 | B5: Bad Data | C5: =1-AVERAGEIF('Bad Data'!$C:$C, Overview!C$2, 'Bad Data'!$D:$D) -> 0.9995025 | D5: 0.1 | E5: =D5*C5 -> 0.09995025 | F5: =1-AVERAGEIF('Bad Data'!$C:$C, Overview!F$2, 'Bad Data'!$D:$D) -> 0.99918077 | G5: 0.1 | H5: =G5*F5 -> 0.099918077
A6: 3 | B6: Pengkinian Data | C6: =AVERAGEIF('Pengkinian Data'!$C:$C, Overview!C$2, 'Pengkinian Data'!$D:$D) -> 0.99823333 | D6: 0.1 | E6: =D6*C6 -> 0.099823333 | F6: =AVERAGEIF('Pengkinian Data'!$C:$C, Overview!F$2, 'Pengkinian Data'!$D:$D) -> 0.99604615 | G6: 0.1 | H6: =G6*F6 -> 0.099604615 | O6: .
A7: 4 | B7: Uji Petik | C7: {=IFERROR(SUMPRODUCT(--('[3]Uji Petik'!$E$3:$E$73<>""), --('[3]Uji Petik'!$C$3:$C$73=C2)) / SUMPRODUCT(--('[3]Uji Petik'!$C$3:$C$73=C2)), 0)} -> 0 | D7: 0 | E7: =D7*C7 -> 0 | F7: {=IFERROR(SUMPRODUCT(--('[3]Uji Petik'!$E$3:$E$73<>""), --('[3]Uji Petik'!$C$3:$C$73=F2)) / SUMPRODUCT(--('[3]Uji Petik'!$C$3:$C$73=F2)), 0)} -> 0 | G7: 0 | H7: =G7*F7 -> 0
A8: 5 | B8: Sosialisasi | C8: {=IFERROR(AVERAGE(IF([1]Sosialisasi!$C$1:$C$10000=C2, [1]Sosialisasi!$D$1:$D$10000)), 0)} -> 0.15384615 | D8: 0.15 | E8: =D8*C8 -> 0.023076923 | F8: {=IFERROR(AVERAGE(IF([1]Sosialisasi!$C$1:$C$10000=F2, [1]Sosialisasi!$D$1:$D$10000)), 0)} -> 0.41666667 | G8: 0.15 | H8: =G8*F8 -> 0.0625
A9: 6 | B9: EDD | C9: =AVERAGEIF('EDD PEP PPATK'!$C:$C, Overview!C$2, 'EDD PEP PPATK'!$D:$D) -> 0.99033488 | D9: 0.1 | E9: =D9*C9 -> 0.099033488 | F9: =AVERAGEIF('EDD PEP PPATK'!$C:$C, Overview!F$2, 'EDD PEP PPATK'!$D:$D) -> 0.99462366 | G9: 0.1 | H9: =G9*F9 -> 0.099462366
A10: 7 | B10: Self Learning Keikutsertaan | C10: {=IF(IFERROR(AVERAGE(IF('[1]Sheet2 (2)'!$C$1:$C$10000=C$2, '[1]Sheet2 (2)'!$D$1:$D$10000)), 0)>0.9, 1, IFERROR(AVERAGE(IF('[1]Sheet2 (2)'!$C$1:$C$10000=C$2, '[1]Sheet2 (2)'!$D$1:$D$10000)), 0))} -> 1 | D10: 0.05 | E10: =D10*C10 -> 0.05 | F10: {=IF(IFERROR(AVERAGE(IF('[1]Sheet2 (2)'!$C$1:$C$10000=F$2, '[1]Sheet2 (2)'!$D$1:$D$10000)), 0)>0.9, 1, IFERROR(AVERAGE(IF('[1]Sheet2 (2)'!$C$1:$C$10000=F$2, '[1]Sheet2 (2)'!$D$1:$D$10000)), 0))} -> 1 | G10: 0.05 | H10: =G10*F10 -> 0.05
A11: 8 | B11: Self Learning Score | C11: {=IF(IFERROR(AVERAGE(IF('[1]Sheet2 (3)'!$C$1:$C$10000=C2, '[1]Sheet2 (3)'!$D$1:$D$10000)), 0)>90, 1, IFERROR(AVERAGE(IF('[1]Sheet2 (3)'!$C$1:$C$10000=C2, '[1]Sheet2 (3)'!$D$1:$D$10000)), 0)/90)} -> 1 | D11: 0.05 | E11: =D11*C11 -> 0.05 | F11: {=IF(IFERROR(AVERAGE(IF('[1]Sheet2 (3)'!$C$1:$C$10000=F2, '[1]Sheet2 (3)'!$D$1:$D$10000)), 0)>90, 1, IFERROR(AVERAGE(IF('[1]Sheet2 (3)'!$C$1:$C$10000=F2, '[1]Sheet2 (3)'!$D$1:$D$10000)), 0)/90)} -> 1 | G11: 0.05 | H11: =G11*F11 -> 0.05
A12: 9 | B12: Maturitas | C12: =IF(AVERAGEIF('Nilai Maturitas'!$C:$C, Overview!C2, 'Nilai Maturitas'!$D:$D) > 8, 110%, AVERAGEIF('Nilai Maturitas'!$C:$C, Overview!C2, 'Nilai Maturitas'!$D:$D)/8*100%) -> 1.1 | D12: 0.1 | E12: =D12*C12 -> 0.11 | F12: =IF(AVERAGEIF('Nilai Maturitas'!$C:$C, Overview!F2, 'Nilai Maturitas'!$D:$D) > 8, 110%, AVERAGEIF('Nilai Maturitas'!$C:$C, Overview!F2, 'Nilai Maturitas'!$D:$D)/8*100%) -> 1.1 | G12: 0.1 | H12: =G12*F12 -> 0.11
A13: 10 | B13: Maturitas Dashboard | C13: =IF(AVERAGEIF('Maturitas Dashboard'!$C:$C, Overview!C$2, 'Maturitas Dashboard'!$D:$D) > 8, 110%, AVERAGEIF('Maturitas Dashboard'!$C:$C, Overview!C$2, 'Maturitas Dashboard'!$D:$D)/8*100%) -> 0.91706731 | D13: 0.1 | E13: =D13*C13 -> 0.091706731 | F13: =IF(AVERAGEIF('Maturitas Dashboard'!$C:$C, Overview!F$2, 'Maturitas Dashboard'!$D:$D) > 8, 110%, AVERAGEIF('Maturitas Dashboard'!$C:$C, Overview!F$2, 'Maturitas Dashboard'!$D:$D)/8*100%) -> 0.91145833 | G13: 0.1 | H13: =G13*F13 -> 0.091145833
A14: 11 | B14: Penilaian Resiko | C14: =IF(AVERAGEIF('Penilaian Resiko'!$C:$C, Overview!C$2, 'Penilaian Resiko'!$D:$D) < 5.8, 110%, IF(AVERAGEIF('Penilaian Resiko'!$C:$C, Overview!C$2, 'Penilaian Resiko'!$D:$D) <7.4, 3/4*100%, 3/5*100%)) -> 0.75 | D14: 0.1 | E14: =D14*C14 -> 0.075 | F14: =IF(AVERAGEIF('Penilaian Resiko'!$C:$C, Overview!F$2, 'Penilaian Resiko'!$D:$D) < 5.8, 110%, IF(AVERAGEIF('Penilaian Resiko'!$C:$C, Overview!F$2, 'Penilaian Resiko'!$D:$D) <7.4, 3/4*100%, 3/5*100%)) -> 0.75 | G14: 0.1 | H14: =G14*F14 -> 0.075
C15: Progress | E15: =SUM(E4:E14) -> 0.84859073 | F15: Progress | H15: =SUM(H4:H14) -> 0.88763089

Sheet Overview tanpa KPI
A2: No | B2: Aspek Penilaian | C2: Febri Dwi Prabowo | F2: Made Windu Kuntara
C3: Nilai | D3: Bobotan | E3: Score | F3: Nilai | G3: Bobotan | H3: Score
A4: 1 | B4: STR | C4: =IFERROR(COUNTIFS(STR!$V:$V, 'Overview tanpa KPI'!C$2, STR!$X:$X, "TRUE")/COUNTIFS(STR!$V:$V, 'Overview tanpa KPI'!C2), 0) -> 1 | D4: 0.15 | E4: =D4*C4 -> 0.15 | F4: =IFERROR(COUNTIFS(STR!$V:$V, 'Overview tanpa KPI'!F$2, STR!$X:$X, "TRUE")/COUNTIFS(STR!$V:$V, 'Overview tanpa KPI'!F2), 0) -> 1 | G4: 0.15 | H4: =G4*F4 -> 0.15
A5: 2 | B5: Bad Data | C5: =1-AVERAGEIF('Bad Data'!$C:$C, 'Overview tanpa KPI'!C$2, 'Bad Data'!$D:$D) -> 0.9995025 | D5: 0.1 | E5: =D5*C5 -> 0.09995025 | F5: =1-AVERAGEIF('Bad Data'!$C:$C, 'Overview tanpa KPI'!F$2, 'Bad Data'!$D:$D) -> 0.99918077 | G5: 0.1 | H5: =G5*F5 -> 0.099918077
A6: 3 | B6: Pengkinian Data | C6: =AVERAGEIF('Pengkinian Data'!$C:$C, 'Overview tanpa KPI'!C$2, 'Pengkinian Data'!$D:$D) -> 0.99823333 | D6: 0.1 | E6: =D6*C6 -> 0.099823333 | F6: =AVERAGEIF('Pengkinian Data'!$C:$C, 'Overview tanpa KPI'!F$2, 'Pengkinian Data'!$D:$D) -> 0.99604615 | G6: 0.1 | H6: =G6*F6 -> 0.099604615 | N6: .
A7: 4 | B7: Uji Petik | C7: {=IFERROR(SUMPRODUCT(--('[3]Uji Petik'!$E$3:$E$73<>""), --('[3]Uji Petik'!$C$3:$C$73=C2)) / SUMPRODUCT(--('[3]Uji Petik'!$C$3:$C$73=C2)), 0)} -> 0 | D7: 0 | E7: =D7*C7 -> 0 | F7: {=IFERROR(SUMPRODUCT(--('[3]Uji Petik'!$E$3:$E$73<>""), --('[3]Uji Petik'!$C$3:$C$73=F2)) / SUMPRODUCT(--('[3]Uji Petik'!$C$3:$C$73=F2)), 0)} -> 0 | G7: 0 | H7: =G7*F7 -> 0
A8: 5 | B8: Sosialisasi | C8: {=IFERROR(AVERAGE(IF([1]Sosialisasi!$C$1:$C$10000=C2, [1]Sosialisasi!$D$1:$D$10000)), 0)} -> 0.15384615 | D8: 0.15 | E8: =D8*C8 -> 0.023076923 | F8: {=IFERROR(AVERAGE(IF([1]Sosialisasi!$C$1:$C$10000=F2, [1]Sosialisasi!$D$1:$D$10000)), 0)} -> 0.41666667 | G8: 0.15 | H8: =G8*F8 -> 0.0625
A9: 6 | B9: EDD | C9: =AVERAGEIF('EDD PEP PPATK'!$C:$C, 'Overview tanpa KPI'!C$2, 'EDD PEP PPATK'!$D:$D) -> 0.99033488 | D9: 0.1 | E9: =D9*C9 -> 0.099033488 | F9: =AVERAGEIF('EDD PEP PPATK'!$C:$C, 'Overview tanpa KPI'!F$2, 'EDD PEP PPATK'!$D:$D) -> 0.99462366 | G9: 0.1 | H9: =G9*F9 -> 0.099462366
A10: 7 | B10: Self Learning Keikutsertaan | C10: {=IFERROR(AVERAGE(IF('[1]Sheet2 (2)'!$C$1:$C$10000=C$2, '[1]Sheet2 (2)'!$D$1:$D$10000)), 0)} -> 0.97031534 | D10: 0.05 | E10: =D10*C10 -> 0.048515767 | F10: {=IFERROR(AVERAGE(IF('[1]Sheet2 (2)'!$C$1:$C$10000=F$2, '[1]Sheet2 (2)'!$D$1:$D$10000)), 0)} -> 0.9577637 | G10: 0.05 | H10: =G10*F10 -> 0.047888185
A11: 8 | B11: Self Learning Score | C11: {=IFERROR(AVERAGE(IF('[1]Sheet2 (3)'!$C$1:$C$10000=C2, '[1]Sheet2 (3)'!$D$1:$D$10000)), 0)} -> 92.801999 | D11: 0.05 | E11: =D11*C11 -> 4.6400999 | F11: {=IFERROR(AVERAGE(IF('[1]Sheet2 (3)'!$C$1:$C$10000=F2, '[1]Sheet2 (3)'!$D$1:$D$10000)), 0)} -> 91.748103 | G11: 0.05 | H11: =G11*F11 -> 4.5874052
A12: 9 | B12: Maturitas | C12: =AVERAGEIF('Nilai Maturitas'!$C:$C, 'Overview tanpa KPI'!C2, 'Nilai Maturitas'!$D:$D) -> 8.458403 | D12: 0.1 | E12: =D12*C12 -> 0.8458403 | F12: =AVERAGEIF('Nilai Maturitas'!$C:$C, 'Overview tanpa KPI'!F2, 'Nilai Maturitas'!$D:$D) -> 8.5231051 | G12: 0.1 | H12: =G12*F12 -> 0.85231051
A13: 10 | B13: Maturitas Dashboard | C13: =AVERAGEIF('Maturitas Dashboard'!$C:$C, 'Overview tanpa KPI'!C$2, 'Maturitas Dashboard'!$D:$D) -> 7.3365385 | D13: 0.1 | E13: =D13*C13 -> 0.73365385 | F13: =AVERAGEIF('Maturitas Dashboard'!$C:$C, 'Overview tanpa KPI'!F$2, 'Maturitas Dashboard'!$D:$D) -> 7.2916667 | G13: 0.1 | H13: =G13*F13 -> 0.72916667
A14: 11 | B14: Penilaian Resiko | C14: =AVERAGEIF('Penilaian Resiko'!$C:$C, 'Overview tanpa KPI'!C$2, 'Penilaian Resiko'!$D:$D) -> 6.4519503 | D14: 0.1 | E14: =D14*C14 -> 0.64519503 | F14: =AVERAGEIF('Penilaian Resiko'!$C:$C, 'Overview tanpa KPI'!F$2, 'Penilaian Resiko'!$D:$D) -> 5.9959205 | G14: 0.1 | H14: =G14*F14 -> 0.59959205
C15: Progress | E15: =SUM(E4:E14) -> 7.3851889 | F15: Progress | H15: =SUM(H4:H14) -> 7.3278476
