Workbook

Sheet STR
A1: POSISI | B1: NAMA | C1: CIF | D1: No Rek/ Kartu Kredit | E1: RESIKO | F1: BRILINK | G1: STATUS PEKERJA | H1: DIGITAL SAVING | I1: SKENARIO | J1: SCORING | K1: INFO PARAM | L1: KATEGORI | M1: UNIT KERJA | N1: KANTOR CABANG | O1: KANTOR KANWIL | P1: REKOMENDASI UKER | Q1: REKOMENDASI UKK | R1: STATUS UKER | S1: STATUS | T1: DISPOSISI | U1: INFO LAINNYA | V1: Disposisi RAC | W1: Tanggal | X1: Status TL
A2: {=_xlfn._xlws.FILTER('[2]STR-2026-8-2026-8'!$A:$U, ISNUMBER(SEARCH("Bandung", '[2]STR-2026-8-2026-8'!$O:$O)), "")} -> 46265 | B2: ANAK BINJAI GROUP | C2: ACFRL16 | D2: 210401000765565 | E2: SEDANG | F2: Tidak | G2: Tidak | H2: Tidak | I2: Perpajakan | J2: 49 | K2: 41 | L2: Perpajakan | M2: KCP RIAU | N2: KC Bandung Martadinata | O2: Bandung | P2: 0 | Q2: 0 | R2: Belum TL | S2: Belum TL | T2: 90185537 - Moh.Khoerul Fajar Ar | U2: "-" | V2: =[3]STR!$V2 -> Gesang Jumadi | X2: =[3]STR!$X2 -> FALSE
A3: 46265 | B3: ALIFAH ADAWIYAH | C3: AZWV496 | D3: 377301060720531 | E3: SEDANG | F3: Tidak | G3: Tidak | H3: Tidak | I3: Narkotika - Area Lapas | J3: 50 | K3: 46 | L3: Narkotika | M3: UNIT CICALENGKA MAJALAYA | N3: KC Majalaya | O3: Bandung | P3: 0 | Q3: 0 | R3: Belum TL | S3: Belum TL | T3: 00336949 - Mochammad Al Farabi | U3: "-" | V3: =[3]STR!$V3 -> Gumilar Rudimaya | X3: =[3]STR!$X3 -> FALSE
A4: 46265 | B4: BIMA SAKTI BERSAUDARA | C4: BFR9769 | D4: 16501002893304 | E4: SEDANG | F4: Tidak | G4: Tidak | H4: Tidak | I4: Perpajakan | J4: 50 | K4: 1.33 | L4: Perpajakan | M4: KC Jatibarang | N4: KC Jatibarang | O4: Bandung | P4: 0 | Q4: 0 | R4: Belum TL | S4: Belum TL | T4: 90150130 - Intan Aida Pratiwi | U4: "-" | V4: =[3]STR!$V4 -> Gesang Jumadi | X4: =[3]STR!$X4 -> TRUE
A5: 46265 | B5: BERLIAN PANGAN INDONESIA | C5: BJT2785 | D5: 38901002567561 | E5: 0 | F5: Tidak | G5: Tidak | H5: Tidak | I5: Perpajakan | J5: 33 | K5: 41 | L5: Perpajakan | M5: KC Bandung Martadinata | N5: KC Bandung Martadinata | O5: Bandung | P5: 0 | Q5: 0 | R5: Belum TL | S5: Belum TL | T5: 90185538 - Muhammad Fahikal Auz | U5: "-" | V5: =[3]STR!$V5 -> Gesang Jumadi | X5: =[3]STR!$X5 -> FALSE | Z5: .
A6: 46265 | B6: CV BERKAH TEXTILE ABADI | C6: CX68960 | D6: 33701888168566 | E6: 0 | F6: Tidak | G6: Tidak | H6: Tidak | I6: Perpajakan | J6: 33 | K6: 41 | L6: Perpajakan | M6: KC Bandung Naripan | N6: KC Bandung Naripan | O6: Bandung | P6: 0 | Q6: 0 | R6: Belum TL | S6: Belum TL | T6: 00394521 - Muhammad Hibbanduta | U6: "-" | V6: =[3]STR!$V6 -> Gumilar Rudimaya | W6: 14/09/2026 | X6: =[3]STR!$X6 -> TRUE
A7: 46265 | B7: HERI YANA | C7: HCA0261 | D7: 40701056456506 | E7: 0 | F7: Tidak | G7: Tidak | H7: 0 | I7: Jual Beli Rekening - E channel Trx | J7: 33 | K7: 113 | L7: Narkotika/Judi Online/Penipuan | M7: KC Bandung Sukarno Hatta | N7: KC Bandung Sukarno Hatta | O7: Bandung | P7: 0 | Q7: 0 | R7: Belum TL | S7: Belum TL | T7: 0 | U7: "-" | V7: =[3]STR!$V7 -> Gumilar Rudimaya | X7: =[3]STR!$X7 -> FALSE
A8: 46265 | B8: IIM IMROAH | C8: IQ80358 | D8: 412301042068535 | E8: SEDANG | F8: Ya | G8: Tidak | H8: Ya | I8: Narkotika - Area Lapas | J8: 50 | K8: 46 | L8: Narkotika | M8: UNIT ASTANAJAPURA CIREBON GUNU | N8: KC Cirebon Gunung Jati | O8: Bandung | P8: 0 | Q8: 0 | R8: Belum TL | S8: Belum TL | T8: 00394520 - Frida Akbar Rani | U8: "-" | V8: =[3]STR!$V8 -> Gesang Jumadi | X8: =[3]STR!$X8 -> TRUE
A9: 46265 | B9: JARNI PRANATA PAKPAHAN | C9: JOX9513 | D9: 40701011707536 | E9: 0 | F9: Tidak | G9: Tidak | H9: 0 | I9: Jual Beli Rekening - E channel Trx | J9: 33 | K9: 113 | L9: Narkotika/Judi Online/Penipuan | M9: KC Bandung Sukarno Hatta | N9: KC Bandung Sukarno Hatta | O9: Bandung | P9: 0 | Q9: 0 | R9: Belum TL | S9: Belum TL | T9: 0 | U9: "-" | V9: =[3]STR!$V9 -> Gesang Jumadi | X9: =[3]STR!$X9 -> FALSE
A10: 46265 | B10: JUNITA DEVIANA | C10: JV63755 | D10: 377601018279536 | E10: SEDANG | F10: Tidak | G10: Tidak | H10: Tidak | I10: Prostitusi | J10: 47 | K10: 104 | L10: Prostitusi | M10: UNIT BUNIHAYU SUBANG | N10: KC Subang | O10: Bandung | P10: 0 | Q10: 0 | R10: Belum TL | S10: Belum TL | T10: 90185538 - Muhammad Fahikal Auz | U10: "-" | V10: =[3]STR!$V10 -> Kartiwan Ferry | X10: =[3]STR!$X10 -> FALSE
A11: 46265 | B11: KOPERASI YUFA JAYA ABADI | C11: KBFC696 | D11: 406301051047538 | E11: 0 | F11: Tidak | G11: Tidak | H11: 0 | I11: Jual Beli Rekening - E channel Trx | J11: 33 | K11: 113 | L11: Narkotika/Judi Online/Penipuan | M11: UNIT BOJONGPICUNG CIANJUR | N11: KC Cianjur | O11: Bandung | P11: 0 | Q11: 0 | R11: Belum TL | S11: Belum TL | T11: 0 | U11: "-" | V11: =[3]STR!$V11 -> Kartiwan Ferry | X11: =[3]STR!$X11 -> FALSE
A12: 46265 | B12: MADHAR MADHAVA MANGGALA | C12: MZXA187 | D12: 501199999308 | E12: SEDANG | F12: Tidak | G12: Tidak | H12: Tidak | I12: Perpajakan | J12: 48 | K12: 41 | L12: Perpajakan | M12: KC Bandung AA | N12: KC Bandung AA | O12: Bandung | P12: 0 | Q12: 0 | R12: Belum TL | S12: Belum TL | T12: 90150130 - Intan Aida Pratiwi | U12: "-" | V12: =[3]STR!$V12 -> Gumilar Rudimaya | X12: =[3]STR!$X12 -> FALSE
A13: 46265 | B13: PUTRI SOVIA GANIA | C13: PHF2053 | D13: 402001000012560 | E13: 0 | F13: Tidak | G13: Tidak | H13: 0 | I13: Jual Beli Rekening - E channel Trx | J13: 33 | K13: 113 | L13: Narkotika/Judi Online/Penipuan | M13: UNIT CISAGA BANJAR | N13: KC Banjar | O13: Bandung | P13: 0 | Q13: 0 | R13: Belum TL | S13: Belum TL | T13: 0 | U13: "-" | V13: =[3]STR!$V13 -> Gumilar Rudimaya | X13: =[3]STR!$X13 -> FALSE
A14: 46265 | B14: PT ROYAL INTI NUSA | C14: PLY8254 | D14: 501111111300 | E14: SEDANG | F14: Tidak | G14: Tidak | H14: Tidak | I14: Perpajakan | J14: 53 | K14: 41 | L14: Perpajakan | M14: KC Bandung AA | N14: KC Bandung AA | O14: Bandung | P14: 0 | Q14: 0 | R14: Belum TL | S14: Belum TL | T14: 90186796 - Devito Arya Wiradila | U14: "-" | V14: =[3]STR!$V14 -> Kartiwan Ferry | X14: =[3]STR!$X14 -> FALSE
A15: 46265 | B15: PANJI SETYO W | C15: POM5252 | D15: 65601039692500 | E15: 0 | F15: Tidak | G15: Tidak | H15: 0 | I15: Jual Beli Rekening - E channel Trx | J15: 33 | K15: 113 | L15: Narkotika/Judi Online/Penipuan | M15: KCP PADALARANG | N15: KC Cimahi | O15: Bandung | P15: 0 | Q15: 0 | R15: Belum TL | S15: Belum TL | T15: 0 | U15: "-" | V15: =[3]STR!$V15 -> Kartiwan Ferry | X15: =[3]STR!$X15 -> FALSE
A16: 46265 | B16: RUKENAH | C16: RERG795 | D16: 373201017322532 | E16: SEDANG | F16: Tidak | G16: Tidak | H16: Tidak | I16: Narkotika - Area Lapas | J16: 50 | K16: 46 | L16: Narkotika | M16: UNIT PAMANUKAN KOTA | N16: KC Pamanukan | O16: Bandung | P16: 0 | Q16: 0 | R16: Belum TL | S16: Belum TL | T16: 90186796 - Devito Arya Wiradila | U16: "-" | V16: =[3]STR!$V16 -> Gesang Jumadi | X16: =[3]STR!$X16 -> FALSE
A17: 46265 | B17: REKA BENTUK RUMAH | C17: RMEH688 | D17: 2501005263304 | E17: SEDANG | F17: Tidak | G17: Tidak | H17: Tidak | I17: Perpajakan | J17: 50 | K17: 41 | L17: Perpajakan | M17: KC Garut | N17: KC Garut | O17: Bandung | P17: 0 | Q17: 0 | R17: Belum TL | S17: Belum TL | T17: 00394520 - Frida Akbar Rani | U17: "-" | V17: =[3]STR!$V17 -> Gumilar Rudimaya | X17: =[3]STR!$X17 -> FALSE
A18: 46265 | B18: ROYAL MITRA SEHAT | C18: ROTM194 | D18: 38901001585304 | E18: 0 | F18: Tidak | G18: Tidak | H18: Tidak | I18: Perpajakan | J18: 33 | K18: 41 | L18: Perpajakan | M18: KC Bandung Martadinata | N18: KC Bandung Martadinata | O18: Bandung | P18: 0 | Q18: 0 | R18: Belum TL | S18: Belum TL | T18: 00336949 - Mochammad Al Farabi | U18: "-" | V18: =[3]STR!$V18 -> Gumilar Rudimaya | X18: =[3]STR!$X18 -> FALSE
A19: 46265 | B19: RULIE YANDI ADIETYA | C19: RROF839 | D19: 76201015872505 | E19: 0 | F19: Tidak | G19: Tidak | H19: 0 | I19: Jual Beli Rekening - E channel Trx | J19: 33 | K19: 113 | L19: Narkotika/Judi Online/Penipuan | M19: UNIT BUAH BATU | N19: KC Bandung Naripan | O19: Bandung | P19: 0 | Q19: 0 | R19: Belum TL | S19: Belum TL | T19: 0 | U19: "-" | V19: =[3]STR!$V19 -> Gumilar Rudimaya | X19: =[3]STR!$X19 -> FALSE
A20: 46265 | B20: PT TRI SAKTI PURWOSARI MAKMUR | C20: TGR7069 | D20: 13201001552302 | E20: SEDANG | F20: Tidak | G20: Tidak | H20: Tidak | I20: Perpajakan | J20: 50 | K20: 1.33 | L20: Perpajakan | M20: KC Majalaya | N20: KC Majalaya | O20: Bandung | P20: 0 | Q20: 0 | R20: Belum TL | S20: Belum TL | T20: 90185538 - Muhammad Fahikal Auz | U20: "-" | V20: =[3]STR!$V20 -> Gumilar Rudimaya | X20: =[3]STR!$X20 -> FALSE
A21: 46265 | B21: TAMIN | C21: TOE0068 | D21: 434501017282538 | E21: SEDANG | F21: Ya | G21: Tidak | H21: Tidak | I21: Narkotika - Area Lapas | J21: 50 | K21: 46 | L21: Narkotika | M21: UNIT SUKASARI PAMANUKAN | N21: KC Pamanukan | O21: Bandung | P21: 0 | Q21: 0 | R21: Belum TL | S21: Belum TL | T21: 00394520 - Frida Akbar Rani | U21: "-" | V21: =[3]STR!$V21 -> Kartiwan Ferry | X21: =[3]STR!$X21 -> FALSE
A22: 46265 | B22: YUNI MULYANINGSIH | C22: YBV9448 | D22: 54201028018504 | E22: 0 | F22: Tidak | G22: Tidak | H22: 0 | I22: Jual Beli Rekening - E channel Trx | J22: 33 | K22: 113 | L22: Narkotika/Judi Online/Penipuan | M22: KCP Pangandaran | N22: KC Banjar | O22: Bandung | P22: 0 | Q22: 0 | R22: Belum TL | S22: Belum TL | T22: 0 | U22: "-" | V22: =[3]STR!$V22 -> Gesang Jumadi | X22: =[3]STR!$X22 -> FALSE
A23: 46265 | B23: YOSHY YOLANDARI | C23: YRM3561 | D23: 326501007174500 | E23: 0 | F23: Tidak | G23: Tidak | H23: 0 | I23: Jual Beli Rekening - E channel Trx | J23: 33 | K23: 113 | L23: Narkotika/Judi Online/Penipuan | M23: UNIT SUKABUMI SELATAN | N23: KC Sukabumi | O23: Bandung | P23: 0 | Q23: 0 | R23: Belum TL | S23: Belum TL | T23: 0 | U23: "-" | V23: =[3]STR!$V23 -> Kartiwan Ferry | X23: =[3]STR!$X23 -> FALSE
A24: 46265 | B24: ZULHAM FADILAH | C24: ZR88602 | D24: 10501174459509 | E24: 0 | F24: Tidak | G24: Tidak | H24: 0 | I24: Jual Beli Rekening - E channel Trx | J24: 33 | K24: 113 | L24: Narkotika/Judi Online/Penipuan | M24: KC Cianjur | N24: KC Cianjur | O24: Bandung | P24: 0 | Q24: 0 | R24: Belum TL | S24: Belum TL | T24: 0 | U24: "-" | V24: =[3]STR!$V24 -> Gesang Jumadi | X24: =[3]STR!$X24 -> FALSE
A25: 46265 | B25: RISMA DARA FEBRIYANTI | C25: RJCM413 | D25: 9201001475568 | E25: SEDANG | F25: Tidak | G25: Tidak | H25: Tidak | I25: Narkotika - Area Lapas | J25: 50 | K25: 46 | L25: Narkotika | M25: KC Sukabumi | N25: KC Sukabumi | O25: Bandung | P25: Ya | Q25: Tidak | R25: Pending Approver | S25: Approved | T25: 00394521 - Muhammad Hibbanduta | U25: "-" | V25: =[3]STR!$V25 -> Gesang Jumadi | X25: =[3]STR!$X25 -> TRUE
A26: 46265 | B26: ELSA ELSANI RACHMADANI S | C26: ECP2218 | D26: 9201002315567 | E26: SEDANG | F26: Tidak | G26: Tidak | H26: Tidak | I26: Narkotika - Area Lapas | J26: 50 | K26: 46 | L26: Narkotika | M26: KC Sukabumi | N26: KC Sukabumi | O26: Bandung | P26: Tidak | Q26: Tidak | R26: Pending Approver | S26: Approved | T26: 90170665 - Mutiara Ayuningtyas | U26: "-" | V26: =[3]STR!$V26 -> Gesang Jumadi | X26: =[3]STR!$X26 -> TRUE
A27: 46265 | B27: DENA MEILANDIRA | C27: DCES557 | D27: 440101034748531 | E27: SEDANG | F27: Ya | G27: Tidak | H27: Tidak | I27: Pencurian Rekening | J27: 49 | K27: 59 | L27: Perbankan | M27: UNIT CIRACAP SUKABUMI | N27: KC Sukabumi | O27: Bandung | P27: Tidak | Q27: Tidak | R27: Pending Approver | S27: Approved | T27: 00394520 - Frida Akbar Rani | U27: "-" | V27: =[3]STR!$V27 -> Gesang Jumadi | X27: =[3]STR!$X27 -> TRUE
A28: 46265 | B28: MARIA MARTOGI SITUMORANG | C28: MJUP858 | D28: 501120307508 | E28: SEDANG | F28: Tidak | G28: Tidak | H28: Tidak | I28: Narkotika - Area Lapas | J28: 50 | K28: 48 | L28: Narkotika | M28: KC Bandung AA | N28: KC Bandung AA | O28: Bandung | P28: Ya | Q28: 0 | R28: Done | S28: Belum TL | T28: 00336949 - Mochammad Al Farabi | U28: "-" | V28: =[3]STR!$V28 -> Kartiwan Ferry | X28: =[3]STR!$X28 -> FALSE
A29: 46265 | B29: PT TAKABEA RESHI CONSULINDO | C29: PNT0204 | D29: 501005617565 | E29: 0 | F29: Tidak | G29: Tidak | H29: Tidak | I29: Perpajakan | J29: 33 | K29: 41 | L29: Perpajakan | M29: KC Bandung AA | N29: KC Bandung AA | O29: Bandung | P29: Tidak | Q29: Tidak | R29: Done | S29: Pending Checker | T29: 00394521 - Muhammad Hibbanduta | U29: "-" | V29: =[3]STR!$V29 -> Gesang Jumadi | X29: =[3]STR!$X29 -> TRUE
A30: 46265 | B30: PT SETIAP HARI BERUNTUNG | C30: PNH3807 | D30: 501575757560 | E30: 0 | F30: Tidak | G30: Tidak | H30: Tidak | I30: Perpajakan | J30: 33 | K30: 41 | L30: Perpajakan | M30: KC Bandung AA | N30: KC Bandung AA | O30: Bandung | P30: Tidak | Q30: Tidak | R30: Done | S30: Pending Checker | T30: 90186790 - Muhammad Alfin Farha | U30: "-" | V30: =[3]STR!$V30 -> Gesang Jumadi | X30: =[3]STR!$X30 -> TRUE
A31: 46265 | B31: RUANG ANTAR BINTANG | C31: RKQO123 | D31: 40501001560302 | E31: SEDANG | F31: Tidak | G31: Tidak | H31: Tidak | I31: Perpajakan | J31: 48 | K31: 41 | L31: Perpajakan | M31: KC Bandung Dago | N31: KC Bandung Dago | O31: Bandung | P31: Tidak | Q31: Tidak | R31: Done | S31: Pending Checker | T31: 00394520 - Frida Akbar Rani | U31: "-" | V31: =[3]STR!$V31 -> Gesang Jumadi | X31: =[3]STR!$X31 -> TRUE
A32: 46265 | B32: POS INDONESIA | C32: P020200 | D32: 501003551307 | E32: SEDANG | F32: Tidak | G32: Tidak | H32: Tidak | I32: Perpajakan | J32: 49 | K32: 1.33 | L32: Perpajakan | M32: KC Bandung AA | N32: KC Bandung AA | O32: Bandung | P32: Tidak | Q32: Tidak | R32: Done | S32: Pending Checker | T32: 90186790 - Muhammad Alfin Farha | U32: "-" | V32: =[3]STR!$V32 -> Gesang Jumadi | X32: =[3]STR!$X32 -> TRUE
A33: 46265 | B33: P3SRSS | C33: PKC2131 | D33: 28601002831300 | E33: SEDANG | F33: Tidak | G33: Tidak | H33: Tidak | I33: Perpajakan | J33: 48 | K33: 41 | L33: Perpajakan | M33: KC Bandung Dewi Sartika | N33: KC Bandung Dewi Sartika | O33: Bandung | P33: Tidak | Q33: Tidak | R33: Done | S33: Pending Checker | T33: 90170665 - Mutiara Ayuningtyas | U33: "-" | V33: =[3]STR!$V33 -> Gumilar Rudimaya | X33: =[3]STR!$X33 -> TRUE
A34: 46265 | B34: SOLUSI INTEGRASI LAYANAN KONEKTIVITAS | C34: SKEFN78 | D34: 40501001865304 | E34: 0 | F34: Tidak | G34: Tidak | H34: Tidak | I34: Perpajakan | J34: 33 | K34: 41 | L34: Perpajakan | M34: KC Bandung Dago | N34: KC Bandung Dago | O34: Bandung | P34: Tidak | Q34: Tidak | R34: Done | S34: Pending Checker | T34: 90171841 - Rifqi Aziz | U34: "-" | V34: =[3]STR!$V34 -> Gesang Jumadi | X34: =[3]STR!$X34 -> TRUE
A35: 46265 | B35: VIA MARGARETTA | C35: V615279 | D35: 40101000926567 | E35: TINGGI | F35: Ya | G35: Tidak | H35: Tidak | I35: Perpajakan | J35: 75 | K35: 1.33 | L35: Perpajakan | M35: KC Bandung Kopo | N35: KC Bandung Kopo | O35: Bandung | P35: Tidak | Q35: Tidak | R35: Done | S35: Pending Checker | T35: 90186790 - Muhammad Alfin Farha | U35: "-" | V35: =[3]STR!$V35 -> Gesang Jumadi | X35: =[3]STR!$X35 -> TRUE
A36: 46265 | B36: GOLDEN MOTOR BERSINAR | C36: GV86074 | D36: 40501999990564 | E36: 0 | F36: Tidak | G36: Tidak | H36: Tidak | I36: Perpajakan | J36: 33 | K36: 41 | L36: Perpajakan | M36: KC Bandung Dago | N36: KC Bandung Dago | O36: Bandung | P36: Tidak | Q36: Tidak | R36: Done | S36: Pending Checker | T36: 00394520 - Frida Akbar Rani | U36: "-" | V36: =[3]STR!$V36 -> Gesang Jumadi | X36: =[3]STR!$X36 -> TRUE
A37: 46265 | B37: HALLAA KREASI NUSANTARA | C37: HAFL387 | D37: 40501001777307 | E37: SEDANG | F37: Tidak | G37: Tidak | H37: Tidak | I37: Perpajakan | J37: 50 | K37: 41 | L37: Perpajakan | M37: KC Bandung Dago | N37: KC Bandung Dago | O37: Bandung | P37: Tidak | Q37: Tidak | R37: Done | S37: Pending Checker | T37: 90186796 - Devito Arya Wiradila | U37: "-" | V37: =[3]STR!$V37 -> Gesang Jumadi | X37: =[3]STR!$X37 -> TRUE
A38: 46265 | B38: HEDI HERMAWAN | C38: HEA4717 | D38: 40101000525565 | E38: SEDANG | F38: Tidak | G38: Tidak | H38: Tidak | I38: Perpajakan | J38: 60 | K38: 1.33 | L38: Perpajakan | M38: KC Bandung Kopo | N38: KC Bandung Kopo | O38: Bandung | P38: Tidak | Q38: Tidak | R38: Done | S38: Pending Checker | T38: 00336949 - Mochammad Al Farabi | U38: "-" | V38: =[3]STR!$V38 -> Gesang Jumadi | X38: =[3]STR!$X38 -> TRUE
A39: 46265 | B39: MITRA DISTRIBUSI SEMBAKO | C39: MACOR46 | D39: 501999999566 | E39: SEDANG | F39: Tidak | G39: Tidak | H39: Tidak | I39: Perpajakan | J39: 50 | K39: 41 | L39: Perpajakan | M39: KC Bandung AA | N39: KC Bandung AA | O39: Bandung | P39: Tidak | Q39: Tidak | R39: Done | S39: Pending Checker | T39: 00394520 - Frida Akbar Rani | U39: "-" | V39: =[3]STR!$V39 -> Gesang Jumadi | X39: =[3]STR!$X39 -> TRUE
A40: 46265 | B40: MEGA ABADI SENTOSA | C40: MAFDF97 | D40: 28601003171305 | E40: SEDANG | F40: Tidak | G40: Tidak | H40: Tidak | I40: Perpajakan | J40: 48 | K40: 41 | L40: Perpajakan | M40: KC Bandung Dewi Sartika | N40: KC Bandung Dewi Sartika | O40: Bandung | P40: Tidak | Q40: Tidak | R40: Done | S40: Pending Checker | T40: 90150130 - Intan Aida Pratiwi | U40: "-" | V40: =[3]STR!$V40 -> Gumilar Rudimaya | X40: =[3]STR!$X40 -> TRUE
...

Sheet EDD PEP PPATK
D1: 46280
A2: No. | B2: Unit Kerja | C2: PIC RAC | D2: %Pengkinian Data | E2: Average RAC RAC
A3: 1 | B3: KC Bandung AA | C3: Gesang Jumadi | D3: =_xlfn.XLOOKUP(B3, [1]PEP!$B:$B,[1]PEP!$G:$G) -> 1 | E3: =AVERAGE(D3:D17) -> 0.96660419
A4: 2 | B4: KC Bandung Dago | C4: Gesang Jumadi | D4: =_xlfn.XLOOKUP(B4, [1]PEP!$B:$B,[1]PEP!$G:$G) -> 1
A5: 3 | B5: KC Bandung Kopo | C5: Gesang Jumadi | D5: =_xlfn.XLOOKUP(B5, [1]PEP!$B:$B,[1]PEP!$G:$G) -> 0.93939394
A6: 4 | B6: KC Bandung Sukarno Hatta | C6: Gesang Jumadi | D6: =_xlfn.XLOOKUP(B6, [1]PEP!$B:$B,[1]PEP!$G:$G) -> 0.984375
A7: 5 | B7: KC Banjar | C7: Gesang Jumadi | D7: =_xlfn.XLOOKUP(B7, [1]PEP!$B:$B,[1]PEP!$G:$G) -> 0.94871795
A8: 6 | B8: KC Ciamis | C8: Gesang Jumadi | D8: =_xlfn.XLOOKUP(B8, [1]PEP!$B:$B,[1]PEP!$G:$G) -> 1
A9: 7 | B9: KC Cianjur | C9: Gesang Jumadi | D9: =_xlfn.XLOOKUP(B9, [1]PEP!$B:$B,[1]PEP!$G:$G) -> 0.97368421
A10: 8 | B10: KC Cirebon Gunung Jati | C10: Gesang Jumadi | D10: =_xlfn.XLOOKUP(B10, [1]PEP!$B:$B,[1]PEP!$G:$G) -> 1
A11: 9 | B11: KC Cirebon Kartini | C11: Gesang Jumadi | D11: =_xlfn.XLOOKUP(B11, [1]PEP!$B:$B,[1]PEP!$G:$G) -> 0.91428571
A12: 10 | B12: KC Indramayu | C12: Gesang Jumadi | D12: =_xlfn.XLOOKUP(B12, [1]PEP!$B:$B,[1]PEP!$G:$G) -> 0.9
A13: 11 | B13: KC Jatibarang | C13: Gesang Jumadi | D13: =_xlfn.XLOOKUP(B13, [1]PEP!$B:$B,[1]PEP!$G:$G) -> 0.88888889
A14: 12 | B14: KC Kuningan | C14: Gesang Jumadi | D14: =_xlfn.XLOOKUP(B14, [1]PEP!$B:$B,[1]PEP!$G:$G) -> 1
A15: 13 | B15: KC Majalengka | C15: Gesang Jumadi | D15: =_xlfn.XLOOKUP(B15, [1]PEP!$B:$B,[1]PEP!$G:$G) -> 0.97297297
... A17: 15 | B17: KC Sukabumi | C17: Gesang Jumadi | D17: =_xlfn.XLOOKUP(B17, [1]PEP!$B:$B,[1]PEP!$G:$G) -> 0.97674419
A18: 16 | B18: KC Bandung A.H. Nasution | C18: Gumilar Rudimaya | D18: =_xlfn.XLOOKUP(B18, [1]PEP!$B:$B,[1]PEP!$G:$G) -> 1 | E18: =AVERAGE(D18:D32) -> 0.96376319
A19: 17 | B19: KC Bandung Dewi Sartika | C19: Gumilar Rudimaya | D19: =_xlfn.XLOOKUP(B19, [1]PEP!$B:$B,[1]PEP!$G:$G) -> 1
A20: 18 | B20: KC Bandung Martadinata | C20: Gumilar Rudimaya | D20: =_xlfn.XLOOKUP(B20, [1]PEP!$B:$B,[1]PEP!$G:$G) -> 0.96103896
A21: 19 | B21: KC Bandung Naripan | C21: Gumilar Rudimaya | D21: =_xlfn.XLOOKUP(B21, [1]PEP!$B:$B,[1]PEP!$G:$G) -> 0.94117647
A22: 20 | B22: KC Bandung Setiabudi | C22: Gumilar Rudimaya | D22: =_xlfn.XLOOKUP(B22, [1]PEP!$B:$B,[1]PEP!$G:$G) -> 1
A23: 21 | B23: KC Cibadak | C23: Gumilar Rudimaya | D23: =_xlfn.XLOOKUP(B23, [1]PEP!$B:$B,[1]PEP!$G:$G) -> 0.92857143
A24: 22 | B24: KC Cimahi | C24: Gumilar Rudimaya | D24: =_xlfn.XLOOKUP(B24, [1]PEP!$B:$B,[1]PEP!$G:$G) -> 0.95555556
A25: 23 | B25: KC Garut | C25: Gumilar Rudimaya | D25: =_xlfn.XLOOKUP(B25, [1]PEP!$B:$B,[1]PEP!$G:$G) -> 0.98076923
A26: 24 | B26: KC Majalaya | C26: Gumilar Rudimaya | D26: =_xlfn.XLOOKUP(B26, [1]PEP!$B:$B,[1]PEP!$G:$G) -> 0.93333333
A27: 25 | B27: KC Purwakarta | C27: Gumilar Rudimaya | D27: =_xlfn.XLOOKUP(B27, [1]PEP!$B:$B,[1]PEP!$G:$G) -> 0.96666667
A28: 26 | B28: KC Singaparna | C28: Gumilar Rudimaya | D28: =_xlfn.XLOOKUP(B28, [1]PEP!$B:$B,[1]PEP!$G:$G) -> 1
A29: 27 | B29: KC Soreang | C29: Gumilar Rudimaya | D29: =_xlfn.XLOOKUP(B29, [1]PEP!$B:$B,[1]PEP!$G:$G) -> 0.9047619
A30: 28 | B30: KC Subang | C30: Gumilar Rudimaya | D30: =_xlfn.XLOOKUP(B30, [1]PEP!$B:$B,[1]PEP!$G:$G) -> 0.97058824
... A32: 30 | B32: KC Tasikmalaya | C32: Gumilar Rudimaya | D32: =_xlfn.XLOOKUP(B32, [1]PEP!$B:$B,[1]PEP!$G:$G) -> 0.92307692

Sheet Sosialisasi
A1: No. | B1: Unit Kerja | C1: PIC RAC | D1: Materi* | E1: Tanggal Rencana Pelaksanaan | F1: Tanggal Pelaksanaan* | G1: Jumlah Peserta* | H1: Jabatan Peserta* | I1: Dokumen Evidence**
A2: 1 | B2: KC Balige
A3: 2 | B3: KC Binjai
A4: 3 | B4: KC Gunung Sitoli
A5: 4 | B5: KC Kabanjahe
A6: 5 | B6: KC Kisaran
A7: 6 | B7: KC Kota Pinang
A8: 7 | B8: KC Lubuk Pakam
A9: 8 | B9: KC Medan Gatot Subroto
A10: 9 | B10: KC Medan Iskandar Muda
A11: 10 | B11: KC Medan Putri Hijau
A12: 11 | B12: KC Medan Sisingamangaraja
A13: 12 | B13: KC Medan Thamrin
... A25: 24 | B25: KC Tebing Tinggi
B27: Keterangan:
B28: *Diisi jika telah dilaksanakan
B29: **https://bbri.id/MonevaRAC
B31: Evidence terdiri dari:
B32: 1. Dokumentasi Foto
B33: 2. Berita Acara
B34: 3. Absensi
B35: 4. Materi Sosisalisasi
B36: 5. List Pertanyaan

Sheet Bad Data
D1: 46280
A2: No. | B2: Unit Kerja | C2: PIC RAC | D2: %Pengkinian Data | E2: Average RAC RAC
A3: 2 | B3: KC Bandung AA | C3: Gesang Jumadi | D3: =_xlfn.XLOOKUP(B3, '[1]Bad Data'!$B:$B, '[1]Bad Data'!$D:$D) -> 0.00552 | E3: =AVERAGE(D3:D17) -> 0.0051446667
A4: 3 | B4: KC Bandung Dago | C4: Gesang Jumadi | D4: =_xlfn.XLOOKUP(B4, '[1]Bad Data'!$B:$B, '[1]Bad Data'!$D:$D) -> 0.00497
A5: 5 | B5: KC Bandung Kopo | C5: Gesang Jumadi | D5: =_xlfn.XLOOKUP(B5, '[1]Bad Data'!$B:$B, '[1]Bad Data'!$D:$D) -> 0.00366
A6: 9 | B6: KC Bandung Sukarno Hatta | C6: Gesang Jumadi | D6: =_xlfn.XLOOKUP(B6, '[1]Bad Data'!$B:$B, '[1]Bad Data'!$D:$D) -> 0.00953
A7: 10 | B7: KC Banjar | C7: Gesang Jumadi | D7: =_xlfn.XLOOKUP(B7, '[1]Bad Data'!$B:$B, '[1]Bad Data'!$D:$D) -> 0.00699
A8: 11 | B8: KC Ciamis | C8: Gesang Jumadi | D8: =_xlfn.XLOOKUP(B8, '[1]Bad Data'!$B:$B, '[1]Bad Data'!$D:$D) -> 0.0029
A9: 12 | B9: KC Cianjur | C9: Gesang Jumadi | D9: =_xlfn.XLOOKUP(B9, '[1]Bad Data'!$B:$B, '[1]Bad Data'!$D:$D) -> 0.00181
A10: 15 | B10: KC Cirebon Gunung Jati | C10: Gesang Jumadi | D10: =_xlfn.XLOOKUP(B10, '[1]Bad Data'!$B:$B, '[1]Bad Data'!$D:$D) -> 0.00238
A11: 16 | B11: KC Cirebon Kartini | C11: Gesang Jumadi | D11: =_xlfn.XLOOKUP(B11, '[1]Bad Data'!$B:$B, '[1]Bad Data'!$D:$D) -> 0.00405
A12: 18 | B12: KC Indramayu | C12: Gesang Jumadi | D12: =_xlfn.XLOOKUP(B12, '[1]Bad Data'!$B:$B, '[1]Bad Data'!$D:$D) -> 0.00414
A13: 19 | B13: KC Jatibarang | C13: Gesang Jumadi | D13: =_xlfn.XLOOKUP(B13, '[1]Bad Data'!$B:$B, '[1]Bad Data'!$D:$D) -> 0.00617
A14: 20 | B14: KC Kuningan | C14: Gesang Jumadi | D14: =_xlfn.XLOOKUP(B14, '[1]Bad Data'!$B:$B, '[1]Bad Data'!$D:$D) -> 0.00676
A15: 22 | B15: KC Majalengka | C15: Gesang Jumadi | D15: =_xlfn.XLOOKUP(B15, '[1]Bad Data'!$B:$B, '[1]Bad Data'!$D:$D) -> 0.00401
... A17: 28 | B17: KC Sukabumi | C17: Gesang Jumadi | D17: =_xlfn.XLOOKUP(B17, '[1]Bad Data'!$B:$B, '[1]Bad Data'!$D:$D) -> 0.00553
A18: 1 | B18: KC Bandung A.H. Nasution | C18: Gumilar Rudimaya | D18: =_xlfn.XLOOKUP(B18, '[1]Bad Data'!$B:$B, '[1]Bad Data'!$D:$D) -> 0.00041 | E18: =AVERAGE(D18:D32) -> 0.0053566667
A19: 4 | B19: KC Bandung Dewi Sartika | C19: Gumilar Rudimaya | D19: =_xlfn.XLOOKUP(B19, '[1]Bad Data'!$B:$B, '[1]Bad Data'!$D:$D) -> 0.00262
A20: 6 | B20: KC Bandung Martadinata | C20: Gumilar Rudimaya | D20: =_xlfn.XLOOKUP(B20, '[1]Bad Data'!$B:$B, '[1]Bad Data'!$D:$D) -> 0.00031
A21: 7 | B21: KC Bandung Naripan | C21: Gumilar Rudimaya | D21: =_xlfn.XLOOKUP(B21, '[1]Bad Data'!$B:$B, '[1]Bad Data'!$D:$D) -> 0.00361
A22: 8 | B22: KC Bandung Setiabudi | C22: Gumilar Rudimaya | D22: =_xlfn.XLOOKUP(B22, '[1]Bad Data'!$B:$B, '[1]Bad Data'!$D:$D) -> 0.00877
A23: 13 | B23: KC Cibadak | C23: Gumilar Rudimaya | D23: =_xlfn.XLOOKUP(B23, '[1]Bad Data'!$B:$B, '[1]Bad Data'!$D:$D) -> 0.01389
A24: 14 | B24: KC Cimahi | C24: Gumilar Rudimaya | D24: =_xlfn.XLOOKUP(B24, '[1]Bad Data'!$B:$B, '[1]Bad Data'!$D:$D) -> 0.00544
A25: 17 | B25: KC Garut | C25: Gumilar Rudimaya | D25: =_xlfn.XLOOKUP(B25, '[1]Bad Data'!$B:$B, '[1]Bad Data'!$D:$D) -> 0.00269
A26: 21 | B26: KC Majalaya | C26: Gumilar Rudimaya | D26: =_xlfn.XLOOKUP(B26, '[1]Bad Data'!$B:$B, '[1]Bad Data'!$D:$D) -> 0.00535
A27: 24 | B27: KC Purwakarta | C27: Gumilar Rudimaya | D27: =_xlfn.XLOOKUP(B27, '[1]Bad Data'!$B:$B, '[1]Bad Data'!$D:$D) -> 0.00406
A28: 25 | B28: KC Singaparna | C28: Gumilar Rudimaya | D28: =_xlfn.XLOOKUP(B28, '[1]Bad Data'!$B:$B, '[1]Bad Data'!$D:$D) -> 0.00493
A29: 26 | B29: KC Soreang | C29: Gumilar Rudimaya | D29: =_xlfn.XLOOKUP(B29, '[1]Bad Data'!$B:$B, '[1]Bad Data'!$D:$D) -> 0.00307
A30: 27 | B30: KC Subang | C30: Gumilar Rudimaya | D30: =_xlfn.XLOOKUP(B30, '[1]Bad Data'!$B:$B, '[1]Bad Data'!$D:$D) -> 0.00978
... A32: 30 | B32: KC Tasikmalaya | C32: Gumilar Rudimaya | D32: =_xlfn.XLOOKUP(B32, '[1]Bad Data'!$B:$B, '[1]Bad Data'!$D:$D) -> 0.00664

Sheet Pengkinian Data
D1: 46280
A2: No. | B2: Unit Kerja | C2: PIC RAC | D2: %Pengkinian Data | E2: Average RAC RAC
A3: 2 | B3: KC Bandung AA | C3: Gesang Jumadi | D3: =_xlfn.XLOOKUP(B3,'[1]Pengkinian Data'!$B:$B, '[1]Pengkinian Data'!$E:$E) -> 0.9968 | E3: =AVERAGE(D3:D17) -> 0.90608
A4: 3 | B4: KC Bandung Dago | C4: Gesang Jumadi | D4: =_xlfn.XLOOKUP(B4,'[1]Pengkinian Data'!$B:$B, '[1]Pengkinian Data'!$E:$E) -> 0.8727
A5: 5 | B5: KC Bandung Kopo | C5: Gesang Jumadi | D5: =_xlfn.XLOOKUP(B5,'[1]Pengkinian Data'!$B:$B, '[1]Pengkinian Data'!$E:$E) -> 0.9608
A6: 9 | B6: KC Bandung Sukarno Hatta | C6: Gesang Jumadi | D6: =_xlfn.XLOOKUP(B6,'[1]Pengkinian Data'!$B:$B, '[1]Pengkinian Data'!$E:$E) -> 0.9266
A7: 10 | B7: KC Banjar | C7: Gesang Jumadi | D7: =_xlfn.XLOOKUP(B7,'[1]Pengkinian Data'!$B:$B, '[1]Pengkinian Data'!$E:$E) -> 0.8433
A8: 11 | B8: KC Ciamis | C8: Gesang Jumadi | D8: =_xlfn.XLOOKUP(B8,'[1]Pengkinian Data'!$B:$B, '[1]Pengkinian Data'!$E:$E) -> 0.9015
A9: 12 | B9: KC Cianjur | C9: Gesang Jumadi | D9: =_xlfn.XLOOKUP(B9,'[1]Pengkinian Data'!$B:$B, '[1]Pengkinian Data'!$E:$E) -> 1
A10: 15 | B10: KC Cirebon Gunung Jati | C10: Gesang Jumadi | D10: =_xlfn.XLOOKUP(B10,'[1]Pengkinian Data'!$B:$B, '[1]Pengkinian Data'!$E:$E) -> 0.8999
A11: 16 | B11: KC Cirebon Kartini | C11: Gesang Jumadi | D11: =_xlfn.XLOOKUP(B11,'[1]Pengkinian Data'!$B:$B, '[1]Pengkinian Data'!$E:$E) -> 0.9432
A12: 18 | B12: KC Indramayu | C12: Gesang Jumadi | D12: =_xlfn.XLOOKUP(B12,'[1]Pengkinian Data'!$B:$B, '[1]Pengkinian Data'!$E:$E) -> 0.8577
A13: 19 | B13: KC Jatibarang | C13: Gesang Jumadi | D13: =_xlfn.XLOOKUP(B13,'[1]Pengkinian Data'!$B:$B, '[1]Pengkinian Data'!$E:$E) -> 0.8376
A14: 20 | B14: KC Kuningan | C14: Gesang Jumadi | D14: =_xlfn.XLOOKUP(B14,'[1]Pengkinian Data'!$B:$B, '[1]Pengkinian Data'!$E:$E) -> 0.8208
A15: 22 | B15: KC Majalengka | C15: Gesang Jumadi | D15: =_xlfn.XLOOKUP(B15,'[1]Pengkinian Data'!$B:$B, '[1]Pengkinian Data'!$E:$E) -> 0.9985
... A17: 28 | B17: KC Sukabumi | C17: Gesang Jumadi | D17: =_xlfn.XLOOKUP(B17,'[1]Pengkinian Data'!$B:$B, '[1]Pengkinian Data'!$E:$E) -> 0.884
A18: 1 | B18: KC Bandung A.H. Nasution | C18: Gumilar Rudimaya | D18: =_xlfn.XLOOKUP(B18,'[1]Pengkinian Data'!$B:$B, '[1]Pengkinian Data'!$E:$E) -> 1 | E18: =AVERAGE(D18:D32) -> 0.90720667
A19: 4 | B19: KC Bandung Dewi Sartika | C19: Gumilar Rudimaya | D19: =_xlfn.XLOOKUP(B19,'[1]Pengkinian Data'!$B:$B, '[1]Pengkinian Data'!$E:$E) -> 0.9672
A20: 6 | B20: KC Bandung Martadinata | C20: Gumilar Rudimaya | D20: =_xlfn.XLOOKUP(B20,'[1]Pengkinian Data'!$B:$B, '[1]Pengkinian Data'!$E:$E) -> 1
A21: 7 | B21: KC Bandung Naripan | C21: Gumilar Rudimaya | D21: =_xlfn.XLOOKUP(B21,'[1]Pengkinian Data'!$B:$B, '[1]Pengkinian Data'!$E:$E) -> 0.9944
A22: 8 | B22: KC Bandung Setiabudi | C22: Gumilar Rudimaya | D22: =_xlfn.XLOOKUP(B22,'[1]Pengkinian Data'!$B:$B, '[1]Pengkinian Data'!$E:$E) -> 0.8844
A23: 13 | B23: KC Cibadak | C23: Gumilar Rudimaya | D23: =_xlfn.XLOOKUP(B23,'[1]Pengkinian Data'!$B:$B, '[1]Pengkinian Data'!$E:$E) -> 0.8479
A24: 14 | B24: KC Cimahi | C24: Gumilar Rudimaya | D24: =_xlfn.XLOOKUP(B24,'[1]Pengkinian Data'!$B:$B, '[1]Pengkinian Data'!$E:$E) -> 0.9163
A25: 17 | B25: KC Garut | C25: Gumilar Rudimaya | D25: =_xlfn.XLOOKUP(B25,'[1]Pengkinian Data'!$B:$B, '[1]Pengkinian Data'!$E:$E) -> 0.9035
A26: 21 | B26: KC Majalaya | C26: Gumilar Rudimaya | D26: =_xlfn.XLOOKUP(B26,'[1]Pengkinian Data'!$B:$B, '[1]Pengkinian Data'!$E:$E) -> 0.8746
A27: 24 | B27: KC Purwakarta | C27: Gumilar Rudimaya | D27: =_xlfn.XLOOKUP(B27,'[1]Pengkinian Data'!$B:$B, '[1]Pengkinian Data'!$E:$E) -> 0.8612
A28: 25 | B28: KC Singaparna | C28: Gumilar Rudimaya | D28: =_xlfn.XLOOKUP(B28,'[1]Pengkinian Data'!$B:$B, '[1]Pengkinian Data'!$E:$E) -> 0.9611
A29: 26 | B29: KC Soreang | C29: Gumilar Rudimaya | D29: =_xlfn.XLOOKUP(B29,'[1]Pengkinian Data'!$B:$B, '[1]Pengkinian Data'!$E:$E) -> 0.8754
A30: 27 | B30: KC Subang | C30: Gumilar Rudimaya | D30: =_xlfn.XLOOKUP(B30,'[1]Pengkinian Data'!$B:$B, '[1]Pengkinian Data'!$E:$E) -> 0.7699
... A32: 30 | B32: KC Tasikmalaya | C32: Gumilar Rudimaya | D32: =_xlfn.XLOOKUP(B32,'[1]Pengkinian Data'!$B:$B, '[1]Pengkinian Data'!$E:$E) -> 0.8816

Sheet Uji Petik
A1: No. | B1: Unit Kerja | C1: PIC RAC | D1: Rencana Pelaksanaan | E1: Tanggal Pelaksanaan* | F1: Dokumen Evidence**
B29: Keterangan:
B30: *Diisi jika telah dilaksanakan
B31: **https://bri2-my.sharepoint.com/:f:/g/personal/00136153_hq_bri_co_id/IgDMlTrUq5noRLL6pF5n7XWFAXQb1qYaRfjoiHenMl06kX8?e=9PfaLg
B34: Evidence terdiri dari:
B35: 1. Dokumentasi Foto
B36: 2. Berita Acara
B37: 3. Absensi
B38: 4.Kertas Kerja
B39: 5. Laporan Uji Petik

Sheet Maturitas Dashboard
A1: No. | B1: Unit Kerja | C1: PIC RAC | D1: Nilai Maturitas | E1: Nilai Maturitas PIC | F1: Rating Maturitas PIC
A2: 2 | B2: BO Bandung Asia Afrika | C2: Gesang Jumadi | D2: 6.375 | E2: =AVERAGE(D2:D16) -> 6.3 | F2: Cukup Baik
A3: 3 | B3: BO Bandung Dago | C3: Gesang Jumadi | D3: 6.375
A4: 5 | B4: BO Bandung Kopo | C4: Gesang Jumadi | D4: 6.875
A5: 9 | B5: BO Bandung Soekarno Hatta | C5: Gesang Jumadi | D5: 5.875
A6: 10 | B6: BO Banjar | C6: Gesang Jumadi | D6: 6.375
A7: 11 | B7: BO Ciamis | C7: Gesang Jumadi | D7: 6.875
A8: 12 | B8: BO Cianjur | C8: Gesang Jumadi | D8: 5.875
A9: 15 | B9: BO Cirebon Gunung Jati | C9: Gesang Jumadi | D9: 6
A10: 16 | B10: BO Cirebon Kartini | C10: Gesang Jumadi | D10: 6
A11: 18 | B11: BO Indramayu | C11: Gesang Jumadi | D11: 5.875
A12: 19 | B12: BO Jatibarang | C12: Gesang Jumadi | D12: 6.375
A13: 20 | B13: BO Kuningan | C13: Gesang Jumadi | D13: 6.375
A14: 22 | B14: BO Majalengka | C14: Gesang Jumadi | D14: 6.5
... A16: 28 | B16: BO Sukabumi | C16: Gesang Jumadi | D16: 6.375
A17: 1 | B17: BO Bandung AH Nasution | C17: Gumilar Rudimaya | D17: 6.375 | E17: =AVERAGE(D17:D31) -> 6.15 | F17: Cukup Baik
A18: 4 | B18: BO Bandung Dewi Sartika | C18: Gumilar Rudimaya | D18: 6.375
A19: 6 | B19: BO Bandung Martadinata | C19: Gumilar Rudimaya | D19: 6.5
A20: 7 | B20: BO Bandung Naripan | C20: Gumilar Rudimaya | D20: 5.625
A21: 8 | B21: BO Bandung Setiabudi | C21: Gumilar Rudimaya | D21: 6.875
A22: 13 | B22: BO Cibadak | C22: Gumilar Rudimaya | D22: 5.875
A23: 14 | B23: BO Cimahi | C23: Gumilar Rudimaya | D23: 5.625
A24: 17 | B24: BO Garut | C24: Gumilar Rudimaya | D24: 7
A25: 21 | B25: BO Majalaya | C25: Gumilar Rudimaya | D25: 5.875
A26: 24 | B26: BO Purwakarta | C26: Gumilar Rudimaya | D26: 6.375
A27: 25 | B27: BO Singaparna | C27: Gumilar Rudimaya | D27: 6.375
A28: 26 | B28: BO Soreang | C28: Gumilar Rudimaya | D28: 4.875
A29: 27 | B29: BO Subang | C29: Gumilar Rudimaya | D29: 6.375
... A31: 30 | B31: BO Tasikmalaya | C31: Gumilar Rudimaya | D31: 6.125

Sheet Penilaian Resiko
A1: No. | B1: Unit Kerja | C1: PIC RAC | D1: Nilai Risiko | E1: Nilai Risiko PIC | F1: Rating Risiko PIC
A2: 2 | B2: BO Bandung Asia Afrika | C2: Gesang Jumadi | D2: 5 | E2: =AVERAGE(D2:D16) -> 5.5273711 | F2: Medium
A3: 3 | B3: BO Bandung Dago | C3: Gesang Jumadi | D3: 5.9791304
A4: 5 | B4: BO Bandung Kopo | C4: Gesang Jumadi | D4: 5.9791304
A5: 9 | B5: BO Bandung Soekarno Hatta | C5: Gesang Jumadi | D5: 4.9749372
A6: 10 | B6: BO Banjar | C6: Gesang Jumadi | D6: 6.1237244
A7: 11 | B7: BO Ciamis | C7: Gesang Jumadi | D7: 6.6332496
A8: 12 | B8: BO Cianjur | C8: Gesang Jumadi | D8: 5.7445626
A9: 15 | B9: BO Cirebon Gunung Jati | C9: Gesang Jumadi | D9: 5.4083269
A10: 16 | B10: BO Cirebon Kartini | C10: Gesang Jumadi | D10: 4.9749372
A11: 18 | B11: BO Indramayu | C11: Gesang Jumadi | D11: 5
A12: 19 | B12: BO Jatibarang | C12: Gesang Jumadi | D12: 5.2440442
A13: 20 | B13: BO Kuningan | C13: Gesang Jumadi | D13: 5.2440442
A14: 22 | B14: BO Majalengka | C14: Gesang Jumadi | D14: 5.1961524
... A16: 28 | B16: BO Sukabumi | C16: Gesang Jumadi | D16: 6
A17: 1 | B17: BO Bandung AH Nasution | C17: Gumilar Rudimaya | D17: 4.3874822 | E17: =AVERAGE(D17:D31) -> 5.4935929 | F17: Medium
A18: 4 | B18: BO Bandung Dewi Sartika | C18: Gumilar Rudimaya | D18: 5.7445626
A19: 6 | B19: BO Bandung Martadinata | C19: Gumilar Rudimaya | D19: 5.6124861
A20: 7 | B20: BO Bandung Naripan | C20: Gumilar Rudimaya | D20: 5.6124861
A21: 8 | B21: BO Bandung Setiabudi | C21: Gumilar Rudimaya | D21: 5.4083269
A22: 13 | B22: BO Cibadak | C22: Gumilar Rudimaya | D22: 5.7008771
A23: 14 | B23: BO Cimahi | C23: Gumilar Rudimaya | D23: 5.9791304
A24: 17 | B24: BO Garut | C24: Gumilar Rudimaya | D24: 4.7434165
A25: 21 | B25: BO Majalaya | C25: Gumilar Rudimaya | D25: 5.0990195
A26: 24 | B26: BO Purwakarta | C26: Gumilar Rudimaya | D26: 5.6124861
A27: 25 | B27: BO Singaparna | C27: Gumilar Rudimaya | D27: 5.7008771
A28: 26 | B28: BO Soreang | C28: Gumilar Rudimaya | D28: 5.7008771
A29: 27 | B29: BO Subang | C29: Gumilar Rudimaya | D29: 6.2048368
... A31: 30 | B31: BO Tasikmalaya | C31: Gumilar Rudimaya | D31: 5.1961524

Sheet Nilai Maturitas
A1: No. | B1: Unit Kerja | C1: PIC RAC | D1: Nilai maturitas | E1: Nilai maturitas | F1: Rating maturitas
A2: 2 | B2: BO Bandung Asia Afrika | C2: Gesang Jumadi | D2: 9.3729359 | E2: =AVERAGE(D2:D16) -> 8.4522677 | F2: AB
A3: 3 | B3: BO Bandung Dago | C3: Gesang Jumadi | D3: 8.2094026
A4: 5 | B4: BO Bandung Kopo | C4: Gesang Jumadi | D4: 9.2438967
A5: 9 | B5: BO Bandung Soekarno Hatta | C5: Gesang Jumadi | D5: 7.4634876
A6: 10 | B6: BO Banjar | C6: Gesang Jumadi | D6: 8.538409
A7: 11 | B7: BO Ciamis | C7: Gesang Jumadi | D7: 9.6229789
A8: 12 | B8: BO Cianjur | C8: Gesang Jumadi | D8: 7.2604333
A9: 15 | B9: BO Cirebon Gunung Jati | C9: Gesang Jumadi | D9: 7.6549458
A10: 16 | B10: BO Cirebon Kartini | C10: Gesang Jumadi | D10: 8.1315676
A11: 18 | B11: BO Indramayu | C11: Gesang Jumadi | D11: 8.0464928
A12: 19 | B12: BO Jatibarang | C12: Gesang Jumadi | D12: 7.5023957
A13: 20 | B13: BO Kuningan | C13: Gesang Jumadi | D13: 9.2963226
A14: 22 | B14: BO Majalengka | C14: Gesang Jumadi | D14: 9.4301805
... A16: 28 | B16: BO Sukabumi | C16: Gesang Jumadi | D16: 8.7778146
A17: 1 | B17: BO Bandung AH Nasution | C17: Gumilar Rudimaya | D17: 9.6575478 | E17: =AVERAGE(D17:D31) -> 8.1641903 | F17: AB
A18: 4 | B18: BO Bandung Dewi Sartika | C18: Gumilar Rudimaya | D18: 6.5640333
A19: 6 | B19: BO Bandung Martadinata | C19: Gumilar Rudimaya | D19: 8.9547964
A20: 7 | B20: BO Bandung Naripan | C20: Gumilar Rudimaya | D20: 9.2817407
A21: 8 | B21: BO Bandung Setiabudi | C21: Gumilar Rudimaya | D21: 9.1019133
A22: 13 | B22: BO Cibadak | C22: Gumilar Rudimaya | D22: 8.354209
A23: 14 | B23: BO Cimahi | C23: Gumilar Rudimaya | D23: 8.0286588
A24: 17 | B24: BO Garut | C24: Gumilar Rudimaya | D24: 9.1901279
A25: 21 | B25: BO Majalaya | C25: Gumilar Rudimaya | D25: 7.4190557
A26: 24 | B26: BO Purwakarta | C26: Gumilar Rudimaya | D26: 8.4160742
A27: 25 | B27: BO Singaparna | C27: Gumilar Rudimaya | D27: 6.1460951
A28: 26 | B28: BO Soreang | C28: Gumilar Rudimaya | D28: 8.527675
A29: 27 | B29: BO Subang | C29: Gumilar Rudimaya | D29: 6.0161143
... A31: 30 | B31: BO Tasikmalaya | C31: Gumilar Rudimaya | D31: 8.555614

Sheet Overview
A2: No | B2: Aspek Penilaian | C2: Gesang Jumadi | F2: Gumilar Rudimaya
C3: Nilai | D3: Bobotan | E3: Score | F3: Nilai | G3: Bobotan | H3: Score
A4: 1 | B4: STR | C4: =IFERROR(COUNTIFS(STR!$V:$V, Overview!C$2, STR!$X:$X, "TRUE")/COUNTIFS(STR!$V:$V, Overview!C2), 0) -> 0.75 | D4: 0.15 | E4: =D4*C4 -> 0.1125 | F4: =IFERROR(COUNTIFS(STR!$V:$V, Overview!F$2, STR!$X:$X, "TRUE")/COUNTIFS(STR!$V:$V, Overview!F2), 0) -> 0.52941176 | G4: 0.15 | H4: =G4*F4 -> 0.079411765
A5: 2 | B5: Bad Data | C5: =1-AVERAGEIF('Bad Data'!$C:$C, Overview!C$2, 'Bad Data'!$D:$D) -> 0.99485533 | D5: 0.1 | E5: =D5*C5 -> 0.099485533 | F5: =1-AVERAGEIF('Bad Data'!$C:$C, Overview!F$2, 'Bad Data'!$D:$D) -> 0.99464333 | G5: 0.1 | H5: =G5*F5 -> 0.099464333
A6: 3 | B6: Pengkinian Data | C6: =AVERAGEIF('Pengkinian Data'!$C:$C, Overview!C$2, 'Pengkinian Data'!$D:$D) -> 0.90608 | D6: 0.1 | E6: =D6*C6 -> 0.090608 | F6: =AVERAGEIF('Pengkinian Data'!$C:$C, Overview!F$2, 'Pengkinian Data'!$D:$D) -> 0.90720667 | G6: 0.1 | H6: =G6*F6 -> 0.090720667 | O6: .
A7: 4 | B7: Uji Petik | C7: {=IFERROR(SUMPRODUCT(--('[3]Uji Petik'!$E$3:$E$73<>""), --('[3]Uji Petik'!$C$3:$C$73=C2)) / SUMPRODUCT(--('[3]Uji Petik'!$C$3:$C$73=C2)), 0)} -> 0 | D7: 0 | E7: =D7*C7 -> 0 | F7: {=IFERROR(SUMPRODUCT(--('[3]Uji Petik'!$E$3:$E$73<>""), --('[3]Uji Petik'!$C$3:$C$73=F2)) / SUMPRODUCT(--('[3]Uji Petik'!$C$3:$C$73=F2)), 0)} -> 0 | G7: 0 | H7: =G7*F7 -> 0
A8: 5 | B8: Sosialisasi | C8: {=IFERROR(AVERAGE(IF([1]Sosialisasi!$C$1:$C$10000=C2, [1]Sosialisasi!$D$1:$D$10000)), 0)} -> 0.33333333 | D8: 0.15 | E8: =D8*C8 -> 0.05 | F8: {=IFERROR(AVERAGE(IF([1]Sosialisasi!$C$1:$C$10000=F2, [1]Sosialisasi!$D$1:$D$10000)), 0)} -> 0.73333333 | G8: 0.15 | H8: =G8*F8 -> 0.11
A9: 6 | B9: EDD | C9: =AVERAGEIF('EDD PEP PPATK'!$C:$C, Overview!C$2, 'EDD PEP PPATK'!$D:$D) -> 0.96660419 | D9: 0.1 | E9: =D9*C9 -> 0.096660419 | F9: =AVERAGEIF('EDD PEP PPATK'!$C:$C, Overview!F$2, 'EDD PEP PPATK'!$D:$D) -> 0.96376319 | G9: 0.1 | H9: =G9*F9 -> 0.096376319
A10: 7 | B10: Self Learning Keikutsertaan | C10: {=IF(IFERROR(AVERAGE(IF('[1]Sheet2 (2)'!$C$1:$C$10000=C$2, '[1]Sheet2 (2)'!$D$1:$D$10000)), 0)>0.9, 1, IFERROR(AVERAGE(IF('[1]Sheet2 (2)'!$C$1:$C$10000=C$2, '[1]Sheet2 (2)'!$D$1:$D$10000)), 0))} -> 0.78965706 | D10: 0.05 | E10: =D10*C10 -> 0.039482853 | F10: {=IF(IFERROR(AVERAGE(IF('[1]Sheet2 (2)'!$C$1:$C$10000=F$2, '[1]Sheet2 (2)'!$D$1:$D$10000)), 0)>0.9, 1, IFERROR(AVERAGE(IF('[1]Sheet2 (2)'!$C$1:$C$10000=F$2, '[1]Sheet2 (2)'!$D$1:$D$10000)), 0))} -> 0.77252204 | G10: 0.05 | H10: =G10*F10 -> 0.038626102
A11: 8 | B11: Self Learning Score | C11: {=IF(IFERROR(AVERAGE(IF('[1]Sheet2 (3)'!$C$1:$C$10000=C2, '[1]Sheet2 (3)'!$D$1:$D$10000)), 0)>90, 1, IFERROR(AVERAGE(IF('[1]Sheet2 (3)'!$C$1:$C$10000=C2, '[1]Sheet2 (3)'!$D$1:$D$10000)), 0)/90)} -> 1 | D11: 0.05 | E11: =D11*C11 -> 0.05 | F11: {=IF(IFERROR(AVERAGE(IF('[1]Sheet2 (3)'!$C$1:$C$10000=F2, '[1]Sheet2 (3)'!$D$1:$D$10000)), 0)>90, 1, IFERROR(AVERAGE(IF('[1]Sheet2 (3)'!$C$1:$C$10000=F2, '[1]Sheet2 (3)'!$D$1:$D$10000)), 0)/90)} -> 1 | G11: 0.05 | H11: =G11*F11 -> 0.05
A12: 9 | B12: Maturitas | C12: =IF(AVERAGEIF('Nilai Maturitas'!$C:$C, Overview!C2, 'Nilai Maturitas'!$D:$D) > 8, 110%, AVERAGEIF('Nilai Maturitas'!$C:$C, Overview!C2, 'Nilai Maturitas'!$D:$D)/8*100%) -> 1.1 | D12: 0.1 | E12: =D12*C12 -> 0.11 | F12: =IF(AVERAGEIF('Nilai Maturitas'!$C:$C, Overview!F2, 'Nilai Maturitas'!$D:$D) > 8, 110%, AVERAGEIF('Nilai Maturitas'!$C:$C, Overview!F2, 'Nilai Maturitas'!$D:$D)/8*100%) -> 1.1 | G12: 0.1 | H12: =G12*F12 -> 0.11
A13: 10 | B13: Maturitas Dashboard | C13: =IF(AVERAGEIF('Maturitas Dashboard'!$C:$C, Overview!C$2, 'Maturitas Dashboard'!$D:$D) > 8, 110%, AVERAGEIF('Maturitas Dashboard'!$C:$C, Overview!C$2, 'Maturitas Dashboard'!$D:$D)/8*100%) -> 0.7875 | D13: 0.1 | E13: =D13*C13 -> 0.07875 | F13: =IF(AVERAGEIF('Maturitas Dashboard'!$C:$C, Overview!F$2, 'Maturitas Dashboard'!$D:$D) > 8, 110%, AVERAGEIF('Maturitas Dashboard'!$C:$C, Overview!F$2, 'Maturitas Dashboard'!$D:$D)/8*100%) -> 0.76875 | G13: 0.1 | H13: =G13*F13 -> 0.076875
A14: 11 | B14: Penilaian Resiko | C14: =IF(AVERAGEIF('Penilaian Resiko'!$C:$C, Overview!C$2, 'Penilaian Resiko'!$D:$D) < 5.8, 110%, IF(AVERAGEIF('Penilaian Resiko'!$C:$C, Overview!C$2, 'Penilaian Resiko'!$D:$D) <7.4, 3/4*100%, 3/5*100%)) -> 1.1 | D14: 0.1 | E14: =D14*C14 -> 0.11 | F14: =IF(AVERAGEIF('Penilaian Resiko'!$C:$C, Overview!F$2, 'Penilaian Resiko'!$D:$D) < 5.8, 110%, IF(AVERAGEIF('Penilaian Resiko'!$C:$C, Overview!F$2, 'Penilaian Resiko'!$D:$D) <7.4, 3/4*100%, 3/5*100%)) -> 1.1 | G14: 0.1 | H14: =G14*F14 -> 0.11
C15: Progress | E15: =SUM(E4:E14) -> 0.83748681 | F15: Progress | H15: =SUM(H4:H14) -> 0.86147419

Sheet Overview tanpa KPI
A2: No | B2: Aspek Penilaian | C2: Gesang Jumadi | F2: Gumilar Rudimaya
C3: Nilai | D3: Bobotan | E3: Score | F3: Nilai | G3: Bobotan | H3: Score
A4: 1 | B4: STR | C4: =IFERROR(COUNTIFS(STR!$V:$V, 'Overview tanpa KPI'!C$2, STR!$X:$X, "TRUE")/COUNTIFS(STR!$V:$V, 'Overview tanpa KPI'!C2), 0) -> 0.75 | D4: 0.15 | E4: =D4*C4 -> 0.1125 | F4: =IFERROR(COUNTIFS(STR!$V:$V, 'Overview tanpa KPI'!F$2, STR!$X:$X, "TRUE")/COUNTIFS(STR!$V:$V, 'Overview tanpa KPI'!F2), 0) -> 0.52941176 | G4: 0.15 | H4: =G4*F4 -> 0.079411765
A5: 2 | B5: Bad Data | C5: =1-AVERAGEIF('Bad Data'!$C:$C, 'Overview tanpa KPI'!C$2, 'Bad Data'!$D:$D) -> 0.99485533 | D5: 0.1 | E5: =D5*C5 -> 0.099485533 | F5: =1-AVERAGEIF('Bad Data'!$C:$C, 'Overview tanpa KPI'!F$2, 'Bad Data'!$D:$D) -> 0.99464333 | G5: 0.1 | H5: =G5*F5 -> 0.099464333
A6: 3 | B6: Pengkinian Data | C6: =AVERAGEIF('Pengkinian Data'!$C:$C, 'Overview tanpa KPI'!C$2, 'Pengkinian Data'!$D:$D) -> 0.90608 | D6: 0.1 | E6: =D6*C6 -> 0.090608 | F6: =AVERAGEIF('Pengkinian Data'!$C:$C, 'Overview tanpa KPI'!F$2, 'Pengkinian Data'!$D:$D) -> 0.90720667 | G6: 0.1 | H6: =G6*F6 -> 0.090720667 | O6: .
A7: 4 | B7: Uji Petik | C7: {=IFERROR(SUMPRODUCT(--('[3]Uji Petik'!$E$3:$E$73<>""), --('[3]Uji Petik'!$C$3:$C$73=C2)) / SUMPRODUCT(--('[3]Uji Petik'!$C$3:$C$73=C2)), 0)} -> 0 | D7: 0 | E7: =D7*C7 -> 0 | F7: {=IFERROR(SUMPRODUCT(--('[3]Uji Petik'!$E$3:$E$73<>""), --('[3]Uji Petik'!$C$3:$C$73=F2)) / SUMPRODUCT(--('[3]Uji Petik'!$C$3:$C$73=F2)), 0)} -> 0 | G7: 0 | H7: =G7*F7 -> 0
A8: 5 | B8: Sosialisasi | C8: {=IFERROR(AVERAGE(IF([1]Sosialisasi!$C$1:$C$10000=C2, [1]Sosialisasi!$D$1:$D$10000)), 0)} -> 0.33333333 | D8: 0.15 | E8: =D8*C8 -> 0.05 | F8: {=IFERROR(AVERAGE(IF([1]Sosialisasi!$C$1:$C$10000=F2, [1]Sosialisasi!$D$1:$D$10000)), 0)} -> 0.73333333 | G8: 0.15 | H8: =G8*F8 -> 0.11
A9: 6 | B9: EDD | C9: =AVERAGEIF('EDD PEP PPATK'!$C:$C, 'Overview tanpa KPI'!C$2, 'EDD PEP PPATK'!$D:$D) -> 0.96660419 | D9: 0.1 | E9: =D9*C9 -> 0.096660419 | F9: =AVERAGEIF('EDD PEP PPATK'!$C:$C, 'Overview tanpa KPI'!F$2, 'EDD PEP PPATK'!$D:$D) -> 0.96376319 | G9: 0.1 | H9: =G9*F9 -> 0.096376319
A10: 7 | B10: Self Learning Keikutsertaan | C10: {=IFERROR(AVERAGE(IF('[1]Sheet2 (2)'!$C$1:$C$10000=C$2, '[1]Sheet2 (2)'!$D$1:$D$10000)), 0)} -> 0.78965706 | D10: 0.05 | E10: =D10*C10 -> 0.039482853 | F10: {=IFERROR(AVERAGE(IF('[1]Sheet2 (2)'!$C$1:$C$10000=F$2, '[1]Sheet2 (2)'!$D$1:$D$10000)), 0)} -> 0.77252204 | G10: 0.05 | H10: =G10*F10 -> 0.038626102
A11: 8 | B11: Self Learning Score | C11: {=IFERROR(AVERAGE(IF('[1]Sheet2 (3)'!$C$1:$C$10000=C2, '[1]Sheet2 (3)'!$D$1:$D$10000)), 0)} -> 95.754478 | D11: 0.05 | E11: =D11*C11 -> 4.7877239 | F11: {=IFERROR(AVERAGE(IF('[1]Sheet2 (3)'!$C$1:$C$10000=F2, '[1]Sheet2 (3)'!$D$1:$D$10000)), 0)} -> 95.11929 | G11: 0.05 | H11: =G11*F11 -> 4.7559645
A12: 9 | B12: Maturitas | C12: =AVERAGEIF('Nilai Maturitas'!$C:$C, 'Overview tanpa KPI'!C2, 'Nilai Maturitas'!$D:$D) -> 8.4522677 | D12: 0.1 | E12: =D12*C12 -> 0.84522677 | F12: =AVERAGEIF('Nilai Maturitas'!$C:$C, 'Overview tanpa KPI'!F2, 'Nilai Maturitas'!$D:$D) -> 8.1641903 | G12: 0.1 | H12: =G12*F12 -> 0.81641903
A13: 10 | B13: Maturitas Dashboard | C13: =AVERAGEIF('Maturitas Dashboard'!$C:$C, 'Overview tanpa KPI'!C$2, 'Maturitas Dashboard'!$D:$D) -> 6.3 | D13: 0.1 | E13: =D13*C13 -> 0.63 | F13: =AVERAGEIF('Maturitas Dashboard'!$C:$C, 'Overview tanpa KPI'!F$2, 'Maturitas Dashboard'!$D:$D) -> 6.15 | G13: 0.1 | H13: =G13*F13 -> 0.615
A14: 11 | B14: Penilaian Resiko | C14: =AVERAGEIF('Penilaian Resiko'!$C:$C, 'Overview tanpa KPI'!C$2, 'Penilaian Resiko'!$D:$D) -> 5.5273711 | D14: 0.1 | E14: =D14*C14 -> 0.55273711 | F14: =AVERAGEIF('Penilaian Resiko'!$C:$C, 'Overview tanpa KPI'!F$2, 'Penilaian Resiko'!$D:$D) -> 5.4935929 | G14: 0.1 | H14: =G14*F14 -> 0.54935929
C15: Progress | E15: =SUM(E4:E14) -> 7.3044246 | F15: Progress | H15: =SUM(H4:H14) -> 7.251342
