Workbook

Sheet STR
A1: POSISI | B1: NAMA | C1: CIF | D1: No Rek/ Kartu Kredit | E1: RESIKO | F1: BRILINK | G1: STATUS PEKERJA | H1: DIGITAL SAVING | I1: SKENARIO | J1: SCORING | K1: INFO PARAM | L1: KATEGORI | M1: UNIT KERJA | N1: KANTOR CABANG | O1: KANTOR KANWIL | P1: REKOMENDASI UKER | Q1: REKOMENDASI UKK | R1: STATUS UKER | S1: STATUS | T1: DISPOSISI | U1: INFO LAINNYA | V1: Disposisi RAC | W1: Tanggal | X1: Status TL
A2: {=_xlfn._xlws.FILTER('[2]STR-2026-8-2026-8'!$A:$U, ISNUMBER(SEARCH("Palembang", '[2]STR-2026-8-2026-8'!$O:$O)), "")} -> 46265 | B2: ABUBAKAR SIDIK | C2: AOMC509 | D2: 6301105720501 | E2: 0 | F2: Tidak | G2: Tidak | H2: 0 | I2: Jual Beli Rekening - E channel Trx | J2: 33 | K2: 113 | L2: Narkotika/Judi Online/Penipuan | M2: KC Pangkal Pinang | N2: KC Pangkal Pinang | O2: Palembang | P2: 0 | Q2: 0 | R2: Belum TL | S2: Belum TL | T2: 0 | U2: "-" | V2: Helvi Juliansyah | W2: 46242 | X2: =[3]STR!$X2 -> TRUE
A3: 46265 | B3: BAMBANG WALUYO | C3: BG62817 | D3: 60701025164506 | E3: SEDANG | F3: Ya | G3: Tidak | H3: Tidak | I3: Narkotika - Area Lapas | J3: 50 | K3: 46 | L3: Narkotika | M3: KC Rimbo Bujang | N3: KC Rimbo Bujang | O3: Palembang | P3: 0 | Q3: 0 | R3: Belum TL | S3: Belum TL | T3: 00394521 - Muhammad Hibbanduta | U3: "-" | V3: Helvi Juliansyah | W3: 46242 | X3: =[3]STR!$X3 -> TRUE
A4: 46265 | B4: DAVID PRATAMA | C4: DGTS779 | D4: 170701005114500 | E4: 0 | F4: Tidak | G4: Tidak | H4: 0 | I4: Jual Beli Rekening - E channel Trx | J4: 33 | K4: 113 | L4: Narkotika/Judi Online/Penipuan | M4: KK BANGKA TRADE CENTER | N4: KC Pangkal Pinang | O4: Palembang | P4: 0 | Q4: 0 | R4: Belum TL | S4: Belum TL | T4: 0 | U4: "-" | V4: Helvi Juliansyah | W4: 46242 | X4: =[3]STR!$X4 -> TRUE
A5: 46265 | B5: DIMAS PRATAMA | C5: DPZ8211 | D5: 16001001564562 | E5: TINGGI | F5: Tidak | G5: Tidak | H5: Tidak | I5: Narkotika - Area Lapas | J5: 65 | K5: 46 | L5: Narkotika | M5: KC Muara Bungo | N5: KC Muara Bungo | O5: Palembang | P5: 0 | Q5: 0 | R5: Belum TL | S5: Belum TL | T5: 90185538 - Muhammad Fahikal Auz | U5: "-" | V5: Helvi Juliansyah | W5: 46242 | X5: =[3]STR!$X5 -> TRUE | Z5: .
A6: 46265 | B6: DIMAS ADRIANTO | C6: DW14159 | D6: 16001086128501 | E6: SEDANG | F6: Tidak | G6: Tidak | H6: Tidak | I6: Narkotika - Area Lapas | J6: 51 | K6: 48 | L6: Narkotika | M6: KC Muara Bungo | N6: KC Muara Bungo | O6: Palembang | P6: 0 | Q6: 0 | R6: Belum TL | S6: Belum TL | T6: 90185537 - Moh.Khoerul Fajar Ar | U6: "-" | V6: Helvi Juliansyah | W6: 46242 | X6: =[3]STR!$X6 -> TRUE
A7: 46265 | B7: EKO EDDY PURNOMO | C7: EZ58153 | D7: 815001002996503 | E7: 0 | F7: Tidak | G7: Tidak | H7: 0 | I7: Jual Beli Rekening - E channel Trx | J7: 33 | K7: 113 | L7: Narkotika/Judi Online/Penipuan | M7: UNIT SUMBER JAYA BATURAJA | N7: KC Baturaja | O7: Palembang | P7: 0 | Q7: 0 | R7: Belum TL | S7: Belum TL | T7: 0 | U7: "-" | V7: Helvi Juliansyah | W7: 46242 | X7: =[3]STR!$X7 -> TRUE
A8: 46265 | B8: ERWIN | C8: EZE4122 | D8: 5901207844503 | E8: 0 | F8: Tidak | G8: Tidak | H8: 0 | I8: Jual Beli Rekening - E channel Trx | J8: 33 | K8: 113 | L8: Narkotika/Judi Online/Penipuan | M8: KC Palembang A. Rivai | N8: KC Palembang A. Rivai | O8: Palembang | P8: 0 | Q8: 0 | R8: Belum TL | S8: Belum TL | T8: 0 | U8: "-" | V8: Helvi Juliansyah | W8: 46242 | X8: =[3]STR!$X8 -> TRUE
A9: 46265 | B9: HENDRAWAN | C9: HAZG606 | D9: 170701005183509 | E9: 0 | F9: Tidak | G9: Tidak | H9: 0 | I9: Jual Beli Rekening - E channel Trx | J9: 33 | K9: 113 | L9: Narkotika/Judi Online/Penipuan | M9: KK BANGKA TRADE CENTER | N9: KC Pangkal Pinang | O9: Palembang | P9: 0 | Q9: 0 | R9: Belum TL | S9: Belum TL | T9: 0 | U9: "-" | V9: Helvi Juliansyah | W9: 46242 | X9: =[3]STR!$X9 -> TRUE
A10: 46265 | B10: IRWANDO | C10: IDJM247 | D10: 5901217221509 | E10: 0 | F10: Tidak | G10: Tidak | H10: 0 | I10: Jual Beli Rekening - E channel Trx | J10: 33 | K10: 113 | L10: Narkotika/Judi Online/Penipuan | M10: KC Palembang A. Rivai | N10: KC Palembang A. Rivai | O10: Palembang | P10: 0 | Q10: 0 | R10: Belum TL | S10: Belum TL | T10: 0 | U10: "-" | V10: Helvi Juliansyah | W10: 46242 | X10: =[3]STR!$X10 -> TRUE
A11: 46265 | B11: JOHANDRI | C11: JPK0953 | D11: 576601008622504 | E11: 0 | F11: Tidak | G11: Tidak | H11: 0 | I11: Jual Beli Rekening - E channel Trx | J11: 33 | K11: 113 | L11: Narkotika/Judi Online/Penipuan | M11: UNIT PANGKAL PINANG III PANGKA | N11: KC Pangkal Pinang | O11: Palembang | P11: 0 | Q11: 0 | R11: Belum TL | S11: Belum TL | T11: 0 | U11: "-" | V11: Ari Yustrianza | W11: 46242 | X11: =[3]STR!$X11 -> TRUE
A12: 46265 | B12: KUD MAKARTI | C12: KBX1712 | D12: 710501013037536 | E12: SEDANG | F12: Ya | G12: Tidak | H12: Tidak | I12: Narkotika - Area Lapas | J12: 48 | K12: 46 | L12: Narkotika | M12: UNIT PETALING ABUNJANI SP | N12: KC Abunjani Sipin | O12: Palembang | P12: 0 | Q12: 0 | R12: Belum TL | S12: Belum TL | T12: 00336949 - Mochammad Al Farabi | U12: "-" | V12: Ari Yustrianza | W12: 46242 | X12: =[3]STR!$X12 -> TRUE
A13: 46265 | B13: M FIERLY RAMADHANI | C13: MDNVG76 | D13: 60601002101567 | E13: 0 | F13: Tidak | G13: Tidak | H13: 0 | I13: Jual Beli Rekening - E channel Trx | J13: 33 | K13: 113 | L13: Narkotika/Judi Online/Penipuan | M13: KC Abunjani Sipin | N13: KC Abunjani Sipin | O13: Palembang | P13: 0 | Q13: 0 | R13: Belum TL | S13: Belum TL | T13: 0 | U13: "-" | V13: Helvi Juliansyah | W13: 46242 | X13: =[3]STR!$X13 -> TRUE
A14: 46265 | B14: MAWAR JAYA SENTOSA | C14: MPSV164 | D14: 13101001484301 | E14: SEDANG | F14: Tidak | G14: Tidak | H14: Tidak | I14: Perpajakan | J14: 48 | K14: 41 | L14: Perpajakan | M14: KC Tanjung Pandan | N14: KC Tanjung Pandan | O14: Palembang | P14: 0 | Q14: 0 | R14: Belum TL | S14: Belum TL | T14: 90185537 - Moh.Khoerul Fajar Ar | U14: "-" | V14: Helvi Juliansyah | W14: 46242 | X14: =[3]STR!$X14 -> TRUE
A15: 46265 | B15: MUHAMMAD RAZIN RAMADHAN | C15: MRTL588 | D15: 6301100578501 | E15: 0 | F15: Tidak | G15: Tidak | H15: 0 | I15: Jual Beli Rekening - E channel Trx | J15: 33 | K15: 113 | L15: Narkotika/Judi Online/Penipuan | M15: KC Pangkal Pinang | N15: KC Pangkal Pinang | O15: Palembang | P15: 0 | Q15: 0 | R15: Belum TL | S15: Belum TL | T15: 0 | U15: "-" | V15: Ari Yustrianza | W15: 46242 | X15: =[3]STR!$X15 -> TRUE
A16: 46265 | B16: NATAL ARIANSYAH | C16: NMVT676 | D16: 574201023497500 | E16: 0 | F16: Tidak | G16: Tidak | H16: 0 | I16: Jual Beli Rekening - E channel Trx | J16: 33 | K16: 113 | L16: Narkotika/Judi Online/Penipuan | M16: UNIT 5 ULU PALEMBANG A RIVAI | N16: KC Palembang A. Rivai | O16: Palembang | P16: 0 | Q16: 0 | R16: Belum TL | S16: Belum TL | T16: 0 | U16: "-" | V16: Ari Yustrianza | W16: 46242 | X16: =[3]STR!$X16 -> TRUE
A17: 46265 | B17: OPLIYANTO | C17: OF35932 | D17: 574201024321508 | E17: 0 | F17: Tidak | G17: Tidak | H17: 0 | I17: Jual Beli Rekening - E channel Trx | J17: 33 | K17: 113 | L17: Narkotika/Judi Online/Penipuan | M17: UNIT 5 ULU PALEMBANG A RIVAI | N17: KC Palembang A. Rivai | O17: Palembang | P17: 0 | Q17: 0 | R17: Belum TL | S17: Belum TL | T17: 0 | U17: "-" | V17: Helvi Juliansyah | W17: 46242 | X17: =[3]STR!$X17 -> TRUE
A18: 46265 | B18: RAJAWALI PUTRAMAS MANDIRI | C18: RAUP534 | D18: 13101001349307 | E18: SEDANG | F18: Tidak | G18: Tidak | H18: Tidak | I18: Perpajakan | J18: 48 | K18: 41 | L18: Perpajakan | M18: KC Tanjung Pandan | N18: KC Tanjung Pandan | O18: Palembang | P18: 0 | Q18: 0 | R18: Belum TL | S18: Belum TL | T18: 90186790 - Muhammad Alfin Farha | U18: "-" | V18: Helvi Juliansyah | W18: 46242 | X18: =[3]STR!$X18 -> TRUE
A19: 46265 | B19: RIZAL | C19: RGN0821 | D19: 714201049832530 | E19: 0 | F19: Tidak | G19: Tidak | H19: 0 | I19: Jual Beli Rekening - E channel Trx | J19: 33 | K19: 113 | L19: Narkotika/Judi Online/Penipuan | M19: UNIT SUKARNO HATTA PANGKAL PIN | N19: KC Pangkal Pinang | O19: Palembang | P19: 0 | Q19: 0 | R19: Belum TL | S19: Belum TL | T19: 0 | U19: "-" | V19: Ari Yustrianza | W19: 46242 | X19: =[3]STR!$X19 -> TRUE
A20: 46265 | B20: RICKY PRATAMA | C20: ROX8484 | D20: 209101000763560 | E20: 0 | F20: Tidak | G20: Tidak | H20: 0 | I20: Jual Beli Rekening - E channel Trx | J20: 33 | K20: 113 | L20: Narkotika/Judi Online/Penipuan | M20: KCP TOBOALI | N20: KC Pangkal Pinang | O20: Palembang | P20: 0 | Q20: 0 | R20: Belum TL | S20: Belum TL | T20: 0 | U20: "-" | V20: Ari Yustrianza | W20: 46242 | X20: =[3]STR!$X20 -> TRUE
A21: 46265 | B21: RIO CANDRA | C21: RQPE345 | D21: 576601008304504 | E21: 0 | F21: Tidak | G21: Tidak | H21: 0 | I21: Jual Beli Rekening - E channel Trx | J21: 33 | K21: 113 | L21: Narkotika/Judi Online/Penipuan | M21: UNIT PANGKAL PINANG III PANGKA | N21: KC Pangkal Pinang | O21: Palembang | P21: 0 | Q21: 0 | R21: Belum TL | S21: Belum TL | T21: 0 | U21: "-" | V21: Ari Yustrianza | W21: 46242 | X21: =[3]STR!$X21 -> TRUE
A22: 46265 | B22: SUCI RAHAYU | C22: SLAAN01 | D22: 573701011760508 | E22: 0 | F22: Tidak | G22: Tidak | H22: 0 | I22: Jual Beli Rekening - E channel Trx | J22: 33 | K22: 113 | L22: Narkotika/Judi Online/Penipuan | M22: UNIT PENDOPO PAGAR ALAM | N22: KC Pagar Alam | O22: Palembang | P22: 0 | Q22: 0 | R22: Belum TL | S22: Belum TL | T22: 0 | U22: "-" | V22: Ari Yustrianza | W22: 46242 | X22: =[3]STR!$X22 -> TRUE
A23: 46265 | B23: SYARIFUDIN | C23: SLESE47 | D23: 574201024331503 | E23: 0 | F23: Tidak | G23: Tidak | H23: 0 | I23: Jual Beli Rekening - E channel Trx | J23: 33 | K23: 113 | L23: Narkotika/Judi Online/Penipuan | M23: UNIT 5 ULU PALEMBANG A RIVAI | N23: KC Palembang A. Rivai | O23: Palembang | P23: 0 | Q23: 0 | R23: Belum TL | S23: Belum TL | T23: 0 | U23: "-" | V23: Ari Yustrianza | W23: 46242 | X23: =[3]STR!$X23 -> TRUE
A24: 46265 | B24: SUPRIYANTO | C24: SMHL247 | D24: 16001000315562 | E24: TINGGI | F24: Tidak | G24: Tidak | H24: Tidak | I24: Perpajakan | J24: 75 | K24: 1.33 | L24: Perpajakan | M24: KC Muara Bungo | N24: KC Muara Bungo | O24: Palembang | P24: 0 | Q24: 0 | R24: Belum TL | S24: Belum TL | T24: 90171841 - Rifqi Aziz | U24: "-" | V24: Ari Yustrianza | W24: 46242 | X24: =[3]STR!$X24 -> TRUE
A25: 46265 | B25: SEPTI INDRIYANI | C25: SWYW625 | D25: 5901212646500 | E25: 0 | F25: Tidak | G25: Tidak | H25: 0 | I25: Jual Beli Rekening - E channel Trx | J25: 33 | K25: 113 | L25: Narkotika/Judi Online/Penipuan | M25: KC Palembang A. Rivai | N25: KC Palembang A. Rivai | O25: Palembang | P25: 0 | Q25: 0 | R25: Belum TL | S25: Belum TL | T25: 0 | U25: "-" | V25: Helvi Juliansyah | W25: 46242 | X25: =[3]STR!$X25 -> TRUE
A26: 46265 | B26: CV BONANZA | C26: C124387 | D26: 13101999999305 | E26: SEDANG | F26: Tidak | G26: Tidak | H26: Tidak | I26: Perpajakan | J26: 50 | K26: 41 | L26: Perpajakan | M26: KC Tanjung Pandan | N26: KC Tanjung Pandan | O26: Palembang | P26: 0 | Q26: Tidak | R26: Belum TL | S26: Approved | T26: 90185538 - Muhammad Fahikal Auz | U26: "-" | V26: Ari Yustrianza | W26: 46242 | X26: =[3]STR!$X26 -> TRUE
A27: 46265 | B27: CV IKHWAH | C27: CQ23555 | D27: 13101002180308 | E27: SEDANG | F27: Tidak | G27: Tidak | H27: Tidak | I27: Perpajakan | J27: 48 | K27: 41 | L27: Perpajakan | M27: KC Tanjung Pandan | N27: KC Tanjung Pandan | O27: Palembang | P27: 0 | Q27: Tidak | R27: Belum TL | S27: Approved | T27: 90170665 - Mutiara Ayuningtyas | U27: "-" | V27: Ari Yustrianza | W27: 46242 | X27: =[3]STR!$X27 -> TRUE
A28: 46265 | B28: KENTDY | C28: KKG2624 | D28: 60601111111564 | E28: SEDANG | F28: Tidak | G28: Tidak | H28: Tidak | I28: Perpajakan | J28: 60 | K28: 1.33 | L28: Perpajakan | M28: KC Abunjani Sipin | N28: KC Abunjani Sipin | O28: Palembang | P28: 0 | Q28: Tidak | R28: Belum TL | S28: Approved | T28: 90186796 - Devito Arya Wiradila | U28: "-" | V28: Helvi Juliansyah | W28: 46242 | X28: =[3]STR!$X28 -> TRUE
A29: 46265 | B29: NOVITA NUR AFIFAH | C29: NBNN862 | D29: 223901000693561 | E29: SEDANG | F29: Ya | G29: Tidak | H29: Ya | I29: Prostitusi | J29: 47 | K29: 104 | L29: Prostitusi | M29: KCP SUNGAI BAHAR | N29: KC Muara Bulian | O29: Palembang | P29: 0 | Q29: Tidak | R29: Belum TL | S29: Approved | T29: 90186790 - Muhammad Alfin Farha | U29: "-" | V29: Helvi Juliansyah | W29: 46242 | X29: =[3]STR!$X29 -> TRUE
A30: 46265 | B30: MASJID BAITUL MAKMUR | C30: MMZJ553 | D30: 220501002101531 | E30: SEDANG | F30: Tidak | G30: Tidak | H30: Tidak | I30: Perpajakan | J30: 48 | K30: 41 | L30: Perpajakan | M30: KCP KM 5 | N30: KC Palembang Sriwijaya | O30: Palembang | P30: 0 | Q30: Tidak | R30: Belum TL | S30: Approved | T30: 00394520 - Frida Akbar Rani | U30: "-" | V30: Ari Yustrianza | W30: 46242 | X30: =[3]STR!$X30 -> TRUE
A31: 46265 | B31: PT HAMPARAN ANUGERAH | C31: POE3622 | D31: 220501000593562 | E31: 0 | F31: Tidak | G31: Tidak | H31: Tidak | I31: Perpajakan | J31: 33 | K31: 41 | L31: Perpajakan | M31: KCP KM 5 | N31: KC Palembang Sriwijaya | O31: Palembang | P31: 0 | Q31: Ya | R31: Belum TL | S31: Approved | T31: 00336949 - Mochammad Al Farabi | U31: "-" | V31: Ari Yustrianza | W31: 46242 | X31: =[3]STR!$X31 -> TRUE
A32: 46265 | B32: PT UMKM RUDI APRIADI | C32: PNW0931 | D32: 220501000580569 | E32: 0 | F32: Tidak | G32: Tidak | H32: Tidak | I32: Perpajakan | J32: 33 | K32: 41 | L32: Perpajakan | M32: KCP KM 5 | N32: KC Palembang Sriwijaya | O32: Palembang | P32: 0 | Q32: Tidak | R32: Belum TL | S32: Approved | T32: 90171841 - Rifqi Aziz | U32: "-" | V32: Ari Yustrianza | W32: 46242 | X32: =[3]STR!$X32 -> TRUE
A33: 46265 | B33: RABU | C33: RSV5790 | D33: 355201054695530 | E33: SEDANG | F33: Ya | G33: Tidak | H33: Tidak | I33: Narkotika - Area Lapas | J33: 53 | K33: 46 | L33: Narkotika | M33: UNIT SANGETI JAMBI | N33: KC Jambi | O33: Palembang | P33: Tidak | Q33: 0 | R33: Pending Approver | S33: Belum TL | T33: 90185537 - Moh.Khoerul Fajar Ar | U33: "-" | V33: Ari Yustrianza | W33: 46242 | X33: =[3]STR!$X33 -> TRUE
A34: 46265 | B34: MUHAMMAD RONI | C34: MECE934 | D34: 567001014406531 | E34: SEDANG | F34: Ya | G34: Tidak | H34: Tidak | I34: Pencurian Rekening | J34: 49 | K34: 59 | L34: Perbankan | M34: UNIT PELABUHAN DAGANG KUALA TU | N34: KC Kuala Tungkal | O34: Palembang | P34: Tidak | Q34: Tidak | R34: Pending Approver | S34: Approved | T34: 90150130 - Intan Aida Pratiwi | U34: "-" | V34: Bukan RAC Palembang | W34: 46242 | X34: =[3]STR!$X34 -> TRUE
A35: 46265 | B35: MARISA PUJI ASTUTI | C35: MCVQ325 | D35: 31501001302563 | E35: SEDANG | F35: Tidak | G35: Tidak | H35: Tidak | I35: Narkotika - Area Lapas | J35: 60 | K35: 46 | L35: Narkotika | M35: KC Muara Bulian | N35: KC Muara Bulian | O35: Palembang | P35: Tidak | Q35: Ya | R35: Pending Approver | S35: Approved | T35: 90186790 - Muhammad Alfin Farha | U35: "-" | V35: Ari Yustrianza | W35: 46242 | X35: =[3]STR!$X35 -> FALSE
A36: 46265 | B36: YULIZA FITRI | C36: YCW5374 | D36: 572401000027564 | E36: SEDANG | F36: Ya | G36: Tidak | H36: Tidak | I36: Narkotika - Area Lapas | J36: 50 | K36: 46 | L36: Narkotika | M36: UNIT MUARA BUNGO | N36: KC Muara Bungo | O36: Palembang | P36: Tidak | Q36: 0 | R36: Done | S36: Belum TL | T36: 90171841 - Rifqi Aziz | U36: "-" | V36: Ari Yustrianza | W36: 46242 | X36: =[3]STR!$X36 -> TRUE
A37: 46265 | B37: PERINTIS LESTARI TALANGDUKU | C37: PH81021 | D37: 2001002996306 | E37: TINGGI | F37: Tidak | G37: Tidak | H37: Tidak | I37: Perpajakan | J37: 63 | K37: 1.33 | L37: Perpajakan | M37: KC Jambi | N37: KC Jambi | O37: Palembang | P37: Tidak | Q37: 0 | R37: Done | S37: Belum TL | T37: 90171841 - Rifqi Aziz | U37: "-" | V37: Ari Yustrianza | W37: 46242 | X37: =[3]STR!$X37 -> TRUE
A38: 46265 | B38: HANIPAH | C38: HNS1043 | D38: 710201007082509 | E38: SEDANG | F38: Ya | G38: Tidak | H38: Tidak | I38: Narkotika - Area Lapas | J38: 60 | K38: 46 | L38: Narkotika | M38: UNIT RANTAU PANJANG BANGKO | N38: KC Bangko | O38: Palembang | P38: Tidak | Q38: Tidak | R38: Done | S38: Approved | T38: 90150130 - Intan Aida Pratiwi | U38: "-" | V38: Bukan RAC Palembang | W38: 46242 | X38: =[3]STR!$X38 -> TRUE
A39: 46265 | B39: JUYAR BRIGIF 8 GARUDA CAKTI | C39: JGU2140 | D39: 12901002076304 | E39: TINGGI | F39: Tidak | G39: Tidak | H39: Tidak | I39: Perpajakan | J39: 68 | K39: 41 | L39: Perpajakan | M39: KC Lubuk Linggau | N39: KC Lubuk Linggau | O39: Palembang | P39: Tidak | Q39: Tidak | R39: Done | S39: Approved | T39: 00336949 - Mochammad Al Farabi | U39: "-" | V39: Helvi Juliansyah | W39: 46242 | X39: =[3]STR!$X39 -> FALSE
A40: 46265 | B40: IRFAN AFRINAL | C40: INL9097 | D40: 572401000033565 | E40: SEDANG | F40: Ya | G40: Tidak | H40: Tidak | I40: Narkotika - Area Lapas | J40: 50 | K40: 46 | L40: Narkotika | M40: UNIT MUARA BUNGO | N40: KC Muara Bungo | O40: Palembang | P40: Tidak | Q40: Ya | R40: Done | S40: Approved | T40: 90171841 - Rifqi Aziz | U40: "-" | V40: Bukan RAC Palembang | W40: 46242 | X40: =[3]STR!$X40 -> TRUE
...

Sheet EDD PEP PPATK
D1: 46280
A2: No. | B2: Unit Kerja | C2: PIC RAC | D2: %TL PEP Done | E2: Average
A3: 1 | B3: KC Abunjani Sipin | C3: Ari | D3: =_xlfn.XLOOKUP(B3,'[4]HASIL TINDAK LANJUT BO 2026'!$D:$D,'[4]HASIL TINDAK LANJUT BO 2026'!$K:$K) -> 1 | E3: =AVERAGE(D3:D23) -> 0.99601187
A4: 2 | B4: KC Bangko | C4: Ari | D4: =_xlfn.XLOOKUP(B4,'[4]HASIL TINDAK LANJUT BO 2026'!$D:$D,'[4]HASIL TINDAK LANJUT BO 2026'!$K:$K) -> 1
A5: 3 | B5: KC Baturaja | C5: Helvi | D5: =_xlfn.XLOOKUP(B5,'[4]HASIL TINDAK LANJUT BO 2026'!$D:$D,'[4]HASIL TINDAK LANJUT BO 2026'!$K:$K) -> 1
A6: 4 | B6: KC Jambi | C6: Ari | D6: =_xlfn.XLOOKUP(B6,'[4]HASIL TINDAK LANJUT BO 2026'!$D:$D,'[4]HASIL TINDAK LANJUT BO 2026'!$K:$K) -> 1
A7: 5 | B7: KC Kayu Agung | C7: Helvi | D7: =_xlfn.XLOOKUP(B7,'[4]HASIL TINDAK LANJUT BO 2026'!$D:$D,'[4]HASIL TINDAK LANJUT BO 2026'!$K:$K) -> 1
A8: 6 | B8: KC Kuala Tungkal | C8: Ari | D8: =_xlfn.XLOOKUP(B8,'[4]HASIL TINDAK LANJUT BO 2026'!$D:$D,'[4]HASIL TINDAK LANJUT BO 2026'!$K:$K) -> 1
A9: 7 | B9: KC Lahat | C9: Helvi | D9: =_xlfn.XLOOKUP(B9,'[4]HASIL TINDAK LANJUT BO 2026'!$D:$D,'[4]HASIL TINDAK LANJUT BO 2026'!$K:$K) -> 1
A10: 8 | B10: KC Lubuk Linggau | C10: Helvi | D10: =_xlfn.XLOOKUP(B10,'[4]HASIL TINDAK LANJUT BO 2026'!$D:$D,'[4]HASIL TINDAK LANJUT BO 2026'!$K:$K) -> 0.97959184
A11: 9 | B11: KC Muara Bulian | C11: Ari | D11: =_xlfn.XLOOKUP(B11,'[4]HASIL TINDAK LANJUT BO 2026'!$D:$D,'[4]HASIL TINDAK LANJUT BO 2026'!$K:$K) -> 1
A12: 10 | B12: KC Muara Bungo | C12: Ari | D12: =_xlfn.XLOOKUP(B12,'[4]HASIL TINDAK LANJUT BO 2026'!$D:$D,'[4]HASIL TINDAK LANJUT BO 2026'!$K:$K) -> 1
A13: 11 | B13: KC Muara Enim | C13: Helvi | D13: =_xlfn.XLOOKUP(B13,'[4]HASIL TINDAK LANJUT BO 2026'!$D:$D,'[4]HASIL TINDAK LANJUT BO 2026'!$K:$K) -> 1
A14: 12 | B14: KC Pagar Alam | C14: Helvi | D14: =_xlfn.XLOOKUP(B14,'[4]HASIL TINDAK LANJUT BO 2026'!$D:$D,'[4]HASIL TINDAK LANJUT BO 2026'!$K:$K) -> 1
A15: 13 | B15: KC Palembang A. Rivai | C15: Ari | D15: =_xlfn.XLOOKUP(B15,'[4]HASIL TINDAK LANJUT BO 2026'!$D:$D,'[4]HASIL TINDAK LANJUT BO 2026'!$K:$K) -> 1
... A23: 21 | B23: KC Tanjung Pandan | C23: Ari | D23: =_xlfn.XLOOKUP(B23,'[4]HASIL TINDAK LANJUT BO 2026'!$D:$D,'[4]HASIL TINDAK LANJUT BO 2026'!$K:$K) -> 1

Sheet Pengkinian Data
D1: 46280
A2: No. | B2: Unit Kerja | C2: PIC RAC | D2: %Pengkinian Data | E2: Average
A3: 1 | B3: KC Abunjani Sipin | C3: Ari | D3: =_xlfn.XLOOKUP(B3,'[1]Pengkinian Data'!$B:$B,'[1]Pengkinian Data'!$E:$E) -> 1 | E3: =AVERAGE(D3:D23) -> 1
A4: 2 | B4: KC Bangko | C4: Ari | D4: =_xlfn.XLOOKUP(B4,'[1]Pengkinian Data'!$B:$B,'[1]Pengkinian Data'!$E:$E) -> 1
A5: 3 | B5: KC Baturaja | C5: Helvi | D5: 1
A6: 4 | B6: KC Jambi | C6: Ari | D6: =_xlfn.XLOOKUP(B6,'[1]Pengkinian Data'!$B:$B,'[1]Pengkinian Data'!$E:$E) -> 1
A7: 5 | B7: KC Kayu Agung | C7: Helvi | D7: =_xlfn.XLOOKUP(B7,'[1]Pengkinian Data'!$B:$B,'[1]Pengkinian Data'!$E:$E) -> 1
A8: 6 | B8: KC Kuala Tungkal | C8: Ari | D8: =_xlfn.XLOOKUP(B8,'[1]Pengkinian Data'!$B:$B,'[1]Pengkinian Data'!$E:$E) -> 1
A9: 7 | B9: KC Lahat | C9: Helvi | D9: =_xlfn.XLOOKUP(B9,'[1]Pengkinian Data'!$B:$B,'[1]Pengkinian Data'!$E:$E) -> 1
A10: 8 | B10: KC Lubuk Linggau | C10: Helvi | D10: =_xlfn.XLOOKUP(B10,'[1]Pengkinian Data'!$B:$B,'[1]Pengkinian Data'!$E:$E) -> 1
A11: 9 | B11: KC Muara Bulian | C11: Ari | D11: =_xlfn.XLOOKUP(B11,'[1]Pengkinian Data'!$B:$B,'[1]Pengkinian Data'!$E:$E) -> 1
A12: 10 | B12: KC Muara Bungo | C12: Ari | D12: =_xlfn.XLOOKUP(B12,'[1]Pengkinian Data'!$B:$B,'[1]Pengkinian Data'!$E:$E) -> 1
A13: 11 | B13: KC Muara Enim | C13: Helvi | D13: =_xlfn.XLOOKUP(B13,'[1]Pengkinian Data'!$B:$B,'[1]Pengkinian Data'!$E:$E) -> 1
A14: 12 | B14: KC Pagar Alam | C14: Helvi | D14: =_xlfn.XLOOKUP(B14,'[1]Pengkinian Data'!$B:$B,'[1]Pengkinian Data'!$E:$E) -> 1
A15: 13 | B15: KC Palembang A. Rivai | C15: Ari | D15: =_xlfn.XLOOKUP(B15,'[1]Pengkinian Data'!$B:$B,'[1]Pengkinian Data'!$E:$E) -> 1
A16: 14 | B16: KC Palembang Sriwijaya | C16: Ari | D16: =_xlfn.XLOOKUP(B16,'[1]Pengkinian Data'!$B:$B,'[1]Pengkinian Data'!$E:$E) -> 1
A17: 15 | B17: KC Pangkal Pinang | C17: Helvi | D17: =_xlfn.XLOOKUP(B17,'[1]Pengkinian Data'!$B:$B,'[1]Pengkinian Data'!$E:$E) -> 1
... A23: 21 | B23: KC Tanjung Pandan | C23: Ari | D23: =_xlfn.XLOOKUP(B23,'[1]Pengkinian Data'!$B:$B,'[1]Pengkinian Data'!$E:$E) -> 1

Sheet Bad Data
D1: 46280
A2: No. | B2: Unit Kerja | C2: PIC RAC | D2: %Bad Data | E2: Average
A3: 1 | B3: KC Abunjani Sipin | C3: Ari | D3: =_xlfn.XLOOKUP(B3, '[1]Bad Data'!$B:$B, '[1]Bad Data'!$D:$D) -> 0.00484 | E3: =AVERAGE(D3:D23) -> 0.0026785714
A4: 2 | B4: KC Bangko | C4: Ari | D4: =_xlfn.XLOOKUP(B4, '[1]Bad Data'!$B:$B, '[1]Bad Data'!$D:$D) -> 0.00105
A5: 3 | B5: KC Baturaja | C5: Helvi | D5: =_xlfn.XLOOKUP(B5, '[1]Bad Data'!$B:$B, '[1]Bad Data'!$D:$D) -> 0.00361
A6: 4 | B6: KC Jambi | C6: Ari | D6: =_xlfn.XLOOKUP(B6, '[1]Bad Data'!$B:$B, '[1]Bad Data'!$D:$D) -> 0.00313
A7: 5 | B7: KC Kayu Agung | C7: Helvi | D7: =_xlfn.XLOOKUP(B7, '[1]Bad Data'!$B:$B, '[1]Bad Data'!$D:$D) -> 0.0023
A8: 6 | B8: KC Kuala Tungkal | C8: Ari | D8: =_xlfn.XLOOKUP(B8, '[1]Bad Data'!$B:$B, '[1]Bad Data'!$D:$D) -> 0.00675
A9: 7 | B9: KC Lahat | C9: Helvi | D9: =_xlfn.XLOOKUP(B9, '[1]Bad Data'!$B:$B, '[1]Bad Data'!$D:$D) -> 0.00032
A10: 8 | B10: KC Lubuk Linggau | C10: Helvi | D10: =_xlfn.XLOOKUP(B10, '[1]Bad Data'!$B:$B, '[1]Bad Data'!$D:$D) -> 0.00373
A11: 9 | B11: KC Muara Bulian | C11: Ari | D11: =_xlfn.XLOOKUP(B11, '[1]Bad Data'!$B:$B, '[1]Bad Data'!$D:$D) -> 0.00379
A12: 10 | B12: KC Muara Bungo | C12: Ari | D12: =_xlfn.XLOOKUP(B12, '[1]Bad Data'!$B:$B, '[1]Bad Data'!$D:$D) -> 0.00506
A13: 11 | B13: KC Muara Enim | C13: Helvi | D13: =_xlfn.XLOOKUP(B13, '[1]Bad Data'!$B:$B, '[1]Bad Data'!$D:$D) -> 0.00296
A14: 12 | B14: KC Pagar Alam | C14: Helvi | D14: =_xlfn.XLOOKUP(B14, '[1]Bad Data'!$B:$B, '[1]Bad Data'!$D:$D) -> 0.00182
A15: 13 | B15: KC Palembang A. Rivai | C15: Ari | D15: =_xlfn.XLOOKUP(B15, '[1]Bad Data'!$B:$B, '[1]Bad Data'!$D:$D) -> 0.00322
... A23: 21 | B23: KC Tanjung Pandan | C23: Ari | D23: =_xlfn.XLOOKUP(B23, '[1]Bad Data'!$B:$B, '[1]Bad Data'!$D:$D) -> 0.00192

Sheet Sosialisasi
A1: No. | B1: Unit Kerja | C1: PIC RAC | D1: Materi* | E1: Tanggal Rencana Pelaksanaan | F1: Tanggal Pelaksanaan* | G1: Jumlah Peserta* | H1: Jabatan Peserta* | I1: Dokumen Evidence**
A2: 1 | B2: KC Balige
A3: 2 | B3: KC Binjai
A4: 3 | B4: KC Gunung Sitoli
A5: 4 | B5: KC Kabanjahe
A6: 5 | B6: KC Kisaran
A7: 6 | B7: KC Kota Pinang
A8: 7 | B8: KC Lubuk Pakam
A9: 8 | B9: KC Medan Gatot Subroto
A10: 9 | B10: KC Medan Iskandar Muda
A11: 10 | B11: KC Medan Putri Hijau
A12: 11 | B12: KC Medan Sisingamangaraja
A13: 12 | B13: KC Medan Thamrin
... A25: 24 | B25: KC Tebing Tinggi
B27: Keterangan:
B28: *Diisi jika telah dilaksanakan
B29: **https://bbri.id/MonevaRAC
B31: Evidence terdiri dari:
B32: 1. Dokumentasi Foto
B33: 2. Berita Acara
B34: 3. Absensi
B35: 4. Materi Sosisalisasi
B36: 5. List Pertanyaan

Sheet Uji Petik
A1: No. | B1: Unit Kerja | C1: PIC RAC | D1: Rencana Pelaksanaan | E1: Tanggal Pelaksanaan* | F1: Dokumen Evidence**
B3: NIHIL | C3: NIHIL | D3: NIHIL | E3: NIHIL | F3: NIHIL
B29: Keterangan:
B30: *Diisi jika telah dilaksanakan
B31: **https://bri2-my.sharepoint.com/:f:/g/personal/00136153_hq_bri_co_id/IgCyAznK-tOuRql7WphBOOIiAbaa6PYz63jt4CsdpgTNFmk?e=RAGbgh
B34: Evidence terdiri dari:
B35: 1. Dokumentasi Foto
B36: 2. Berita Acara
B37: 3. Absensi
B38: 4.Kertas Kerja
B39: 5. Laporan Uji Petik

Sheet Nilai Maturitas
A1: No. | B1: Unit Kerja | C1: PIC RAC | D1: Nilai maturitas | E1: Nilai maturitas | F1: Rating maturitas
A2: 1 | B2: KC Abunjani Sipin | C2: Ari | D2: 7.834 | E2: =AVERAGE(D2:D11) -> 7.7413 | F2: =AVERAGE(E2:E11) -> 7.7413
A3: 2 | B3: KC Bangko | C3: Ari | D3: 7.569
A4: 4 | B4: KC Jambi | C4: Ari | D4: 8.385
A5: 6 | B5: KC Kuala Tungkal | C5: Ari | D5: 8.131
A6: 9 | B6: KC Muara Bulian | C6: Ari | D6: 6.166
A7: 10 | B7: KC Muara Bungo | C7: Ari | D7: 6.784
A8: 13 | B8: KC Palembang A. Rivai | C8: Ari | D8: 8.527
A9: 14 | B9: KC Palembang Sriwijaya | C9: Ari | D9: 8.482
A10: 17 | B10: KC Rimbo Bujang | C10: Ari | D10: 7.958
A11: 21 | B11: KC Tanjung Pandan | C11: Ari | D11: 7.577
A12: 3 | B12: KC Baturaja | C12: Helvi | D12: 7.506 | E12: =AVERAGE(D12:D22) -> 6.6892727 | F12: =AVERAGE(E12:E22) -> 6.6892727
A13: 5 | B13: KC Kayu Agung | C13: Helvi | D13: 6.242
A14: 7 | B14: KC Lahat | C14: Helvi | D14: 7.85
A15: 8 | B15: KC Lubuk Linggau | C15: Helvi | D15: 5.737
A16: 11 | B16: KC Muara Enim | C16: Helvi | D16: 5.874
A17: 12 | B17: KC Pagar Alam | C17: Helvi | D17: 5.106
A18: 15 | B18: KC Pangkal Pinang | C18: Helvi | D18: 8.963
A19: 16 | B19: KC Prabumulih | C19: Helvi | D19: 7.006
A20: 18 | B20: KC Sarolangun | C20: Helvi | D20: 5.754
A21: 19 | B21: KC Sekayu | C21: Helvi | D21: 6.146
A22: 20 | B22: KC Sungai Liat | C22: Helvi | D22: 7.398

Sheet Penilaian Resiko
A1: No. | B1: Unit Kerja | C1: PIC RAC | D1: Nilai Risiko | E1: Nilai Risiko PIC | F1: Rating Risiko PIC
A2: 1 | B2: KC Abunjani Sipin | C2: Ari | D2: 4.472 | E2: =AVERAGE(D2:D11) -> 5.174 | F2: =AVERAGE(E2:E11) -> 5.174
A3: 2 | B3: KC Bangko | C3: Ari | D3: 4.243
A4: 4 | B4: KC Jambi | C4: Ari | D4: 4.899
A5: 6 | B5: KC Kuala Tungkal | C5: Ari | D5: 6.124
A6: 9 | B6: KC Muara Bulian | C6: Ari | D6: 6.124
A7: 10 | B7: KC Muara Bungo | C7: Ari | D7: 5.612
A8: 13 | B8: KC Palembang A. Rivai | C8: Ari | D8: 4.899
A9: 14 | B9: KC Palembang Sriwijaya | C9: Ari | D9: 4.5
A10: 17 | B10: KC Rimbo Bujang | C10: Ari | D10: 6.124
A11: 21 | B11: KC Tanjung Pandan | C11: Ari | D11: 4.743
A12: 3 | B12: KC Baturaja | C12: Helvi | D12: 4.899 | E12: =AVERAGE(D12:D22) -> 5.2534545 | F12: =AVERAGE(E12:E22) -> 5.2534545
A13: 5 | B13: KC Kayu Agung | C13: Helvi | D13: 5.196
A14: 7 | B14: KC Lahat | C14: Helvi | D14: 4.899
A15: 8 | B15: KC Lubuk Linggau | C15: Helvi | D15: 5.196
A16: 11 | B16: KC Muara Enim | C16: Helvi | D16: 4.975
A17: 12 | B17: KC Pagar Alam | C17: Helvi | D17: 5.408
A18: 15 | B18: KC Pangkal Pinang | C18: Helvi | D18: 5.831
A19: 16 | B19: KC Prabumulih | C19: Helvi | D19: 5.701
A20: 18 | B20: KC Sarolangun | C20: Helvi | D20: 5.292
A21: 19 | B21: KC Sekayu | C21: Helvi | D21: 5.701
A22: 20 | B22: KC Sungai Liat | C22: Helvi | D22: 4.69

Sheet Maturitas Dashboard
A1: No. | B1: Unit Kerja | C1: PIC RAC | D1: Nilai Maturitas | E1: Nilai Maturitas PIC | F1: Rating Maturitas PIC
A2: 1 | B2: KC Abunjani Sipin | C2: Ari | D2: 7.625 | E2: =AVERAGE(D2:D11) -> 7.275 | F2: =AVERAGE(E2:E11) -> 7.275
A3: 2 | B3: KC Bangko | C3: Ari | D3: 8.125
A4: 4 | B4: KC Jambi | C4: Ari | D4: 7.125
A5: 6 | B5: KC Kuala Tungkal | C5: Ari | D5: 7.625
A6: 9 | B6: KC Muara Bulian | C6: Ari | D6: 7.625
A7: 10 | B7: KC Muara Bungo | C7: Ari | D7: 7.125
A8: 13 | B8: KC Palembang A. Rivai | C8: Ari | D8: 6.625
A9: 14 | B9: KC Palembang Sriwijaya | C9: Ari | D9: 6.625
A10: 17 | B10: KC Rimbo Bujang | C10: Ari | D10: 6.625
A11: 21 | B11: KC Tanjung Pandan | C11: Ari | D11: 7.625
A12: 3 | B12: KC Baturaja | C12: Helvi | D12: 6.625 | E12: =AVERAGE(D12:D22) -> 7.5340909 | F12: =AVERAGE(E12:E22) -> 7.5340909
A13: 5 | B13: KC Kayu Agung | C13: Helvi | D13: 8.125
A14: 7 | B14: KC Lahat | C14: Helvi | D14: 7.125
A15: 8 | B15: KC Lubuk Linggau | C15: Helvi | D15: 8.125
A16: 11 | B16: KC Muara Enim | C16: Helvi | D16: 7.625
A17: 12 | B17: KC Pagar Alam | C17: Helvi | D17: 7.625
A18: 15 | B18: KC Pangkal Pinang | C18: Helvi | D18: 7.125
A19: 16 | B19: KC Prabumulih | C19: Helvi | D19: 8.125
A20: 18 | B20: KC Sarolangun | C20: Helvi | D20: 8.125
A21: 19 | B21: KC Sekayu | C21: Helvi | D21: 6.625
A22: 20 | B22: KC Sungai Liat | C22: Helvi | D22: 7.625

Sheet Overview
A2: No | B2: Aspek Penilaian | C2: Ari | F2: Helvi
C3: Nilai | D3: Bobotan | E3: Score | F3: Nilai | G3: Bobotan | H3: Score
A4: 1 | B4: STR | C4: =IFERROR(COUNTIFS(STR!$V:$V, Overview!C$2 & " *", STR!$X:$X, "TRUE") / COUNTIFS(STR!$V:$V, Overview!C$2 & " *"), 0) -> 0.95454545 | D4: 0.15 | E4: =D4*C4 -> 0.14318182 | F4: =IFERROR(COUNTIFS(STR!$V:$V, Overview!F$2 & " *", STR!$X:$X, "TRUE") / COUNTIFS(STR!$V:$V, Overview!F$2 & " *"), 0) -> 0.9 | G4: 0.15 | H4: =G4*F4 -> 0.135
A5: 2 | B5: Bad Data | C5: =1-AVERAGEIF('Bad Data'!$C:$C, Overview!C$2, 'Bad Data'!$D:$D) -> 0.996891 | D5: 0.1 | E5: =D5*C5 -> 0.0996891 | F5: =1-AVERAGEIF('Bad Data'!$C:$C, Overview!F$2, 'Bad Data'!$D:$D) -> 0.99771273 | G5: 0.1 | H5: =G5*F5 -> 0.099771273
A6: 3 | B6: Pengkinian Data | C6: =AVERAGEIF('Pengkinian Data'!$C:$C, Overview!C$2, 'Pengkinian Data'!$D:$D) -> 1 | D6: 0.1 | E6: =D6*C6 -> 0.1 | F6: =AVERAGEIF('Pengkinian Data'!$C:$C, Overview!F$2, 'Pengkinian Data'!$D:$D) -> 1 | G6: 0.1 | H6: =G6*F6 -> 0.1 | O6: .
A7: 4 | B7: Uji Petik | C7: {=IFERROR(SUMPRODUCT(--('[3]Uji Petik'!$E$3:$E$73<>""), --('[3]Uji Petik'!$C$3:$C$73=C2)) / SUMPRODUCT(--('[3]Uji Petik'!$C$3:$C$73=C2)), 0)} -> 0 | D7: 0 | E7: =D7*C7 -> 0 | F7: {=IFERROR(SUMPRODUCT(--('[3]Uji Petik'!$E$3:$E$73<>""), --('[3]Uji Petik'!$C$3:$C$73=F2)) / SUMPRODUCT(--('[3]Uji Petik'!$C$3:$C$73=F2)), 0)} -> 0 | G7: 0 | H7: =G7*F7 -> 0
A8: 5 | B8: Sosialisasi | C8: {=IFERROR(AVERAGE(IF([1]Sosialisasi!$C$1:$C$10000=C2, [1]Sosialisasi!$D$1:$D$10000)), 0)} -> 0.2 | D8: 0.15 | E8: =D8*C8 -> 0.03 | F8: {=IFERROR(AVERAGE(IF([1]Sosialisasi!$C$1:$C$10000=F2, [1]Sosialisasi!$D$1:$D$10000)), 0)} -> 0.090909091 | G8: 0.15 | H8: =G8*F8 -> 0.013636364
A9: 6 | B9: EDD | C9: =AVERAGEIF('EDD PEP PPATK'!$C:$C, Overview!C$2, 'EDD PEP PPATK'!$D:$D) -> 0.99935484 | D9: 0.1 | E9: =D9*C9 -> 0.099935484 | F9: =AVERAGEIF('EDD PEP PPATK'!$C:$C, Overview!F$2, 'EDD PEP PPATK'!$D:$D) -> 0.9929728 | G9: 0.1 | H9: =G9*F9 -> 0.09929728
A10: 7 | B10: Self Learning Keikutsertaan | C10: {=IF(IFERROR(AVERAGE(IF('[1]Sheet2 (2)'!$C$1:$C$10000=C$2, '[1]Sheet2 (2)'!$D$1:$D$10000)), 0)>0.9, 1, IFERROR(AVERAGE(IF('[1]Sheet2 (2)'!$C$1:$C$10000=C$2, '[1]Sheet2 (2)'!$D$1:$D$10000)), 0))} -> 1 | D10: 0.05 | E10: =D10*C10 -> 0.05 | F10: {=IF(IFERROR(AVERAGE(IF('[1]Sheet2 (2)'!$C$1:$C$10000=F$2, '[1]Sheet2 (2)'!$D$1:$D$10000)), 0)>0.9, 1, IFERROR(AVERAGE(IF('[1]Sheet2 (2)'!$C$1:$C$10000=F$2, '[1]Sheet2 (2)'!$D$1:$D$10000)), 0))} -> 1 | G10: 0.05 | H10: =G10*F10 -> 0.05
A11: 8 | B11: Self Learning Score | C11: {=IF(IFERROR(AVERAGE(IF('[1]Sheet2 (3)'!$C$1:$C$10000=C2, '[1]Sheet2 (3)'!$D$1:$D$10000)), 0)>90, 1, IFERROR(AVERAGE(IF('[1]Sheet2 (3)'!$C$1:$C$10000=C2, '[1]Sheet2 (3)'!$D$1:$D$10000)), 0)/90)} -> 1 | D11: 0.05 | E11: =D11*C11 -> 0.05 | F11: {=IF(IFERROR(AVERAGE(IF('[1]Sheet2 (3)'!$C$1:$C$10000=F2, '[1]Sheet2 (3)'!$D$1:$D$10000)), 0)>90, 1, IFERROR(AVERAGE(IF('[1]Sheet2 (3)'!$C$1:$C$10000=F2, '[1]Sheet2 (3)'!$D$1:$D$10000)), 0)/90)} -> 1 | G11: 0.05 | H11: =G11*F11 -> 0.05
A12: 9 | B12: Maturitas | C12: =IF(AVERAGEIF('Nilai Maturitas'!$C:$C, Overview!C2, 'Nilai Maturitas'!$D:$D) > 8, 110%, AVERAGEIF('Nilai Maturitas'!$C:$C, Overview!C2, 'Nilai Maturitas'!$D:$D)/8*100%) -> 0.9676625 | D12: 0.1 | E12: =D12*C12 -> 0.09676625 | F12: =IF(AVERAGEIF('Nilai Maturitas'!$C:$C, Overview!F2, 'Nilai Maturitas'!$D:$D) > 8, 110%, AVERAGEIF('Nilai Maturitas'!$C:$C, Overview!F2, 'Nilai Maturitas'!$D:$D)/8*100%) -> 0.83615909 | G12: 0.1 | H12: =G12*F12 -> 0.083615909
A13: 10 | B13: Maturitas Dashboard | C13: =IF(AVERAGEIF('Maturitas Dashboard'!$C:$C, Overview!C$2, 'Maturitas Dashboard'!$D:$D) > 8, 110%, AVERAGEIF('Maturitas Dashboard'!$C:$C, Overview!C$2, 'Maturitas Dashboard'!$D:$D)/8*100%) -> 0.909375 | D13: 0.1 | E13: =D13*C13 -> 0.0909375 | F13: =IF(AVERAGEIF('Maturitas Dashboard'!$C:$C, Overview!F$2, 'Maturitas Dashboard'!$D:$D) > 8, 110%, AVERAGEIF('Maturitas Dashboard'!$C:$C, Overview!F$2, 'Maturitas Dashboard'!$D:$D)/8*100%) -> 0.94176136 | G13: 0.1 | H13: =G13*F13 -> 0.094176136
A14: 11 | B14: Penilaian Resiko | C14: =IF(AVERAGEIF('Penilaian Resiko'!$C:$C, Overview!C$2, 'Penilaian Resiko'!$D:$D) < 5.8, 110%, IF(AVERAGEIF('Penilaian Resiko'!$C:$C, Overview!C$2, 'Penilaian Resiko'!$D:$D) <7.4, 3/4*100%, 3/5*100%)) -> 1.1 | D14: 0.1 | E14: =D14*C14 -> 0.11 | F14: =IF(AVERAGEIF('Penilaian Resiko'!$C:$C, Overview!F$2, 'Penilaian Resiko'!$D:$D) < 5.8, 110%, IF(AVERAGEIF('Penilaian Resiko'!$C:$C, Overview!F$2, 'Penilaian Resiko'!$D:$D) <7.4, 3/4*100%, 3/5*100%)) -> 1.1 | G14: 0.1 | H14: =G14*F14 -> 0.11
C15: Progress | E15: =SUM(E4:E14) -> 0.87051015 | F15: Progress | H15: =SUM(H4:H14) -> 0.83549696

Sheet Overview tanpa KPI
A2: No | B2: Aspek Penilaian | C2: Ari | F2: Helvi
C3: Nilai | D3: Bobotan | E3: Score | F3: Nilai | G3: Bobotan | H3: Score
A4: 1 | B4: STR | C4: =IFERROR(COUNTIFS(STR!$V:$V, Overview!C$2 & " *", STR!$X:$X, "TRUE") / COUNTIFS(STR!$V:$V, Overview!C$2 & " *"), 0) -> 0.95454545 | D4: 0.15 | E4: =D4*C4 -> 0.14318182 | F4: =IFERROR(COUNTIFS(STR!$V:$V, Overview!F$2 & " *", STR!$X:$X, "TRUE") / COUNTIFS(STR!$V:$V, Overview!F$2 & " *"), 0) -> 0.9 | G4: 0.15 | H4: =G4*F4 -> 0.135
A5: 2 | B5: Bad Data | C5: =1-AVERAGEIF('Bad Data'!$C:$C, 'Overview tanpa KPI'!C$2, 'Bad Data'!$D:$D) -> 0.996891 | D5: 0.1 | E5: =D5*C5 -> 0.0996891 | F5: =1-AVERAGEIF('Bad Data'!$C:$C, 'Overview tanpa KPI'!F$2, 'Bad Data'!$D:$D) -> 0.99771273 | G5: 0.1 | H5: =G5*F5 -> 0.099771273
A6: 3 | B6: Pengkinian Data | C6: =AVERAGEIF('Pengkinian Data'!$C:$C, 'Overview tanpa KPI'!C$2, 'Pengkinian Data'!$D:$D) -> 1 | D6: 0.1 | E6: =D6*C6 -> 0.1 | F6: =AVERAGEIF('Pengkinian Data'!$C:$C, 'Overview tanpa KPI'!F$2, 'Pengkinian Data'!$D:$D) -> 1 | G6: 0.1 | H6: =G6*F6 -> 0.1 | O6: .
A7: 4 | B7: Uji Petik | C7: {=IFERROR(SUMPRODUCT(--('[3]Uji Petik'!$E$3:$E$73<>""), --('[3]Uji Petik'!$C$3:$C$73=C2)) / SUMPRODUCT(--('[3]Uji Petik'!$C$3:$C$73=C2)), 0)} -> 0 | D7: 0 | E7: =D7*C7 -> 0 | F7: {=IFERROR(SUMPRODUCT(--('[3]Uji Petik'!$E$3:$E$73<>""), --('[3]Uji Petik'!$C$3:$C$73=F2)) / SUMPRODUCT(--('[3]Uji Petik'!$C$3:$C$73=F2)), 0)} -> 0 | G7: 0 | H7: =G7*F7 -> 0
A8: 5 | B8: Sosialisasi | C8: {=IFERROR(AVERAGE(IF([1]Sosialisasi!$C$1:$C$10000=C2, [1]Sosialisasi!$D$1:$D$10000)), 0)} -> 0.2 | D8: 0.15 | E8: =D8*C8 -> 0.03 | F8: {=IFERROR(AVERAGE(IF([1]Sosialisasi!$C$1:$C$10000=F2, [1]Sosialisasi!$D$1:$D$10000)), 0)} -> 0.090909091 | G8: 0.15 | H8: =G8*F8 -> 0.013636364
A9: 6 | B9: EDD | C9: =AVERAGEIF('EDD PEP PPATK'!$C:$C, 'Overview tanpa KPI'!C$2, 'EDD PEP PPATK'!$D:$D) -> 0.99935484 | D9: 0.1 | E9: =D9*C9 -> 0.099935484 | F9: =AVERAGEIF('EDD PEP PPATK'!$C:$C, 'Overview tanpa KPI'!F$2, 'EDD PEP PPATK'!$D:$D) -> 0.9929728 | G9: 0.1 | H9: =G9*F9 -> 0.09929728
A10: 7 | B10: Self Learning Keikutsertaan | C10: {=IFERROR(AVERAGE(IF('[1]Sheet2 (2)'!$C$1:$C$10000=C$2, '[1]Sheet2 (2)'!$D$1:$D$10000)), 0)} -> 0.9224162 | D10: 0.05 | E10: =D10*C10 -> 0.04612081 | F10: {=IFERROR(AVERAGE(IF('[1]Sheet2 (2)'!$C$1:$C$10000=F$2, '[1]Sheet2 (2)'!$D$1:$D$10000)), 0)} -> 0.92336483 | G10: 0.05 | H10: =G10*F10 -> 0.046168242
A11: 8 | B11: Self Learning Score | C11: {=IFERROR(AVERAGE(IF('[1]Sheet2 (3)'!$C$1:$C$10000=C2, '[1]Sheet2 (3)'!$D$1:$D$10000)), 0)} -> 96.763282 | D11: 0.05 | E11: =D11*C11 -> 4.8381641 | F11: {=IFERROR(AVERAGE(IF('[1]Sheet2 (3)'!$C$1:$C$10000=F2, '[1]Sheet2 (3)'!$D$1:$D$10000)), 0)} -> 96.79123 | G11: 0.05 | H11: =G11*F11 -> 4.8395615
A12: 9 | B12: Maturitas | C12: =AVERAGEIF('Nilai Maturitas'!$C:$C, 'Overview tanpa KPI'!C2, 'Nilai Maturitas'!$D:$D) -> 7.7413 | D12: 0.1 | E12: =D12*C12 -> 0.77413 | F12: =AVERAGEIF('Nilai Maturitas'!$C:$C, 'Overview tanpa KPI'!F2, 'Nilai Maturitas'!$D:$D) -> 6.6892727 | G12: 0.1 | H12: =G12*F12 -> 0.66892727
A13: 10 | B13: Maturitas Dashboard | C13: =AVERAGEIF('Maturitas Dashboard'!$C:$C, 'Overview tanpa KPI'!C$2, 'Maturitas Dashboard'!$D:$D) -> 7.275 | D13: 0.1 | E13: =D13*C13 -> 0.7275 | F13: =AVERAGEIF('Maturitas Dashboard'!$C:$C, 'Overview tanpa KPI'!F$2, 'Maturitas Dashboard'!$D:$D) -> 7.5340909 | G13: 0.1 | H13: =G13*F13 -> 0.75340909
A14: 11 | B14: Penilaian Resiko | C14: =AVERAGEIF('Penilaian Resiko'!$C:$C, 'Overview tanpa KPI'!C$2, 'Penilaian Resiko'!$D:$D) -> 5.174 | D14: 0.1 | E14: =D14*C14 -> 0.5174 | F14: =AVERAGEIF('Penilaian Resiko'!$C:$C, 'Overview tanpa KPI'!F$2, 'Penilaian Resiko'!$D:$D) -> 5.2534545 | G14: 0.1 | H14: =G14*F14 -> 0.52534545
C15: Progress | E15: =SUM(E4:E14) -> 7.3761213 | F15: Progress | H15: =SUM(H4:H14) -> 7.2811165
