Workbook

Sheet STR
A1: POSISI | B1: NAMA | C1: CIF | D1: No Rek/ Kartu Kredit | E1: RESIKO | F1: BRILINK | G1: STATUS PEKERJA | H1: DIGITAL SAVING | I1: SKENARIO | J1: SCORING | K1: INFO PARAM | L1: KATEGORI | M1: UNIT KERJA | N1: KANTOR CABANG | O1: KANTOR KANWIL | P1: REKOMENDASI UKER | Q1: REKOMENDASI UKK | R1: STATUS UKER | S1: STATUS | T1: DISPOSISI | U1: INFO LAINNYA | V1: Disposisi RAC | W1: Tanggal | X1: Status TL
A2: {=_xlfn._xlws.FILTER('[3]STR-2026-8-2026-8'!$A:$U, ISNUMBER(SEARCH("Medan", '[3]STR-2026-8-2026-8'!$O:$O)), "")} -> 46265 | B2: ANDRE PANGESTU | C2: ADXYK74 | D2: 23801093444509 | E2: 0 | F2: Tidak | G2: Tidak | H2: 0 | I2: Jual Beli Rekening - E channel Trx | J2: 33 | K2: 113 | L2: Narkotika/Judi Online/Penipuan | M2: KC Binjai | N2: KC Binjai | O2: Medan | P2: 0 | Q2: 0 | R2: Belum TL | S2: Belum TL | T2: 0 | U2: "-" | V2: Zulkarnain | W2: 46241 | X2: TRUE | Y2: =_xlfn.XLOOKUP(TRIM(B2), [4]penilaian_STR!$2:$2, [4]penilaian_STR!$44:$44, "") -> 3.0169643 | AC2: =TRIM(B2) -> ANDRE PANGESTU | AD2: ANDRE PANGESTU
A3: 46265 | B3: ALVIN ADAM | C3: AEYSY93 | D3: 23801097339502 | E3: 0 | F3: Tidak | G3: Tidak | H3: 0 | I3: Jual Beli Rekening - E channel Trx | J3: 33 | K3: 113 | L3: Narkotika/Judi Online/Penipuan | M3: KC Binjai | N3: KC Binjai | O3: Medan | P3: 0 | Q3: 0 | R3: Belum TL | S3: Belum TL | T3: 0 | U3: "-" | V3: Zulkarnain | W3: 46241 | X3: TRUE | Y3: =_xlfn.XLOOKUP(TRIM(B3), [4]penilaian_STR!$2:$2, [4]penilaian_STR!$44:$44, "") -> 2.9794643 | Z3: Zulkarnain | AA3: TL Done | AB3: =COUNTIFS($V:$V, Z3, X:X, "TRUE") -> 14 | AC3: =TRIM(B3) -> ALVIN ADAM | AD3: ALVIN ADAM
A4: 46265 | B4: ABDULLAH | C4: AVH4880 | D4: 621701051854538 | E4: SEDANG | F4: Tidak | G4: Tidak | H4: Tidak | I4: Pencurian Rekening | J4: 50 | K4: 58 | L4: Perbankan | M4: KC BANDA ACEH CUT MEUTIA | N4: KANWIL Medan | O4: Medan | P4: 0 | Q4: 0 | R4: Belum TL | S4: Belum TL | T4: 90171841 - Rifqi Aziz | U4: "-" | V4: Firdaus A Hamid | W4: 46241 | X4: TRUE | Y4: =_xlfn.XLOOKUP(TRIM(B4), [4]penilaian_STR!$2:$2, [4]penilaian_STR!$44:$44, "") | AA4: Total Diposisi | AB4: =COUNTIF(V:V,Z3) -> 14 | AC4: =TRIM(B4) -> ABDULLAH | AD4: ABDULLAH
A5: 46265 | B5: CINTA RAJA | C5: C060929 | D5: 69401888333569 | E5: TINGGI | F5: Tidak | G5: Tidak | H5: Tidak | I5: Perpajakan | J5: 63 | K5: 1.33 | L5: Perpajakan | M5: KCP KRAKATAU MEDAN | N5: KC Medan Putri Hijau | O5: Medan | P5: 0 | Q5: 0 | R5: Belum TL | S5: Belum TL | T5: 90185538 - Muhammad Fahikal Auz | U5: "-" | V5: Bambang Dwi Raharjo | W5: 46241 | X5: TRUE | Y5: =_xlfn.XLOOKUP(TRIM(B5), [4]penilaian_STR!$2:$2, [4]penilaian_STR!$44:$44, "") | AA5: % Done | AB5: =AB3/AB4 -> 1 | AC5: =TRIM(B5) -> CINTA RAJA | AD5: CINTA RAJA
A6: 46265 | B6: CV DHARINDO CORP | C6: CZ20634 | D6: 222701001543564 | E6: 0 | F6: Tidak | G6: Tidak | H6: Tidak | I6: Business Email Compromise (BEC) | J6: 30 | K6: 13 | L6: Penipuan | M6: KCP RING ROAD | N6: KC Medan Iskandar Muda | O6: Medan | P6: 0 | Q6: 0 | R6: Belum TL | S6: Belum TL | T6: 90185537 - Moh.Khoerul Fajar Ar | U6: "-" | V6: Herry Kurniawan | W6: 46241 | X6: TRUE | Y6: =_xlfn.XLOOKUP(TRIM(B6), [4]penilaian_STR!$2:$2, [4]penilaian_STR!$44:$44, "") | Z6: Firdaus A Hamid | AA6: TL Done | AB6: =COUNTIFS($V:$V, Z6, X:X, "TRUE") -> 7 | AC6: =TRIM(B6) -> CV DHARINDO CORP | AD6: CV DHARINDO CORP
A7: 46265 | B7: DEDE HANDOKO | C7: DFWZ832 | D7: 335201069347532 | E7: 0 | F7: Tidak | G7: Tidak | H7: 0 | I7: Jual Beli Rekening - E channel Trx | J7: 33 | K7: 113 | L7: Narkotika/Judi Online/Penipuan | M7: UNIT PASAR HORAS | N7: KC Pematang Siantar | O7: Medan | P7: 0 | Q7: 0 | R7: Belum TL | S7: Belum TL | T7: 0 | U7: "-" | V7: Zulkarnain | W7: 46241 | X7: TRUE | Y7: =_xlfn.XLOOKUP(TRIM(B7), [4]penilaian_STR!$2:$2, [4]penilaian_STR!$44:$44, "") | AA7: Total Diposisi | AB7: =COUNTIF(V:V,Z6) -> 7 | AC7: =TRIM(B7) -> DEDE HANDOKO | AD7: DEDE HANDOKO
A8: 46265 | B8: EVA | C8: EWA4533 | D8: 529401053024532 | E8: 0 | F8: Tidak | G8: Tidak | H8: 0 | I8: Jual Beli Rekening - E channel Trx | J8: 33 | K8: 113 | L8: Narkotika/Judi Online/Penipuan | M8: UNIT SIMPANG KOLAM THAMRIN | N8: KC Medan Thamrin | O8: Medan | P8: 0 | Q8: 0 | R8: Belum TL | S8: Belum TL | T8: 0 | U8: "-" | V8: Richard Siburian | W8: 46241 | X8: TRUE | Y8: =_xlfn.XLOOKUP(TRIM(B8), [4]penilaian_STR!$2:$2, [4]penilaian_STR!$44:$44, "") -> 3.1241071 | AA8: % Done | AB8: =AB6/AB7 -> 1 | AC8: =TRIM(B8) -> EVA | AD8: EVA
A9: 46265 | B9: FARHAN ADRIAN | C9: FPE3381 | D9: 108701018971509 | E9: 0 | F9: Tidak | G9: Tidak | H9: 0 | I9: Jual Beli Rekening - E channel Trx | J9: 33 | K9: 113 | L9: Narkotika/Judi Online/Penipuan | M9: KCP GADJAHMADA | N9: KC Medan Iskandar Muda | O9: Medan | P9: 0 | Q9: 0 | R9: Belum TL | S9: Belum TL | T9: 0 | U9: "-" | V9: Herry Kurniawan | W9: 46241 | X9: TRUE | Y9: =_xlfn.XLOOKUP(TRIM(B9), [4]penilaian_STR!$2:$2, [4]penilaian_STR!$44:$44, "") -> 2.4522321 | Z9: Bambang Dwi Raharjo | AA9: TL Done | AB9: =COUNTIFS($V:$V, Z9, X:X, "TRUE") -> 16 | AC9: =TRIM(B9) -> FARHAN ADRIAN | AD9: FARHAN ADRIAN
A10: 46265 | B10: HUSAINI | C10: HCAF912 | D10: 69401036018507 | E10: 0 | F10: Tidak | G10: Tidak | H10: 0 | I10: Jual Beli Rekening - E channel Trx | J10: 33 | K10: 113 | L10: Narkotika/Judi Online/Penipuan | M10: KCP KRAKATAU MEDAN | N10: KC Medan Putri Hijau | O10: Medan | P10: 0 | Q10: 0 | R10: Belum TL | S10: Belum TL | T10: 0 | U10: "-" | V10: Bambang Dwi Raharjo | W10: 46241 | X10: TRUE | Y10: =_xlfn.XLOOKUP(TRIM(B10), [4]penilaian_STR!$2:$2, [4]penilaian_STR!$44:$44, "") | AA10: Total Diposisi | AB10: =COUNTIF(V:V,Z9) -> 16 | AC10: =TRIM(B10) -> HUSAINI | AD10: HUSAINI
A11: 46265 | B11: HARIS MATIUS SILAEN | C11: HNW9351 | D11: 206201038412502 | E11: SEDANG | F11: Tidak | G11: Tidak | H11: Ya | I11: Narkotika - Area Lapas | J11: 48 | K11: 48 | L11: Narkotika | M11: KC Kota Pinang | N11: KC Kota Pinang | O11: Medan | P11: 0 | Q11: 0 | R11: Belum TL | S11: Belum TL | T11: 90186790 - Muhammad Alfin Farha | U11: "-" | V11: Richard Siburian | W11: 46241 | X11: TRUE | Y11: =_xlfn.XLOOKUP(TRIM(B11), [4]penilaian_STR!$2:$2, [4]penilaian_STR!$44:$44, "") | AA11: % Done | AB11: =AB9/AB10 -> 1 | AC11: =TRIM(B11) -> HARIS MATIUS SILAEN | AD11: HARIS MATIUS SILAEN
A12: 46265 | B12: HASMERI | C12: HTF8991 | D12: 40401089317509 | E12: 0 | F12: Tidak | G12: Tidak | H12: 0 | I12: Jual Beli Rekening - E channel Trx | J12: 33 | K12: 113 | L12: Narkotika/Judi Online/Penipuan | M12: KC Medan Gatot Subroto | N12: KC Medan Gatot Subroto | O12: Medan | P12: 0 | Q12: 0 | R12: Belum TL | S12: Belum TL | T12: 0 | U12: "-" | V12: Richard Siburian | W12: 46241 | X12: TRUE | Y12: =_xlfn.XLOOKUP(TRIM(B12), [4]penilaian_STR!$2:$2, [4]penilaian_STR!$44:$44, "") | Z12: Herry Kurniawan | AA12: TL Done | AB12: =COUNTIFS($V:$V, Z12, X:X, "TRUE") -> 11 | AC12: =TRIM(B12) -> HASMERI | AD12: HASMERI
A13: 46265 | B13: ICHSAN ANDARA | C13: ICTS631 | D13: 158701002935507 | E13: 0 | F13: Tidak | G13: Tidak | H13: 0 | I13: Jual Beli Rekening - E channel Trx | J13: 33 | K13: 113 | L13: Narkotika/Judi Online/Penipuan | M13: KK PASAR RAME | N13: KC Medan Thamrin | O13: Medan | P13: 0 | Q13: 0 | R13: Belum TL | S13: Belum TL | T13: 0 | U13: "-" | V13: Richard Siburian | W13: 46241 | X13: TRUE | Y13: =_xlfn.XLOOKUP(TRIM(B13), [4]penilaian_STR!$2:$2, [4]penilaian_STR!$44:$44, "") | AA13: Total Diposisi | AB13: =COUNTIF(V:V,Z12) -> 11 | AC13: =TRIM(B13) -> ICHSAN ANDARA | AD13: ICHSAN ANDARA
A14: 46265 | B14: INDORASAPRIMA SUKSES MAKMUR | C14: IDPK933 | D14: 11301003484309 | E14: 0 | F14: Tidak | G14: Tidak | H14: Tidak | I14: Perpajakan | J14: 33 | K14: 41 | L14: Perpajakan | M14: KC Pematang Siantar | N14: KC Pematang Siantar | O14: Medan | P14: 0 | Q14: 0 | R14: Belum TL | S14: Belum TL | T14: 90185537 - Moh.Khoerul Fajar Ar | U14: "-" | V14: Zulkarnain | W14: 46241 | X14: TRUE | Y14: =_xlfn.XLOOKUP(TRIM(B14), [4]penilaian_STR!$2:$2, [4]penilaian_STR!$44:$44, "") | AA14: % Done | AB14: =AB12/AB13 -> 1 | AC14: =TRIM(B14) -> INDORASAPRIMA SUKSES MAKMUR | AD14: INDORASAPRIMA SUKSES MAKMUR
A15: 46265 | B15: INDRA WADI | C15: IMQ2459 | D15: 533601012159534 | E15: SEDANG | F15: Tidak | G15: Tidak | H15: Tidak | I15: Narkotika - Area Lapas | J15: 50 | K15: 46 | L15: Narkotika | M15: UNIT MUARA SOMA PANYABUNGAN | N15: KC Panyabungan | O15: Medan | P15: 0 | Q15: 0 | R15: Belum TL | S15: Belum TL | T15: 90186790 - Muhammad Alfin Farha | U15: "-" | V15: Zulkarnain | W15: 46241 | X15: TRUE | Y15: =_xlfn.XLOOKUP(TRIM(B15), [4]penilaian_STR!$2:$2, [4]penilaian_STR!$44:$44, "") | AC15: =TRIM(B15) -> INDRA WADI | AD15: INDRA WADI
A16: 46265 | B16: IMRON HARAHAP | C16: IO81279 | D16: 109701000432564 | E16: TINGGI | F16: Tidak | G16: Tidak | H16: Tidak | I16: Perpajakan | J16: 73 | K16: 1.33 | L16: Perpajakan | M16: KC Sibuhuan | N16: KC Sibuhuan | O16: Medan | P16: 0 | Q16: 0 | R16: Belum TL | S16: Belum TL | T16: 90185537 - Moh.Khoerul Fajar Ar | U16: "-" | V16: Herry Kurniawan | W16: 46241 | X16: TRUE | Y16: =_xlfn.XLOOKUP(TRIM(B16), [4]penilaian_STR!$2:$2, [4]penilaian_STR!$44:$44, "") | AC16: =TRIM(B16) -> IMRON HARAHAP | AD16: IMRON HARAHAP
A17: 46265 | B17: IRAWATI PONTOH | C17: IX49020 | D17: 523201033906538 | E17: SEDANG | F17: Tidak | G17: Tidak | H17: Tidak | I17: Pencurian Rekening | J17: 49 | K17: 58 | L17: Perbankan | M17: KC BANDA ACEH CUT MEUTIA | N17: KANWIL Medan | O17: Medan | P17: 0 | Q17: 0 | R17: Belum TL | S17: Belum TL | T17: 90170665 - Mutiara Ayuningtyas | U17: "-" | V17: Firdaus A Hamid | W17: 46241 | X17: TRUE | Y17: =_xlfn.XLOOKUP(TRIM(B17), [4]penilaian_STR!$2:$2, [4]penilaian_STR!$44:$44, "") | AA17: =B2 -> ANDRE PANGESTU | AC17: =TRIM(B17) -> IRAWATI PONTOH | AD17: IRAWATI PONTOH
A18: 46265 | B18: JOKO SUSILO SITORUS | C18: J641244 | D18: 63601001644561 | E18: SEDANG | F18: Ya | G18: Tidak | H18: Tidak | I18: Narkotika - Area Lapas | J18: 50 | K18: 46 | L18: Narkotika | M18: KC Perdagangan | N18: KC Perdagangan | O18: Medan | P18: 0 | Q18: 0 | R18: Belum TL | S18: Belum TL | T18: 90150130 - Intan Aida Pratiwi | U18: "-" | V18: Herry Kurniawan | W18: 46241 | X18: TRUE | Y18: =_xlfn.XLOOKUP(TRIM(B18), [4]penilaian_STR!$2:$2, [4]penilaian_STR!$44:$44, "") | AC18: =TRIM(B18) -> JOKO SUSILO SITORUS | AD18: JOKO SUSILO SITORUS
A19: 46265 | B19: LILIANI | C19: LGG4540 | D19: 804201040988537 | E19: 0 | F19: Tidak | G19: Tidak | H19: 0 | I19: Jual Beli Rekening - E channel Trx | J19: 33 | K19: 113 | L19: Narkotika/Judi Online/Penipuan | M19: UNIT CINTA RAKYAT THAMRIN | N19: KC Medan Thamrin | O19: Medan | P19: 0 | Q19: 0 | R19: Belum TL | S19: Belum TL | T19: 0 | U19: "-" | V19: Richard Siburian | W19: 46241 | X19: TRUE | Y19: =_xlfn.XLOOKUP(TRIM(B19), [4]penilaian_STR!$2:$2, [4]penilaian_STR!$44:$44, "") | AC19: =TRIM(B19) -> LILIANI | AD19: LILIANI
A20: 46265 | B20: M. ALFAIZ ZAHY MUFLIH | C20: MFDGO03 | D20: 108701019440501 | E20: 0 | F20: Tidak | G20: Tidak | H20: 0 | I20: Jual Beli Rekening - E channel Trx | J20: 33 | K20: 113 | L20: Narkotika/Judi Online/Penipuan | M20: KCP GADJAHMADA | N20: KC Medan Iskandar Muda | O20: Medan | P20: 0 | Q20: 0 | R20: Belum TL | S20: Belum TL | T20: 0 | U20: "-" | V20: Herry Kurniawan | W20: 46241 | X20: TRUE | Y20: =_xlfn.XLOOKUP(TRIM(B20), [4]penilaian_STR!$2:$2, [4]penilaian_STR!$44:$44, "") -> 2.4772321 | AC20: =TRIM(B20) -> M. ALFAIZ ZAHY MUFLIH | AD20: M. ALFAIZ ZAHY MUFLIH
A21: 46265 | B21: MUHAMMAD RAFLI | C21: MQDG925 | D21: 69301025965505 | E21: 0 | F21: Tidak | G21: Tidak | H21: 0 | I21: Jual Beli Rekening - E channel Trx | J21: 33 | K21: 113 | L21: Narkotika/Judi Online/Penipuan | M21: KCP AKSARA | N21: KC Medan Sisingamangaraja | O21: Medan | P21: 0 | Q21: 0 | R21: Belum TL | S21: Belum TL | T21: 0 | U21: "-" | V21: Zulkarnain | W21: 46241 | X21: TRUE | Y21: =_xlfn.XLOOKUP(TRIM(B21), [4]penilaian_STR!$2:$2, [4]penilaian_STR!$44:$44, "") | AC21: =TRIM(B21) -> MUHAMMAD RAFLI | AD21: MUHAMMAD RAFLI
A22: 46265 | B22: MUZAINAH | C22: MTNL180 | D22: 814701008014532 | E22: SEDANG | F22: Tidak | G22: Tidak | H22: Tidak | I22: Pencurian Rekening | J22: 49 | K22: 58 | L22: Perbankan | M22: KC BANDA ACEH CUT MEUTIA | N22: KANWIL Medan | O22: Medan | P22: 0 | Q22: 0 | R22: Belum TL | S22: Belum TL | T22: 90170665 - Mutiara Ayuningtyas | U22: "-" | V22: Firdaus A Hamid | W22: 46241 | X22: TRUE | Y22: =_xlfn.XLOOKUP(TRIM(B22), [4]penilaian_STR!$2:$2, [4]penilaian_STR!$44:$44, "") | AC22: =TRIM(B22) -> MUZAINAH | AD22: MUZAINAH
A23: 46265 | B23: M SALEH | C23: MVIP977 | D23: 109201053817501 | E23: 0 | F23: Tidak | G23: Tidak | H23: 0 | I23: Jual Beli Rekening - E channel Trx | J23: 33 | K23: 113 | L23: Narkotika/Judi Online/Penipuan | M23: KCP TEMBUNG | N23: KC Medan Thamrin | O23: Medan | P23: 0 | Q23: 0 | R23: Belum TL | S23: Belum TL | T23: 0 | U23: "-" | V23: Richard Siburian | W23: 46241 | X23: TRUE | Y23: =_xlfn.XLOOKUP(TRIM(B23), [4]penilaian_STR!$2:$2, [4]penilaian_STR!$44:$44, "") | AC23: =TRIM(B23) -> M SALEH | AD23: M SALEH
A24: 46265 | B24: MUCHLISIN HABIBIE | C24: MVIY748 | D24: 108301023789501 | E24: 0 | F24: Tidak | G24: Tidak | H24: 0 | I24: Jual Beli Rekening - E channel Trx | J24: 33 | K24: 113 | L24: Narkotika/Judi Online/Penipuan | M24: KCP KESAWAN | N24: KC Medan Putri Hijau | O24: Medan | P24: 0 | Q24: 0 | R24: Belum TL | S24: Belum TL | T24: 0 | U24: "-" | V24: Bambang Dwi Raharjo | W24: 46241 | X24: TRUE | Y24: =_xlfn.XLOOKUP(TRIM(B24), [4]penilaian_STR!$2:$2, [4]penilaian_STR!$44:$44, "") | AC24: =TRIM(B24) -> MUCHLISIN HABIBIE | AD24: MUCHLISIN HABIBIE
A25: 46265 | B25: MAPPASESSU | C25: MVR1308 | D25: 769501017490539 | E25: SEDANG | F25: Tidak | G25: Tidak | H25: Tidak | I25: Pencurian Rekening | J25: 46 | K25: 58 | L25: Perbankan | M25: KC BANDA ACEH CUT MEUTIA | N25: KANWIL Medan | O25: Medan | P25: 0 | Q25: 0 | R25: Belum TL | S25: Belum TL | T25: 90186790 - Muhammad Alfin Farha | U25: "-" | V25: Firdaus A Hamid | W25: 46241 | X25: TRUE | Y25: =_xlfn.XLOOKUP(TRIM(B25), [4]penilaian_STR!$2:$2, [4]penilaian_STR!$44:$44, "") | AC25: =TRIM(B25) -> MAPPASESSU | AD25: MAPPASESSU
A26: 46265 | B26: NURUL HADI | C26: NMBS662 | D26: 115401034791502 | E26: 0 | F26: Tidak | G26: Tidak | H26: 0 | I26: Jual Beli Rekening - E channel Trx | J26: 33 | K26: 113 | L26: Narkotika/Judi Online/Penipuan | M26: KCP DISKI | N26: KC Binjai | O26: Medan | P26: 0 | Q26: 0 | R26: Belum TL | S26: Belum TL | T26: 0 | U26: "-" | V26: Zulkarnain | W26: 46241 | X26: TRUE | Y26: =_xlfn.XLOOKUP(TRIM(B26), [4]penilaian_STR!$2:$2, [4]penilaian_STR!$44:$44, "") | AC26: =TRIM(B26) -> NURUL HADI | AD26: NURUL HADI
A27: 46265 | B27: NICKHOLAS JEFFRY BUNGARAN BATUBARA | C27: NMNF995 | D27: 108701018921504 | E27: 0 | F27: Tidak | G27: Tidak | H27: 0 | I27: Jual Beli Rekening - E channel Trx | J27: 33 | K27: 113 | L27: Narkotika/Judi Online/Penipuan | M27: KCP GADJAHMADA | N27: KC Medan Iskandar Muda | O27: Medan | P27: 0 | Q27: 0 | R27: Belum TL | S27: Belum TL | T27: 0 | U27: "-" | V27: Herry Kurniawan | W27: 46241 | X27: TRUE | Y27: =_xlfn.XLOOKUP(TRIM(B27), [4]penilaian_STR!$2:$2, [4]penilaian_STR!$44:$44, "") | AC27: =TRIM(B27) -> NICKHOLAS JEFFRY BUNGARAN BATUBARA | AD27: NICKHOLAS JEFFRY BUNGARAN BATUBARA
A28: 46265 | B28: NUR ELISAH BR HASIBUAN | C28: NNY2817 | D28: 337501073914531 | E28: 0 | F28: Tidak | G28: Tidak | H28: 0 | I28: Jual Beli Rekening - E channel Trx | J28: 33 | K28: 113 | L28: Narkotika/Judi Online/Penipuan | M28: UNIT JATINEGARA BINJAI | N28: KC Binjai | O28: Medan | P28: 0 | Q28: 0 | R28: Belum TL | S28: Belum TL | T28: 0 | U28: "-" | V28: Zulkarnain | W28: 46241 | X28: TRUE | Y28: =_xlfn.XLOOKUP(TRIM(B28), [4]penilaian_STR!$2:$2, [4]penilaian_STR!$44:$44, "") | AC28: =TRIM(B28) -> NUR ELISAH BR HASIBUAN | AD28: NUR ELISAH BR HASIBUAN
A29: 46265 | B29: RUMAH SAKIT UMUM SAWIT INDAH | C29: PK68945 | D29: 353801000006305 | E29: SEDANG | F29: Tidak | G29: Tidak | H29: Tidak | I29: Perpajakan | J29: 48 | K29: 41 | L29: Perpajakan | M29: UNIT SEI RAMPAH TEBING TINGGI | N29: KC Tebing Tinggi | O29: Medan | P29: 0 | Q29: 0 | R29: Belum TL | S29: Belum TL | T29: 90150130 - Intan Aida Pratiwi | U29: "-" | V29: Richard Siburian | W29: 46241 | X29: TRUE | Y29: =_xlfn.XLOOKUP(TRIM(B29), [4]penilaian_STR!$2:$2, [4]penilaian_STR!$44:$44, "") | AC29: =TRIM(B29) -> RUMAH SAKIT UMUM SAWIT INDAH | AD29: RUMAH SAKIT UMUM SAWIT INDAH
A30: 46265 | B30: PT SINUNUKAN ENERGI GEMILANG | C30: PNM6408 | D30: 723401000014568 | E30: 0 | F30: Tidak | G30: Tidak | H30: Tidak | I30: Perpajakan | J30: 33 | K30: 41 | L30: Perpajakan | M30: UNIT SINUNUKAN PANYABUNGAN | N30: KC Panyabungan | O30: Medan | P30: 0 | Q30: 0 | R30: Belum TL | S30: Belum TL | T30: 00394520 - Frida Akbar Rani | U30: "-" | V30: Zulkarnain | W30: 46241 | X30: TRUE | Y30: =_xlfn.XLOOKUP(TRIM(B30), [4]penilaian_STR!$2:$2, [4]penilaian_STR!$44:$44, "") | AC30: =TRIM(B30) -> PT SINUNUKAN ENERGI GEMILANG | AD30: PT SINUNUKAN ENERGI GEMILANG
A31: 46265 | B31: PT ANUGERAH KENCANA CORP | C31: PPE1182 | D31: 32301002943309 | E31: 0 | F31: Tidak | G31: Tidak | H31: Tidak | I31: Business Email Compromise (BEC) | J31: 30 | K31: 13 | L31: Penipuan | M31: KC Kisaran | N31: KC Kisaran | O31: Medan | P31: 0 | Q31: 0 | R31: Belum TL | S31: Belum TL | T31: 90186796 - Devito Arya Wiradila | U31: "-" | V31: Bambang Dwi Raharjo | W31: 46241 | X31: TRUE | Y31: =_xlfn.XLOOKUP(TRIM(B31), [4]penilaian_STR!$2:$2, [4]penilaian_STR!$44:$44, "") | AC31: =TRIM(B31) -> PT ANUGERAH KENCANA CORP | AD31: PT ANUGERAH KENCANA CORP
A32: 46265 | B32: RAZALI HUSEIN SE | C32: ROA4191 | D32: 115401000001503 | E32: TINGGI | F32: Tidak | G32: Tidak | H32: Tidak | I32: Perpajakan | J32: 73 | K32: 1.33 | L32: Perpajakan | M32: KCP DISKI | N32: KC Binjai | O32: Medan | P32: 0 | Q32: 0 | R32: Belum TL | S32: Belum TL | T32: 90186790 - Muhammad Alfin Farha | U32: "-" | V32: Zulkarnain | W32: 46241 | X32: TRUE | Y32: =_xlfn.XLOOKUP(TRIM(B32), [4]penilaian_STR!$2:$2, [4]penilaian_STR!$44:$44, "") -> 3.25625 | AC32: =TRIM(B32) -> RAZALI HUSEIN SE | AD32: RAZALI HUSEIN SE
A33: 46265 | B33: RANGGA APRIYANDI SIREGAR | C33: ROOA642 | D33: 108801019478508 | E33: 0 | F33: Tidak | G33: Tidak | H33: 0 | I33: Jual Beli Rekening - E channel Trx | J33: 33 | K33: 113 | L33: Narkotika/Judi Online/Penipuan | M33: KCP MEDAN SETIABUDI | N33: KC Medan Gatot Subroto | O33: Medan | P33: 0 | Q33: 0 | R33: Belum TL | S33: Belum TL | T33: 0 | U33: "-" | V33: Richard Siburian | W33: 46241 | X33: TRUE | Y33: =_xlfn.XLOOKUP(TRIM(B33), [4]penilaian_STR!$2:$2, [4]penilaian_STR!$44:$44, "") | AC33: =TRIM(B33) -> RANGGA APRIYANDI SIREGAR | AD33: RANGGA APRIYANDI SIREGAR
A34: 46265 | B34: ROSITA ANGGEREK | C34: RU71957 | D34: 28301000993560 | E34: TINGGI | F34: Tidak | G34: Tidak | H34: Tidak | I34: Perpajakan | J34: 73 | K34: 1.33 | L34: Perpajakan | M34: KC Tebing Tinggi | N34: KC Tebing Tinggi | O34: Medan | P34: 0 | Q34: 0 | R34: Belum TL | S34: Belum TL | T34: 90186796 - Devito Arya Wiradila | U34: "-" | V34: Richard Siburian | W34: 46241 | X34: TRUE | Y34: =_xlfn.XLOOKUP(TRIM(B34), [4]penilaian_STR!$2:$2, [4]penilaian_STR!$44:$44, "") | AC34: =TRIM(B34) -> ROSITA ANGGEREK | AD34: ROSITA ANGGEREK
A35: 46265 | B35: SUGIANTO | C35: SEKWX69 | D35: 754301014191533 | E35: SEDANG | F35: Ya | G35: Tidak | H35: Tidak | I35: Pencurian Rekening | J35: 46 | K35: 58 | L35: Perbankan | M35: KC BANDA ACEH CUT MEUTIA | N35: KANWIL Medan | O35: Medan | P35: 0 | Q35: 0 | R35: Belum TL | S35: Belum TL | T35: 00336949 - Mochammad Al Farabi | U35: "-" | V35: Firdaus A Hamid | W35: 46241 | X35: TRUE | Y35: =_xlfn.XLOOKUP(TRIM(B35), [4]penilaian_STR!$2:$2, [4]penilaian_STR!$44:$44, "") | AC35: =TRIM(B35) -> SUGIANTO | AD35: SUGIANTO
A36: 46265 | B36: SULASMI | C36: SJSML89 | D36: 529401007494501 | E36: 0 | F36: Tidak | G36: Tidak | H36: 0 | I36: Jual Beli Rekening - E channel Trx | J36: 33 | K36: 113 | L36: Narkotika/Judi Online/Penipuan | M36: UNIT SIMPANG KOLAM THAMRIN | N36: KC Medan Thamrin | O36: Medan | P36: 0 | Q36: 0 | R36: Belum TL | S36: Belum TL | T36: 0 | U36: "-" | V36: Richard Siburian | W36: 46241 | X36: TRUE | Y36: =_xlfn.XLOOKUP(TRIM(B36), [4]penilaian_STR!$2:$2, [4]penilaian_STR!$44:$44, "") -> 3.2022321 | AC36: =TRIM(B36) -> SULASMI | AD36: SULASMI
A37: 46265 | B37: SRIYATI | C37: SRV0386 | D37: 558901029838538 | E37: SEDANG | F37: Ya | G37: Tidak | H37: Tidak | I37: Pencurian Rekening | J37: 46 | K37: 58 | L37: Perbankan | M37: KC BANDA ACEH CUT MEUTIA | N37: KANWIL Medan | O37: Medan | P37: 0 | Q37: 0 | R37: Belum TL | S37: Belum TL | T37: 00394520 - Frida Akbar Rani | U37: "-" | V37: Firdaus A Hamid | W37: 46241 | X37: TRUE | Y37: =_xlfn.XLOOKUP(TRIM(B37), [4]penilaian_STR!$2:$2, [4]penilaian_STR!$44:$44, "") | AC37: =TRIM(B37) -> SRIYATI | AD37: SRIYATI
A38: 46265 | B38: YETTI SUNARSIH | C38: YL53029 | D38: 760401002609532 | E38: SEDANG | F38: Tidak | G38: Tidak | H38: Tidak | I38: Pencurian Rekening | J38: 46 | K38: 58 | L38: Perbankan | M38: KC BANDA ACEH CUT MEUTIA | N38: KANWIL Medan | O38: Medan | P38: 0 | Q38: 0 | R38: Belum TL | S38: Belum TL | T38: 90185537 - Moh.Khoerul Fajar Ar | U38: "-" | V38: Firdaus A Hamid | W38: 46241 | X38: TRUE | Y38: =_xlfn.XLOOKUP(TRIM(B38), [4]penilaian_STR!$2:$2, [4]penilaian_STR!$44:$44, "") | AC38: =TRIM(B38) -> YETTI SUNARSIH | AD38: YETTI SUNARSIH
A39: 46265 | B39: CV OHZP PARDOMUAN SEJAHTERA | C39: CU64419 | D39: 222801001499303 | E39: 0 | F39: Tidak | G39: Tidak | H39: Tidak | I39: Perpajakan | J39: 33 | K39: 41 | L39: Perpajakan | M39: KCP GUNUNG TUA | N39: KC Padang Sidempuan | O39: Medan | P39: 0 | Q39: Tidak | R39: Belum TL | S39: Approved | T39: 90186790 - Muhammad Alfin Farha | U39: "-" | V39: Herry Kurniawan | W39: 46241 | X39: TRUE | Y39: =_xlfn.XLOOKUP(TRIM(B39), [4]penilaian_STR!$2:$2, [4]penilaian_STR!$44:$44, "") | AC39: =TRIM(B39) -> CV OHZP PARDOMUAN SEJAHTERA | AD39: CV OHZP PARDOMUAN SEJAHTERA
A40: 46265 | B40: RITA PURNAMA | C40: RLJX288 | D40: 33601036119537 | E40: 0 | F40: Tidak | G40: Tidak | H40: 0 | I40: Jual Beli Rekening - E channel Trx | J40: 33 | K40: 113 | L40: Narkotika/Judi Online/Penipuan | M40: KC Medan Iskandar Muda | N40: KC Medan Iskandar Muda | O40: Medan | P40: Ya | Q40: 0 | R40: Pending Approver | S40: Belum TL | T40: 0 | U40: "-" | V40: Herry Kurniawan | W40: 46241 | X40: TRUE | Y40: =_xlfn.XLOOKUP(TRIM(B40), [4]penilaian_STR!$2:$2, [4]penilaian_STR!$44:$44, "") | AC40: =TRIM(B40) -> RITA PURNAMA | AD40: RITA PURNAMA
...

Sheet EDD PEP PPATK
D1: 46280
A2: No. | B2: Unit Kerja | C2: PIC RAC | D2: %PEP TL Done | E2: Average
A3: 3 | B3: KC Gunung Sitoli | C3: Bambang Dwi Raharjo | D3: =_xlfn.XLOOKUP(B3, [2]PEP!$B:$B,[2]PEP!$G:$G) -> 0.98591549 | E3: =AVERAGE(D3:D8) -> 0.98043986
A4: 4 | B4: KC Kabanjahe | C4: Bambang Dwi Raharjo | D4: =_xlfn.XLOOKUP(B4, [2]PEP!$B:$B,[2]PEP!$G:$G) -> 0.97222222
A5: 5 | B5: KC Kisaran | C5: Bambang Dwi Raharjo | D5: =_xlfn.XLOOKUP(B5, [2]PEP!$B:$B,[2]PEP!$G:$G) -> 1
A6: 7 | B6: KC Lubuk Pakam | C6: Bambang Dwi Raharjo | D6: =_xlfn.XLOOKUP(B6, [2]PEP!$B:$B,[2]PEP!$G:$G) -> 1
A7: 10 | B7: KC Medan Putri Hijau | C7: Bambang Dwi Raharjo | D7: =_xlfn.XLOOKUP(B7, [2]PEP!$B:$B,[2]PEP!$G:$G) -> 0.96153846
A8: 20 | B8: KC Sidikalang | C8: Bambang Dwi Raharjo | D8: =_xlfn.XLOOKUP(B8, [2]PEP!$B:$B,[2]PEP!$G:$G) -> 0.96296296
A9: 9 | B9: KC Medan Iskandar Muda | C9: Herry Kurniawan | D9: =_xlfn.XLOOKUP(B9, [2]PEP!$B:$B,[2]PEP!$G:$G) -> 0.98773006 | E9: =AVERAGE(D9:D14) -> 0.99227158
A10: 13 | B10: KC Padang Sidempuan | C10: Herry Kurniawan | D10: =_xlfn.XLOOKUP(B10, [2]PEP!$B:$B,[2]PEP!$G:$G) -> 0.98550725
A11: 16 | B11: KC Perdagangan | C11: Herry Kurniawan | D11: =_xlfn.XLOOKUP(B11, [2]PEP!$B:$B,[2]PEP!$G:$G) -> 1
A12: 19 | B12: KC Sibuhuan | C12: Herry Kurniawan | D12: =_xlfn.XLOOKUP(B12, [2]PEP!$B:$B,[2]PEP!$G:$G) -> 1
A13: 21 | B13: KC Stabat | C13: Herry Kurniawan | D13: =_xlfn.XLOOKUP(B13, [2]PEP!$B:$B,[2]PEP!$G:$G) -> 0.98039216
A14: 23 | B14: KC Tarutung | C14: Herry Kurniawan | D14: =_xlfn.XLOOKUP(B14, [2]PEP!$B:$B,[2]PEP!$G:$G) -> 1
A15: 6 | B15: KC Kota Pinang | C15: Richard Siburian | D15: =_xlfn.XLOOKUP(B15, [2]PEP!$B:$B,[2]PEP!$G:$G) -> 1 | E15: =AVERAGE(D15:D20) -> 0.99253394
A16: 8 | B16: KC Medan Gatot Subroto | C16: Richard Siburian | D16: =_xlfn.XLOOKUP(B16, [2]PEP!$B:$B,[2]PEP!$G:$G) -> 1
A17: 12 | B17: KC Medan Thamrin | C17: Richard Siburian | D17: =_xlfn.XLOOKUP(B17, [2]PEP!$B:$B,[2]PEP!$G:$G) -> 0.98461538
A18: 17 | B18: KC Rantau Prapat | C18: Richard Siburian | D18: =_xlfn.XLOOKUP(B18, [2]PEP!$B:$B,[2]PEP!$G:$G) -> 1
A19: 18 | B19: KC Sibolga | C19: Richard Siburian | D19: =_xlfn.XLOOKUP(B19, [2]PEP!$B:$B,[2]PEP!$G:$G) -> 0.97058824
A20: 24 | B20: KC Tebing Tinggi | C20: Richard Siburian | D20: =_xlfn.XLOOKUP(B20, [2]PEP!$B:$B,[2]PEP!$G:$G) -> 1
A21: 1 | B21: KC Balige | C21: Zulkarnain | D21: =_xlfn.XLOOKUP(B21, [2]PEP!$B:$B,[2]PEP!$G:$G) -> 1 | E21: =AVERAGE(D21:D26) -> 0.97114232
A22: 2 | B22: KC Binjai | C22: Zulkarnain | D22: =_xlfn.XLOOKUP(B22, [2]PEP!$B:$B,[2]PEP!$G:$G) -> 0.97959184
A23: 11 | B23: KC Medan Sisingamangaraja | C23: Zulkarnain | D23: =_xlfn.XLOOKUP(B23, [2]PEP!$B:$B,[2]PEP!$G:$G) -> 0.96363636
A24: 14 | B24: KC Panyabungan | C24: Zulkarnain | D24: =_xlfn.XLOOKUP(B24, [2]PEP!$B:$B,[2]PEP!$G:$G) -> 0.89473684
A25: 15 | B25: KC Pematang Siantar | C25: Zulkarnain | D25: =_xlfn.XLOOKUP(B25, [2]PEP!$B:$B,[2]PEP!$G:$G) -> 0.98888889
A26: 22 | B26: KC Tanjung Balai | C26: Zulkarnain | D26: =_xlfn.XLOOKUP(B26, [2]PEP!$B:$B,[2]PEP!$G:$G) -> 1

Sheet Bad Data
D1: 46280
A2: No. | B2: Unit Kerja | C2: PIC RAC | D2: Bad Data | E2: Average
A3: 1 | B3: KC Gunung Sitoli | C3: Bambang Dwi Raharjo | D3: =_xlfn.XLOOKUP(B3, '[2]Bad Data'!$B:$B, '[2]Bad Data'!$D:$D) -> 0.00083 | E3: =AVERAGE(D3:D8) -> 0.0016883333
A4: 2 | B4: KC Kabanjahe | C4: Bambang Dwi Raharjo | D4: =_xlfn.XLOOKUP(B4, '[2]Bad Data'!$B:$B, '[2]Bad Data'!$D:$D) -> 0.00235
A5: 3 | B5: KC Kisaran | C5: Bambang Dwi Raharjo | D5: =_xlfn.XLOOKUP(B5, '[2]Bad Data'!$B:$B, '[2]Bad Data'!$D:$D) -> 0.00293
A6: 4 | B6: KC Lubuk Pakam | C6: Bambang Dwi Raharjo | D6: =_xlfn.XLOOKUP(B6, '[2]Bad Data'!$B:$B, '[2]Bad Data'!$D:$D) -> 0.00062
A7: 5 | B7: KC Medan Putri Hijau | C7: Bambang Dwi Raharjo | D7: =_xlfn.XLOOKUP(B7, '[2]Bad Data'!$B:$B, '[2]Bad Data'!$D:$D) -> 0.0013
A8: 6 | B8: KC Sidikalang | C8: Bambang Dwi Raharjo | D8: =_xlfn.XLOOKUP(B8, '[2]Bad Data'!$B:$B, '[2]Bad Data'!$D:$D) -> 0.0021
A9: 7 | B9: KC Medan Iskandar Muda | C9: Herry Kurniawan | D9: =_xlfn.XLOOKUP(B9, '[2]Bad Data'!$B:$B, '[2]Bad Data'!$D:$D) -> 0.00272 | E9: =AVERAGE(D9:D14) -> 0.0022483333
A10: 8 | B10: KC Padang Sidempuan | C10: Herry Kurniawan | D10: =_xlfn.XLOOKUP(B10, '[2]Bad Data'!$B:$B, '[2]Bad Data'!$D:$D) -> 0.00167
A11: 9 | B11: KC Perdagangan | C11: Herry Kurniawan | D11: =_xlfn.XLOOKUP(B11, '[2]Bad Data'!$B:$B, '[2]Bad Data'!$D:$D) -> 0.00121
A12: 10 | B12: KC Sibuhuan | C12: Herry Kurniawan | D12: =_xlfn.XLOOKUP(B12, '[2]Bad Data'!$B:$B, '[2]Bad Data'!$D:$D) -> 0.002
A13: 11 | B13: KC Stabat | C13: Herry Kurniawan | D13: =_xlfn.XLOOKUP(B13, '[2]Bad Data'!$B:$B, '[2]Bad Data'!$D:$D) -> 0.00291
A14: 12 | B14: KC Tarutung | C14: Herry Kurniawan | D14: =_xlfn.XLOOKUP(B14, '[2]Bad Data'!$B:$B, '[2]Bad Data'!$D:$D) -> 0.00298
A15: 13 | B15: KC Kota Pinang | C15: Richard Siburian | D15: =_xlfn.XLOOKUP(B15, '[2]Bad Data'!$B:$B, '[2]Bad Data'!$D:$D) -> 8e-05 | E15: =AVERAGE(D15:D20) -> 0.0018766667
A16: 14 | B16: KC Medan Gatot Subroto | C16: Richard Siburian | D16: =_xlfn.XLOOKUP(B16, '[2]Bad Data'!$B:$B, '[2]Bad Data'!$D:$D) -> 0.00352
A17: 15 | B17: KC Medan Thamrin | C17: Richard Siburian | D17: =_xlfn.XLOOKUP(B17, '[2]Bad Data'!$B:$B, '[2]Bad Data'!$D:$D) -> 0.00161
A18: 16 | B18: KC Rantau Prapat | C18: Richard Siburian | D18: =_xlfn.XLOOKUP(B18, '[2]Bad Data'!$B:$B, '[2]Bad Data'!$D:$D) -> 0.00165
A19: 17 | B19: KC Sibolga | C19: Richard Siburian | D19: =_xlfn.XLOOKUP(B19, '[2]Bad Data'!$B:$B, '[2]Bad Data'!$D:$D) -> 0.00255
A20: 18 | B20: KC Tebing Tinggi | C20: Richard Siburian | D20: =_xlfn.XLOOKUP(B20, '[2]Bad Data'!$B:$B, '[2]Bad Data'!$D:$D) -> 0.00185
A21: 19 | B21: KC Balige | C21: Zulkarnain | D21: =_xlfn.XLOOKUP(B21, '[2]Bad Data'!$B:$B, '[2]Bad Data'!$D:$D) -> 0.00047 | E21: =AVERAGE(D21:D26) -> 0.00127
A22: 20 | B22: KC Binjai | C22: Zulkarnain | D22: =_xlfn.XLOOKUP(B22, '[2]Bad Data'!$B:$B, '[2]Bad Data'!$D:$D) -> 0.00107
A23: 21 | B23: KC Medan Sisingamangaraja | C23: Zulkarnain | D23: =_xlfn.XLOOKUP(B23, '[2]Bad Data'!$B:$B, '[2]Bad Data'!$D:$D) -> 0.00145
A24: 22 | B24: KC Panyabungan | C24: Zulkarnain | D24: =_xlfn.XLOOKUP(B24, '[2]Bad Data'!$B:$B, '[2]Bad Data'!$D:$D) -> 0.00036
A25: 23 | B25: KC Pematang Siantar | C25: Zulkarnain | D25: =_xlfn.XLOOKUP(B25, '[2]Bad Data'!$B:$B, '[2]Bad Data'!$D:$D) -> 0.00194
A26: 24 | B26: KC Tanjung Balai | C26: Zulkarnain | D26: =_xlfn.XLOOKUP(B26, '[2]Bad Data'!$B:$B, '[2]Bad Data'!$D:$D) -> 0.00233

Sheet Pengkinian Data
D1: 46277
A2: No. | B2: Unit Kerja | C2: PIC RAC | D2: Pengkinian Data | E2: Average
A3: 1 | B3: KC Gunung Sitoli | C3: Bambang Dwi Raharjo | D3: =_xlfn.XLOOKUP(B3,'[2]Pengkinian Data'!$B:$B,'[2]Pengkinian Data'!$E:$E) -> 1 | E3: =AVERAGE(D3:D8) -> 0.9978
A4: 2 | B4: KC Kabanjahe | C4: Bambang Dwi Raharjo | D4: =_xlfn.XLOOKUP(B4,'[2]Pengkinian Data'!$B:$B,'[2]Pengkinian Data'!$E:$E) -> 1
A5: 3 | B5: KC Kisaran | C5: Bambang Dwi Raharjo | D5: =_xlfn.XLOOKUP(B5,'[2]Pengkinian Data'!$B:$B,'[2]Pengkinian Data'!$E:$E) -> 0.9868
A6: 4 | B6: KC Lubuk Pakam | C6: Bambang Dwi Raharjo | D6: =_xlfn.XLOOKUP(B6,'[2]Pengkinian Data'!$B:$B,'[2]Pengkinian Data'!$E:$E) -> 1
A7: 5 | B7: KC Medan Putri Hijau | C7: Bambang Dwi Raharjo | D7: =_xlfn.XLOOKUP(B7,'[2]Pengkinian Data'!$B:$B,'[2]Pengkinian Data'!$E:$E) -> 1
A8: 6 | B8: KC Sidikalang | C8: Bambang Dwi Raharjo | D8: =_xlfn.XLOOKUP(B8,'[2]Pengkinian Data'!$B:$B,'[2]Pengkinian Data'!$E:$E) -> 1
A9: 7 | B9: KC Medan Iskandar Muda | C9: Herry Kurniawan | D9: =_xlfn.XLOOKUP(B9,'[2]Pengkinian Data'!$B:$B,'[2]Pengkinian Data'!$E:$E) -> 0.9985 | E9: =AVERAGE(D9:D14) -> 0.99795
A10: 8 | B10: KC Padang Sidempuan | C10: Herry Kurniawan | D10: =_xlfn.XLOOKUP(B10,'[2]Pengkinian Data'!$B:$B,'[2]Pengkinian Data'!$E:$E) -> 1
A11: 9 | B11: KC Perdagangan | C11: Herry Kurniawan | D11: =_xlfn.XLOOKUP(B11,'[2]Pengkinian Data'!$B:$B,'[2]Pengkinian Data'!$E:$E) -> 0.9998
A12: 10 | B12: KC Sibuhuan | C12: Herry Kurniawan | D12: =_xlfn.XLOOKUP(B12,'[2]Pengkinian Data'!$B:$B,'[2]Pengkinian Data'!$E:$E) -> 1
A13: 11 | B13: KC Stabat | C13: Herry Kurniawan | D13: =_xlfn.XLOOKUP(B13,'[2]Pengkinian Data'!$B:$B,'[2]Pengkinian Data'!$E:$E) -> 0.9917
A14: 12 | B14: KC Tarutung | C14: Herry Kurniawan | D14: =_xlfn.XLOOKUP(B14,'[2]Pengkinian Data'!$B:$B,'[2]Pengkinian Data'!$E:$E) -> 0.9977
A15: 13 | B15: KC Kota Pinang | C15: Richard Siburian | D15: =_xlfn.XLOOKUP(B15,'[2]Pengkinian Data'!$B:$B,'[2]Pengkinian Data'!$E:$E) -> 1 | E15: =AVERAGE(D15:D20) -> 0.99891667
A16: 14 | B16: KC Medan Gatot Subroto | C16: Richard Siburian | D16: =_xlfn.XLOOKUP(B16,'[2]Pengkinian Data'!$B:$B,'[2]Pengkinian Data'!$E:$E) -> 0.9935
A17: 15 | B17: KC Medan Thamrin | C17: Richard Siburian | D17: =_xlfn.XLOOKUP(B17,'[2]Pengkinian Data'!$B:$B,'[2]Pengkinian Data'!$E:$E) -> 1
A18: 16 | B18: KC Rantau Prapat | C18: Richard Siburian | D18: =_xlfn.XLOOKUP(B18,'[2]Pengkinian Data'!$B:$B,'[2]Pengkinian Data'!$E:$E) -> 1
A19: 17 | B19: KC Sibolga | C19: Richard Siburian | D19: =_xlfn.XLOOKUP(B19,'[2]Pengkinian Data'!$B:$B,'[2]Pengkinian Data'!$E:$E) -> 1
A20: 18 | B20: KC Tebing Tinggi | C20: Richard Siburian | D20: =_xlfn.XLOOKUP(B20,'[2]Pengkinian Data'!$B:$B,'[2]Pengkinian Data'!$E:$E) -> 1
A21: 19 | B21: KC Balige | C21: Zulkarnain | D21: =_xlfn.XLOOKUP(B21,'[2]Pengkinian Data'!$B:$B,'[2]Pengkinian Data'!$E:$E) -> 1 | E21: =AVERAGE(D21:D26) -> 0.99966667
A22: 20 | B22: KC Binjai | C22: Zulkarnain | D22: =_xlfn.XLOOKUP(B22,'[2]Pengkinian Data'!$B:$B,'[2]Pengkinian Data'!$E:$E) -> 0.9995
A23: 21 | B23: KC Medan Sisingamangaraja | C23: Zulkarnain | D23: =_xlfn.XLOOKUP(B23,'[2]Pengkinian Data'!$B:$B,'[2]Pengkinian Data'!$E:$E) -> 1
A24: 22 | B24: KC Panyabungan | C24: Zulkarnain | D24: =_xlfn.XLOOKUP(B24,'[2]Pengkinian Data'!$B:$B,'[2]Pengkinian Data'!$E:$E) -> 1
A25: 23 | B25: KC Pematang Siantar | C25: Zulkarnain | D25: =_xlfn.XLOOKUP(B25,'[2]Pengkinian Data'!$B:$B,'[2]Pengkinian Data'!$E:$E) -> 0.9998
A26: 24 | B26: KC Tanjung Balai | C26: Zulkarnain | D26: =_xlfn.XLOOKUP(B26,'[2]Pengkinian Data'!$B:$B,'[2]Pengkinian Data'!$E:$E) -> 0.9987

Sheet Sosialisasi
A1: No. | B1: Unit Kerja | C1: PIC RAC | D1: Materi* | E1: Tanggal Rencana Pelaksanaan | F1: Tanggal Pelaksanaan* | G1: Jumlah Peserta* | H1: Jabatan Peserta* | I1: Dokumen Evidence**
A2: 1 | B2: KC Balige
A3: 2 | B3: KC Binjai
A4: 3 | B4: KC Gunung Sitoli
A5: 4 | B5: KC Kabanjahe
A6: 5 | B6: KC Kisaran
A7: 6 | B7: KC Kota Pinang
A8: 7 | B8: KC Lubuk Pakam
A9: 8 | B9: KC Medan Gatot Subroto
A10: 9 | B10: KC Medan Iskandar Muda
A11: 10 | B11: KC Medan Putri Hijau
A12: 11 | B12: KC Medan Sisingamangaraja
A13: 12 | B13: KC Medan Thamrin
... A25: 24 | B25: KC Tebing Tinggi
B27: Keterangan:
B28: *Diisi jika telah dilaksanakan
B29: **https://bbri.id/MonevaRAC
B31: Evidence terdiri dari:
B32: 1. Dokumentasi Foto
B33: 2. Berita Acara
B34: 3. Absensi
B35: 4. Materi Sosisalisasi
B36: 5. List Pertanyaan

Sheet Uji Petik
A1: No. | B1: Unit Kerja | C1: PIC RAC | D1: Rencana Pelaksanaan | E1: Tanggal Pelaksanaan* | F1: Dokumen Evidence**
A3: 1 | B3: BO Gunung Sitoli | C3: Bambang Dwi Raharjo
A4: 2 | B4: BO Tarutung | C4: Zulkarnain
A5: 3 | B5: BO Panyambungan | C5: Herry Kurniawan
A6: 4 | B6: BO Stabat | C6: Herry Kurniawan
B29: Keterangan:
B30: *Diisi jika telah dilaksanakan
B31: **https://bri2-my.sharepoint.com/:f:/g/personal/00136153_hq_bri_co_id/IgAuv24GYPy3RpGb6TL-1UiQAWtriwDtmLPjkUVVkls_5vg?e=04gQla
B34: Evidence terdiri dari:
B35: 1. Dokumentasi Foto
B36: 2. Berita Acara
B37: 3. Absensi
B38: 4.Kertas Kerja
B39: 5. Laporan Uji Petik

Sheet Nilai Maturitas
A1: No. | B1: Unit Kerja | C1: PIC RAC | D1: Nilai maturitas | E1: Nilai maturitas | F1: Rating maturitas
A2: 3 | B2: BO Gunung Sitoli | C2: Bambang Dwi Raharjo | D2: 4.7298031 | E2: =AVERAGE(D2:D7) -> 8.0876158 | F2: AB
A3: 4 | B3: BO Kabanjahe | C3: Bambang Dwi Raharjo | D3: 9.4057584
A4: 5 | B4: BO Kisaran | C4: Bambang Dwi Raharjo | D4: 8.5113418
A5: 7 | B5: BO Lubuk Pakam | C5: Bambang Dwi Raharjo | D5: 8.6743065
A6: 10 | B6: BO Medan Putri Hijau | C6: Bambang Dwi Raharjo | D6: 9.0327473
A7: 20 | B7: BO Sidikalang | C7: Bambang Dwi Raharjo | D7: 8.1717374
A8: 9 | B8: BO Medan Iskandar Muda | C8: Herry Kurniawan | D8: 7.901213 | E8: =AVERAGE(D8:D13) -> 8.010596 | F8: AB
A9: 13 | B9: BO Padang Sidempuan | C9: Herry Kurniawan | D9: 9.2604112
A10: 16 | B10: BO Perdagangan | C10: Herry Kurniawan | D10: 9.569123
A11: 19 | B11: BO Sibuhuan | C11: Herry Kurniawan | D11: 7.6803279
A12: 21 | B12: BO Stabat | C12: Herry Kurniawan | D12: 7.4302497
A13: 23 | B13: BO Tarutung | C13: Herry Kurniawan | D13: 6.2222513
A14: 6 | B14: BO Kota Pinang | C14: Richard Siburian | D14: 8.6008988 | E14: =AVERAGE(D14:D19) -> 9.1021211 | F14: A
A15: 8 | B15: BO Medan Gatot Subroto | C15: Richard Siburian | D15: 9.5682462
A16: 12 | B16: BO Medan Thamrin | C16: Richard Siburian | D16: 8.3892129
A17: 17 | B17: BO Rantau Prapat | C17: Richard Siburian | D17: 9.8958333
A18: 18 | B18: BO Sibolga | C18: Richard Siburian | D18: 8.5926811
A19: 24 | B19: BO Tebing Tinggi | C19: Richard Siburian | D19: 9.5658544
A20: 1 | B20: BO Balige | C20: Zulkarnain | D20: 8.5187191 | E20: =AVERAGE(D20:D25) -> 8.3476713 | F20: AB
A21: 2 | B21: BO Binjai | C21: Zulkarnain | D21: 9.3454885
A22: 11 | B22: BO Medan Sisingamangaraja | C22: Zulkarnain | D22: 9.7069689
A23: 14 | B23: BO Panyabungan | C23: Zulkarnain | D23: 6.4145677
A24: 15 | B24: BO Pematang Siantar | C24: Zulkarnain | D24: 7.179481
A25: 22 | B25: BO Tanjung Balai | C25: Zulkarnain | D25: 8.9208025

Sheet Penilaian Resiko
A1: No. | B1: Unit Kerja | C1: PIC RAC | D1: Nilai Risiko | E1: Nilai Risiko PIC | F1: Rating Risiko PIC
A2: 3 | B2: KC Gunung Sitoli | C2: Bambang Dwi Raharjo | D2: 5.408 | E2: =AVERAGE(D2:D7) -> 6.0846667 | F2: Medium to High
A3: 4 | B3: KC Kabanjahe | C3: Bambang Dwi Raharjo | D3: 6.481
A4: 5 | B4: KC Kisaran | C4: Bambang Dwi Raharjo | D4: 6.633
A5: 7 | B5: KC Lubuk Pakam | C5: Bambang Dwi Raharjo | D5: 5.745
A6: 10 | B6: KC Medan Putri Hijau | C6: Bambang Dwi Raharjo | D6: 5.916
A7: 20 | B7: KC Sidikalang | C7: Bambang Dwi Raharjo | D7: 6.325
A8: 9 | B8: KC Medan Iskandar Muda | C8: Herry Kurniawan | D8: 5.745 | E8: =AVERAGE(D8:D13) -> 6.0491667 | F8: Medium to High
A9: 13 | B9: KC Padang Sidempuan | C9: Herry Kurniawan | D9: 5.809
A10: 16 | B10: KC Perdagangan | C10: Herry Kurniawan | D10: 6.423
A11: 19 | B11: KC Sibuhuan | C11: Herry Kurniawan | D11: 6.423
A12: 21 | B12: KC Stabat | C12: Herry Kurniawan | D12: 5.916
A13: 23 | B13: KC Tarutung | C13: Herry Kurniawan | D13: 5.979
A14: 6 | B14: KC Kota Pinang | C14: Richard Siburian | D14: 6.708 | E14: =AVERAGE(D14:D19) -> 6.3056667 | F14: Medium to High
A15: 8 | B15: KC Medan Gatot Subroto | C15: Richard Siburian | D15: 5.745
A16: 12 | B16: KC Medan Thamrin | C16: Richard Siburian | D16: 6.205
A17: 17 | B17: KC Rantau Prapat | C17: Richard Siburian | D17: 6.837
A18: 18 | B18: KC Sibolga | C18: Richard Siburian | D18: 6.423
A19: 24 | B19: KC Tebing Tinggi | C19: Richard Siburian | D19: 5.916
A20: 1 | B20: KC Balige | C20: Zulkarnain | D20: 6.928 | E20: =AVERAGE(D20:D25) -> 6.2488333 | F20: AB
A21: 2 | B21: KC Binjai | C21: Zulkarnain | D21: 5.809
A22: 11 | B22: KC Medan Sisingamangaraja | C22: Zulkarnain | D22: 5.745
A23: 14 | B23: KC Panyabungan | C23: Zulkarnain | D23: 6.633
A24: 15 | B24: KC Pematang Siantar | C24: Zulkarnain | D24: 5.745
A25: 22 | B25: KC Tanjung Balai | C25: Zulkarnain | D25: 6.633

Sheet Maturitas Dashboard
A1: No. | B1: Unit Kerja | C1: PIC RAC | D1: Nilai Maturitas | E1: Nilai Maturitas PIC | F1: Rating Maturitas PIC
A2: 3 | B2: KC Gunung Sitoli | C2: Bambang Dwi Raharjo | D2: 8.875 | E2: =AVERAGE(D2:D7) -> 8.7083333 | F2: Sangat Baik
A3: 4 | B3: KC Kabanjahe | C3: Bambang Dwi Raharjo | D3: 8.875
A4: 5 | B4: KC Kisaran | C4: Bambang Dwi Raharjo | D4: 8.875
A5: 7 | B5: KC Lubuk Pakam | C5: Bambang Dwi Raharjo | D5: 8.875
A6: 10 | B6: KC Medan Putri Hijau | C6: Bambang Dwi Raharjo | D6: 8.875
A7: 20 | B7: KC Sidikalang | C7: Bambang Dwi Raharjo | D7: 7.875
A8: 9 | B8: KC Medan Iskandar Muda | C8: Herry Kurniawan | D8: 8.375 | E8: =AVERAGE(D8:D13) -> 8.5416667 | F8: Sangat Baik
A9: 13 | B9: KC Padang Sidempuan | C9: Herry Kurniawan | D9: 8.375
A10: 16 | B10: KC Perdagangan | C10: Herry Kurniawan | D10: 8.875
A11: 19 | B11: KC Sibuhuan | C11: Herry Kurniawan | D11: 8.875
A12: 21 | B12: KC Stabat | C12: Herry Kurniawan | D12: 7.875
A13: 23 | B13: KC Tarutung | C13: Herry Kurniawan | D13: 8.875
A14: 6 | B14: KC Kota Pinang | C14: Richard Siburian | D14: 8.875 | E14: =AVERAGE(D14:D19) -> 8.7083333 | F14: Sangat Baik
A15: 8 | B15: KC Medan Gatot Subroto | C15: Richard Siburian | D15: 7.875
A16: 12 | B16: KC Medan Thamrin | C16: Richard Siburian | D16: 8.875
A17: 17 | B17: KC Rantau Prapat | C17: Richard Siburian | D17: 8.875
A18: 18 | B18: KC Sibolga | C18: Richard Siburian | D18: 8.875
A19: 24 | B19: KC Tebing Tinggi | C19: Richard Siburian | D19: 8.875
A20: 1 | B20: KC Balige | C20: Zulkarnain | D20: 8.875 | E20: =AVERAGE(D20:D25) -> 8.5833333 | F20: Sangat Baik
A21: 2 | B21: KC Binjai | C21: Zulkarnain | D21: 8.625
A22: 11 | B22: KC Medan Sisingamangaraja | C22: Zulkarnain | D22: 8.375
A23: 14 | B23: KC Panyabungan | C23: Zulkarnain | D23: 8.875
A24: 15 | B24: KC Pematang Siantar | C24: Zulkarnain | D24: 7.875
A25: 22 | B25: KC Tanjung Balai | C25: Zulkarnain | D25: 8.875

Sheet Overview
A2: No | B2: Aspek Penilaian | C2: Bambang Dwi Raharjo | F2: Herry Kurniawan | I2: Richard Siburian | L2: Zulkarnain
C3: Nilai | D3: Bobot | E3: Score | F3: Nilai | G3: Bobot | H3: Score | I3: Nilai | J3: Bobot | K3: Score | L3: Nilai | M3: Bobot | N3: Score
A4: 1 | B4: STR | C4: =IFERROR(COUNTIFS(STR!$V:$V, Overview!C$2, STR!$X:$X, "TRUE")/COUNTIFS(STR!$V:$V, Overview!C2), 0) -> 1 | D4: 0.15 | E4: =D4*C4 -> 0.15 | F4: =IFERROR(COUNTIFS(STR!$V:$V, Overview!F$2, STR!$X:$X, "TRUE")/COUNTIFS(STR!$V:$V, Overview!F2), 0) -> 1 | G4: 0.15 | H4: =G4*F4 -> 0.15 | I4: =IFERROR(COUNTIFS(STR!$V:$V, Overview!I$2, STR!$X:$X, "TRUE")/COUNTIFS(STR!$V:$V, Overview!I2), 0) -> 1 | J4: 0.15 | K4: =J4*I4 -> 0.15 | L4: =IFERROR(COUNTIFS(STR!$V:$V, Overview!L$2, STR!$X:$X, "TRUE")/COUNTIFS(STR!$V:$V, Overview!L2), 0) -> 1 | M4: 0.15 | N4: =M4*L4 -> 0.15
A5: 2 | B5: Bad Data | C5: =1-AVERAGEIF('Bad Data'!$C:$C, Overview!C$2, 'Bad Data'!$D:$D) -> 0.99831167 | D5: 0.1 | E5: =D5*C5 -> 0.099831167 | F5: =1-AVERAGEIF('Bad Data'!$C:$C, Overview!F$2, 'Bad Data'!$D:$D) -> 0.99775167 | G5: 0.1 | H5: =G5*F5 -> 0.099775167 | I5: =1-AVERAGEIF('Bad Data'!$C:$C, Overview!I$2, 'Bad Data'!$D:$D) -> 0.99812333 | J5: 0.1 | K5: =J5*I5 -> 0.099812333 | L5: =1-AVERAGEIF('Bad Data'!$C:$C, Overview!L$2, 'Bad Data'!$D:$D) -> 0.99873 | M5: 0.1 | N5: =M5*L5 -> 0.099873
A6: 3 | B6: Pengkinian Data | C6: =AVERAGEIF('Pengkinian Data'!$C:$C, Overview!C$2, 'Pengkinian Data'!$D:$D) -> 0.9978 | D6: 0.1 | E6: =D6*C6 -> 0.09978 | F6: =AVERAGEIF('Pengkinian Data'!$C:$C, Overview!F$2, 'Pengkinian Data'!$D:$D) -> 0.99795 | G6: 0.1 | H6: =G6*F6 -> 0.099795 | I6: =AVERAGEIF('Pengkinian Data'!$C:$C, Overview!I$2, 'Pengkinian Data'!$D:$D) -> 0.99891667 | J6: 0.1 | K6: =J6*I6 -> 0.099891667 | L6: =AVERAGEIF('Pengkinian Data'!$C:$C, Overview!L$2, 'Pengkinian Data'!$D:$D) -> 0.99966667 | M6: 0.1 | N6: =M6*L6 -> 0.099966667 | U6: .
A7: 4 | B7: Uji Petik | C7: {=IFERROR(SUMPRODUCT(--('[1]Uji Petik'!$E$3:$E$73<>""), --('[1]Uji Petik'!$C$3:$C$73=C2)) / SUMPRODUCT(--('[1]Uji Petik'!$C$3:$C$73=C2)), 0)} -> 0 | D7: 0 | E7: =D7*C7 -> 0 | F7: {=IFERROR(SUMPRODUCT(--('[1]Uji Petik'!$E$3:$E$73<>""), --('[1]Uji Petik'!$C$3:$C$73=F2)) / SUMPRODUCT(--('[1]Uji Petik'!$C$3:$C$73=F2)), 0)} -> 0.66666667 | G7: 0 | H7: =G7*F7 -> 0 | I7: {=IFERROR(SUMPRODUCT(--('[1]Uji Petik'!$E$3:$E$73<>""), --('[1]Uji Petik'!$C$3:$C$73=I2)) / SUMPRODUCT(--('[1]Uji Petik'!$C$3:$C$73=I2)), 0)} -> 1 | J7: 0 | K7: =J7*I7 -> 0 | L7: {=IFERROR(SUMPRODUCT(--('[1]Uji Petik'!$E$3:$E$73<>""), --('[1]Uji Petik'!$C$3:$C$73=L2)) / SUMPRODUCT(--('[1]Uji Petik'!$C$3:$C$73=L2)), 0)} -> 0 | M7: 0 | N7: =M7*L7 -> 0
A8: 5 | B8: Sosialisasi | C8: {=IFERROR(AVERAGE(IF([2]Sosialisasi!$C$1:$C$10000=C2, [2]Sosialisasi!$D$1:$D$10000)), 0)} -> 0 | D8: 0.15 | E8: =D8*C8 -> 0 | F8: {=IFERROR(AVERAGE(IF([2]Sosialisasi!$C$1:$C$10000=F2, [2]Sosialisasi!$D$1:$D$10000)), 0)} -> 0.66666667 | G8: 0.15 | H8: =G8*F8 -> 0.1 | I8: {=IFERROR(AVERAGE(IF([2]Sosialisasi!$C$1:$C$10000=I2, [2]Sosialisasi!$D$1:$D$10000)), 0)} -> 0.5 | J8: 0.15 | K8: =J8*I8 -> 0.075 | L8: {=IFERROR(AVERAGE(IF([2]Sosialisasi!$C$1:$C$10000=L2, [2]Sosialisasi!$D$1:$D$10000)), 0)} -> 0.5 | M8: 0.15 | N8: =M8*L8 -> 0.075
A9: 6 | B9: EDD | C9: =AVERAGEIF('EDD PEP PPATK'!$C:$C, Overview!C$2, 'EDD PEP PPATK'!$D:$D) -> 0.98043986 | D9: 0.1 | E9: =D9*C9 -> 0.098043986 | F9: =AVERAGEIF('EDD PEP PPATK'!$C:$C, Overview!F$2, 'EDD PEP PPATK'!$D:$D) -> 0.99227158 | G9: 0.1 | H9: =G9*F9 -> 0.099227158 | I9: =AVERAGEIF('EDD PEP PPATK'!$C:$C, Overview!I$2, 'EDD PEP PPATK'!$D:$D) -> 0.99253394 | J9: 0.1 | K9: =J9*I9 -> 0.099253394 | L9: =AVERAGEIF('EDD PEP PPATK'!$C:$C, Overview!L$2, 'EDD PEP PPATK'!$D:$D) -> 0.97114232 | M9: 0.1 | N9: =M9*L9 -> 0.097114232
A10: 7 | B10: Self Learning Keikutsertaan | C10: {=IF(IFERROR(AVERAGE(IF('[2]Sheet2 (2)'!$C$1:$C$10000=C$2, '[2]Sheet2 (2)'!$D$1:$D$10000)), 0)>0.9, 1, IFERROR(AVERAGE(IF('[2]Sheet2 (2)'!$C$1:$C$10000=C$2, '[2]Sheet2 (2)'!$D$1:$D$10000)), 0))} -> 1 | D10: 0.05 | E10: =D10*C10 -> 0.05 | F10: {=IF(IFERROR(AVERAGE(IF('[2]Sheet2 (2)'!$C$1:$C$10000=F$2, '[2]Sheet2 (2)'!$D$1:$D$10000)), 0)>0.9, 1, IFERROR(AVERAGE(IF('[2]Sheet2 (2)'!$C$1:$C$10000=F$2, '[2]Sheet2 (2)'!$D$1:$D$10000)), 0))} -> 0.82593986 | G10: 0.05 | H10: =G10*F10 -> 0.041296993 | I10: {=IF(IFERROR(AVERAGE(IF('[2]Sheet2 (2)'!$C$1:$C$10000=I$2, '[2]Sheet2 (2)'!$D$1:$D$10000)), 0)>0.9, 1, IFERROR(AVERAGE(IF('[2]Sheet2 (2)'!$C$1:$C$10000=I$2, '[2]Sheet2 (2)'!$D$1:$D$10000)), 0))} -> 1 | J10: 0.05 | K10: =J10*I10 -> 0.05 | L10: {=IF(IFERROR(AVERAGE(IF('[2]Sheet2 (2)'!$C$1:$C$10000=L$2, '[2]Sheet2 (2)'!$D$1:$D$10000)), 0)>0.9, 1, IFERROR(AVERAGE(IF('[2]Sheet2 (2)'!$C$1:$C$10000=L$2, '[2]Sheet2 (2)'!$D$1:$D$10000)), 0))} -> 0 | M10: 0.05 | N10: =M10*L10 -> 0
A11: 8 | B11: Self Learning Score | C11: {=IF(IFERROR(AVERAGE(IF('[2]Sheet2 (3)'!$C$1:$C$10000=C2, '[2]Sheet2 (3)'!$D$1:$D$10000)), 0)>90, 1, IFERROR(AVERAGE(IF('[2]Sheet2 (3)'!$C$1:$C$10000=C2, '[2]Sheet2 (3)'!$D$1:$D$10000)), 0)/90)} -> 1 | D11: 0.05 | E11: =D11*C11 -> 0.05 | F11: {=IF(IFERROR(AVERAGE(IF('[2]Sheet2 (3)'!$C$1:$C$10000=F2, '[2]Sheet2 (3)'!$D$1:$D$10000)), 0)>90, 1, IFERROR(AVERAGE(IF('[2]Sheet2 (3)'!$C$1:$C$10000=F2, '[2]Sheet2 (3)'!$D$1:$D$10000)), 0)/90)} -> 1 | G11: 0.05 | H11: =G11*F11 -> 0.05 | I11: {=IF(IFERROR(AVERAGE(IF('[2]Sheet2 (3)'!$C$1:$C$10000=I2, '[2]Sheet2 (3)'!$D$1:$D$10000)), 0)>90, 1, IFERROR(AVERAGE(IF('[2]Sheet2 (3)'!$C$1:$C$10000=I2, '[2]Sheet2 (3)'!$D$1:$D$10000)), 0)/90)} -> 1 | J11: 0.05 | K11: =J11*I11 -> 0.05 | L11: {=IF(IFERROR(AVERAGE(IF('[2]Sheet2 (3)'!$C$1:$C$10000=L2, '[2]Sheet2 (3)'!$D$1:$D$10000)), 0)>90, 1, IFERROR(AVERAGE(IF('[2]Sheet2 (3)'!$C$1:$C$10000=L2, '[2]Sheet2 (3)'!$D$1:$D$10000)), 0)/90)} -> 1 | M11: 0.05 | N11: =M11*L11 -> 0.05
A12: 9 | B12: Maturitas | C12: =IF(AVERAGEIF('Nilai Maturitas'!$C:$C, Overview!C2, 'Nilai Maturitas'!$D:$D) > 8, 110%, AVERAGEIF('Nilai Maturitas'!$C:$C, Overview!C2, 'Nilai Maturitas'!$D:$D)/8*100%) -> 1.1 | D12: 0.1 | E12: =D12*C12 -> 0.11 | F12: =IF(AVERAGEIF('Nilai Maturitas'!$C:$C, Overview!F2, 'Nilai Maturitas'!$D:$D) > 8, 110%, AVERAGEIF('Nilai Maturitas'!$C:$C, Overview!F2, 'Nilai Maturitas'!$D:$D)/8*100%) -> 1.1 | G12: 0.1 | H12: =G12*F12 -> 0.11 | I12: =IF(AVERAGEIF('Nilai Maturitas'!$C:$C, Overview!I2, 'Nilai Maturitas'!$D:$D) > 8, 110%, AVERAGEIF('Nilai Maturitas'!$C:$C, Overview!I2, 'Nilai Maturitas'!$D:$D)/8*100%) -> 1.1 | J12: 0.1 | K12: =J12*I12 -> 0.11 | L12: =IF(AVERAGEIF('Nilai Maturitas'!$C:$C, Overview!L2, 'Nilai Maturitas'!$D:$D) > 8, 110%, AVERAGEIF('Nilai Maturitas'!$C:$C, Overview!L2, 'Nilai Maturitas'!$D:$D)/8*100%) -> 1.1 | M12: 0.1 | N12: =M12*L12 -> 0.11
A13: 10 | B13: Maturitas Dashboard | C13: =IF(AVERAGEIF('Maturitas Dashboard'!$C:$C, Overview!C$2, 'Maturitas Dashboard'!$D:$D) > 8, 110%, AVERAGEIF('Maturitas Dashboard'!$C:$C, Overview!C$2, 'Maturitas Dashboard'!$D:$D)/8*100%) -> 1.1 | D13: 0.1 | E13: =D13*C13 -> 0.11 | F13: =IF(AVERAGEIF('Maturitas Dashboard'!$C:$C, Overview!F$2, 'Maturitas Dashboard'!$D:$D) > 8, 110%, AVERAGEIF('Maturitas Dashboard'!$C:$C, Overview!F$2, 'Maturitas Dashboard'!$D:$D)/8*100%) -> 1.1 | G13: 0.1 | H13: =G13*F13 -> 0.11 | I13: =IF(AVERAGEIF('Maturitas Dashboard'!$C:$C, Overview!I$2, 'Maturitas Dashboard'!$D:$D) > 8, 110%, AVERAGEIF('Maturitas Dashboard'!$C:$C, Overview!I$2, 'Maturitas Dashboard'!$D:$D)/8*100%) -> 1.1 | J13: 0.1 | K13: =J13*I13 -> 0.11 | L13: =IF(AVERAGEIF('Maturitas Dashboard'!$C:$C, Overview!L$2, 'Maturitas Dashboard'!$D:$D) > 8, 110%, AVERAGEIF('Maturitas Dashboard'!$C:$C, Overview!L$2, 'Maturitas Dashboard'!$D:$D)/8*100%) -> 1.1 | M13: 0.1 | N13: =M13*L13 -> 0.11
A14: 11 | B14: Penilaian Resiko | C14: =IF(AVERAGEIF('Penilaian Resiko'!$C:$C, Overview!C$2, 'Penilaian Resiko'!$D:$D) < 5.8, 110%, IF(AVERAGEIF('Penilaian Resiko'!$C:$C, Overview!C$2, 'Penilaian Resiko'!$D:$D) <7.4, 3/4*100%, 3/5*100%)) -> 0.75 | D14: 0.1 | E14: =D14*C14 -> 0.075 | F14: =IF(AVERAGEIF('Penilaian Resiko'!$C:$C, Overview!F$2, 'Penilaian Resiko'!$D:$D) < 5.8, 110%, IF(AVERAGEIF('Penilaian Resiko'!$C:$C, Overview!F$2, 'Penilaian Resiko'!$D:$D) <7.4, 3/4*100%, 3/5*100%)) -> 0.75 | G14: 0.1 | H14: =G14*F14 -> 0.075 | I14: =IF(AVERAGEIF('Penilaian Resiko'!$C:$C, Overview!I$2, 'Penilaian Resiko'!$D:$D) < 5.8, 110%, IF(AVERAGEIF('Penilaian Resiko'!$C:$C, Overview!I$2, 'Penilaian Resiko'!$D:$D) <7.4, 3/4*100%, 3/5*100%)) -> 0.75 | J14: 0.1 | K14: =J14*I14 -> 0.075 | L14: =IF(AVERAGEIF('Penilaian Resiko'!$C:$C, Overview!L$2, 'Penilaian Resiko'!$D:$D) < 5.8, 110%, IF(AVERAGEIF('Penilaian Resiko'!$C:$C, Overview!L$2, 'Penilaian Resiko'!$D:$D) <7.4, 3/4*100%, 3/5*100%)) -> 0.75 | M14: 0.1 | N14: =M14*L14 -> 0.075
C15: Progress | E15: =SUM(E4:E14) -> 0.84265515 | F15: Progress | H15: =SUM(H4:H14) -> 0.93509432 | I15: Progress | K15: =SUM(K4:K14) -> 0.91895739 | L15: Progress | N15: =SUM(N4:N14) -> 0.8669539

Sheet Overview tanpa KPI
A2: No | B2: Aspek Penilaian | C2: Bambang Dwi Raharjo | F2: Herry Kurniawan | I2: Richard Siburian | L2: Zulkarnain
C3: Nilai | D3: Bobotan | E3: Score | F3: Nilai | G3: Bobotan | H3: Score | I3: Nilai | J3: Bobotan | K3: Score | L3: Nilai | M3: Bobotan | N3: Score
A4: 1 | B4: STR | C4: =IFERROR(COUNTIFS(STR!$V:$V, 'Overview tanpa KPI'!C$2, STR!$X:$X, "TRUE")/COUNTIFS(STR!$V:$V, 'Overview tanpa KPI'!C2), 0) -> 1 | D4: 0.15 | E4: =D4*C4 -> 0.15 | F4: =IFERROR(COUNTIFS(STR!$V:$V, 'Overview tanpa KPI'!F$2, STR!$X:$X, "TRUE")/COUNTIFS(STR!$V:$V, 'Overview tanpa KPI'!F2), 0) -> 1 | G4: 0.15 | H4: =G4*F4 -> 0.15 | I4: =IFERROR(COUNTIFS(STR!$V:$V, 'Overview tanpa KPI'!I$2, STR!$X:$X, "TRUE")/COUNTIFS(STR!$V:$V, 'Overview tanpa KPI'!I2), 0) -> 1 | J4: 0.15 | K4: =J4*I4 -> 0.15 | L4: =IFERROR(COUNTIFS(STR!$V:$V, 'Overview tanpa KPI'!L$2, STR!$X:$X, "TRUE")/COUNTIFS(STR!$V:$V, 'Overview tanpa KPI'!L2), 0) -> 1 | M4: 0.15 | N4: =M4*L4 -> 0.15
A5: 2 | B5: Bad Data | C5: =1-AVERAGEIF('Bad Data'!$C:$C, 'Overview tanpa KPI'!C$2, 'Bad Data'!$D:$D) -> 0.99831167 | D5: 0.1 | E5: =D5*C5 -> 0.099831167 | F5: =1-AVERAGEIF('Bad Data'!$C:$C, 'Overview tanpa KPI'!F$2, 'Bad Data'!$D:$D) -> 0.99775167 | G5: 0.1 | H5: =G5*F5 -> 0.099775167 | I5: =1-AVERAGEIF('Bad Data'!$C:$C, 'Overview tanpa KPI'!I$2, 'Bad Data'!$D:$D) -> 0.99812333 | J5: 0.1 | K5: =J5*I5 -> 0.099812333 | L5: =1-AVERAGEIF('Bad Data'!$C:$C, 'Overview tanpa KPI'!L$2, 'Bad Data'!$D:$D) -> 0.99873 | M5: 0.1 | N5: =M5*L5 -> 0.099873
A6: 3 | B6: Pengkinian Data | C6: =AVERAGEIF('Pengkinian Data'!$C:$C, 'Overview tanpa KPI'!C$2, 'Pengkinian Data'!$D:$D) -> 0.9978 | D6: 0.1 | E6: =D6*C6 -> 0.09978 | F6: =AVERAGEIF('Pengkinian Data'!$C:$C, 'Overview tanpa KPI'!F$2, 'Pengkinian Data'!$D:$D) -> 0.99795 | G6: 0.1 | H6: =G6*F6 -> 0.099795 | I6: =AVERAGEIF('Pengkinian Data'!$C:$C, 'Overview tanpa KPI'!I$2, 'Pengkinian Data'!$D:$D) -> 0.99891667 | J6: 0.1 | K6: =J6*I6 -> 0.099891667 | L6: =AVERAGEIF('Pengkinian Data'!$C:$C, 'Overview tanpa KPI'!L$2, 'Pengkinian Data'!$D:$D) -> 0.99966667 | M6: 0.1 | N6: =M6*L6 -> 0.099966667 | R6: .
A7: 4 | B7: Uji Petik | C7: {=IFERROR(SUMPRODUCT(--('[1]Uji Petik'!$E$3:$E$73<>""), --('[1]Uji Petik'!$C$3:$C$73=C2)) / SUMPRODUCT(--('[1]Uji Petik'!$C$3:$C$73=C2)), 0)} -> 0 | D7: 0 | E7: =D7*C7 -> 0 | F7: {=IFERROR(SUMPRODUCT(--('[1]Uji Petik'!$E$3:$E$73<>""), --('[1]Uji Petik'!$C$3:$C$73=F2)) / SUMPRODUCT(--('[1]Uji Petik'!$C$3:$C$73=F2)), 0)} -> 0.66666667 | G7: 0 | H7: =G7*F7 -> 0 | I7: {=IFERROR(SUMPRODUCT(--('[1]Uji Petik'!$E$3:$E$73<>""), --('[1]Uji Petik'!$C$3:$C$73=I2)) / SUMPRODUCT(--('[1]Uji Petik'!$C$3:$C$73=I2)), 0)} -> 1 | J7: 0 | K7: =J7*I7 -> 0 | L7: {=IFERROR(SUMPRODUCT(--('[1]Uji Petik'!$E$3:$E$73<>""), --('[1]Uji Petik'!$C$3:$C$73=L2)) / SUMPRODUCT(--('[1]Uji Petik'!$C$3:$C$73=L2)), 0)} -> 0 | M7: 0 | N7: =M7*L7 -> 0
A8: 5 | B8: Sosialisasi | C8: {=IFERROR(AVERAGE(IF([2]Sosialisasi!$C$1:$C$10000=C2, [2]Sosialisasi!$D$1:$D$10000)), 0)} -> 0 | D8: 0.15 | E8: =D8*C8 -> 0 | F8: {=IFERROR(AVERAGE(IF([2]Sosialisasi!$C$1:$C$10000=F2, [2]Sosialisasi!$D$1:$D$10000)), 0)} -> 0.66666667 | G8: 0.15 | H8: =G8*F8 -> 0.1 | I8: {=IFERROR(AVERAGE(IF([2]Sosialisasi!$C$1:$C$10000=I2, [2]Sosialisasi!$D$1:$D$10000)), 0)} -> 0.5 | J8: 0.15 | K8: =J8*I8 -> 0.075 | L8: {=IFERROR(AVERAGE(IF([2]Sosialisasi!$C$1:$C$10000=L2, [2]Sosialisasi!$D$1:$D$10000)), 0)} -> 0.5 | M8: 0.15 | N8: =M8*L8 -> 0.075
A9: 6 | B9: EDD | C9: =AVERAGEIF('EDD PEP PPATK'!$C:$C, 'Overview tanpa KPI'!C$2, 'EDD PEP PPATK'!$D:$D) -> 0.98043986 | D9: 0.1 | E9: =D9*C9 -> 0.098043986 | F9: =AVERAGEIF('EDD PEP PPATK'!$C:$C, 'Overview tanpa KPI'!F$2, 'EDD PEP PPATK'!$D:$D) -> 0.99227158 | G9: 0.1 | H9: =G9*F9 -> 0.099227158 | I9: =AVERAGEIF('EDD PEP PPATK'!$C:$C, 'Overview tanpa KPI'!I$2, 'EDD PEP PPATK'!$D:$D) -> 0.99253394 | J9: 0.1 | K9: =J9*I9 -> 0.099253394 | L9: =AVERAGEIF('EDD PEP PPATK'!$C:$C, 'Overview tanpa KPI'!L$2, 'EDD PEP PPATK'!$D:$D) -> 0.97114232 | M9: 0.1 | N9: =M9*L9 -> 0.097114232
A10: 7 | B10: Self Learning Keikutsertaan | C10: {=IFERROR(AVERAGE(IF('[2]Sheet2 (2)'!$C$1:$C$10000=C$2, '[2]Sheet2 (2)'!$D$1:$D$10000)), 0)} -> 0.92832844 | D10: 0.05 | E10: =D10*C10 -> 0.046416422 | F10: {=IFERROR(AVERAGE(IF('[2]Sheet2 (2)'!$C$1:$C$10000=F$2, '[2]Sheet2 (2)'!$D$1:$D$10000)), 0)} -> 0.82593986 | G10: 0.05 | H10: =G10*F10 -> 0.041296993 | I10: {=IFERROR(AVERAGE(IF('[2]Sheet2 (2)'!$C$1:$C$10000=I$2, '[2]Sheet2 (2)'!$D$1:$D$10000)), 0)} -> 0.93426982 | J10: 0.05 | K10: =J10*I10 -> 0.046713491 | L10: {=IFERROR(AVERAGE(IF('[2]Sheet2 (2)'!$C$1:$C$10000=L$2, '[2]Sheet2 (2)'!$D$1:$D$10000)), 0)} -> 0 | M10: 0.05 | N10: =M10*L10 -> 0
A11: 8 | B11: Self Learning Score | C11: {=IFERROR(AVERAGE(IF('[2]Sheet2 (3)'!$C$1:$C$10000=C2, '[2]Sheet2 (3)'!$D$1:$D$10000)), 0)} -> 97.472092 | D11: 0.05 | E11: =D11*C11 -> 4.8736046 | F11: {=IFERROR(AVERAGE(IF('[2]Sheet2 (3)'!$C$1:$C$10000=F2, '[2]Sheet2 (3)'!$D$1:$D$10000)), 0)} -> 96.733306 | G11: 0.05 | H11: =G11*F11 -> 4.8366653 | I11: {=IFERROR(AVERAGE(IF('[2]Sheet2 (3)'!$C$1:$C$10000=I2, '[2]Sheet2 (3)'!$D$1:$D$10000)), 0)} -> 97.383946 | J11: 0.05 | K11: =J11*I11 -> 4.8691973 | L11: {=IFERROR(AVERAGE(IF('[2]Sheet2 (3)'!$C$1:$C$10000=L2, '[2]Sheet2 (3)'!$D$1:$D$10000)), 0)} -> 95.534685 | M11: 0.05 | N11: =M11*L11 -> 4.7767343
A12: 9 | B12: Maturitas | C12: =AVERAGEIF('Nilai Maturitas'!$C:$C, 'Overview tanpa KPI'!C2, 'Nilai Maturitas'!$D:$D) -> 8.0876158 | D12: 0.1 | E12: =D12*C12 -> 0.80876158 | F12: =AVERAGEIF('Nilai Maturitas'!$C:$C, 'Overview tanpa KPI'!F2, 'Nilai Maturitas'!$D:$D) -> 8.010596 | G12: 0.1 | H12: =G12*F12 -> 0.8010596 | I12: =AVERAGEIF('Nilai Maturitas'!$C:$C, 'Overview tanpa KPI'!I2, 'Nilai Maturitas'!$D:$D) -> 9.1021211 | J12: 0.1 | K12: =J12*I12 -> 0.91021211 | L12: =AVERAGEIF('Nilai Maturitas'!$C:$C, 'Overview tanpa KPI'!L2, 'Nilai Maturitas'!$D:$D) -> 8.3476713 | M12: 0.1 | N12: =M12*L12 -> 0.83476713
A13: 10 | B13: Maturitas Dashboard | C13: =AVERAGEIF('Maturitas Dashboard'!$C:$C, 'Overview tanpa KPI'!C$2, 'Maturitas Dashboard'!$D:$D) -> 8.7083333 | D13: 0.1 | E13: =D13*C13 -> 0.87083333 | F13: =AVERAGEIF('Maturitas Dashboard'!$C:$C, 'Overview tanpa KPI'!F$2, 'Maturitas Dashboard'!$D:$D) -> 8.5416667 | G13: 0.1 | H13: =G13*F13 -> 0.85416667 | I13: =AVERAGEIF('Maturitas Dashboard'!$C:$C, 'Overview tanpa KPI'!I$2, 'Maturitas Dashboard'!$D:$D) -> 8.7083333 | J13: 0.1 | K13: =J13*I13 -> 0.87083333 | L13: =AVERAGEIF('Maturitas Dashboard'!$C:$C, 'Overview tanpa KPI'!L$2, 'Maturitas Dashboard'!$D:$D) -> 8.5833333 | M13: 0.1 | N13: =M13*L13 -> 0.85833333
A14: 11 | B14: Penilaian Resiko | C14: =AVERAGEIF('Penilaian Resiko'!$C:$C, 'Overview tanpa KPI'!C$2, 'Penilaian Resiko'!$D:$D) -> 6.0846667 | D14: 0.1 | E14: =D14*C14 -> 0.60846667 | F14: =AVERAGEIF('Penilaian Resiko'!$C:$C, 'Overview tanpa KPI'!F$2, 'Penilaian Resiko'!$D:$D) -> 6.0491667 | G14: 0.1 | H14: =G14*F14 -> 0.60491667 | I14: =AVERAGEIF('Penilaian Resiko'!$C:$C, 'Overview tanpa KPI'!I$2, 'Penilaian Resiko'!$D:$D) -> 6.3056667 | J14: 0.1 | K14: =J14*I14 -> 0.63056667 | L14: =AVERAGEIF('Penilaian Resiko'!$C:$C, 'Overview tanpa KPI'!L$2, 'Penilaian Resiko'!$D:$D) -> 6.2488333 | M14: 0.1 | N14: =M14*L14 -> 0.62488333
C15: Progress | E15: =SUM(E4:E14) -> 7.6557377 | F15: Progress | H15: =SUM(H4:H14) -> 7.6869025 | I15: Progress | K15: =SUM(K4:K14) -> 7.8514803 | L15: Progress | N15: =SUM(N4:N14) -> 7.616672

Sheet Overview KPI
A2: No | B2: Aspek Penilaian | C2: Bambang Dwi Raharjo | F2: Herry Kurniawan | I2: Richard Siburian | L2: Zulkarnain
C3: Nilai | D3: Bobot | E3: Score | F3: Nilai | G3: Bobot | H3: Score | I3: Nilai | J3: Bobot | K3: Score | L3: Nilai | M3: Bobot | N3: Score
A4: 1 | B4: STR | C4: =IFERROR(COUNTIFS(STR!$V:$V, 'Overview KPI'!C$2, STR!$X:$X, "TRUE")/COUNTIFS(STR!$V:$V, 'Overview KPI'!C2), 0) -> 1 | D4: 0.05 | E4: =D4*C4 -> 0.05 | F4: =IFERROR(COUNTIFS(STR!$V:$V, 'Overview KPI'!F$2, STR!$X:$X, "TRUE")/COUNTIFS(STR!$V:$V, 'Overview KPI'!F2), 0) -> 1 | G4: 0.05 | H4: =G4*F4 -> 0.05 | I4: =IFERROR(COUNTIFS(STR!$V:$V, 'Overview KPI'!I$2, STR!$X:$X, "TRUE")/COUNTIFS(STR!$V:$V, 'Overview KPI'!I2), 0) -> 1 | J4: 0.05 | K4: =J4*I4 -> 0.05 | L4: =IFERROR(COUNTIFS(STR!$V:$V, 'Overview KPI'!L$2, STR!$X:$X, "TRUE")/COUNTIFS(STR!$V:$V, 'Overview KPI'!L2), 0) -> 1 | M4: 0.05 | N4: =M4*L4 -> 0.05
A5: 2 | B5: Kualitas STR | C5: =IFERROR(AVERAGEIF(STR!$V:$V, 'Overview KPI'!C2, STR!$Y:$Y), 0)/4 -> 0.75189732 | D5: 0.15 | E5: =D5*C5 -> 0.1127846 | F5: =IFERROR(AVERAGEIF(STR!$V:$V, 'Overview KPI'!F2, STR!$Y:$Y), 0)/4 -> 0.62243304 | G5: 0.15 | H5: =G5*F5 -> 0.093364955 | I5: =IFERROR(AVERAGEIF(STR!$V:$V, 'Overview KPI'!I2, STR!$Y:$Y), 0)/4 -> 0.76498326 | J5: 0.15 | K5: =J5*I5 -> 0.11474749 | L5: =IFERROR(AVERAGEIF(STR!$V:$V, 'Overview KPI'!L2, STR!$Y:$Y), 0)/4 -> 0.74294643 | M5: 0.15 | N5: =M5*L5 -> 0.11144196
A6: 2 | B6: Bad Data | C6: =1-AVERAGEIF('Bad Data'!$C:$C, 'Overview KPI'!C$2, 'Bad Data'!$D:$D) -> 0.99831167 | D6: 0.1 | E6: =D6*C6 -> 0.099831167 | F6: =1-AVERAGEIF('Bad Data'!$C:$C, 'Overview KPI'!F$2, 'Bad Data'!$D:$D) -> 0.99775167 | G6: 0.1 | H6: =G6*F6 -> 0.099775167 | I6: =1-AVERAGEIF('Bad Data'!$C:$C, 'Overview KPI'!I$2, 'Bad Data'!$D:$D) -> 0.99812333 | J6: 0.1 | K6: =J6*I6 -> 0.099812333 | L6: =1-AVERAGEIF('Bad Data'!$C:$C, 'Overview KPI'!L$2, 'Bad Data'!$D:$D) -> 0.99873 | M6: 0.1 | N6: =M6*L6 -> 0.099873
A7: 3 | B7: Pengkinian Data | C7: =AVERAGEIF('Pengkinian Data'!$C:$C, 'Overview KPI'!C$2, 'Pengkinian Data'!$D:$D) -> 0.9978 | D7: 0.1 | E7: =D7*C7 -> 0.09978 | F7: =AVERAGEIF('Pengkinian Data'!$C:$C, 'Overview KPI'!F$2, 'Pengkinian Data'!$D:$D) -> 0.99795 | G7: 0.1 | H7: =G7*F7 -> 0.099795 | I7: =AVERAGEIF('Pengkinian Data'!$C:$C, 'Overview KPI'!I$2, 'Pengkinian Data'!$D:$D) -> 0.99891667 | J7: 0.1 | K7: =J7*I7 -> 0.099891667 | L7: =AVERAGEIF('Pengkinian Data'!$C:$C, 'Overview KPI'!L$2, 'Pengkinian Data'!$D:$D) -> 0.99966667 | M7: 0.1 | N7: =M7*L7 -> 0.099966667 | U7: .
A8: 4 | B8: Uji Petik | C8: {=IFERROR(SUMPRODUCT(--('[1]Uji Petik'!$E$3:$E$73<>""), --('[1]Uji Petik'!$C$3:$C$73=C2)) / SUMPRODUCT(--('[1]Uji Petik'!$C$3:$C$73=C2)), 0)} -> 0 | D8: 0.075 | E8: =D8*C8 -> 0 | F8: {=IFERROR(SUMPRODUCT(--('[1]Uji Petik'!$E$3:$E$73<>""), --('[1]Uji Petik'!$C$3:$C$73=F3)) / SUMPRODUCT(--('[1]Uji Petik'!$C$3:$C$73=F3)), 0)} -> 0 | G8: 0.075 | H8: =G8*F8 -> 0 | I8: {=IFERROR(SUMPRODUCT(--('[1]Uji Petik'!$E$3:$E$73<>""), --('[1]Uji Petik'!$C$3:$C$73=I3)) / SUMPRODUCT(--('[1]Uji Petik'!$C$3:$C$73=I3)), 0)} -> 0 | J8: 0.075 | K8: =J8*I8 -> 0 | L8: {=IFERROR(SUMPRODUCT(--('[1]Uji Petik'!$E$3:$E$73<>""), --('[1]Uji Petik'!$C$3:$C$73=L3)) / SUMPRODUCT(--('[1]Uji Petik'!$C$3:$C$73=L3)), 0)} -> 0 | M8: 0.075 | N8: =M8*L8 -> 0
A9: 5 | B9: Sosialisasi | C9: {=IFERROR(AVERAGE(IF([2]Sosialisasi!$C$1:$C$10000=C2, [2]Sosialisasi!$D$1:$D$10000)), 0)} -> 0 | D9: 0.075 | E9: =D9*C9 -> 0 | F9: {=IFERROR(AVERAGE(IF([2]Sosialisasi!$C$1:$C$10000=F2, [2]Sosialisasi!$D$1:$D$10000)), 0)} -> 0.66666667 | G9: 0.075 | H9: =G9*F9 -> 0.05 | I9: {=IFERROR(AVERAGE(IF([2]Sosialisasi!$C$1:$C$10000=I2, [2]Sosialisasi!$D$1:$D$10000)), 0)} -> 0.5 | J9: 0.075 | K9: =J9*I9 -> 0.0375 | L9: {=IFERROR(AVERAGE(IF([2]Sosialisasi!$C$1:$C$10000=L2, [2]Sosialisasi!$D$1:$D$10000)), 0)} -> 0.5 | M9: 0.075 | N9: =M9*L9 -> 0.0375
