Workbook

Sheet STR
A1: POSISI | B1: NAMA | C1: CIF | D1: No Rek/ Kartu Kredit | E1: RESIKO | F1: BRILINK | G1: STATUS PEKERJA | H1: DIGITAL SAVING | I1: SKENARIO | J1: SCORING | K1: INFO PARAM | L1: KATEGORI | M1: UNIT KERJA | N1: KANTOR CABANG | O1: KANTOR KANWIL | P1: REKOMENDASI UKER | Q1: REKOMENDASI UKK | R1: STATUS UKER | S1: STATUS | T1: DISPOSISI | U1: INFO LAINNYA | V1: Disposisi RAC | W1: Tanggal | X1: Status TL
A2: {=_xlfn._xlws.FILTER('[2]STR-2026-8-2026-8'!$A:$U, ISNUMBER(SEARCH("DKI2", '[2]STR-2026-8-2026-8'!$O:$O)), "")} -> 46265 | B2: AULIA ROHMAN ROKHIM | C2: AAWQ591 | D2: 42701000492306 | E2: SEDANG | F2: Tidak | G2: Tidak | H2: Tidak | I2: Perpajakan | J2: 51 | K2: 41 | L2: Perpajakan | M2: KC Jakarta Gatot Subroto | N2: KC Jakarta Gatot Subroto | O2: DKI2 | P2: 0 | Q2: 0 | R2: Belum TL | S2: Belum TL | T2: 90186796 - Devito Arya Wiradila | U2: "-" | V2: Imelda Mayestika P. | X2: =[3]STR!$X2 -> TRUE
A3: 46265 | B3: ARDOVI INDO TRAVEL | C3: ACDMR55 | D3: 42601002117306 | E3: SEDANG | F3: Tidak | G3: Tidak | H3: Tidak | I3: Perpajakan | J3: 48 | K3: 41 | L3: Perpajakan | M3: KC BRI Jakarta Menara Brilian | N3: KC BRI Jakarta Menara Brilian | O3: DKI2 | P3: 0 | Q3: 0 | R3: Belum TL | S3: Belum TL | T3: 90186790 - Muhammad Alfin Farha | U3: "-" | V3: Imelda Mayestika P. | X3: =[3]STR!$X3 -> TRUE
A4: 46265 | B4: AMARTHA MIKRO FINTEK | C4: AHDR268 | D4: 42501001099569 | E4: SEDANG | F4: Tidak | G4: Tidak | H4: Tidak | I4: Perpajakan | J4: 50 | K4: 1.33 | L4: Perpajakan | M4: KC Ampera | N4: KC Ampera | O4: DKI2 | P4: 0 | Q4: 0 | R4: Belum TL | S4: Belum TL | T4: 00394521 - Muhammad Hibbanduta | U4: "-" | V4: Imelda Mayestika P. | X4: =[3]STR!$X4 -> TRUE
A5: 46265 | B5: AGUSTINUS GUSTAF BRUGMAN | C5: AQX3992 | D5: 5.32659e+15 | E5: TINGGI | F5: Tidak | G5: Tidak | H5: Tidak | I5: Private or Priority Customer Investment | J5: 83 | K5: 93 | L5: Pasar Modal | M5: KC Jakarta Gatot Subroto | N5: KC Jakarta Gatot Subroto | O5: DKI2 | P5: 0 | Q5: 0 | R5: Belum TL | S5: Belum TL | T5: 90185538 - Muhammad Fahikal Auz | U5: "-" | V5: Imelda Mayestika P. | X5: =[3]STR!$X5 -> FALSE | Z5: .
A6: 46265 | B6: BERCA INDONESIA | C6: BX43053 | D6: 37602000159305 | E6: SEDANG | F6: Tidak | G6: Tidak | H6: Tidak | I6: Perpajakan | J6: 50 | K6: 41 | L6: Perpajakan | M6: KC Jakarta Sudirman 1 | N6: KC Jakarta Sudirman 1 | O6: DKI2 | P6: 0 | Q6: 0 | R6: Belum TL | S6: Belum TL | T6: 90186790 - Muhammad Alfin Farha | U6: "-" | V6: Imelda Mayestika P. | X6: =[3]STR!$X6 -> FALSE
A7: 46265 | B7: CIPTA CAKRA MURDAYA | C7: CG23315 | D7: 37601001937302 | E7: SEDANG | F7: Tidak | G7: Tidak | H7: Tidak | I7: Perpajakan | J7: 48 | K7: 41 | L7: Perpajakan | M7: KC Jakarta Sudirman 1 | N7: KC Jakarta Sudirman 1 | O7: DKI2 | P7: 0 | Q7: 0 | R7: Belum TL | S7: Belum TL | T7: 00394520 - Frida Akbar Rani | U7: "-" | V7: Imelda Mayestika P. | X7: =[3]STR!$X7 -> FALSE
A8: 46265 | B8: DARMAWAN PRASODJO, PH.D | C8: DGK7192 | D8: 0 | E8: TINGGI | F8: Tidak | G8: Tidak | H8: Tidak | I8: Private or Priority Customer Investment | J8: 78 | K8: 93 | L8: Pasar Modal | M8: KCP TELKOM LANDMARK TOWER | N8: KC Jakarta Gatot Subroto | O8: DKI2 | P8: 0 | Q8: 0 | R8: Belum TL | S8: Belum TL | T8: 00394521 - Muhammad Hibbanduta | U8: "-" | V8: Imelda Mayestika P. | X8: =[3]STR!$X8 -> FALSE
A9: 46265 | B9: DERRY APRIANTI | C9: DGRJ257 | D9: 80101017826506 | E9: 0 | F9: Tidak | G9: Tidak | H9: 0 | I9: Jual Beli Rekening - E channel Trx | J9: 33 | K9: 113 | L9: Narkotika/Judi Online/Penipuan | M9: UNIT WARUNG JAMBU | N9: KC Bogor Pajajaran | O9: DKI2 | P9: 0 | Q9: 0 | R9: Belum TL | S9: Belum TL | T9: 0 | U9: "-" | V9: Imelda Mayestika P. | X9: =[3]STR!$X9 -> FALSE
A10: 46265 | B10: DEDI SURYADI | C10: DHRI111 | D10: 479401000064560 | E10: 0 | F10: Tidak | G10: Tidak | H10: 0 | I10: Jual Beli Rekening - E channel Trx | J10: 33 | K10: 113 | L10: Narkotika/Judi Online/Penipuan | M10: UNIT PONDOK UNGU PERMAI BEKASI | N10: KC Bekasi | O10: DKI2 | P10: 0 | Q10: 0 | R10: Belum TL | S10: Belum TL | T10: 0 | U10: "-" | V10: Imelda Mayestika P. | X10: =[3]STR!$X10 -> FALSE
A11: 46265 | B11: EKO SUPRIYADI | C11: EZO9900 | D11: 38701078253508 | E11: 0 | F11: Tidak | G11: Tidak | H11: 0 | I11: Jual Beli Rekening - E channel Trx | J11: 33 | K11: 113 | L11: Narkotika/Judi Online/Penipuan | M11: KC Bogor Pajajaran | N11: KC Bogor Pajajaran | O11: DKI2 | P11: 0 | Q11: 0 | R11: Belum TL | S11: Belum TL | T11: 0 | U11: "-" | V11: Imelda Mayestika P. | X11: =[3]STR!$X11 -> FALSE
A12: 46265 | B12: FLIPTECH LENTERA INSPIRASI PERTIWI | C12: FM60762 | D12: 67201000299301 | E12: TINGGI | F12: Tidak | G12: Tidak | H12: Tidak | I12: TPPO - Perusahaan PJTKI | J12: 65 | K12: 103 | L12: TPPO | M12: KCP UNIVERSITAS INDONESIA | N12: KC Depok | O12: DKI2 | P12: 0 | Q12: 0 | R12: Belum TL | S12: Belum TL | T12: 90150130 - Intan Aida Pratiwi | U12: "-" | V12: Imelda Mayestika P. | X12: =[3]STR!$X12 -> TRUE
A13: 46265 | B13: INTEGRA CIPTA KREASI | C13: IEB4240 | D13: 141401000008303 | E13: SEDANG | F13: Tidak | G13: Tidak | H13: Tidak | I13: Perpajakan | J13: 48 | K13: 41 | L13: Perpajakan | M13: KCP PLN JAKARTA | N13: KC Jakarta Kebayoran Baru | O13: DKI2 | P13: 0 | Q13: 0 | R13: Belum TL | S13: Belum TL | T13: 90186790 - Muhammad Alfin Farha | U13: "-" | V13: Imelda Mayestika P. | X13: =[3]STR!$X13 -> FALSE
A14: 46265 | B14: KARTINI SUKSES MAKMUR | C14: KHY9859 | D14: 38701000921305 | E14: TINGGI | F14: Tidak | G14: Tidak | H14: Tidak | I14: Perpajakan | J14: 65 | K14: 1.33 | L14: Perpajakan | M14: KC Bogor Pajajaran | N14: KC Bogor Pajajaran | O14: DKI2 | P14: 0 | Q14: 0 | R14: Belum TL | S14: Belum TL | T14: 00394521 - Muhammad Hibbanduta | U14: "-" | V14: Imelda Mayestika P. | X14: =[3]STR!$X14 -> TRUE
A15: 46265 | B15: LUMBUNG PANGAN REJEKI AULIA | C15: LHM1155 | D15: 35901002519307 | E15: SEDANG | F15: Tidak | G15: Tidak | H15: Tidak | I15: Perpajakan | J15: 48 | K15: 41 | L15: Perpajakan | M15: KC Jakarta Gatot Subroto | N15: KC Jakarta Gatot Subroto | O15: DKI2 | P15: 0 | Q15: 0 | R15: Belum TL | S15: Belum TL | T15: 90186796 - Devito Arya Wiradila | U15: "-" | V15: Imelda Mayestika P. | X15: =[3]STR!$X15 -> TRUE
A16: 46265 | B16: MISBAUL MUNIR | C16: MDSEZ72 | D16: 725401012349507 | E16: 0 | F16: Tidak | G16: Tidak | H16: 0 | I16: Jual Beli Rekening - E channel Trx | J16: 33 | K16: 113 | L16: Narkotika/Judi Online/Penipuan | M16: UNIT KAYURINGIN BEKASI | N16: KC Bekasi | O16: DKI2 | P16: 0 | Q16: 0 | R16: Belum TL | S16: Belum TL | T16: 0 | U16: "-" | V16: Imelda Mayestika P. | X16: =[3]STR!$X16 -> FALSE
A17: 46265 | B17: MUHAMAD MUTTAQIN HAESYI | C17: MEBEB49 | D17: 479601074752509 | E17: 0 | F17: Tidak | G17: Tidak | H17: 0 | I17: Jual Beli Rekening - E channel Trx | J17: 33 | K17: 113 | L17: Narkotika/Judi Online/Penipuan | M17: UNIT CIBUNG BULANGÂ BOGOR | N17: KC Bogor | O17: DKI2 | P17: 0 | Q17: 0 | R17: Belum TL | S17: Belum TL | T17: 0 | U17: "-" | V17: Imelda Mayestika P. | X17: =[3]STR!$X17 -> FALSE
A18: 46265 | B18: MIRAH AGUNG RAYA, PT | C18: MLZ2573 | D18: 37802000171305 | E18: SEDANG | F18: Tidak | G18: Tidak | H18: Tidak | I18: Perpajakan | J18: 48 | K18: 41 | L18: Perpajakan | M18: KC Jakarta Rasuna Said | N18: KC Jakarta Rasuna Said | O18: DKI2 | P18: 0 | Q18: 0 | R18: Belum TL | S18: Belum TL | T18: 90171841 - Rifqi Aziz | U18: "-" | V18: Imelda Mayestika P. | X18: =[3]STR!$X18 -> FALSE
A19: 46265 | B19: DRS MUDJI WALUYO SH MM | C19: MVC5934 | D19: 0 | E19: TINGGI | F19: Tidak | G19: Tidak | H19: Tidak | I19: Private or Priority Customer Investment | J19: 78 | K19: 93 | L19: Pasar Modal | M19: KCP TELKOM LANDMARK TOWER | N19: KC Jakarta Gatot Subroto | O19: DKI2 | P19: 0 | Q19: 0 | R19: Belum TL | S19: Belum TL | T19: 90186790 - Muhammad Alfin Farha | U19: "-" | V19: Imelda Mayestika P. | X19: =[3]STR!$X19 -> FALSE
A20: 46265 | B20: PT. POLA PENAWAR BANGUN SEMESTA | C20: PF57896 | D20: 37801001039306 | E20: SEDANG | F20: Tidak | G20: Tidak | H20: Tidak | I20: Perpajakan | J20: 48 | K20: 41 | L20: Perpajakan | M20: KC Jakarta Rasuna Said | N20: KC Jakarta Rasuna Said | O20: DKI2 | P20: 0 | Q20: 0 | R20: Belum TL | S20: Belum TL | T20: 00394520 - Frida Akbar Rani | U20: "-" | V20: Imelda Mayestika P. | X20: =[3]STR!$X20 -> FALSE
A21: 46265 | B21: PT HARDAYA INTI PLANTATIONS | C21: POG7708 | D21: 37601998899568 | E21: 0 | F21: Tidak | G21: Tidak | H21: Tidak | I21: Perpajakan | J21: 33 | K21: 41 | L21: Perpajakan | M21: KC Jakarta Sudirman 1 | N21: KC Jakarta Sudirman 1 | O21: DKI2 | P21: 0 | Q21: 0 | R21: Belum TL | S21: Belum TL | T21: 00394521 - Muhammad Hibbanduta | U21: "-" | V21: Imelda Mayestika P. | X21: =[3]STR!$X21 -> FALSE
A22: 46265 | B22: RUDI HADI SUWARNO | C22: RCZP717 | D22: 1201262485506 | E22: TINGGI | F22: Tidak | G22: Tidak | H22: Tidak | I22: Narkotika - Area Lapas | J22: 65 | K22: 48 | L22: Narkotika | M22: KC Bogor | N22: KC Bogor | O22: DKI2 | P22: 0 | Q22: 0 | R22: Belum TL | S22: Belum TL | T22: 90186796 - Devito Arya Wiradila | U22: "-" | V22: Imelda Mayestika P. | X22: =[3]STR!$X22 -> FALSE
A23: 46265 | B23: RANI MUSTIKA ZAHRA SUPRIADI | C23: ROS8128 | D23: 1201284821500 | E23: 0 | F23: Tidak | G23: Tidak | H23: 0 | I23: Jual Beli Rekening - E channel Trx | J23: 33 | K23: 113 | L23: Narkotika/Judi Online/Penipuan | M23: KC Bogor | N23: KC Bogor | O23: DKI2 | P23: 0 | Q23: 0 | R23: Belum TL | S23: Belum TL | T23: 0 | U23: "-" | V23: Imelda Mayestika P. | X23: =[3]STR!$X23 -> FALSE
A24: 46265 | B24: WAHANA AGUNG ABADI | C24: WJI9743 | D24: 42601002005567 | E24: SEDANG | F24: Tidak | G24: Tidak | H24: Tidak | I24: Perpajakan | J24: 48 | K24: 41 | L24: Perpajakan | M24: KC BRI Jakarta Menara Brilian | N24: KC BRI Jakarta Menara Brilian | O24: DKI2 | P24: 0 | Q24: 0 | R24: Belum TL | S24: Belum TL | T24: 90170665 - Mutiara Ayuningtyas | U24: "-" | V24: Imelda Mayestika P. | X24: =[3]STR!$X24 -> FALSE
A25: 46265 | B25: PT SINARNIAGA SEJAHTERA | C25: PU95219 | D25: 115301000034308 | E25: TINGGI | F25: Tidak | G25: Tidak | H25: Tidak | I25: Perpajakan | J25: 65 | K25: 1.33 | L25: Perpajakan | M25: KCP SULTAN AGUNG | N25: KC Bekasi Harapan Indah | O25: DKI2 | P25: Tidak | Q25: Tidak | R25: Pending Approver | S25: Pending Checker | T25: 90171841 - Rifqi Aziz | U25: "-" | V25: Imelda Mayestika P. | X25: =[3]STR!$X25 -> TRUE
A26: 46265 | B26: PT DIGITAL RAYA SEMESTA | C26: DDT0643 | D26: 122301000162304 | E26: SEDANG | F26: Tidak | G26: Tidak | H26: Tidak | I26: Narkotika - Area Lapas | J26: 50 | K26: 46 | L26: Narkotika | M26: KC JAKARTA MEGA KUNINGAN | N26: KC JAKARTA MEGA KUNINGAN | O26: DKI2 | P26: Tidak | Q26: 0 | R26: Done | S26: Belum TL | T26: 90150130 - Intan Aida Pratiwi | U26: "-" | V26: Imelda Mayestika P. | X26: =[3]STR!$X26 -> TRUE
A27: 46265 | B27: KRISTIAN SIHAR MANULLANG | C27: KVP8409 | D27: 0 | E27: TINGGI | F27: Tidak | G27: Tidak | H27: Tidak | I27: Private or Priority Customer Investment | J27: 78 | K27: 93 | L27: Pasar Modal | M27: KC Jakarta Gatot Subroto | N27: KC Jakarta Gatot Subroto | O27: DKI2 | P27: Tidak | Q27: 0 | R27: Done | S27: Belum TL | T27: 90170665 - Mutiara Ayuningtyas | U27: "-" | V27: Imelda Mayestika P. | X27: =[3]STR!$X27 -> FALSE
A28: 46265 | B28: PT DAYA KOBELCO CMI | C28: DUR9925 | D28: 36201002132304 | E28: SEDANG | F28: Tidak | G28: Tidak | H28: Tidak | I28: Narkotika - Area Lapas | J28: 50 | K28: 47 | L28: Narkotika | M28: KC Jakarta Pondok Indah | N28: KC Jakarta Pondok Indah | O28: DKI2 | P28: Tidak | Q28: 0 | R28: Done | S28: Belum TL | T28: 90185537 - Moh.Khoerul Fajar Ar | U28: "-" | V28: Imelda Mayestika P. | X28: =[3]STR!$X28 -> TRUE
A29: 46265 | B29: MEGA GEMILANG INDOPRIMA PLANT 1 | C29: MDJY811 | D29: 201801000080306 | E29: SEDANG | F29: Tidak | G29: Tidak | H29: Tidak | I29: Perpajakan | J29: 50 | K29: 41 | L29: Perpajakan | M29: KCP MABES POLRI | N29: KC Jakarta Kebayoran Baru | O29: DKI2 | P29: Tidak | Q29: Tidak | R29: Done | S29: Pending Checker | T29: 90185537 - Moh.Khoerul Fajar Ar | U29: "-" | V29: Imelda Mayestika P. | X29: =[3]STR!$X29 -> TRUE
A30: 46265 | B30: RPL 088 PS PUSKEU POLRI UTK KPRLN RUTIN | C30: RCZD612 | D30: 201801000121306 | E30: SEDANG | F30: Tidak | G30: Tidak | H30: Tidak | I30: Perpajakan | J30: 48 | K30: 41 | L30: Perpajakan | M30: KCP MABES POLRI | N30: KC Jakarta Kebayoran Baru | O30: DKI2 | P30: Tidak | Q30: Tidak | R30: Done | S30: Pending Checker | T30: 00394521 - Muhammad Hibbanduta | U30: "-" | V30: Imelda Mayestika P. | X30: =[3]STR!$X30 -> TRUE
A31: 46265 | B31: PT MENTARI KARYA TANI | C31: PNL6130 | D31: 43001001436308 | E31: 0 | F31: Tidak | G31: Tidak | H31: Tidak | I31: Perpajakan | J31: 33 | K31: 41 | L31: Perpajakan | M31: KC Jakarta Radio Dalam | N31: KC Jakarta Radio Dalam | O31: DKI2 | P31: Tidak | Q31: Tidak | R31: Done | S31: Pending Checker | T31: 90186796 - Devito Arya Wiradila | U31: "-" | V31: Imelda Mayestika P. | X31: =[3]STR!$X31 -> TRUE
A32: 46265 | B32: PRIMA PUTRA AGUNG | C32: PHS7632 | D32: 43001000881306 | E32: SEDANG | F32: Tidak | G32: Tidak | H32: Tidak | I32: Perpajakan | J32: 50 | K32: 1.33 | L32: Perpajakan | M32: KC Jakarta Radio Dalam | N32: KC Jakarta Radio Dalam | O32: DKI2 | P32: Tidak | Q32: Tidak | R32: Done | S32: Pending Checker | T32: 00394521 - Muhammad Hibbanduta | U32: "-" | V32: Imelda Mayestika P. | X32: =[3]STR!$X32 -> TRUE
A33: 46265 | B33: SINAR DIGITAL TERDEPAN | C33: SQZW367 | D33: 122301000593301 | E33: SEDANG | F33: Tidak | G33: Tidak | H33: Tidak | I33: Narkotika/Psikotropika- Remark | J33: 50 | K33: 9 | L33: Narkotika/Psikotropika | M33: KC JAKARTA MEGA KUNINGAN | N33: KC JAKARTA MEGA KUNINGAN | O33: DKI2 | P33: Tidak | Q33: Tidak | R33: Done | S33: Pending Checker | T33: 90185538 - Muhammad Fahikal Auz | U33: "-" | V33: Imelda Mayestika P. | X33: =[3]STR!$X33 -> TRUE
A34: 46265 | B34: KLINIK YADIKA SIBISA MANGATUR | C34: KTC3299 | D34: 43001001128303 | E34: SEDANG | F34: Tidak | G34: Tidak | H34: Tidak | I34: Perpajakan | J34: 50 | K34: 41 | L34: Perpajakan | M34: KC Jakarta Radio Dalam | N34: KC Jakarta Radio Dalam | O34: DKI2 | P34: Tidak | Q34: Tidak | R34: Done | S34: Pending Checker | T34: 90150130 - Intan Aida Pratiwi | U34: "-" | V34: Imelda Mayestika P. | X34: =[3]STR!$X34 -> TRUE
A35: 46265 | B35: KARYA YAKIN SUKSES SEJAHTERA | C35: KZI4907 | D35: 210101001839307 | E35: 0 | F35: Tidak | G35: Tidak | H35: Tidak | I35: Perpajakan | J35: 33 | K35: 41 | L35: Perpajakan | M35: KC Mabes TNI Cilangkap | N35: KC Mabes TNI Cilangkap | O35: DKI2 | P35: Tidak | Q35: Tidak | R35: Done | S35: Pending Checker | T35: 90171841 - Rifqi Aziz | U35: "-" | V35: Imelda Mayestika P. | X35: =[3]STR!$X35 -> TRUE
A36: 46265 | B36: KREASI USAHA CIPTA UTAMA | C36: KATS206 | D36: 31901002606306 | E36: 0 | F36: Tidak | G36: Tidak | H36: Tidak | I36: Perpajakan | J36: 33 | K36: 41 | L36: Perpajakan | M36: KC Cikarang | N36: KC Cikarang | O36: DKI2 | P36: Tidak | Q36: Tidak | R36: Done | S36: Pending Checker | T36: 90150130 - Intan Aida Pratiwi | U36: "-" | V36: Imelda Mayestika P. | X36: =[3]STR!$X36 -> TRUE
A37: 46265 | B37: KOPERASI KARYAWAN PT PLN UPD | C37: KFK5524 | D37: 141401000036306 | E37: SEDANG | F37: Tidak | G37: Tidak | H37: Tidak | I37: Perpajakan | J37: 48 | K37: 41 | L37: Perpajakan | M37: KCP PLN JAKARTA | N37: KC Jakarta Kebayoran Baru | O37: DKI2 | P37: Tidak | Q37: Tidak | R37: Done | S37: Pending Checker | T37: 90185538 - Muhammad Fahikal Auz | U37: "-" | V37: Imelda Mayestika P. | X37: =[3]STR!$X37 -> TRUE
A38: 46265 | B38: CITRA MARGA NUSAPHALA PERSADA TBK | C38: CT70848 | D38: 121101000376300 | E38: 0 | F38: Tidak | G38: Tidak | H38: Tidak | I38: Perpajakan | J38: 33 | K38: 41 | L38: Perpajakan | M38: KCP KEMENTERIAN PU | N38: KC Jakarta Kebayoran Baru | O38: DKI2 | P38: Tidak | Q38: Tidak | R38: Done | S38: Pending Checker | T38: 90186790 - Muhammad Alfin Farha | U38: "-" | V38: Imelda Mayestika P. | X38: =[3]STR!$X38 -> TRUE
A39: 46265 | B39: ALJERINDO NAWA SENA | C39: ADBNF29 | D39: 207101000459301 | E39: 0 | F39: Tidak | G39: Tidak | H39: Tidak | I39: Perpajakan | J39: 33 | K39: 41 | L39: Perpajakan | M39: KCP JAMSOSTEK | N39: KC Jakarta Gatot Subroto | O39: DKI2 | P39: Tidak | Q39: Tidak | R39: Done | S39: Pending Checker | T39: 00394520 - Frida Akbar Rani | U39: "-" | V39: Imelda Mayestika P. | X39: =[3]STR!$X39 -> TRUE
A40: 46265 | B40: HARDAYA INTI PLANTATIONS | C40: HXZ5646 | D40: 37601001929309 | E40: SEDANG | F40: Tidak | G40: Tidak | H40: Tidak | I40: Perpajakan | J40: 48 | K40: 41 | L40: Perpajakan | M40: KC Jakarta Sudirman 1 | N40: KC Jakarta Sudirman 1 | O40: DKI2 | P40: Tidak | Q40: Tidak | R40: Done | S40: Approved | T40: 90185537 - Moh.Khoerul Fajar Ar | U40: "-" | V40: Imelda Mayestika P. | X40: =[3]STR!$X40 -> TRUE
...

Sheet Sosialisasi
A1: No. | B1: Unit Kerja | C1: PIC RAC | D1: Materi* | E1: Tanggal Rencana Pelaksanaan | F1: Tanggal Pelaksanaan* | G1: Jumlah Peserta* | H1: Jabatan Peserta* | I1: Dokumen Evidence**
A2: 1 | B2: KC Balige
A3: 2 | B3: KC Binjai
A4: 3 | B4: KC Gunung Sitoli
A5: 4 | B5: KC Kabanjahe
A6: 5 | B6: KC Kisaran
A7: 6 | B7: KC Kota Pinang
A8: 7 | B8: KC Lubuk Pakam
A9: 8 | B9: KC Medan Gatot Subroto
A10: 9 | B10: KC Medan Iskandar Muda
A11: 10 | B11: KC Medan Putri Hijau
A12: 11 | B12: KC Medan Sisingamangaraja
A13: 12 | B13: KC Medan Thamrin
... A25: 24 | B25: KC Tebing Tinggi
B27: Keterangan:
B28: *Diisi jika telah dilaksanakan
B29: **https://bbri.id/MonevaRAC
B31: Evidence terdiri dari:
B32: 1. Dokumentasi Foto
B33: 2. Berita Acara
B34: 3. Absensi
B35: 4. Materi Sosisalisasi
B36: 5. List Pertanyaan

Sheet EDD PEP PPATK
D1: 46280
A2: No. | B2: Unit Kerja | C2: PIC RAC | D2: %PEP TL Done | E2: Average
A3: 1 | B3: KC Jakarta Mega Kuningan | C3: Imelda Mayestika P. | D3: =_xlfn.XLOOKUP(B3, [1]PEP!$B:$B,[1]PEP!$G:$G) -> 1 | E3: =AVERAGE(D3:D34) -> 0.96460274
A4: 2 | B4: KC Bekasi | C4: Imelda Mayestika P. | D4: =_xlfn.XLOOKUP(B4, [1]PEP!$B:$B,[1]PEP!$G:$G) -> 0.95757576
A5: 3 | B5: KC Bekasi Harapan Indah | C5: Imelda Mayestika P. | D5: =_xlfn.XLOOKUP(B5, [1]PEP!$B:$B,[1]PEP!$G:$G) -> 1
A6: 4 | B6: KC Bogor | C6: Imelda Mayestika P. | D6: =_xlfn.XLOOKUP(B6, [1]PEP!$B:$B,[1]PEP!$G:$G) -> 0.89940828
A7: 5 | B7: KC Bogor Pajajaran | C7: Imelda Mayestika P. | D7: =_xlfn.XLOOKUP(B7, [1]PEP!$B:$B,[1]PEP!$G:$G) -> 0.97826087
A8: 6 | B8: KC Bursa Efek Indonesia | C8: Imelda Mayestika P. | D8: =_xlfn.XLOOKUP(B8, [1]PEP!$B:$B,[1]PEP!$G:$G) -> 0.98666667
A9: 7 | B9: KC Cibinong | C9: Imelda Mayestika P. | D9: =_xlfn.XLOOKUP(B9, [1]PEP!$B:$B,[1]PEP!$G:$G) -> 0.93939394
A10: 8 | B10: KC Cibubur | C10: Imelda Mayestika P. | D10: =_xlfn.XLOOKUP(B10, [1]PEP!$B:$B,[1]PEP!$G:$G) -> 0.98360656
A11: 9 | B11: KC Cikampek | C11: Imelda Mayestika P. | D11: =_xlfn.XLOOKUP(B11, [1]PEP!$B:$B,[1]PEP!$G:$G) -> 1
A12: 10 | B12: KC Cikarang | C12: Imelda Mayestika P. | D12: =_xlfn.XLOOKUP(B12, [1]PEP!$B:$B,[1]PEP!$G:$G) -> 0.96774194
A13: 11 | B13: KC Cimanggis | C13: Imelda Mayestika P. | D13: =_xlfn.XLOOKUP(B13, [1]PEP!$B:$B,[1]PEP!$G:$G) -> 0.95555556
A14: 12 | B14: KC Depok | C14: Imelda Mayestika P. | D14: =_xlfn.XLOOKUP(B14, [1]PEP!$B:$B,[1]PEP!$G:$G) -> 0.96638655
A15: 13 | B15: KC Ampera | C15: Imelda Mayestika P. | D15: =_xlfn.XLOOKUP(B15, [1]PEP!$B:$B,[1]PEP!$G:$G) -> 0.95652174
... A34: 32 | B34: KC Jakarta Sudirman 1 | C34: Imelda Mayestika P. | D34: =_xlfn.XLOOKUP(B34, [1]PEP!$B:$B,[1]PEP!$G:$G) -> 0.85

Sheet Bad Data
D1: 46280
A2: No. | B2: Unit Kerja | C2: PIC RAC | D2: %Bad Data | E2: Average
A3: 1 | B3: KC Jakarta Mega Kuningan | C3: Imelda Mayestika P. | D3: =_xlfn.XLOOKUP(B3, '[1]Bad Data'!$B:$B, '[1]Bad Data'!$D:$D) -> 0.00022 | E3: =AVERAGE(D3:D34) -> 0.0009634375
A4: 2 | B4: KC Bekasi | C4: Imelda Mayestika P. | D4: =_xlfn.XLOOKUP(B4, '[1]Bad Data'!$B:$B, '[1]Bad Data'!$D:$D) -> 0.00212
A5: 3 | B5: KC Bekasi Harapan Indah | C5: Imelda Mayestika P. | D5: =_xlfn.XLOOKUP(B5, '[1]Bad Data'!$B:$B, '[1]Bad Data'!$D:$D) -> 8e-05
A6: 4 | B6: KC Bogor | C6: Imelda Mayestika P. | D6: =_xlfn.XLOOKUP(B6, '[1]Bad Data'!$B:$B, '[1]Bad Data'!$D:$D) -> 0.00053
A7: 5 | B7: KC Bogor Pajajaran | C7: Imelda Mayestika P. | D7: =_xlfn.XLOOKUP(B7, '[1]Bad Data'!$B:$B, '[1]Bad Data'!$D:$D) -> 0.00112
A8: 6 | B8: KC Bursa Efek Indonesia | C8: Imelda Mayestika P. | D8: =_xlfn.XLOOKUP(B8, '[1]Bad Data'!$B:$B, '[1]Bad Data'!$D:$D) -> 0.00109
A9: 7 | B9: KC Cibinong | C9: Imelda Mayestika P. | D9: =_xlfn.XLOOKUP(B9, '[1]Bad Data'!$B:$B, '[1]Bad Data'!$D:$D) -> 0.00117
A10: 8 | B10: KC Cibubur | C10: Imelda Mayestika P. | D10: =_xlfn.XLOOKUP(B10, '[1]Bad Data'!$B:$B, '[1]Bad Data'!$D:$D) -> 0.00174
A11: 9 | B11: KC Cikampek | C11: Imelda Mayestika P. | D11: =_xlfn.XLOOKUP(B11, '[1]Bad Data'!$B:$B, '[1]Bad Data'!$D:$D) -> 0.00021
A12: 10 | B12: KC Cikarang | C12: Imelda Mayestika P. | D12: =_xlfn.XLOOKUP(B12, '[1]Bad Data'!$B:$B, '[1]Bad Data'!$D:$D) -> 0.00218
A13: 11 | B13: KC Cimanggis | C13: Imelda Mayestika P. | D13: =_xlfn.XLOOKUP(B13, '[1]Bad Data'!$B:$B, '[1]Bad Data'!$D:$D) -> 0.00123
A14: 12 | B14: KC Depok | C14: Imelda Mayestika P. | D14: =_xlfn.XLOOKUP(B14, '[1]Bad Data'!$B:$B, '[1]Bad Data'!$D:$D) -> 0.00231
A15: 13 | B15: KC Ampera | C15: Imelda Mayestika P. | D15: =_xlfn.XLOOKUP(B15, '[1]Bad Data'!$B:$B, '[1]Bad Data'!$D:$D) -> 0.00015
... A34: 32 | B34: KC Jakarta Sudirman 1 | C34: Imelda Mayestika P. | D34: =_xlfn.XLOOKUP(B34, '[1]Bad Data'!$B:$B, '[1]Bad Data'!$D:$D) -> 0.00124

Sheet Pengkinian Data
D1: 46280
A2: No. | B2: Unit Kerja | C2: PIC RAC | D2: %Pengkinian Data | E2: Average
A3: 1 | B3: KC Jakarta Mega Kuningan | C3: Imelda Mayestika P. | D3: =_xlfn.XLOOKUP(B3,'[1]Pengkinian Data'!$B:$B,'[1]Pengkinian Data'!$E:$E) -> 1 | E3: =AVERAGE(D3:D34) -> 0.99999063
A4: 2 | B4: KC Bekasi | C4: Imelda Mayestika P. | D4: =_xlfn.XLOOKUP(B4,'[1]Pengkinian Data'!$B:$B,'[1]Pengkinian Data'!$E:$E) -> 1
A5: 3 | B5: KC Bekasi Harapan Indah | C5: Imelda Mayestika P. | D5: =_xlfn.XLOOKUP(B5,'[1]Pengkinian Data'!$B:$B,'[1]Pengkinian Data'!$E:$E) -> 1
A6: 4 | B6: KC Bogor | C6: Imelda Mayestika P. | D6: =_xlfn.XLOOKUP(B6,'[1]Pengkinian Data'!$B:$B,'[1]Pengkinian Data'!$E:$E) -> 1
A7: 5 | B7: KC Bogor Pajajaran | C7: Imelda Mayestika P. | D7: =_xlfn.XLOOKUP(B7,'[1]Pengkinian Data'!$B:$B,'[1]Pengkinian Data'!$E:$E) -> 1
A8: 6 | B8: KC Bursa Efek Indonesia | C8: Imelda Mayestika P. | D8: =_xlfn.XLOOKUP(B8,'[1]Pengkinian Data'!$B:$B,'[1]Pengkinian Data'!$E:$E) -> 1
A9: 7 | B9: KC Cibinong | C9: Imelda Mayestika P. | D9: =_xlfn.XLOOKUP(B9,'[1]Pengkinian Data'!$B:$B,'[1]Pengkinian Data'!$E:$E) -> 1
A10: 8 | B10: KC Cibubur | C10: Imelda Mayestika P. | D10: =_xlfn.XLOOKUP(B10,'[1]Pengkinian Data'!$B:$B,'[1]Pengkinian Data'!$E:$E) -> 1
A11: 9 | B11: KC Cikampek | C11: Imelda Mayestika P. | D11: =_xlfn.XLOOKUP(B11,'[1]Pengkinian Data'!$B:$B,'[1]Pengkinian Data'!$E:$E) -> 1
A12: 10 | B12: KC Cikarang | C12: Imelda Mayestika P. | D12: =_xlfn.XLOOKUP(B12,'[1]Pengkinian Data'!$B:$B,'[1]Pengkinian Data'!$E:$E) -> 1
A13: 11 | B13: KC Cimanggis | C13: Imelda Mayestika P. | D13: =_xlfn.XLOOKUP(B13,'[1]Pengkinian Data'!$B:$B,'[1]Pengkinian Data'!$E:$E) -> 1
A14: 12 | B14: KC Depok | C14: Imelda Mayestika P. | D14: =_xlfn.XLOOKUP(B14,'[1]Pengkinian Data'!$B:$B,'[1]Pengkinian Data'!$E:$E) -> 1
A15: 13 | B15: KC Ampera | C15: Imelda Mayestika P. | D15: =_xlfn.XLOOKUP(B15,'[1]Pengkinian Data'!$B:$B,'[1]Pengkinian Data'!$E:$E) -> 1
... A34: 32 | B34: KC Jakarta Sudirman 1 | C34: Imelda Mayestika P. | D34: =_xlfn.XLOOKUP(B34,'[1]Pengkinian Data'!$B:$B,'[1]Pengkinian Data'!$E:$E) -> 1

Sheet Uji Petik
A1: No. | B1: Unit Kerja | C1: PIC RAC | D1: Rencana Pelaksanaan | E1: Tanggal Pelaksanaan* | F1: Dokumen Evidence**
B29: Keterangan:
B30: *Diisi jika telah dilaksanakan
B31: **https://bri2-my.sharepoint.com/:f:/g/personal/00136153_hq_bri_co_id/IgBxKKO1DH9aT6uDsEcjnb-IAZNDDDPCI811IL1T3q9k6mo?e=XntHQ3
B34: Evidence terdiri dari:
B35: 1. Dokumentasi Foto
B36: 2. Berita Acara
B37: 3. Absensi
B38: 4.Kertas Kerja
B39: 5. Laporan Uji Petik
B41: (sedang dalam tahap drafting laporan uji petik untuk BO Gatot Subroto, SBO Patra Jasa, dan SBO Telkom Landmark)

Sheet Nilai Maturitas
A1: No. | B1: Unit Kerja | C1: PIC RAC | D1: Nilai maturitas | E1: Nilai maturitas | F1: Rating maturitas
A2: 2 | B2: KC Bekasi | C2: Imelda Mayestika P. | D2: 8.016 | E2: =AVERAGE(D2:D33) -> 8.3360938 | F2: AB
A3: 3 | B3: KC Bekasi Harapan Indah | C3: Imelda Mayestika P. | D3: 8.676
A4: 28 | B4: KC Bekasi Siliwangi | C4: Imelda Mayestika P. | D4: 7.497
A5: 4 | B5: KC Bogor Dewi Sartika | C5: Imelda Mayestika P. | D5: 9.361
A6: 5 | B6: KC Bogor Padjajaran | C6: Imelda Mayestika P. | D6: 8.442
A7: 6 | B7: KC Bursa Efek Indonesia | C7: Imelda Mayestika P. | D7: 8.989
A8: 7 | B8: KC Cibinong | C8: Imelda Mayestika P. | D8: 9.239
A9: 8 | B9: KC Cibubur | C9: Imelda Mayestika P. | D9: 8.312
A10: 9 | B10: KC Cikampek | C10: Imelda Mayestika P. | D10: 7.097
A11: 10 | B11: KC Cikarang | C11: Imelda Mayestika P. | D11: 6.866
A12: 11 | B12: KC Cimanggis | C12: Imelda Mayestika P. | D12: 7.41
A13: 12 | B13: KC Depok | C13: Imelda Mayestika P. | D13: 9.339
A14: 13 | B14: KC Jakarta Ampera | C14: Imelda Mayestika P. | D14: 7.936
... A33: 30 | B33: KC Tambun | C33: Imelda Mayestika P. | D33: 8.562

Sheet Penilaian Resiko
A1: No. | B1: Unit Kerja | C1: PIC RAC | D1: Nilai Risiko | E1: Nilai Risiko PIC | F1: Rating Risiko PIC
A2: 1 | B2: BO Jakarta Mega Kuningan | C2: Imelda Mayestika P. | D2: 6.9282032 | E2: =AVERAGE(D2:D33) -> 5.8736156 | F2: Medium to High
A3: 2 | B3: BO Bekasi | C3: Imelda Mayestika P. | D3: 4.7434165
A4: 3 | B4: BO Bekasi Harapan Indah | C4: Imelda Mayestika P. | D4: 5.4772256
A5: 4 | B5: BO Bogor Dewi Sartika | C5: Imelda Mayestika P. | D5: 4.9749372
A6: 5 | B6: BO Bogor Padjajaran | C6: Imelda Mayestika P. | D6: 5.4772256
A7: 6 | B7: BO Bursa Efek Indonesia | C7: Imelda Mayestika P. | D7: 4.8989795
A8: 7 | B8: BO Cibinong | C8: Imelda Mayestika P. | D8: 5.9791304
A9: 8 | B9: BO Cibubur | C9: Imelda Mayestika P. | D9: 5.7445626
A10: 9 | B10: BO Cikampek | C10: Imelda Mayestika P. | D10: 5.4772256
A11: 10 | B11: BO Cikarang | C11: Imelda Mayestika P. | D11: 5
A12: 11 | B12: BO Cimanggis | C12: Imelda Mayestika P. | D12: 5.7445626
A13: 12 | B13: BO Depok | C13: Imelda Mayestika P. | D13: 5.9160798
A14: 13 | B14: BO Jakarta Ampera | C14: Imelda Mayestika P. | D14: 6.7453688
... A33: 32 | B33: BO Jakarta Sudirman 1 | C33: Imelda Mayestika P. | D33: 5.9791304

Sheet Maturitas Dashboard
A1: No. | B1: Unit Kerja | C1: PIC RAC | D1: Nilai Maturitas | E1: Nilai Maturitas PIC | F1: Rating Maturitas PIC
A2: 1 | B2: KC Jakarta Mega Kuningan | C2: Imelda Mayestika P. | D2: 8.125 | E2: =AVERAGE(D2:D33) -> 7.5039062 | F2: Baik
A3: 2 | B3: KC Bekasi | C3: Imelda Mayestika P. | D3: 7.125
A4: 3 | B4: KC Bekasi Harapan Indah | C4: Imelda Mayestika P. | D4: 7.625
A5: 4 | B5: KC Bogor Dewi Sartika | C5: Imelda Mayestika P. | D5: 7.125
A6: 5 | B6: KC Bogor Padjajaran | C6: Imelda Mayestika P. | D6: 7.125
A7: 6 | B7: KC Bursa Efek Indonesia | C7: Imelda Mayestika P. | D7: 7.875
A8: 7 | B8: KC Cibinong | C8: Imelda Mayestika P. | D8: 7.125
A9: 8 | B9: KC Cibubur | C9: Imelda Mayestika P. | D9: 7.125
A10: 9 | B10: KC Cikampek | C10: Imelda Mayestika P. | D10: 7.625
A11: 10 | B11: KC Cikarang | C11: Imelda Mayestika P. | D11: 7.625
A12: 11 | B12: KC Cimanggis | C12: Imelda Mayestika P. | D12: 8.125
A13: 12 | B13: KC Depok | C13: Imelda Mayestika P. | D13: 7.125
A14: 13 | B14: KC Jakarta Ampera | C14: Imelda Mayestika P. | D14: 7.625
... A33: 32 | B33: KC Jakarta Sudirman 1 | C33: Imelda Mayestika P. | D33: 7.625

Sheet Overview
A2: No | B2: Aspek Penilaian | C2: Imelda Mayestika P.
C3: Nilai | D3: Bobotan | E3: Score
A4: 1 | B4: STR | C4: =IFERROR(COUNTIFS(STR!$V:$V, Overview!C$2, STR!$X:$X, "TRUE")/COUNTIFS(STR!$V:$V, Overview!C2), 0) -> 0.66129032 | D4: 0.15 | E4: =D4*C4 -> 0.099193548
A5: 2 | B5: Bad Data | C5: =1-AVERAGEIF('Bad Data'!$C:$C, Overview!C$2, 'Bad Data'!$D:$D) -> 0.99903656 | D5: 0.1 | E5: =D5*C5 -> 0.099903656
A6: 3 | B6: Pengkinian Data | C6: =AVERAGEIF('Pengkinian Data'!$C:$C, Overview!C$2, 'Pengkinian Data'!$D:$D) -> 0.99999063 | D6: 0.1 | E6: =D6*C6 -> 0.099999063 | L6: .
A7: 4 | B7: Uji Petik | C7: {=IFERROR(SUMPRODUCT(--('[3]Uji Petik'!$E$3:$E$73<>""), --('[3]Uji Petik'!$C$3:$C$73=C2)) / SUMPRODUCT(--('[3]Uji Petik'!$C$3:$C$73=C2)), 0)} -> 0 | D7: 0 | E7: =D7*C7 -> 0
A8: 5 | B8: Sosialisasi | C8: {=IFERROR(AVERAGE(IF([1]Sosialisasi!$C$1:$C$10000=C2, [1]Sosialisasi!$D$1:$D$10000)), 0)} -> 0 | D8: 0.15 | E8: =D8*C8 -> 0
A9: 6 | B9: EDD | C9: =AVERAGEIF('EDD PEP PPATK'!$C:$C, Overview!C$2, 'EDD PEP PPATK'!$D:$D) -> 0.96460274 | D9: 0.1 | E9: =D9*C9 -> 0.096460274
A10: 7 | B10: Self Learning Keikutsertaan | C10: {=IF(IFERROR(AVERAGE(IF('[1]Sheet2 (2)'!$C$1:$C$10000=C$2, '[1]Sheet2 (2)'!$D$1:$D$10000)), 0)>0.9, 1, IFERROR(AVERAGE(IF('[1]Sheet2 (2)'!$C$1:$C$10000=C$2, '[1]Sheet2 (2)'!$D$1:$D$10000)), 0))} -> 0.77705894 | D10: 0.05 | E10: =D10*C10 -> 0.038852947
A11: 8 | B11: Self Learning Score | C11: {=IF(IFERROR(AVERAGE(IF('[1]Sheet2 (3)'!$C$1:$C$10000=C2, '[1]Sheet2 (3)'!$D$1:$D$10000)), 0)>90, 1, IFERROR(AVERAGE(IF('[1]Sheet2 (3)'!$C$1:$C$10000=C2, '[1]Sheet2 (3)'!$D$1:$D$10000)), 0)/90)} -> 1 | D11: 0.05 | E11: =D11*C11 -> 0.05
A12: 9 | B12: Maturitas | C12: =IF(AVERAGEIF('Nilai Maturitas'!$C:$C, Overview!C2, 'Nilai Maturitas'!$D:$D) > 8, 110%, AVERAGEIF('Nilai Maturitas'!$C:$C, Overview!C2, 'Nilai Maturitas'!$D:$D)/8*100%) -> 1.1 | D12: 0.1 | E12: =D12*C12 -> 0.11
A13: 10 | B13: Maturitas Dashboard | C13: =IF(AVERAGEIF('Maturitas Dashboard'!$C:$C, Overview!C$2, 'Maturitas Dashboard'!$D:$D) > 8, 110%, AVERAGEIF('Maturitas Dashboard'!$C:$C, Overview!C$2, 'Maturitas Dashboard'!$D:$D)/8*100%) -> 0.93798828 | D13: 0.1 | E13: =D13*C13 -> 0.093798828
A14: 11 | B14: Penilaian Resiko | C14: =IF(AVERAGEIF('Penilaian Resiko'!$C:$C, Overview!C$2, 'Penilaian Resiko'!$D:$D) < 5.8, 110%, IF(AVERAGEIF('Penilaian Resiko'!$C:$C, Overview!C$2, 'Penilaian Resiko'!$D:$D) <7.4, 3/4*100%, 3/5*100%)) -> 0.75 | D14: 0.1 | E14: =D14*C14 -> 0.075
C15: Progress | E15: =SUM(E4:E14) -> 0.76320832

Sheet Overview tanpa KPI
A2: No | B2: Aspek Penilaian | C2: Imelda Mayestika P.
C3: Nilai | D3: Bobotan | E3: Score
A4: 1 | B4: STR | C4: =IFERROR(COUNTIFS(STR!$V:$V, 'Overview tanpa KPI'!C$2, STR!$X:$X, "TRUE")/COUNTIFS(STR!$V:$V, 'Overview tanpa KPI'!C2), 0) -> 0.66129032 | D4: 0.15 | E4: =D4*C4 -> 0.099193548
A5: 2 | B5: Bad Data | C5: =1-AVERAGEIF('Bad Data'!$C:$C, 'Overview tanpa KPI'!C$2, 'Bad Data'!$D:$D) -> 0.99903656 | D5: 0.1 | E5: =D5*C5 -> 0.099903656
A6: 3 | B6: Pengkinian Data | C6: =AVERAGEIF('Pengkinian Data'!$C:$C, 'Overview tanpa KPI'!C$2, 'Pengkinian Data'!$D:$D) -> 0.99999063 | D6: 0.1 | E6: =D6*C6 -> 0.099999063 | L6: .
A7: 4 | B7: Uji Petik | C7: {=IFERROR(SUMPRODUCT(--('[3]Uji Petik'!$E$3:$E$73<>""), --('[3]Uji Petik'!$C$3:$C$73=C2)) / SUMPRODUCT(--('[3]Uji Petik'!$C$3:$C$73=C2)), 0)} -> 0 | D7: 0 | E7: =D7*C7 -> 0
A8: 5 | B8: Sosialisasi | C8: {=IFERROR(AVERAGE(IF([1]Sosialisasi!$C$1:$C$10000=C2, [1]Sosialisasi!$D$1:$D$10000)), 0)} -> 0 | D8: 0.15 | E8: =D8*C8 -> 0
A9: 6 | B9: EDD | C9: =AVERAGEIF('EDD PEP PPATK'!$C:$C, 'Overview tanpa KPI'!C$2, 'EDD PEP PPATK'!$D:$D) -> 0.96460274 | D9: 0.1 | E9: =D9*C9 -> 0.096460274
A10: 7 | B10: Self Learning Keikutsertaan | C10: {=IFERROR(AVERAGE(IF('[1]Sheet2 (2)'!$C$1:$C$10000=C$2, '[1]Sheet2 (2)'!$D$1:$D$10000)), 0)} -> 0.77705894 | D10: 0.05 | E10: =D10*C10 -> 0.038852947
A11: 8 | B11: Self Learning Score | C11: {=IFERROR(AVERAGE(IF('[1]Sheet2 (3)'!$C$1:$C$10000=C2, '[1]Sheet2 (3)'!$D$1:$D$10000)), 0)} -> 95.026375 | D11: 0.05 | E11: =D11*C11 -> 4.7513187
A12: 9 | B12: Maturitas | C12: =AVERAGEIF('Nilai Maturitas'!$C:$C, 'Overview tanpa KPI'!C2, 'Nilai Maturitas'!$D:$D) -> 8.3360938 | D12: 0.1 | E12: =D12*C12 -> 0.83360938
A13: 10 | B13: Maturitas Dashboard | C13: =AVERAGEIF('Maturitas Dashboard'!$C:$C, 'Overview tanpa KPI'!C$2, 'Maturitas Dashboard'!$D:$D) -> 7.5039062 | D13: 0.1 | E13: =D13*C13 -> 0.75039063
A14: 11 | B14: Penilaian Resiko | C14: =AVERAGEIF('Penilaian Resiko'!$C:$C, 'Overview tanpa KPI'!C$2, 'Penilaian Resiko'!$D:$D) -> 5.8736156 | D14: 0.1 | E14: =D14*C14 -> 0.58736156
C15: Progress | E15: =SUM(E4:E14) -> 7.3570898
