Workbook

Sheet STR
A1: POSISI | B1: NAMA | C1: CIF | D1: No Rek/ Kartu Kredit | E1: RESIKO | F1: BRILINK | G1: STATUS PEKERJA | H1: DIGITAL SAVING | I1: SKENARIO | J1: SCORING | K1: INFO PARAM | L1: KATEGORI | M1: UNIT KERJA | N1: KANTOR CABANG | O1: KANTOR KANWIL | P1: REKOMENDASI UKER | Q1: REKOMENDASI UKK | R1: STATUS UKER | S1: STATUS | T1: DISPOSISI | U1: INFO LAINNYA | V1: Disposisi RAC | W1: Tanggal | X1: Status TL
A2: 46265 | B2: AMAM SUKRIYANTO | C2: A564673 | D2: 5.326599e+15 | E2: TINGGI | I2: Private or Priority Customer Investment | L2: Pasar Modal | M2: Jkt KCK | N2: Jkt KCK | O2: DKI | V2: Indra Jantana | X2: =[1]STR!$X2 -> FALSE | Y2: Indra Jantana
A3: 46265 | B3: ADHIBALARAJA INTERNATIONAL INDUSTRIAL PA | C3: ADEWK77 | D3: 1801004656309 | E3: 0 | I3: Perpajakan | L3: Perpajakan | M3: KC Jakarta Tanah Abang | N3: KC Jakarta Tanah Abang | O3: DKI | V3: Indra Jantana | X3: =[1]STR!$X3 -> FALSE | Y3: Indra Jantana
A4: 46265 | B4: ASTRA SEDAYA FINANCE | C4: ANM7907 | D4: 1801001127301 | E4: SEDANG | I4: Perpajakan | L4: Perpajakan | M4: KC Jakarta Tanah Abang | N4: KC Jakarta Tanah Abang | O4: DKI | V4: Indra Jantana | X4: =[1]STR!$X4 -> FALSE | Y4: Indra Jantana
A5: 46265 | B5: ADITYA PASHA ZULQA | C5: AWNB686 | D5: 50201000645561 | E5: 0 | I5: Jual Beli Rekening - E channel Trx | L5: Narkotika/Judi Online/Penipuan | M5: KCP Cikini | N5: KC Jakarta Cut Mutiah | O5: DKI | V5: Indra Jantana | X5: =[1]STR!$X5 -> FALSE | Y5: Indra Jantana | Z5: .
A6: 46265 | B6: AWAL BROS BANJAR | C6: AXSY028 | D6: 43401000834305 | E6: SEDANG | I6: Perpajakan | L6: Perpajakan | M6: KC Jakarta Cempaka Mas | N6: KC Jakarta Cempaka Mas | O6: DKI | V6: Indra Jantana | X6: =[1]STR!$X6 -> FALSE | Y6: Indra Jantana
A7: 46265 | B7: PERUM BULOG | C7: B157179 | D7: 20601007093301 | E7: SEDANG | I7: Perpajakan | L7: Perpajakan | M7: KC SUDIRMAN SEMANGGI | N7: KC SUDIRMAN SEMANGGI | O7: DKI | V7: Indra Jantana | X7: =[1]STR!$X7 -> TRUE | Y7: Indra Jantana
A8: 46265 | B8: BINA ARTHA VENTURA | C8: BH83647 | D8: 20601005112303 | E8: SEDANG | I8: Perpajakan | L8: Perpajakan | M8: KC SUDIRMAN SEMANGGI | N8: KC SUDIRMAN SEMANGGI | O8: DKI | V8: Indra Jantana | X8: =[1]STR!$X8 -> FALSE | Y8: Indra Jantana
A9: 46265 | B9: BINTANG CEMERLANG UTAMA | C9: BL68970 | D9: 26101001073301 | E9: SEDANG | I9: Perpajakan | L9: Perpajakan | M9: KC Jakarta Krekot | N9: KC Jakarta Krekot | O9: DKI | V9: Indra Jantana | X9: =[1]STR!$X9 -> FALSE | Y9: Indra Jantana
A10: 46265 | B10: DARWOTO | C10: DBB2983 | D10: 12201109911504 | E10: SEDANG | I10: Narkotika - Area Lapas | L10: Narkotika | M10: KC Jakarta Jatinegara | N10: KC Jakarta Jatinegara | O10: DKI | V10: Indra Jantana | X10: =[1]STR!$X10 -> FALSE | Y10: Indra Jantana
A11: 46265 | B11: ELIN MONICA | C11: EAS1429 | D11: 94301016569507 | E11: 0 | I11: Jual Beli Rekening - E channel Trx | L11: Narkotika/Judi Online/Penipuan | M11: UNIT SEMPER SUKAPURA | N11: KC Jakarta Tanjung Priok | O11: DKI | V11: Indra Jantana | X11: =[1]STR!$X11 -> FALSE | Y11: Indra Jantana
A12: 46265 | B12: FADLAN HERDIANSYAH | C12: FTT7313 | D12: 322101010896509 | E12: 0 | I12: Jual Beli Rekening - E channel Trx | L12: Narkotika/Judi Online/Penipuan | M12: UNIT PONDOK KOPI | N12: KC JAKARTA KALIMALANG | O12: DKI | V12: Indra Jantana | X12: =[1]STR!$X12 -> FALSE | Y12: Indra Jantana
A13: 46265 | B13: FIERIS LIFESTYLES GROUP | C13: FTW9475 | D13: 12201002975568 | E13: 0 | I13: Perpajakan | L13: Perpajakan | M13: KC Jakarta Jatinegara | N13: KC Jakarta Jatinegara | O13: DKI | V13: Indra Jantana | X13: =[1]STR!$X13 -> FALSE | Y13: Indra Jantana
A14: 46265 | B14: GAMETRACO TUNGGAL | C14: GM04878 | D14: 38601333888565 | E14: SEDANG | I14: Perpajakan | L14: Perpajakan | M14: KC JAKARTA RAWAMANGUN | N14: KC JAKARTA RAWAMANGUN | O14: DKI | V14: Indra Jantana | X14: =[1]STR!$X14 -> FALSE | Y14: Indra Jantana
A15: 46265 | B15: GERAKAN EKONOMI DAN BUDAYA MINANG | C15: GQ07290 | D15: 38601121989567 | E15: SEDANG | I15: Perpajakan | L15: Perpajakan | M15: KC JAKARTA RAWAMANGUN | N15: KC JAKARTA RAWAMANGUN | O15: DKI | V15: Indra Jantana | X15: =[1]STR!$X15 -> TRUE | Y15: Indra Jantana
A16: 46265 | B16: HERMANTO SIREGAR | C16: HU22329 | D16: 5.326599e+15 | E16: TINGGI | I16: Private or Priority Customer Investment | L16: Pasar Modal | M16: Jkt KCK | N16: Jkt KCK | O16: DKI | V16: Indra Jantana | X16: =[1]STR!$X16 -> FALSE | Y16: Indra Jantana
A17: 46265 | B17: HARKATJAYA BUMIPERSADA | C17: HYJ5136 | D17: 38601001724566 | E17: TINGGI | I17: Perpajakan | L17: Perpajakan | M17: KC JAKARTA RAWAMANGUN | N17: KC JAKARTA RAWAMANGUN | O17: DKI | V17: Indra Jantana | X17: =[1]STR!$X17 -> FALSE | Y17: Indra Jantana
A18: 46265 | B18: IMAM SAFI'I | C18: ICE8152 | D18: 33801000397563 | E18: TINGGI | I18: Pencurian Rekening | L18: Perbankan | M18: KC JAKARTA ROXI | N18: KC JAKARTA ROXI | O18: DKI | V18: Indra Jantana | X18: =[1]STR!$X18 -> FALSE | Y18: Indra Jantana
A19: 46265 | B19: JESSINDO PRAKARSA | C19: JKU6322 | D19: 44201002095300 | E19: SEDANG | I19: Perpajakan | L19: Perpajakan | M19: KC Jakarta Kramat Jati | N19: KC Jakarta Kramat Jati | O19: DKI | V19: Indra Jantana | X19: =[1]STR!$X19 -> FALSE | Y19: Indra Jantana
A20: 46265 | B20: JIMMY FRANCISCUS SAMANTHA | C20: JO76160 | D20: 35601092515507 | E20: 0 | I20: Jual Beli Rekening - E channel Trx | L20: Narkotika/Judi Online/Penipuan | M20: KC JAKARTA KEMAYORAN | N20: KC JAKARTA KEMAYORAN | O20: DKI | V20: Indra Jantana | X20: =[1]STR!$X20 -> FALSE | Y20: Indra Jantana
A21: 46265 | B21: KUSUMANDARU | C21: KB88688 | D21: 5.32659e+15 | E21: SEDANG | I21: Private or Priority Customer Investment | L21: Pasar Modal | M21: Jkt KCK | N21: Jkt KCK | O21: DKI | V21: Indra Jantana | X21: =[1]STR!$X21 -> FALSE | Y21: Indra Jantana
A22: 46265 | B22: KODIN NASARUDIN | C22: KBGB987 | D22: 33801069135500 | E22: 0 | I22: Jual Beli Rekening - E channel Trx | L22: Narkotika/Judi Online/Penipuan | M22: KC JAKARTA ROXI | N22: KC JAKARTA ROXI | O22: DKI | V22: Indra Jantana | X22: =[1]STR!$X22 -> FALSE | Y22: Indra Jantana
A23: 46265 | B23: KIMIA FARMA APOTEK | C23: KIT7044 | D23: 32901005484308 | E23: SEDANG | I23: Perpajakan | L23: Perpajakan | M23: KC Jakarta Veteran | N23: KC Jakarta Veteran | O23: DKI | V23: Indra Jantana | X23: =[1]STR!$X23 -> TRUE | Y23: Indra Jantana
A24: 46265 | B24: KENCANA JAYA BANGUNAN | C24: KYK5816 | D24: 41901002210307 | E24: SEDANG | I24: Perpajakan | L24: Perpajakan | M24: KC JAKARTA KALIMALANG | N24: KC JAKARTA KALIMALANG | O24: DKI | V24: Indra Jantana | X24: =[1]STR!$X24 -> FALSE | Y24: Indra Jantana
A25: 46265 | B25: KOPEGTEL KANTOR DIVRE III | C25: KZK2192 | D25: 207901000201302 | E25: 0 | I25: Perpajakan | L25: Perpajakan | M25: KCP TASPEN | N25: KC Jakarta Veteran | O25: DKI | V25: Indra Jantana | X25: =[1]STR!$X25 -> TRUE | Y25: Indra Jantana
A26: 46265 | B26: MUHAMMAD FADHEL AZHARI | C26: MEDMW14 | D26: 330601010338503 | E26: 0 | I26: Jual Beli Rekening - E channel Trx | L26: Narkotika/Judi Online/Penipuan | M26: UNIT PONDOK BAMBU | N26: KC JAKARTA KALIMALANG | O26: DKI | V26: Indra Jantana | X26: =[1]STR!$X26 -> FALSE | Y26: Indra Jantana
A27: 46265 | B27: PT NIAGA NUSA ABADI | C27: PCH8695 | D27: 38601000997564 | E27: SEDANG | I27: Perpajakan | L27: Perpajakan | M27: KC JAKARTA RAWAMANGUN | N27: KC JAKARTA RAWAMANGUN | O27: DKI | V27: Indra Jantana | X27: =[1]STR!$X27 -> FALSE | Y27: Indra Jantana
A28: 46265 | B28: PT KHARISMA MAJU ABADI | C28: PGN2660 | D28: 202001000270300 | E28: SEDANG | I28: Perpajakan | L28: Perpajakan | M28: KCP KEMENTRIAN BUMN | N28: KC Jakarta Veteran | O28: DKI | V28: Indra Jantana | X28: =[1]STR!$X28 -> FALSE | Y28: Indra Jantana
A29: 46265 | B29: PT SEKAR SARIDANA | C29: PGN2671 | D29: 202001000271306 | E29: SEDANG | I29: Perpajakan | L29: Perpajakan | M29: KCP KEMENTRIAN BUMN | N29: KC Jakarta Veteran | O29: DKI | V29: Indra Jantana | X29: =[1]STR!$X29 -> FALSE | Y29: Indra Jantana
A30: 46265 | B30: PT GADING ADIPERMAI | C30: PGN2683 | D30: 202001000272302 | E30: SEDANG | I30: Perpajakan | L30: Perpajakan | M30: KCP KEMENTRIAN BUMN | N30: KC Jakarta Veteran | O30: DKI | V30: Indra Jantana | X30: =[1]STR!$X30 -> FALSE | Y30: Indra Jantana
A31: 46265 | B31: PT KARTIKA INSANI RAYA | C31: PGN3129 | D31: 202001000273308 | E31: SEDANG | I31: Perpajakan | L31: Perpajakan | M31: KCP KEMENTRIAN BUMN | N31: KC Jakarta Veteran | O31: DKI | V31: Indra Jantana | X31: =[1]STR!$X31 -> FALSE | Y31: Indra Jantana
A32: 46265 | B32: PT LIA ANUGRAH SEMESTA | C32: PGU0899 | D32: 202001000279304 | E32: SEDANG | I32: Perpajakan | L32: Perpajakan | M32: KCP KEMENTRIAN BUMN | N32: KC Jakarta Veteran | O32: DKI | V32: Indra Jantana | X32: =[1]STR!$X32 -> FALSE | Y32: Indra Jantana
A33: 46265 | B33: PERTAMINA PATRA NIAGA BRI AREA 2 | C33: PHR9328 | D33: 32901004612306 | E33: SEDANG | I33: Perpajakan | L33: Perpajakan | M33: KC Jakarta Veteran | N33: KC Jakarta Veteran | O33: DKI | V33: Indra Jantana | X33: =[1]STR!$X33 -> TRUE | Y33: Indra Jantana
A34: 46265 | B34: PERKUMPULAN PARSIBONA INDONESIA RAYA | C34: PLL4124 | D34: 38601002682301 | E34: SEDANG | I34: Perpajakan | L34: Perpajakan | M34: KC JAKARTA RAWAMANGUN | N34: KC JAKARTA RAWAMANGUN | O34: DKI | V34: Indra Jantana | X34: =[1]STR!$X34 -> TRUE | Y34: Indra Jantana
A35: 46265 | B35: PT RAGAMURTI INTIBOGA ARTO | C35: PMT8115 | D35: 207901000188300 | E35: SEDANG | I35: Perpajakan | L35: Perpajakan | M35: KCP TASPEN | N35: KC Jakarta Veteran | O35: DKI | V35: Indra Jantana | X35: =[1]STR!$X35 -> FALSE | Y35: Indra Jantana
A36: 46265 | B36: PT MNJ MENJAGA INDO | C36: POH1722 | D36: 35601002355303 | E36: 0 | I36: Perpajakan | L36: Perpajakan | M36: KC JAKARTA KEMAYORAN | N36: KC JAKARTA KEMAYORAN | O36: DKI | V36: Indra Jantana | X36: =[1]STR!$X36 -> FALSE | Y36: Indra Jantana
A37: 46265 | B37: PILAR MEDIKA SELARAS | C37: POM7563 | D37: 38601003059307 | E37: 0 | I37: Perpajakan | L37: Perpajakan | M37: KC JAKARTA RAWAMANGUN | N37: KC JAKARTA RAWAMANGUN | O37: DKI | V37: Indra Jantana | X37: =[1]STR!$X37 -> FALSE | Y37: Indra Jantana
A38: 46265 | B38: RIZKI SUBAKTI | C38: RQGX488 | D38: 224801007780504 | E38: 0 | I38: Jual Beli Rekening - E channel Trx | L38: Narkotika/Judi Online/Penipuan | M38: KCP DELTA MAS JAKARTA | N38: KC Jakarta Pluit | O38: DKI | V38: Indra Jantana | X38: =[1]STR!$X38 -> FALSE | Y38: Indra Jantana
A39: 46265 | B39: RIAN SANJAYA | C39: RRV9763 | D39: 35601095224503 | E39: 0 | I39: Jual Beli Rekening - E channel Trx | L39: Narkotika/Judi Online/Penipuan | M39: KC JAKARTA KEMAYORAN | N39: KC JAKARTA KEMAYORAN | O39: DKI | V39: Indra Jantana | X39: =[1]STR!$X39 -> FALSE | Y39: Indra Jantana
A40: 46265 | B40: SALIYAH | C40: SKDVR44 | D40: 321801013109508 | E40: 0 | I40: Jual Beli Rekening - E channel Trx | L40: Narkotika/Judi Online/Penipuan | M40: UNIT PISANGAN LAMA | N40: KC JAKARTA OTISTA | O40: DKI | V40: Indra Jantana | X40: =[1]STR!$X40 -> FALSE | Y40: Indra Jantana
...

Sheet EDD PEP PPATK
D1: 46280
A2: No. | B2: Unit Kerja | C2: PIC RAC | D2: %PEP TL Done | E2: Average
A3: 1 | B3: KC Jakarta Kramat Jati | C3: Indra Jantana | D3: =_xlfn.XLOOKUP(B3, [2]PEP!$B:$B,[2]PEP!$G:$G) -> 0.95721925 | E3: =AVERAGE(D3:D26) -> 0.93104021
A4: 2 | B4: KC Jakarta Artha Gading | C4: Indra Jantana | D4: =_xlfn.XLOOKUP(B4, [2]PEP!$B:$B,[2]PEP!$G:$G) -> 1
A5: 3 | B5: KC Jakarta Cempaka Mas | C5: Indra Jantana | D5: =_xlfn.XLOOKUP(B5, [2]PEP!$B:$B,[2]PEP!$G:$G) -> 0.96428571
A6: 4 | B6: KC Jakarta Cut Mutiah | C6: Indra Jantana | D6: =_xlfn.XLOOKUP(B6, [2]PEP!$B:$B,[2]PEP!$G:$G) -> 0.88059701
A7: 5 | B7: KC Jakarta Gading Boulevard | C7: Indra Jantana | D7: =_xlfn.XLOOKUP(B7, [2]PEP!$B:$B,[2]PEP!$G:$G) -> 0.9
A8: 6 | B8: KC Jakarta Gunung Sahari | C8: Indra Jantana | D8: =_xlfn.XLOOKUP(B8, [2]PEP!$B:$B,[2]PEP!$G:$G) -> 1
A9: 7 | B9: KC Jakarta Jatinegara | C9: Indra Jantana | D9: =_xlfn.XLOOKUP(B9, [2]PEP!$B:$B,[2]PEP!$G:$G) -> 0.93939394
A10: 8 | B10: KC Jakarta Kelapa Gading | C10: Indra Jantana | D10: =_xlfn.XLOOKUP(B10, [2]PEP!$B:$B,[2]PEP!$G:$G) -> 0.8
A11: 9 | B11: KC Jakarta Kramat | C11: Indra Jantana | D11: =_xlfn.XLOOKUP(B11, [2]PEP!$B:$B,[2]PEP!$G:$G) -> 0.96153846
A12: 10 | B12: KC Jakarta Krekot | C12: Indra Jantana | D12: =_xlfn.XLOOKUP(B12, [2]PEP!$B:$B,[2]PEP!$G:$G) -> 0.96551724
A13: 11 | B13: KC Jakarta Mangga Dua | C13: Indra Jantana | D13: =_xlfn.XLOOKUP(B13, [2]PEP!$B:$B,[2]PEP!$G:$G) -> 0.83333333
A14: 12 | B14: KC Jakarta Pluit | C14: Indra Jantana | D14: =_xlfn.XLOOKUP(B14, [2]PEP!$B:$B,[2]PEP!$G:$G) -> 0.80952381
A15: 13 | B15: KC Jakarta Segitiga Senen | C15: Indra Jantana | D15: =_xlfn.XLOOKUP(B15, [2]PEP!$B:$B,[2]PEP!$G:$G) -> 0.8
... A26: 24 | B26: KC Jakarta Pantai Indah Kapuk | C26: Indra Jantana | D26: =_xlfn.XLOOKUP(B26, [2]PEP!$B:$B,[2]PEP!$G:$G) -> 1

Sheet Bad Data
D1: 46280
A2: No. | B2: Unit Kerja | C2: PIC RAC | D2: %Bad Data | E2: Average
A3: 1 | B3: KC Jakarta Kramat Jati | C3: Indra Jantana | D3: =_xlfn.XLOOKUP(B3, '[2]Bad Data'!$B:$B, '[2]Bad Data'!$D:$D) -> 0.00368 | E3: =AVERAGE(D3:D26) -> 0.0022066667
A4: 2 | B4: KC Jakarta Artha Gading | C4: Indra Jantana | D4: =_xlfn.XLOOKUP(B4, '[2]Bad Data'!$B:$B, '[2]Bad Data'!$D:$D) -> 0.00019
A5: 3 | B5: KC Jakarta Cempaka Mas | C5: Indra Jantana | D5: =_xlfn.XLOOKUP(B5, '[2]Bad Data'!$B:$B, '[2]Bad Data'!$D:$D) -> 0.00629
A6: 4 | B6: KC Jakarta Cut Mutiah | C6: Indra Jantana | D6: =_xlfn.XLOOKUP(B6, '[2]Bad Data'!$B:$B, '[2]Bad Data'!$D:$D) -> 0.00055
A7: 5 | B7: KC Jakarta Gading Boulevard | C7: Indra Jantana | D7: =_xlfn.XLOOKUP(B7, '[2]Bad Data'!$B:$B, '[2]Bad Data'!$D:$D) -> 0.00078
A8: 6 | B8: KC Jakarta Gunung Sahari | C8: Indra Jantana | D8: =_xlfn.XLOOKUP(B8, '[2]Bad Data'!$B:$B, '[2]Bad Data'!$D:$D) -> 0.00071
A9: 7 | B9: KC Jakarta Jatinegara | C9: Indra Jantana | D9: =_xlfn.XLOOKUP(B9, '[2]Bad Data'!$B:$B, '[2]Bad Data'!$D:$D) -> 0.00097
A10: 8 | B10: KC Jakarta Kelapa Gading | C10: Indra Jantana | D10: =_xlfn.XLOOKUP(B10, '[2]Bad Data'!$B:$B, '[2]Bad Data'!$D:$D) -> 0.00012
A11: 9 | B11: KC Jakarta Kramat | C11: Indra Jantana | D11: =_xlfn.XLOOKUP(B11, '[2]Bad Data'!$B:$B, '[2]Bad Data'!$D:$D) -> 0.00045
A12: 10 | B12: KC Jakarta Krekot | C12: Indra Jantana | D12: =_xlfn.XLOOKUP(B12, '[2]Bad Data'!$B:$B, '[2]Bad Data'!$D:$D) -> 0.00623
A13: 11 | B13: KC Jakarta Mangga Dua | C13: Indra Jantana | D13: =_xlfn.XLOOKUP(B13, '[2]Bad Data'!$B:$B, '[2]Bad Data'!$D:$D) -> 0.00139
A14: 12 | B14: KC Jakarta Pluit | C14: Indra Jantana | D14: =_xlfn.XLOOKUP(B14, '[2]Bad Data'!$B:$B, '[2]Bad Data'!$D:$D) -> 0.00355
A15: 13 | B15: KC Jakarta Segitiga Senen | C15: Indra Jantana | D15: =_xlfn.XLOOKUP(B15, '[2]Bad Data'!$B:$B, '[2]Bad Data'!$D:$D) -> 0.00039
... A26: 24 | B26: KC Jakarta Pantai Indah Kapuk | C26: Indra Jantana | D26: =_xlfn.XLOOKUP(B26, '[2]Bad Data'!$B:$B, '[2]Bad Data'!$D:$D) -> 0.00038

Sheet Sosialisasi
A1: No. | B1: Unit Kerja | C1: PIC RAC | D1: Materi* | E1: Tanggal Rencana Pelaksanaan | F1: Tanggal Pelaksanaan* | G1: Jumlah Peserta* | H1: Jabatan Peserta* | I1: Dokumen Evidence**
A2: 1 | B2: KC Balige
A3: 2 | B3: KC Binjai
A4: 3 | B4: KC Gunung Sitoli
A5: 4 | B5: KC Kabanjahe
A6: 5 | B6: KC Kisaran
A7: 6 | B7: KC Kota Pinang
A8: 7 | B8: KC Lubuk Pakam
A9: 8 | B9: KC Medan Gatot Subroto
A10: 9 | B10: KC Medan Iskandar Muda
A11: 10 | B11: KC Medan Putri Hijau
A12: 11 | B12: KC Medan Sisingamangaraja
A13: 12 | B13: KC Medan Thamrin
... A25: 24 | B25: KC Tebing Tinggi
B27: Keterangan:
B28: *Diisi jika telah dilaksanakan
B29: **https://bbri.id/MonevaRAC
B31: Evidence terdiri dari:
B32: 1. Dokumentasi Foto
B33: 2. Berita Acara
B34: 3. Absensi
B35: 4. Materi Sosisalisasi
B36: 5. List Pertanyaan

Sheet Pengkinian Data
D1: 46280
A2: No. | B2: Unit Kerja | C2: PIC RAC | D2: %Pengkinian Data | E2: Average
A3: 1 | B3: KC Jakarta Kramat Jati | C3: Indra Jantana | D3: =_xlfn.XLOOKUP(B3,'[2]Pengkinian Data'!$B:$B,'[2]Pengkinian Data'!$E:$E) -> 0.9775 | E3: =AVERAGE(D3:D26) -> 0.9796625
A4: 2 | B4: KC Jakarta Artha Gading | C4: Indra Jantana | D4: =_xlfn.XLOOKUP(B4,'[2]Pengkinian Data'!$B:$B,'[2]Pengkinian Data'!$E:$E) -> 1
A5: 3 | B5: KC Jakarta Cempaka Mas | C5: Indra Jantana | D5: =_xlfn.XLOOKUP(B5,'[2]Pengkinian Data'!$B:$B,'[2]Pengkinian Data'!$E:$E) -> 0.9692
A6: 4 | B6: KC Jakarta Cut Mutiah | C6: Indra Jantana | D6: =_xlfn.XLOOKUP(B6,'[2]Pengkinian Data'!$B:$B,'[2]Pengkinian Data'!$E:$E) -> 0.9678
A7: 5 | B7: KC Jakarta Gading Boulevard | C7: Indra Jantana | D7: =_xlfn.XLOOKUP(B7,'[2]Pengkinian Data'!$B:$B,'[2]Pengkinian Data'!$E:$E) -> 0.9996
A8: 6 | B8: KC Jakarta Gunung Sahari | C8: Indra Jantana | D8: =_xlfn.XLOOKUP(B8,'[2]Pengkinian Data'!$B:$B,'[2]Pengkinian Data'!$E:$E) -> 0.996
A9: 7 | B9: KC Jakarta Jatinegara | C9: Indra Jantana | D9: =_xlfn.XLOOKUP(B9,'[2]Pengkinian Data'!$B:$B,'[2]Pengkinian Data'!$E:$E) -> 0.9971
A10: 8 | B10: KC Jakarta Kelapa Gading | C10: Indra Jantana | D10: =_xlfn.XLOOKUP(B10,'[2]Pengkinian Data'!$B:$B,'[2]Pengkinian Data'!$E:$E) -> 0.9994
A11: 9 | B11: KC Jakarta Kramat | C11: Indra Jantana | D11: =_xlfn.XLOOKUP(B11,'[2]Pengkinian Data'!$B:$B,'[2]Pengkinian Data'!$E:$E) -> 0.9978
A12: 10 | B12: KC Jakarta Krekot | C12: Indra Jantana | D12: =_xlfn.XLOOKUP(B12,'[2]Pengkinian Data'!$B:$B,'[2]Pengkinian Data'!$E:$E) -> 0.8832
A13: 11 | B13: KC Jakarta Mangga Dua | C13: Indra Jantana | D13: =_xlfn.XLOOKUP(B13,'[2]Pengkinian Data'!$B:$B,'[2]Pengkinian Data'!$E:$E) -> 0.9685
A14: 12 | B14: KC Jakarta Pluit | C14: Indra Jantana | D14: =_xlfn.XLOOKUP(B14,'[2]Pengkinian Data'!$B:$B,'[2]Pengkinian Data'!$E:$E) -> 0.9609
A15: 13 | B15: KC Jakarta Segitiga Senen | C15: Indra Jantana | D15: =_xlfn.XLOOKUP(B15,'[2]Pengkinian Data'!$B:$B,'[2]Pengkinian Data'!$E:$E) -> 0.9917
... A26: 24 | B26: KC Jakarta Pantai Indah Kapuk | C26: Indra Jantana | D26: =_xlfn.XLOOKUP(B26,'[2]Pengkinian Data'!$B:$B,'[2]Pengkinian Data'!$E:$E) -> 0.9994

Sheet Uji Petik
A1: No. | B1: Unit Kerja | C1: PIC RAC | D1: Rencana Pelaksanaan | E1: Tanggal Pelaksanaan* | F1: Dokumen Evidence**
C3: Indra Jantana
C4: Indra Jantana
C5: Indra Jantana
C6: Indra Jantana
C7: Indra Jantana
C8: Indra Jantana
C9: Indra Jantana
C10: Indra Jantana
C11: Indra Jantana
C12: Indra Jantana
C13: Indra Jantana
C14: Indra Jantana
... C26: Indra Jantana
B29: Keterangan:
B30: *Diisi jika telah dilaksanakan
B31: **https://bri2-my.sharepoint.com/:f:/g/personal/00136153_hq_bri_co_id/IgAVXSWEmAfbQ5mg2nHxWg2ZATDMLT5GguXvHObWaU1FcJY?e=tDVEZG
B34: Evidence terdiri dari:
B35: 1. Dokumentasi Foto
B36: 2. Berita Acara
B37: 3. Absensi
B38: 4.Kertas Kerja
B39: 5. Laporan Uji Petik

Sheet Nilai Maturitas
A1: No. | B1: Unit Kerja | C1: PIC RAC | D1: Nilai maturitas | E1: Nilai maturitas | F1: Rating maturitas
A2: 2 | B2: KC Jakarta Artha Gading | C2: Indra Jantana | D2: 8.29 | E2: =AVERAGE(D2:D25) -> 7.9724167 | F2: B
A3: 3 | B3: KC Jakarta Cempaka Mas | C3: Indra Jantana | D3: 9.347
A4: 4 | B4: KC Jakarta Cut Mutiah | C4: Indra Jantana | D4: 8.865
A5: 5 | B5: KC Jakarta Gading Boulevard | C5: Indra Jantana | D5: 6.089
A6: 6 | B6: KC Jakarta Gunung Sahari | C6: Indra Jantana | D6: 8.44
A7: 7 | B7: KC Jakarta Jatinegara | C7: Indra Jantana | D7: 8.128
A8: 19 | B8: KC Jakarta Kalimalang | C8: Indra Jantana | D8: 5.821
A9: 8 | B9: KC Jakarta Kelapa Gading | C9: Indra Jantana | D9: 8.875
A10: 23 | B10: KC Jakarta Kemayoran | C10: Indra Jantana | D10: 6.225
A11: 9 | B11: KC Jakarta Kramat | C11: Indra Jantana | D11: 8.213
A12: 1 | B12: KC Jakarta Kramat Jati | C12: Indra Jantana | D12: 8.776
A13: 10 | B13: KC Jakarta Krekot | C13: Indra Jantana | D13: 4.537
A14: 11 | B14: KC Jakarta Mangga Dua | C14: Indra Jantana | D14: 7.426
... A25: 16 | B25: KC Sunter | C25: Indra Jantana | D25: 8.133

Sheet Penilaian Resiko
A1: No. | B1: Unit Kerja | C1: PIC RAC | D1: Nilai Risiko | E1: Nilai Risiko PIC | F1: Rating Risiko PIC
A2: 2 | B2: KC Jakarta Artha Gading | C2: Indra Jantana | D2: 6.325 | E2: =AVERAGE(D2:D25) -> 6.1267917 | F2: Medium to High
A3: 3 | B3: KC Jakarta Cempaka Mas | C3: Indra Jantana | D3: 6.205
A4: 4 | B4: KC Jakarta Cut Mutiah | C4: Indra Jantana | D4: 5.477
A5: 5 | B5: KC Jakarta Gading Boulevard | C5: Indra Jantana | D5: 6.745
A6: 6 | B6: KC Jakarta Gunung Sahari | C6: Indra Jantana | D6: 4.975
A7: 7 | B7: KC Jakarta Jatinegara | C7: Indra Jantana | D7: 5.477
A8: 19 | B8: KC Jakarta Kalimalang | C8: Indra Jantana | D8: 5.745
A9: 8 | B9: KC Jakarta Kelapa Gading | C9: Indra Jantana | D9: 6.982
A10: 23 | B10: KC Jakarta Kemayoran | C10: Indra Jantana | D10: 5.701
A11: 9 | B11: KC Jakarta Kramat | C11: Indra Jantana | D11: 5.745
A12: 1 | B12: KC Jakarta Kramat Jati | C12: Indra Jantana | D12: 5.745
A13: 10 | B13: KC Jakarta Krekot | C13: Indra Jantana | D13: 6.481
A14: 11 | B14: KC Jakarta Mangga Dua | C14: Indra Jantana | D14: 7
... A25: 16 | B25: KC Sunter | C25: Indra Jantana | D25: 5.477

Sheet Maturitas Dashboard
A1: No. | B1: Unit Kerja | C1: PIC RAC | D1: Nilai Maturitas | E1: Nilai Maturitas PIC | F1: Rating Maturitas PIC
A2: 2 | B2: KC Jakarta Artha Gading | C2: Indra Jantana | D2: 7.375 | E2: =AVERAGE(D2:D25) -> 7.1458333 | F2: Baik
A3: 3 | B3: KC Jakarta Cempaka Mas | C3: Indra Jantana | D3: 7.375
A4: 4 | B4: KC Jakarta Cut Mutiah | C4: Indra Jantana | D4: 6.875
A5: 5 | B5: KC Jakarta Gading Boulevard | C5: Indra Jantana | D5: 7.375
A6: 6 | B6: KC Jakarta Gunung Sahari | C6: Indra Jantana | D6: 7.375
A7: 7 | B7: KC Jakarta Jatinegara | C7: Indra Jantana | D7: 6.875
A8: 19 | B8: KC Jakarta Kalimalang | C8: Indra Jantana | D8: 6.875
A9: 8 | B9: KC Jakarta Kelapa Gading | C9: Indra Jantana | D9: 7.375
A10: 23 | B10: KC Jakarta Kemayoran | C10: Indra Jantana | D10: 7.375
A11: 9 | B11: KC Jakarta Kramat | C11: Indra Jantana | D11: 7.375
A12: 1 | B12: KC Jakarta Kramat Jati | C12: Indra Jantana | D12: 6.875
A13: 10 | B13: KC Jakarta Krekot | C13: Indra Jantana | D13: 7.375
A14: 11 | B14: KC Jakarta Mangga Dua | C14: Indra Jantana | D14: 6.875
... A25: 16 | B25: KC Sunter | C25: Indra Jantana | D25: 7.375

Sheet Overview
A2: No | B2: Aspek Penilaian | C2: Indra Jantana
C3: Nilai | D3: Bobotan | E3: Score
A4: 1 | B4: STR | C4: =IFERROR(COUNTIFS(STR!$V:$V, Overview!C$2, STR!$X:$X, "TRUE")/COUNTIFS(STR!$V:$V, Overview!C2), 0) -> 0.13253012 | D4: 0.15 | E4: =D4*C4 -> 0.019879518
A5: 2 | B5: Bad Data | C5: =1-AVERAGEIF('Bad Data'!$C:$C, Overview!C$2, 'Bad Data'!$D:$D) -> 0.99779333 | D5: 0.1 | E5: =D5*C5 -> 0.099779333
A6: 3 | B6: Pengkinian Data | C6: =AVERAGEIF('Pengkinian Data'!$C:$C, Overview!C$2, 'Pengkinian Data'!$D:$D) -> 0.9796625 | D6: 0.1 | E6: =D6*C6 -> 0.09796625 | L6: .
A7: 4 | B7: Uji Petik | C7: {=IFERROR(SUMPRODUCT(--('[1]Uji Petik'!$E$3:$E$73<>""), --('[1]Uji Petik'!$C$3:$C$73=C2)) / SUMPRODUCT(--('[1]Uji Petik'!$C$3:$C$73=C2)), 0)} -> 0 | D7: 0 | E7: =D7*C7 -> 0
A8: 5 | B8: Sosialisasi | C8: {=IFERROR(AVERAGE(IF([2]Sosialisasi!$C$1:$C$10000=C2, [2]Sosialisasi!$D$1:$D$10000)), 0)} -> 0.041666667 | D8: 0.15 | E8: =D8*C8 -> 0.00625
A9: 6 | B9: EDD | C9: =AVERAGEIF('EDD PEP PPATK'!$C:$C, Overview!C$2, 'EDD PEP PPATK'!$D:$D) -> 0.93104021 | D9: 0.1 | E9: =D9*C9 -> 0.093104021
A10: 7 | B10: Self Learning Keikutsertaan | C10: {=IF(IFERROR(AVERAGE(IF('[2]Sheet2 (2)'!$C$1:$C$10000=C$2, '[2]Sheet2 (2)'!$D$1:$D$10000)), 0)>0.9, 1, IFERROR(AVERAGE(IF('[2]Sheet2 (2)'!$C$1:$C$10000=C$2, '[2]Sheet2 (2)'!$D$1:$D$10000)), 0))} -> 1 | D10: 0.05 | E10: =D10*C10 -> 0.05
A11: 8 | B11: Self Learning Score | C11: {=IF(IFERROR(AVERAGE(IF('[2]Sheet2 (3)'!$C$1:$C$10000=C2, '[2]Sheet2 (3)'!$D$1:$D$10000)), 0)>90, 1, IFERROR(AVERAGE(IF('[2]Sheet2 (3)'!$C$1:$C$10000=C2, '[2]Sheet2 (3)'!$D$1:$D$10000)), 0)/90)} -> 1 | D11: 0.05 | E11: =D11*C11 -> 0.05
A12: 9 | B12: Maturitas | C12: =IF(AVERAGEIF('Nilai Maturitas'!$C:$C, Overview!C2, 'Nilai Maturitas'!$D:$D) > 8, 110%, AVERAGEIF('Nilai Maturitas'!$C:$C, Overview!C2, 'Nilai Maturitas'!$D:$D)/8*100%) -> 0.99655208 | D12: 0.1 | E12: =D12*C12 -> 0.099655208
A13: 10 | B13: Maturitas Dashboard | C13: =IF(AVERAGEIF('Maturitas Dashboard'!$C:$C, Overview!C$2, 'Maturitas Dashboard'!$D:$D) > 8, 110%, AVERAGEIF('Maturitas Dashboard'!$C:$C, Overview!C$2, 'Maturitas Dashboard'!$D:$D)/8*100%) -> 0.89322917 | D13: 0.1 | E13: =D13*C13 -> 0.089322917
A14: 11 | B14: Penilaian Resiko | C14: =IF(AVERAGEIF('Penilaian Resiko'!$C:$C, Overview!C$2, 'Penilaian Resiko'!$D:$D) < 5.8, 110%, IF(AVERAGEIF('Penilaian Resiko'!$C:$C, Overview!C$2, 'Penilaian Resiko'!$D:$D) <7.4, 3/4*100%, 3/5*100%)) -> 0.75 | D14: 0.1 | E14: =D14*C14 -> 0.075
C15: Progress | E15: =SUM(E4:E14) -> 0.68095725

Sheet Overview tanpa KPI
A2: No | B2: Aspek Penilaian | C2: Indra Jantana
C3: Nilai | D3: Bobotan | E3: Score
A4: 1 | B4: STR | C4: =IFERROR(COUNTIFS(STR!$V:$V, 'Overview tanpa KPI'!C$2, STR!$X:$X, "TRUE")/COUNTIFS(STR!$V:$V, 'Overview tanpa KPI'!C2), 0) -> 0.13253012 | D4: 0.15 | E4: =D4*C4 -> 0.019879518
A5: 2 | B5: Bad Data | C5: =1-AVERAGEIF('Bad Data'!$C:$C, 'Overview tanpa KPI'!C$2, 'Bad Data'!$D:$D) -> 0.99779333 | D5: 0.1 | E5: =D5*C5 -> 0.099779333
A6: 3 | B6: Pengkinian Data | C6: =AVERAGEIF('Pengkinian Data'!$C:$C, 'Overview tanpa KPI'!C$2, 'Pengkinian Data'!$D:$D) -> 0.9796625 | D6: 0.1 | E6: =D6*C6 -> 0.09796625 | I6: .
A7: 4 | B7: Uji Petik | C7: {=IFERROR(SUMPRODUCT(--('[1]Uji Petik'!$E$3:$E$73<>""), --('[1]Uji Petik'!$C$3:$C$73=C2)) / SUMPRODUCT(--('[1]Uji Petik'!$C$3:$C$73=C2)), 0)} -> 0 | D7: 0 | E7: =D7*C7 -> 0
A8: 5 | B8: Sosialisasi | C8: {=IFERROR(AVERAGE(IF([2]Sosialisasi!$C$1:$C$10000=C2, [2]Sosialisasi!$D$1:$D$10000)), 0)} -> 0.041666667 | D8: 0.15 | E8: =D8*C8 -> 0.00625
A9: 6 | B9: EDD | C9: =AVERAGEIF('EDD PEP PPATK'!$C:$C, 'Overview tanpa KPI'!C$2, 'EDD PEP PPATK'!$D:$D) -> 0.93104021 | D9: 0.1 | E9: =D9*C9 -> 0.093104021
A10: 7 | B10: Self Learning Keikutsertaan | C10: {=IFERROR(AVERAGE(IF('[2]Sheet2 (2)'!$C$1:$C$10000=C$2, '[2]Sheet2 (2)'!$D$1:$D$10000)), 0)} -> 0.97051355 | D10: 0.05 | E10: =D10*C10 -> 0.048525677
A11: 8 | B11: Self Learning Score | C11: {=IFERROR(AVERAGE(IF('[2]Sheet2 (3)'!$C$1:$C$10000=C2, '[2]Sheet2 (3)'!$D$1:$D$10000)), 0)} -> 96.409038 | D11: 0.05 | E11: =D11*C11 -> 4.8204519
A12: 9 | B12: Maturitas | C12: =AVERAGEIF('Nilai Maturitas'!$C:$C, 'Overview tanpa KPI'!C2, 'Nilai Maturitas'!$D:$D) -> 7.9724167 | D12: 0.1 | E12: =D12*C12 -> 0.79724167
A13: 10 | B13: Maturitas Dashboard | C13: =AVERAGEIF('Maturitas Dashboard'!$C:$C, 'Overview tanpa KPI'!C$2, 'Maturitas Dashboard'!$D:$D) -> 7.1458333 | D13: 0.1 | E13: =D13*C13 -> 0.71458333
A14: 11 | B14: Penilaian Resiko | C14: =AVERAGEIF('Penilaian Resiko'!$C:$C, 'Overview tanpa KPI'!C$2, 'Penilaian Resiko'!$D:$D) -> 6.1267917 | D14: 0.1 | E14: =D14*C14 -> 0.61267917
C15: Progress | E15: =SUM(E4:E14) -> 7.3104609
